{1} setUpClass (tempest.api.volume.admin.test_multi_backend.VolumeMultiBackendTest) ... SKIPPED: Cinder multi-backend feature disabled
{3} setUpClass (tempest.api.volume.admin.test_encrypted_volumes_extend.EncryptedVolumesExtendAttachedTest) ... SKIPPED: Attached encrypted volume extend is disabled.
{0} setUpClass (tempest.api.volume.test_volumes_backup.VolumesBackupsV39Test) ... SKIPPED: Cinder backup feature disabled
{5} setUpClass (tempest.api.volume.admin.test_volume_retype.VolumeRetypeWithMigrationTest) ... SKIPPED: Cinder multi-backend feature disabled
{35} tempest.api.volume.test_versions.VersionsTest.test_list_versions [0.029903s] ... ok
{35} tempest.api.volume.test_versions.VersionsTest.test_show_version [6.238097s] ... ok
{26} tempest.api.volume.test_volumes_snapshots_negative.VolumesSnapshotNegativeTestJSON.test_create_snapshot_with_nonexistent_volume_id [7.136513s] ... ok
{36} tempest.api.volume.test_extensions.ExtensionsTestJSON.test_list_extensions [5.006607s] ... ok
{38} tempest.api.volume.test_availability_zone.AvailabilityZoneTestJSON.test_get_availability_zone_list [3.616697s] ... ok
{37} tempest.api.volume.test_volumes_get.VolumesSummaryTest.test_show_volume_summary [4.712521s] ... ok
{26} tempest.api.volume.test_volumes_snapshots_negative.VolumesSnapshotNegativeTestJSON.test_create_snapshot_without_passing_volume_id [0.840616s] ... ok
{26} tempest.api.volume.test_volumes_snapshots_negative.VolumesSnapshotNegativeTestJSON.test_list_snapshot_invalid_param_limit [0.010094s] ... ok
{26} tempest.api.volume.test_volumes_snapshots_negative.VolumesSnapshotNegativeTestJSON.test_list_snapshots_invalid_param_marker [0.084845s] ... ok
{26} tempest.api.volume.test_volumes_snapshots_negative.VolumesSnapshotNegativeTestJSON.test_list_snapshots_invalid_param_sort [0.011695s] ... ok
{24} tempest.api.volume.admin.test_volume_services_negative.VolumeServicesNegativeTest.test_disable_log_reason_with_no_reason [3.552111s] ... ok
{13} tempest.api.volume.admin.test_volume_services.VolumesServicesTestJSON.test_get_service_by_host_name [3.920936s] ... ok
{21} tempest.api.volume.admin.test_volume_hosts.VolumeHostsAdminTestsJSON.test_list_hosts [5.202436s] ... ok
{24} tempest.api.volume.admin.test_volume_services_negative.VolumeServicesNegativeTest.test_disable_service_with_invalid_binary [3.554050s] ... ok
{13} tempest.api.volume.admin.test_volume_services.VolumesServicesTestJSON.test_get_service_by_service_and_host_name [4.993029s] ... ok
{14} tempest.api.volume.admin.test_volume_quota_classes.VolumeQuotaClassesTest.test_show_default_quota [6.161103s] ... ok
{29} tempest.api.volume.admin.test_volume_pools.VolumePoolsAdminTestsJSON.test_get_pools_with_details [6.168841s] ... ok
{25} tempest.api.volume.admin.test_backends_capabilities.BackendsCapabilitiesAdminTestsJSON.test_compare_volume_stats_values [8.945015s] ... ok
{24} tempest.api.volume.admin.test_volume_services_negative.VolumeServicesNegativeTest.test_enable_service_with_invalid_host [3.071824s] ... ok
{20} tempest.api.volume.admin.test_volume_types_extra_specs_negative.ExtraSpecsNegativeTest.test_create_invalid_body [2.599453s] ... ok
{17} tempest.api.volume.admin.test_volume_types_negative.VolumeTypesNegativeTest.test_create_volume_type_encryption_nonexistent_type_id [8.414515s] ... ok
{13} tempest.api.volume.admin.test_volume_services.VolumesServicesTestJSON.test_get_service_by_service_binary_name [2.898708s] ... ok
{29} tempest.api.volume.admin.test_volume_pools.VolumePoolsAdminTestsJSON.test_get_pools_without_details [3.126386s] ... ok
{25} tempest.api.volume.admin.test_backends_capabilities.BackendsCapabilitiesAdminTestsJSON.test_get_capabilities_backend [3.336767s] ... ok
{24} tempest.api.volume.admin.test_volume_services_negative.VolumeServicesNegativeTest.test_freeze_host_with_invalid_host [7.948903s] ... ok
{20} tempest.api.volume.admin.test_volume_types_extra_specs_negative.ExtraSpecsNegativeTest.test_create_none_body [7.949452s] ... ok
{4} tempest.api.volume.admin.test_volume_types.VolumeTypesTest.test_volume_type_create_get_delete [38.251817s] ... ok
{24} tempest.api.volume.admin.test_volume_services_negative.VolumeServicesNegativeTest.test_thaw_host_with_invalid_host [13.373055s] ... ok
{20} tempest.api.volume.admin.test_volume_types_extra_specs_negative.ExtraSpecsNegativeTest.test_create_nonexistent_type_id [17.396038s] ... ok
{21} tempest.api.volume.admin.test_volume_hosts.VolumeHostsAdminTestsJSON.test_show_host [32.553572s] ... ok
{20} tempest.api.volume.admin.test_volume_types_extra_specs_negative.ExtraSpecsNegativeTest.test_delete_nonexistent_volume_type_id [4.133906s] ... ok
{20} tempest.api.volume.admin.test_volume_types_extra_specs_negative.ExtraSpecsNegativeTest.test_get_nonexistent_extra_spec_name [1.537174s] ... ok
{20} tempest.api.volume.admin.test_volume_types_extra_specs_negative.ExtraSpecsNegativeTest.test_get_nonexistent_volume_type_id [0.093267s] ... ok
{20} tempest.api.volume.admin.test_volume_types_extra_specs_negative.ExtraSpecsNegativeTest.test_list_nonexistent_volume_type_id [0.014943s] ... ok
{19} tempest.api.volume.admin.test_volume_types_extra_specs.VolumeTypesExtraSpecsTest.test_volume_type_extra_spec_create_get_delete [32.984143s] ... ok
{20} tempest.api.volume.admin.test_volume_types_extra_specs_negative.ExtraSpecsNegativeTest.test_update_multiple_extra_spec [0.015214s] ... ok
{20} tempest.api.volume.admin.test_volume_types_extra_specs_negative.ExtraSpecsNegativeTest.test_update_no_body [2.704929s] ... ok
{20} tempest.api.volume.admin.test_volume_types_extra_specs_negative.ExtraSpecsNegativeTest.test_update_none_extra_spec_id [3.056774s] ... ok
{19} tempest.api.volume.admin.test_volume_types_extra_specs.VolumeTypesExtraSpecsTest.test_volume_type_extra_specs_list [5.884789s] ... ok
{20} tempest.api.volume.admin.test_volume_types_extra_specs_negative.ExtraSpecsNegativeTest.test_update_nonexistent_extra_spec_id [1.246064s] ... ok
{17} tempest.api.volume.admin.test_volume_types_negative.VolumeTypesNegativeTest.test_create_volume_with_private_volume_type [39.335611s] ... ok
{20} tempest.api.volume.admin.test_volume_types_extra_specs_negative.ExtraSpecsNegativeTest.test_update_nonexistent_type_id [3.944059s] ... ok
{17} tempest.api.volume.admin.test_volume_types_negative.VolumeTypesNegativeTest.test_create_with_empty_name [1.469840s] ... ok
{27} tempest.api.volume.test_volume_metadata.VolumesMetadataTest.test_crud_volume_metadata [28.656514s] ... ok
{17} tempest.api.volume.admin.test_volume_types_negative.VolumeTypesNegativeTest.test_create_with_repeated_name [20.643201s] ... ok
{19} tempest.api.volume.admin.test_volume_types_extra_specs.VolumeTypesExtraSpecsTest.test_volume_type_extra_specs_update [26.267579s] ... ok
{17} tempest.api.volume.admin.test_volume_types_negative.VolumeTypesNegativeTest.test_delete_nonexistent_type_id [4.582248s] ... ok
{33} tempest.api.volume.test_volume_absolute_limits.AbsoluteLimitsTests.test_get_volume_absolute_limits [5.562924s] ... ok
{15} setUpClass (tempest.api.volume.admin.test_volumes_actions.VolumesActionsTest) [0.000000s] ... FAILED

Captured traceback:
~~~~~~~~~~~~~~~~~~~
    Traceback (most recent call last):

      File "/home/stguser/devstack/python-tempestconf/.venv/lib/python3.12/site-packages/urllib3/connectionpool.py", line 534, in _make_request
    response = conn.getresponse()
               ^^^^^^^^^^^^^^^^^^

      File "/home/stguser/devstack/python-tempestconf/.venv/lib/python3.12/site-packages/urllib3/connection.py", line 565, in getresponse
    httplib_response = super().getresponse()
                       ^^^^^^^^^^^^^^^^^^^^^

      File "/usr/lib/python3.12/http/client.py", line 1428, in getresponse
    response.begin()

      File "/usr/lib/python3.12/http/client.py", line 331, in begin
    version, status, reason = self._read_status()
                              ^^^^^^^^^^^^^^^^^^^

      File "/usr/lib/python3.12/http/client.py", line 292, in _read_status
    line = str(self.fp.readline(_MAXLINE + 1), "iso-8859-1")
               ^^^^^^^^^^^^^^^^^^^^^^^^^^^^^^

      File "/usr/lib/python3.12/socket.py", line 707, in readinto
    return self._sock.recv_into(b)
           ^^^^^^^^^^^^^^^^^^^^^^^

    TimeoutError: timed out

    
The above exception was the direct cause of the following exception:


    Traceback (most recent call last):

      File "/home/stguser/devstack/python-tempestconf/.venv/lib/python3.12/site-packages/tempest/test.py", line 185, in setUpClass
    raise value.with_traceback(trace)

      File "/home/stguser/devstack/python-tempestconf/.venv/lib/python3.12/site-packages/tempest/test.py", line 170, in setUpClass
    cls.setup_credentials()

      File "/home/stguser/devstack/python-tempestconf/.venv/lib/python3.12/site-packages/tempest/api/volume/base.py", line 62, in setup_credentials
    super(BaseVolumeTest, cls).setup_credentials()

      File "/home/stguser/devstack/python-tempestconf/.venv/lib/python3.12/site-packages/tempest/test.py", line 398, in setup_credentials
    manager = cls.get_client_manager(
              ^^^^^^^^^^^^^^^^^^^^^^^

      File "/home/stguser/devstack/python-tempestconf/.venv/lib/python3.12/site-packages/tempest/test.py", line 743, in get_client_manager
    creds = getattr(cred_provider, credentials_method)()
            ^^^^^^^^^^^^^^^^^^^^^^^^^^^^^^^^^^^^^^^^^^^^

      File "/home/stguser/devstack/python-tempestconf/.venv/lib/python3.12/site-packages/tempest/lib/common/dynamic_creds.py", line 473, in get_primary_creds
    return self.get_project_member_creds()
           ^^^^^^^^^^^^^^^^^^^^^^^^^^^^^^^

      File "/home/stguser/devstack/python-tempestconf/.venv/lib/python3.12/site-packages/tempest/lib/common/dynamic_creds.py", line 514, in get_project_member_creds
    return self.get_credentials(['member'], scope='project')
           ^^^^^^^^^^^^^^^^^^^^^^^^^^^^^^^^^^^^^^^^^^^^^^^^^

      File "/home/stguser/devstack/python-tempestconf/.venv/lib/python3.12/site-packages/tempest/lib/common/dynamic_creds.py", line 459, in get_credentials
    network, subnet, router = self._create_network_resources(
                              ^^^^^^^^^^^^^^^^^^^^^^^^^^^^^^^

      File "/home/stguser/devstack/python-tempestconf/.venv/lib/python3.12/site-packages/tempest/lib/common/dynamic_creds.py", line 310, in _create_network_resources
    network = self._create_network(network_name, tenant_id)
              ^^^^^^^^^^^^^^^^^^^^^^^^^^^^^^^^^^^^^^^^^^^^^

      File "/home/stguser/devstack/python-tempestconf/.venv/lib/python3.12/site-packages/tempest/lib/common/dynamic_creds.py", line 338, in _create_network
    resp_body = self.networks_admin_client.create_network(
                ^^^^^^^^^^^^^^^^^^^^^^^^^^^^^^^^^^^^^^^^^^

      File "/home/stguser/devstack/python-tempestconf/.venv/lib/python3.12/site-packages/tempest/lib/services/network/networks_client.py", line 27, in create_network
    return self.create_resource(uri, post_data)
           ^^^^^^^^^^^^^^^^^^^^^^^^^^^^^^^^^^^^

      File "/home/stguser/devstack/python-tempestconf/.venv/lib/python3.12/site-packages/tempest/lib/services/network/base.py", line 62, in create_resource
    resp, body = self.post(req_uri, req_post_data)
                 ^^^^^^^^^^^^^^^^^^^^^^^^^^^^^^^^^

      File "/home/stguser/devstack/python-tempestconf/.venv/lib/python3.12/site-packages/tempest/lib/common/rest_client.py", line 314, in post
    resp_header, resp_body = self.request(
                             ^^^^^^^^^^^^^

      File "/home/stguser/devstack/python-tempestconf/.venv/lib/python3.12/site-packages/tempest/lib/common/rest_client.py", line 746, in request
    resp, resp_body = self._request(method, url, headers=headers,
                      ^^^^^^^^^^^^^^^^^^^^^^^^^^^^^^^^^^^^^^^^^^^

      File "/home/stguser/devstack/python-tempestconf/.venv/lib/python3.12/site-packages/tempest/lib/common/rest_client.py", line 612, in _request
    resp, resp_body = self.raw_request(
                      ^^^^^^^^^^^^^^^^^

      File "/home/stguser/devstack/python-tempestconf/.venv/lib/python3.12/site-packages/tempest/lib/common/rest_client.py", line 661, in raw_request
    resp, resp_body = self.http_obj.request(
                      ^^^^^^^^^^^^^^^^^^^^^^

      File "/home/stguser/devstack/python-tempestconf/.venv/lib/python3.12/site-packages/tempest/lib/common/http.py", line 123, in request
    r = super(ClosingHttp, self).request(method, url, retries=retry,
        ^^^^^^^^^^^^^^^^^^^^^^^^^^^^^^^^^^^^^^^^^^^^^^^^^^^^^^^^^^^^

      File "/home/stguser/devstack/python-tempestconf/.venv/lib/python3.12/site-packages/urllib3/_request_methods.py", line 143, in request
    return self.request_encode_body(
           ^^^^^^^^^^^^^^^^^^^^^^^^^

      File "/home/stguser/devstack/python-tempestconf/.venv/lib/python3.12/site-packages/urllib3/_request_methods.py", line 278, in request_encode_body
    return self.urlopen(method, url, **extra_kw)
           ^^^^^^^^^^^^^^^^^^^^^^^^^^^^^^^^^^^^^

      File "/home/stguser/devstack/python-tempestconf/.venv/lib/python3.12/site-packages/urllib3/poolmanager.py", line 459, in urlopen
    response = conn.urlopen(method, u.request_uri, **kw)
               ^^^^^^^^^^^^^^^^^^^^^^^^^^^^^^^^^^^^^^^^^

      File "/home/stguser/devstack/python-tempestconf/.venv/lib/python3.12/site-packages/urllib3/connectionpool.py", line 841, in urlopen
    retries = retries.increment(
              ^^^^^^^^^^^^^^^^^^

      File "/home/stguser/devstack/python-tempestconf/.venv/lib/python3.12/site-packages/urllib3/util/retry.py", line 474, in increment
    raise reraise(type(error), error, _stacktrace)
          ^^^^^^^^^^^^^^^^^^^^^^^^^^^^^^^^^^^^^^^^

      File "/home/stguser/devstack/python-tempestconf/.venv/lib/python3.12/site-packages/urllib3/util/util.py", line 39, in reraise
    raise value

      File "/home/stguser/devstack/python-tempestconf/.venv/lib/python3.12/site-packages/urllib3/connectionpool.py", line 787, in urlopen
    response = self._make_request(
               ^^^^^^^^^^^^^^^^^^^

      File "/home/stguser/devstack/python-tempestconf/.venv/lib/python3.12/site-packages/urllib3/connectionpool.py", line 536, in _make_request
    self._raise_timeout(err=e, url=url, timeout_value=read_timeout)

      File "/home/stguser/devstack/python-tempestconf/.venv/lib/python3.12/site-packages/urllib3/connectionpool.py", line 367, in _raise_timeout
    raise ReadTimeoutError(

    urllib3.exceptions.ReadTimeoutError: HTTPConnectionPool(host='9.180.170.14', port=9696): Read timed out. (read timeout=60)

{17} tempest.api.volume.admin.test_volume_types_negative.VolumeTypesNegativeTest.test_get_nonexistent_type_id [1.702878s] ... ok
{4} tempest.api.volume.admin.test_volume_types.VolumeTypesTest.test_volume_type_encryption_create_get_update_delete [48.506521s] ... ok
{4} tempest.api.volume.admin.test_volume_types.VolumeTypesTest.test_volume_type_list [3.473071s] ... ok
{31} tempest.api.volume.admin.test_volume_quotas_negative.VolumeQuotasNegativeTestJSON.test_quota_volume_gigabytes [11.664757s] ... ok
{27} tempest.api.volume.test_volume_metadata.VolumesMetadataTest.test_update_show_volume_metadata_item [21.986410s] ... ok
{9} tempest.api.volume.admin.test_user_messages.UserMessagesTest.test_delete_message [99.310420s] ... ok
{11} tempest.api.volume.test_volumes_clone_negative.VolumesCloneNegativeTest.test_create_from_volume_decreasing_size [114.860472s] ... ok
{31} tempest.api.volume.admin.test_volume_quotas_negative.VolumeQuotasNegativeTestJSON.test_quota_volumes [3.786299s] ... ok
{14} tempest.api.volume.admin.test_volume_quota_classes.VolumeQuotaClassesTest.test_update_default_quota [88.117219s] ... ok
{12} tempest.api.volume.admin.test_qos.QosSpecsTestJSON.test_associate_disassociate_qos [59.442684s] ... ok
{30} tempest.api.volume.test_snapshot_metadata.SnapshotMetadataTestJSON.test_crud_snapshot_metadata [7.142043s] ... ok
{23} setUpClass (tempest.api.volume.test_volumes_actions.VolumesActionsTest) [0.000000s] ... FAILED

Captured traceback:
~~~~~~~~~~~~~~~~~~~
    Traceback (most recent call last):

      File "/home/stguser/devstack/python-tempestconf/.venv/lib/python3.12/site-packages/urllib3/connectionpool.py", line 534, in _make_request
    response = conn.getresponse()
               ^^^^^^^^^^^^^^^^^^

      File "/home/stguser/devstack/python-tempestconf/.venv/lib/python3.12/site-packages/urllib3/connection.py", line 565, in getresponse
    httplib_response = super().getresponse()
                       ^^^^^^^^^^^^^^^^^^^^^

      File "/usr/lib/python3.12/http/client.py", line 1428, in getresponse
    response.begin()

      File "/usr/lib/python3.12/http/client.py", line 331, in begin
    version, status, reason = self._read_status()
                              ^^^^^^^^^^^^^^^^^^^

      File "/usr/lib/python3.12/http/client.py", line 292, in _read_status
    line = str(self.fp.readline(_MAXLINE + 1), "iso-8859-1")
               ^^^^^^^^^^^^^^^^^^^^^^^^^^^^^^

      File "/usr/lib/python3.12/socket.py", line 707, in readinto
    return self._sock.recv_into(b)
           ^^^^^^^^^^^^^^^^^^^^^^^

    TimeoutError: timed out

    
The above exception was the direct cause of the following exception:


    Traceback (most recent call last):

      File "/home/stguser/devstack/python-tempestconf/.venv/lib/python3.12/site-packages/tempest/test.py", line 185, in setUpClass
    raise value.with_traceback(trace)

      File "/home/stguser/devstack/python-tempestconf/.venv/lib/python3.12/site-packages/tempest/test.py", line 170, in setUpClass
    cls.setup_credentials()

      File "/home/stguser/devstack/python-tempestconf/.venv/lib/python3.12/site-packages/tempest/api/volume/base.py", line 62, in setup_credentials
    super(BaseVolumeTest, cls).setup_credentials()

      File "/home/stguser/devstack/python-tempestconf/.venv/lib/python3.12/site-packages/tempest/test.py", line 398, in setup_credentials
    manager = cls.get_client_manager(
              ^^^^^^^^^^^^^^^^^^^^^^^

      File "/home/stguser/devstack/python-tempestconf/.venv/lib/python3.12/site-packages/tempest/test.py", line 743, in get_client_manager
    creds = getattr(cred_provider, credentials_method)()
            ^^^^^^^^^^^^^^^^^^^^^^^^^^^^^^^^^^^^^^^^^^^^

      File "/home/stguser/devstack/python-tempestconf/.venv/lib/python3.12/site-packages/tempest/lib/common/dynamic_creds.py", line 473, in get_primary_creds
    return self.get_project_member_creds()
           ^^^^^^^^^^^^^^^^^^^^^^^^^^^^^^^

      File "/home/stguser/devstack/python-tempestconf/.venv/lib/python3.12/site-packages/tempest/lib/common/dynamic_creds.py", line 514, in get_project_member_creds
    return self.get_credentials(['member'], scope='project')
           ^^^^^^^^^^^^^^^^^^^^^^^^^^^^^^^^^^^^^^^^^^^^^^^^^

      File "/home/stguser/devstack/python-tempestconf/.venv/lib/python3.12/site-packages/tempest/lib/common/dynamic_creds.py", line 459, in get_credentials
    network, subnet, router = self._create_network_resources(
                              ^^^^^^^^^^^^^^^^^^^^^^^^^^^^^^^

      File "/home/stguser/devstack/python-tempestconf/.venv/lib/python3.12/site-packages/tempest/lib/common/dynamic_creds.py", line 314, in _create_network_resources
    subnet = self._create_subnet(subnet_name, tenant_id,
             ^^^^^^^^^^^^^^^^^^^^^^^^^^^^^^^^^^^^^^^^^^^

      File "/home/stguser/devstack/python-tempestconf/.venv/lib/python3.12/site-packages/tempest/lib/common/dynamic_creds.py", line 349, in _create_subnet
    create_subnet(

      File "/home/stguser/devstack/python-tempestconf/.venv/lib/python3.12/site-packages/tempest/lib/services/network/subnets_client.py", line 27, in create_subnet
    return self.create_resource(uri, post_data)
           ^^^^^^^^^^^^^^^^^^^^^^^^^^^^^^^^^^^^

      File "/home/stguser/devstack/python-tempestconf/.venv/lib/python3.12/site-packages/tempest/lib/services/network/base.py", line 62, in create_resource
    resp, body = self.post(req_uri, req_post_data)
                 ^^^^^^^^^^^^^^^^^^^^^^^^^^^^^^^^^

      File "/home/stguser/devstack/python-tempestconf/.venv/lib/python3.12/site-packages/tempest/lib/common/rest_client.py", line 314, in post
    resp_header, resp_body = self.request(
                             ^^^^^^^^^^^^^

      File "/home/stguser/devstack/python-tempestconf/.venv/lib/python3.12/site-packages/tempest/lib/common/rest_client.py", line 746, in request
    resp, resp_body = self._request(method, url, headers=headers,
                      ^^^^^^^^^^^^^^^^^^^^^^^^^^^^^^^^^^^^^^^^^^^

      File "/home/stguser/devstack/python-tempestconf/.venv/lib/python3.12/site-packages/tempest/lib/common/rest_client.py", line 612, in _request
    resp, resp_body = self.raw_request(
                      ^^^^^^^^^^^^^^^^^

      File "/home/stguser/devstack/python-tempestconf/.venv/lib/python3.12/site-packages/tempest/lib/common/rest_client.py", line 661, in raw_request
    resp, resp_body = self.http_obj.request(
                      ^^^^^^^^^^^^^^^^^^^^^^

      File "/home/stguser/devstack/python-tempestconf/.venv/lib/python3.12/site-packages/tempest/lib/common/http.py", line 123, in request
    r = super(ClosingHttp, self).request(method, url, retries=retry,
        ^^^^^^^^^^^^^^^^^^^^^^^^^^^^^^^^^^^^^^^^^^^^^^^^^^^^^^^^^^^^

      File "/home/stguser/devstack/python-tempestconf/.venv/lib/python3.12/site-packages/urllib3/_request_methods.py", line 143, in request
    return self.request_encode_body(
           ^^^^^^^^^^^^^^^^^^^^^^^^^

      File "/home/stguser/devstack/python-tempestconf/.venv/lib/python3.12/site-packages/urllib3/_request_methods.py", line 278, in request_encode_body
    return self.urlopen(method, url, **extra_kw)
           ^^^^^^^^^^^^^^^^^^^^^^^^^^^^^^^^^^^^^

      File "/home/stguser/devstack/python-tempestconf/.venv/lib/python3.12/site-packages/urllib3/poolmanager.py", line 459, in urlopen
    response = conn.urlopen(method, u.request_uri, **kw)
               ^^^^^^^^^^^^^^^^^^^^^^^^^^^^^^^^^^^^^^^^^

      File "/home/stguser/devstack/python-tempestconf/.venv/lib/python3.12/site-packages/urllib3/connectionpool.py", line 841, in urlopen
    retries = retries.increment(
              ^^^^^^^^^^^^^^^^^^

      File "/home/stguser/devstack/python-tempestconf/.venv/lib/python3.12/site-packages/urllib3/util/retry.py", line 474, in increment
    raise reraise(type(error), error, _stacktrace)
          ^^^^^^^^^^^^^^^^^^^^^^^^^^^^^^^^^^^^^^^^

      File "/home/stguser/devstack/python-tempestconf/.venv/lib/python3.12/site-packages/urllib3/util/util.py", line 39, in reraise
    raise value

      File "/home/stguser/devstack/python-tempestconf/.venv/lib/python3.12/site-packages/urllib3/connectionpool.py", line 787, in urlopen
    response = self._make_request(
               ^^^^^^^^^^^^^^^^^^^

      File "/home/stguser/devstack/python-tempestconf/.venv/lib/python3.12/site-packages/urllib3/connectionpool.py", line 536, in _make_request
    self._raise_timeout(err=e, url=url, timeout_value=read_timeout)

      File "/home/stguser/devstack/python-tempestconf/.venv/lib/python3.12/site-packages/urllib3/connectionpool.py", line 367, in _raise_timeout
    raise ReadTimeoutError(

    urllib3.exceptions.ReadTimeoutError: HTTPConnectionPool(host='9.180.170.14', port=9696): Read timed out. (read timeout=60)

{13} tempest.api.volume.admin.test_volume_services.VolumesServicesTestJSON.test_get_service_by_volume_host_name [93.034800s] ... ok
{13} tempest.api.volume.admin.test_volume_services.VolumesServicesTestJSON.test_list_services [0.375738s] ... ok
{30} tempest.api.volume.test_snapshot_metadata.SnapshotMetadataTestJSON.test_update_show_snapshot_metadata_item [3.905129s] ... ok
{16} tempest.api.volume.admin.test_snapshots_actions.SnapshotsActionsTest.test_reset_snapshot_status [2.562364s] ... ok
{18} setUpClass (tempest.api.volume.admin.test_volume_retype.VolumeRetypeWithoutMigrationTest) [0.000000s] ... FAILED

Captured traceback:
~~~~~~~~~~~~~~~~~~~
    Traceback (most recent call last):

      File "/home/stguser/devstack/python-tempestconf/.venv/lib/python3.12/site-packages/tempest/test.py", line 185, in setUpClass
    raise value.with_traceback(trace)

      File "/home/stguser/devstack/python-tempestconf/.venv/lib/python3.12/site-packages/tempest/test.py", line 178, in setUpClass
    cls.resource_setup()

      File "/home/stguser/devstack/python-tempestconf/.venv/lib/python3.12/site-packages/tempest/api/volume/admin/test_volume_retype.py", line 172, in resource_setup
    cls.src_vol_type = cls.create_volume_type('volume-type-1')
                       ^^^^^^^^^^^^^^^^^^^^^^^^^^^^^^^^^^^^^^^

      File "/home/stguser/devstack/python-tempestconf/.venv/lib/python3.12/site-packages/tempest/api/volume/base.py", line 366, in create_volume_type
    volume_type = self.admin_volume_types_client.create_volume_type(
                  ^^^^^^^^^^^^^^^^^^^^^^^^^^^^^^^^^^^^^^^^^^^^^^^^^^

      File "/home/stguser/devstack/python-tempestconf/.venv/lib/python3.12/site-packages/tempest/lib/services/volume/v3/types_client.py", line 90, in create_volume_type
    resp, body = self.post('types', post_body)
                 ^^^^^^^^^^^^^^^^^^^^^^^^^^^^^

      File "/home/stguser/devstack/python-tempestconf/.venv/lib/python3.12/site-packages/tempest/lib/common/rest_client.py", line 314, in post
    resp_header, resp_body = self.request(
                             ^^^^^^^^^^^^^

      File "/home/stguser/devstack/python-tempestconf/.venv/lib/python3.12/site-packages/tempest/lib/common/rest_client.py", line 762, in request
    self._error_checker(resp, resp_body)

      File "/home/stguser/devstack/python-tempestconf/.venv/lib/python3.12/site-packages/tempest/lib/common/rest_client.py", line 892, in _error_checker
    raise exceptions.Conflict(resp_body, resp=resp)

    tempest.lib.exceptions.Conflict: Conflict with state of target resource
Details: {'code': 409, 'message': 'Volume Type volume-type-1 already exists.'}

{2} tempest.api.volume.admin.test_volume_quotas.VolumeQuotasAdminTestJSON.test_delete_quota [96.969561s] ... ok
{2} tempest.api.volume.admin.test_volume_quotas.VolumeQuotasAdminTestJSON.test_list_default_quotas [0.397720s] ... ok
{2} tempest.api.volume.admin.test_volume_quotas.VolumeQuotasAdminTestJSON.test_list_quotas [0.481442s] ... ok
{9} tempest.api.volume.admin.test_user_messages.UserMessagesTest.test_list_show_messages [19.752927s] ... ok
{12} tempest.api.volume.admin.test_qos.QosSpecsTestJSON.test_create_delete_qos_with_back_end_consumer [14.060268s] ... ok
{32} tempest.api.volume.admin.test_volume_snapshot_quotas_negative.VolumeSnapshotQuotasNegativeTestJSON.test_quota_volume_gigabytes_snapshots [4.604826s] ... ok
{32} tempest.api.volume.admin.test_volume_snapshot_quotas_negative.VolumeSnapshotQuotasNegativeTestJSON.test_quota_volume_snapshots [0.615123s] ... ok
{34} tempest.api.volume.test_volumes_list.VolumesListTestJSON.test_volume_list [0.771771s] ... ok
{34} tempest.api.volume.test_volumes_list.VolumesListTestJSON.test_volume_list_by_name [0.169912s] ... ok
{34} tempest.api.volume.test_volumes_list.VolumesListTestJSON.test_volume_list_details_by_name [0.179261s] ... ok
{34} tempest.api.volume.test_volumes_list.VolumesListTestJSON.test_volume_list_details_pagination [0.539929s] ... ok
{34} tempest.api.volume.test_volumes_list.VolumesListTestJSON.test_volume_list_details_with_multiple_params [0.315746s] ... ok
{34} tempest.api.volume.test_volumes_list.VolumesListTestJSON.test_volume_list_pagination [0.297046s] ... ok
{34} tempest.api.volume.test_volumes_list.VolumesListTestJSON.test_volume_list_param_display_name_and_status [0.122164s] ... ok
{34} tempest.api.volume.test_volumes_list.VolumesListTestJSON.test_volume_list_with_detail_param_display_name_and_status [0.148948s] ... ok
{34} tempest.api.volume.test_volumes_list.VolumesListTestJSON.test_volume_list_with_detail_param_marker [0.125398s] ... ok
{10} tempest.api.volume.admin.test_volume_type_access.VolumeTypesAccessTest.test_volume_type_access_add [108.267907s] ... ok
{34} tempest.api.volume.test_volumes_list.VolumesListTestJSON.test_volume_list_with_detail_param_metadata [0.171086s] ... ok
{34} tempest.api.volume.test_volumes_list.VolumesListTestJSON.test_volume_list_with_details [0.099599s] ... ok
{34} tempest.api.volume.test_volumes_list.VolumesListTestJSON.test_volume_list_with_param_metadata [0.090813s] ... ok
{34} tempest.api.volume.test_volumes_list.VolumesListTestJSON.test_volumes_list_by_availability_zone [0.411765s] ... ok
{34} tempest.api.volume.test_volumes_list.VolumesListTestJSON.test_volumes_list_by_bootable [0.293293s] ... ok
{34} tempest.api.volume.test_volumes_list.VolumesListTestJSON.test_volumes_list_by_status [0.205402s] ... ok
{34} tempest.api.volume.test_volumes_list.VolumesListTestJSON.test_volumes_list_details_by_availability_zone [0.129669s] ... ok
{34} tempest.api.volume.test_volumes_list.VolumesListTestJSON.test_volumes_list_details_by_bootable [0.181900s] ... ok
{34} tempest.api.volume.test_volumes_list.VolumesListTestJSON.test_volumes_list_details_by_status [0.102408s] ... ok
{12} tempest.api.volume.admin.test_qos.QosSpecsTestJSON.test_create_delete_qos_with_both_consumer [9.611615s] ... ok
{10} tempest.api.volume.admin.test_volume_type_access.VolumeTypesAccessTest.test_volume_type_access_list [6.257999s] ... ok
{6} tempest.api.volume.test_volume_transfers.VolumesTransfersTest.test_create_get_list_accept_volume_transfer [116.138574s] ... ok
{7} tempest.api.volume.test_volume_transfers.VolumesTransfersV357Test.test_create_get_list_accept_volume_transfer [121.731608s] ... ok
{12} tempest.api.volume.admin.test_qos.QosSpecsTestJSON.test_create_delete_qos_with_front_end_consumer [8.326113s] ... ok
{12} tempest.api.volume.admin.test_qos.QosSpecsTestJSON.test_get_qos [0.129405s] ... ok
{22} setUpClass (tempest.api.volume.test_volumes_snapshots.VolumesSnapshotTestJSON) [0.000000s] ... FAILED

Captured traceback:
~~~~~~~~~~~~~~~~~~~
    Traceback (most recent call last):

      File "/home/stguser/devstack/python-tempestconf/.venv/lib/python3.12/site-packages/urllib3/connectionpool.py", line 534, in _make_request
    response = conn.getresponse()
               ^^^^^^^^^^^^^^^^^^

      File "/home/stguser/devstack/python-tempestconf/.venv/lib/python3.12/site-packages/urllib3/connection.py", line 565, in getresponse
    httplib_response = super().getresponse()
                       ^^^^^^^^^^^^^^^^^^^^^

      File "/usr/lib/python3.12/http/client.py", line 1428, in getresponse
    response.begin()

      File "/usr/lib/python3.12/http/client.py", line 331, in begin
    version, status, reason = self._read_status()
                              ^^^^^^^^^^^^^^^^^^^

      File "/usr/lib/python3.12/http/client.py", line 292, in _read_status
    line = str(self.fp.readline(_MAXLINE + 1), "iso-8859-1")
               ^^^^^^^^^^^^^^^^^^^^^^^^^^^^^^

      File "/usr/lib/python3.12/socket.py", line 707, in readinto
    return self._sock.recv_into(b)
           ^^^^^^^^^^^^^^^^^^^^^^^

    TimeoutError: timed out

    
The above exception was the direct cause of the following exception:


    Traceback (most recent call last):

      File "/home/stguser/devstack/python-tempestconf/.venv/lib/python3.12/site-packages/tempest/test.py", line 185, in setUpClass
    raise value.with_traceback(trace)

      File "/home/stguser/devstack/python-tempestconf/.venv/lib/python3.12/site-packages/tempest/test.py", line 170, in setUpClass
    cls.setup_credentials()

      File "/home/stguser/devstack/python-tempestconf/.venv/lib/python3.12/site-packages/tempest/api/volume/base.py", line 62, in setup_credentials
    super(BaseVolumeTest, cls).setup_credentials()

      File "/home/stguser/devstack/python-tempestconf/.venv/lib/python3.12/site-packages/tempest/test.py", line 398, in setup_credentials
    manager = cls.get_client_manager(
              ^^^^^^^^^^^^^^^^^^^^^^^

      File "/home/stguser/devstack/python-tempestconf/.venv/lib/python3.12/site-packages/tempest/test.py", line 743, in get_client_manager
    creds = getattr(cred_provider, credentials_method)()
            ^^^^^^^^^^^^^^^^^^^^^^^^^^^^^^^^^^^^^^^^^^^^

      File "/home/stguser/devstack/python-tempestconf/.venv/lib/python3.12/site-packages/tempest/lib/common/dynamic_creds.py", line 473, in get_primary_creds
    return self.get_project_member_creds()
           ^^^^^^^^^^^^^^^^^^^^^^^^^^^^^^^

      File "/home/stguser/devstack/python-tempestconf/.venv/lib/python3.12/site-packages/tempest/lib/common/dynamic_creds.py", line 514, in get_project_member_creds
    return self.get_credentials(['member'], scope='project')
           ^^^^^^^^^^^^^^^^^^^^^^^^^^^^^^^^^^^^^^^^^^^^^^^^^

      File "/home/stguser/devstack/python-tempestconf/.venv/lib/python3.12/site-packages/tempest/lib/common/dynamic_creds.py", line 459, in get_credentials
    network, subnet, router = self._create_network_resources(
                              ^^^^^^^^^^^^^^^^^^^^^^^^^^^^^^^

      File "/home/stguser/devstack/python-tempestconf/.venv/lib/python3.12/site-packages/tempest/lib/common/dynamic_creds.py", line 318, in _create_network_resources
    router = self._create_router(router_name, tenant_id)
             ^^^^^^^^^^^^^^^^^^^^^^^^^^^^^^^^^^^^^^^^^^^

      File "/home/stguser/devstack/python-tempestconf/.venv/lib/python3.12/site-packages/tempest/lib/common/dynamic_creds.py", line 379, in _create_router
    resp_body = self.routers_admin_client.create_router(**kwargs)
                ^^^^^^^^^^^^^^^^^^^^^^^^^^^^^^^^^^^^^^^^^^^^^^^^^

      File "/home/stguser/devstack/python-tempestconf/.venv/lib/python3.12/site-packages/tempest/lib/services/network/routers_client.py", line 27, in create_router
    return self.create_resource(uri, post_body)
           ^^^^^^^^^^^^^^^^^^^^^^^^^^^^^^^^^^^^

      File "/home/stguser/devstack/python-tempestconf/.venv/lib/python3.12/site-packages/tempest/lib/services/network/base.py", line 62, in create_resource
    resp, body = self.post(req_uri, req_post_data)
                 ^^^^^^^^^^^^^^^^^^^^^^^^^^^^^^^^^

      File "/home/stguser/devstack/python-tempestconf/.venv/lib/python3.12/site-packages/tempest/lib/common/rest_client.py", line 314, in post
    resp_header, resp_body = self.request(
                             ^^^^^^^^^^^^^

      File "/home/stguser/devstack/python-tempestconf/.venv/lib/python3.12/site-packages/tempest/lib/common/rest_client.py", line 746, in request
    resp, resp_body = self._request(method, url, headers=headers,
                      ^^^^^^^^^^^^^^^^^^^^^^^^^^^^^^^^^^^^^^^^^^^

      File "/home/stguser/devstack/python-tempestconf/.venv/lib/python3.12/site-packages/tempest/lib/common/rest_client.py", line 612, in _request
    resp, resp_body = self.raw_request(
                      ^^^^^^^^^^^^^^^^^

      File "/home/stguser/devstack/python-tempestconf/.venv/lib/python3.12/site-packages/tempest/lib/common/rest_client.py", line 661, in raw_request
    resp, resp_body = self.http_obj.request(
                      ^^^^^^^^^^^^^^^^^^^^^^

      File "/home/stguser/devstack/python-tempestconf/.venv/lib/python3.12/site-packages/tempest/lib/common/http.py", line 123, in request
    r = super(ClosingHttp, self).request(method, url, retries=retry,
        ^^^^^^^^^^^^^^^^^^^^^^^^^^^^^^^^^^^^^^^^^^^^^^^^^^^^^^^^^^^^

      File "/home/stguser/devstack/python-tempestconf/.venv/lib/python3.12/site-packages/urllib3/_request_methods.py", line 143, in request
    return self.request_encode_body(
           ^^^^^^^^^^^^^^^^^^^^^^^^^

      File "/home/stguser/devstack/python-tempestconf/.venv/lib/python3.12/site-packages/urllib3/_request_methods.py", line 278, in request_encode_body
    return self.urlopen(method, url, **extra_kw)
           ^^^^^^^^^^^^^^^^^^^^^^^^^^^^^^^^^^^^^

      File "/home/stguser/devstack/python-tempestconf/.venv/lib/python3.12/site-packages/urllib3/poolmanager.py", line 459, in urlopen
    response = conn.urlopen(method, u.request_uri, **kw)
               ^^^^^^^^^^^^^^^^^^^^^^^^^^^^^^^^^^^^^^^^^

      File "/home/stguser/devstack/python-tempestconf/.venv/lib/python3.12/site-packages/urllib3/connectionpool.py", line 841, in urlopen
    retries = retries.increment(
              ^^^^^^^^^^^^^^^^^^

      File "/home/stguser/devstack/python-tempestconf/.venv/lib/python3.12/site-packages/urllib3/util/retry.py", line 474, in increment
    raise reraise(type(error), error, _stacktrace)
          ^^^^^^^^^^^^^^^^^^^^^^^^^^^^^^^^^^^^^^^^

      File "/home/stguser/devstack/python-tempestconf/.venv/lib/python3.12/site-packages/urllib3/util/util.py", line 39, in reraise
    raise value

      File "/home/stguser/devstack/python-tempestconf/.venv/lib/python3.12/site-packages/urllib3/connectionpool.py", line 787, in urlopen
    response = self._make_request(
               ^^^^^^^^^^^^^^^^^^^

      File "/home/stguser/devstack/python-tempestconf/.venv/lib/python3.12/site-packages/urllib3/connectionpool.py", line 536, in _make_request
    self._raise_timeout(err=e, url=url, timeout_value=read_timeout)

      File "/home/stguser/devstack/python-tempestconf/.venv/lib/python3.12/site-packages/urllib3/connectionpool.py", line 367, in _raise_timeout
    raise ReadTimeoutError(

    urllib3.exceptions.ReadTimeoutError: HTTPConnectionPool(host='9.180.170.14', port=9696): Read timed out. (read timeout=60)

{5} tempest.api.volume.test_volume_transfers.VolumesTransfersV355Test.test_create_get_list_accept_volume_transfer [122.930673s] ... ok
{39} tempest.api.volume.test_volumes_snapshots_list.VolumesSnapshotListTestJSON.test_snapshot_list_param_limit [0.042246s] ... ok
{39} tempest.api.volume.test_volumes_snapshots_list.VolumesSnapshotListTestJSON.test_snapshot_list_param_limit_equals_infinite [0.333406s] ... ok
{39} tempest.api.volume.test_volumes_snapshots_list.VolumesSnapshotListTestJSON.test_snapshot_list_param_limit_equals_zero [0.025783s] ... ok
{39} tempest.api.volume.test_volumes_snapshots_list.VolumesSnapshotListTestJSON.test_snapshot_list_param_marker [0.077066s] ... ok
{39} tempest.api.volume.test_volumes_snapshots_list.VolumesSnapshotListTestJSON.test_snapshot_list_param_offset [0.039092s] ... ok
{39} tempest.api.volume.test_volumes_snapshots_list.VolumesSnapshotListTestJSON.test_snapshot_list_param_sort_created_at_asc [0.044330s] ... ok
{39} tempest.api.volume.test_volumes_snapshots_list.VolumesSnapshotListTestJSON.test_snapshot_list_param_sort_created_at_desc [0.031515s] ... ok
{39} tempest.api.volume.test_volumes_snapshots_list.VolumesSnapshotListTestJSON.test_snapshot_list_param_sort_id_asc [0.095120s] ... ok
{39} tempest.api.volume.test_volumes_snapshots_list.VolumesSnapshotListTestJSON.test_snapshot_list_param_sort_id_desc [0.070491s] ... ok
{39} tempest.api.volume.test_volumes_snapshots_list.VolumesSnapshotListTestJSON.test_snapshot_list_param_sort_name_asc [0.043636s] ... ok
{39} tempest.api.volume.test_volumes_snapshots_list.VolumesSnapshotListTestJSON.test_snapshot_list_param_sort_name_desc [0.045125s] ... ok
{39} tempest.api.volume.test_volumes_snapshots_list.VolumesSnapshotListTestJSON.test_snapshots_list_details_with_params [0.229300s] ... ok
{39} tempest.api.volume.test_volumes_snapshots_list.VolumesSnapshotListTestJSON.test_snapshots_list_with_params [0.110680s] ... ok
{12} tempest.api.volume.admin.test_qos.QosSpecsTestJSON.test_list_qos [5.220869s] ... ok
{16} tempest.api.volume.admin.test_snapshots_actions.SnapshotsActionsTest.test_snapshot_force_delete_when_snapshot_is_creating [30.741507s] ... ok
{12} tempest.api.volume.admin.test_qos.QosSpecsTestJSON.test_set_unset_qos_key [2.650278s] ... ok
{0} tempest.api.volume.test_volumes_get.VolumesGetTest.test_volume_create_get_update_delete [164.251248s] ... ok
{28} tempest.api.volume.admin.test_volumes_list.VolumesListAdminTestJSON.test_volume_list_param_tenant [18.672967s] ... ok
{4} tempest.api.volume.admin.test_volume_types.VolumeTypesTest.test_volume_type_update [64.939308s] ... ok
{2} tempest.api.volume.admin.test_volume_quotas.VolumeQuotasAdminTestJSON.test_quota_usage [38.791891s] ... ok
{1} tempest.api.volume.test_volume_delete_cascade.VolumesDeleteCascade.test_volume_delete_cascade [187.371389s] ... ok
{3} tempest.api.volume.test_volumes_clone.VolumesCloneTest.test_create_from_volume [188.343933s] ... ok
{6} tempest.api.volume.test_volume_transfers.VolumesTransfersTest.test_create_list_delete_volume_transfer [36.411163s] ... ok
{16} tempest.api.volume.admin.test_snapshots_actions.SnapshotsActionsTest.test_snapshot_force_delete_when_snapshot_is_deleting [28.648754s] ... ok
{7} tempest.api.volume.test_volume_transfers.VolumesTransfersV357Test.test_create_list_delete_volume_transfer [37.010299s] ... ok
{4} setUpClass (tempest.api.volume.test_volumes_backup.VolumesBackupsTest) ... SKIPPED: Cinder backup feature disabled
{5} tempest.api.volume.test_volume_transfers.VolumesTransfersV355Test.test_create_list_delete_volume_transfer [37.165992s] ... ok
{8} tempest.api.volume.test_volumes_negative.VolumesNegativeTest.test_attach_volumes_with_nonexistent_volume_id [117.610692s] ... ok
{8} tempest.api.volume.test_volumes_negative.VolumesNegativeTest.test_create_volume_from_deactivated_image [8.052405s] ... ok
{16} tempest.api.volume.admin.test_snapshots_actions.SnapshotsActionsTest.test_snapshot_force_delete_when_snapshot_is_error [15.483101s] ... ok
{2} tempest.api.volume.admin.test_volume_quotas.VolumeQuotasAdminTestJSON.test_quota_usage_after_volume_transfer [33.870894s] ... ok
{2} tempest.api.volume.admin.test_volume_quotas.VolumeQuotasAdminTestJSON.test_show_quota_usage [0.464808s] ... ok
{8} tempest.api.volume.test_volumes_negative.VolumesNegativeTest.test_create_volume_from_image_with_decreasing_size [5.835222s] ... ok
{8} tempest.api.volume.test_volumes_negative.VolumesNegativeTest.test_create_volume_with_invalid_size [0.028271s] ... ok
{8} tempest.api.volume.test_volumes_negative.VolumesNegativeTest.test_create_volume_with_nonexistent_snapshot_id [0.103161s] ... ok
{8} tempest.api.volume.test_volumes_negative.VolumesNegativeTest.test_create_volume_with_nonexistent_source_volid [0.119928s] ... ok
{8} tempest.api.volume.test_volumes_negative.VolumesNegativeTest.test_create_volume_with_nonexistent_volume_type [0.046242s] ... ok
{8} tempest.api.volume.test_volumes_negative.VolumesNegativeTest.test_create_volume_with_size_negative [0.017920s] ... ok
{8} tempest.api.volume.test_volumes_negative.VolumesNegativeTest.test_create_volume_with_size_zero [0.017365s] ... ok
{8} tempest.api.volume.test_volumes_negative.VolumesNegativeTest.test_create_volume_without_passing_size [0.016491s] ... ok
{8} tempest.api.volume.test_volumes_negative.VolumesNegativeTest.test_delete_invalid_volume_id [0.072908s] ... ok
{8} tempest.api.volume.test_volumes_negative.VolumesNegativeTest.test_delete_volume_without_passing_volume_id [0.015853s] ... ok
{8} tempest.api.volume.test_volumes_negative.VolumesNegativeTest.test_detach_volumes_with_invalid_volume_id [0.035567s] ... ok
{8} tempest.api.volume.test_volumes_negative.VolumesNegativeTest.test_get_invalid_volume_id [0.028073s] ... ok
{8} tempest.api.volume.test_volumes_negative.VolumesNegativeTest.test_get_volume_without_passing_volume_id [0.010444s] ... ok
{8} tempest.api.volume.test_volumes_negative.VolumesNegativeTest.test_list_volumes_detail_with_invalid_status [0.380686s] ... ok
{8} tempest.api.volume.test_volumes_negative.VolumesNegativeTest.test_list_volumes_detail_with_nonexistent_name [0.125634s] ... ok
{8} tempest.api.volume.test_volumes_negative.VolumesNegativeTest.test_list_volumes_with_invalid_status [0.110131s] ... ok
{8} tempest.api.volume.test_volumes_negative.VolumesNegativeTest.test_list_volumes_with_nonexistent_name [0.030717s] ... ok
{8} tempest.api.volume.test_volumes_negative.VolumesNegativeTest.test_reserve_volume_with_negative_volume_status [0.988557s] ... ok
{8} tempest.api.volume.test_volumes_negative.VolumesNegativeTest.test_reserve_volume_with_nonexistent_volume_id [0.132813s] ... ok
{8} tempest.api.volume.test_volumes_negative.VolumesNegativeTest.test_unreserve_volume_with_nonexistent_volume_id [0.128457s] ... ok
{8} tempest.api.volume.test_volumes_negative.VolumesNegativeTest.test_update_volume_with_empty_volume_id [0.007954s] ... ok
{8} tempest.api.volume.test_volumes_negative.VolumesNegativeTest.test_update_volume_with_invalid_volume_id [0.026278s] ... ok
{8} tempest.api.volume.test_volumes_negative.VolumesNegativeTest.test_update_volume_with_nonexistent_volume_id [0.128669s] ... ok
{8} tempest.api.volume.test_volumes_negative.VolumesNegativeTest.test_volume_delete_nonexistent_volume_id [0.168521s] ... ok
{8} tempest.api.volume.test_volumes_negative.VolumesNegativeTest.test_volume_get_nonexistent_volume_id [0.099873s] ... ok
{2} tempest.api.volume.admin.test_volume_quotas.VolumeQuotasAdminTestJSON.test_update_all_quota_resources_for_tenant [6.259027s] ... ok
{16} tempest.api.volume.admin.test_snapshots_actions.SnapshotsActionsTest.test_snapshot_force_delete_when_snapshot_is_error_deleting [11.799190s] ... ok
{16} tempest.api.volume.admin.test_snapshots_actions.SnapshotsActionsTest.test_update_snapshot_status [0.598741s] ... ok
{0} tempest.api.volume.test_volumes_get.VolumesGetTest.test_volume_create_get_update_delete_as_clone [60.493400s] ... ok
{2} setUpClass (tempest.api.volume.admin.test_volumes_backup.VolumesBackupsAdminTest) ... SKIPPED: Cinder backup feature disabled

==============================
Failed 4 tests - output below:
==============================

setUpClass (tempest.api.volume.admin.test_volumes_actions.VolumesActionsTest)
-----------------------------------------------------------------------------

Captured traceback:
~~~~~~~~~~~~~~~~~~~
    Traceback (most recent call last):

      File "/home/stguser/devstack/python-tempestconf/.venv/lib/python3.12/site-packages/urllib3/connectionpool.py", line 534, in _make_request
    response = conn.getresponse()
               ^^^^^^^^^^^^^^^^^^

      File "/home/stguser/devstack/python-tempestconf/.venv/lib/python3.12/site-packages/urllib3/connection.py", line 565, in getresponse
    httplib_response = super().getresponse()
                       ^^^^^^^^^^^^^^^^^^^^^

      File "/usr/lib/python3.12/http/client.py", line 1428, in getresponse
    response.begin()

      File "/usr/lib/python3.12/http/client.py", line 331, in begin
    version, status, reason = self._read_status()
                              ^^^^^^^^^^^^^^^^^^^

      File "/usr/lib/python3.12/http/client.py", line 292, in _read_status
    line = str(self.fp.readline(_MAXLINE + 1), "iso-8859-1")
               ^^^^^^^^^^^^^^^^^^^^^^^^^^^^^^

      File "/usr/lib/python3.12/socket.py", line 707, in readinto
    return self._sock.recv_into(b)
           ^^^^^^^^^^^^^^^^^^^^^^^

    TimeoutError: timed out

    
The above exception was the direct cause of the following exception:


    Traceback (most recent call last):

      File "/home/stguser/devstack/python-tempestconf/.venv/lib/python3.12/site-packages/tempest/test.py", line 185, in setUpClass
    raise value.with_traceback(trace)

      File "/home/stguser/devstack/python-tempestconf/.venv/lib/python3.12/site-packages/tempest/test.py", line 170, in setUpClass
    cls.setup_credentials()

      File "/home/stguser/devstack/python-tempestconf/.venv/lib/python3.12/site-packages/tempest/api/volume/base.py", line 62, in setup_credentials
    super(BaseVolumeTest, cls).setup_credentials()

      File "/home/stguser/devstack/python-tempestconf/.venv/lib/python3.12/site-packages/tempest/test.py", line 398, in setup_credentials
    manager = cls.get_client_manager(
              ^^^^^^^^^^^^^^^^^^^^^^^

      File "/home/stguser/devstack/python-tempestconf/.venv/lib/python3.12/site-packages/tempest/test.py", line 743, in get_client_manager
    creds = getattr(cred_provider, credentials_method)()
            ^^^^^^^^^^^^^^^^^^^^^^^^^^^^^^^^^^^^^^^^^^^^

      File "/home/stguser/devstack/python-tempestconf/.venv/lib/python3.12/site-packages/tempest/lib/common/dynamic_creds.py", line 473, in get_primary_creds
    return self.get_project_member_creds()
           ^^^^^^^^^^^^^^^^^^^^^^^^^^^^^^^

      File "/home/stguser/devstack/python-tempestconf/.venv/lib/python3.12/site-packages/tempest/lib/common/dynamic_creds.py", line 514, in get_project_member_creds
    return self.get_credentials(['member'], scope='project')
           ^^^^^^^^^^^^^^^^^^^^^^^^^^^^^^^^^^^^^^^^^^^^^^^^^

      File "/home/stguser/devstack/python-tempestconf/.venv/lib/python3.12/site-packages/tempest/lib/common/dynamic_creds.py", line 459, in get_credentials
    network, subnet, router = self._create_network_resources(
                              ^^^^^^^^^^^^^^^^^^^^^^^^^^^^^^^

      File "/home/stguser/devstack/python-tempestconf/.venv/lib/python3.12/site-packages/tempest/lib/common/dynamic_creds.py", line 310, in _create_network_resources
    network = self._create_network(network_name, tenant_id)
              ^^^^^^^^^^^^^^^^^^^^^^^^^^^^^^^^^^^^^^^^^^^^^

      File "/home/stguser/devstack/python-tempestconf/.venv/lib/python3.12/site-packages/tempest/lib/common/dynamic_creds.py", line 338, in _create_network
    resp_body = self.networks_admin_client.create_network(
                ^^^^^^^^^^^^^^^^^^^^^^^^^^^^^^^^^^^^^^^^^^

      File "/home/stguser/devstack/python-tempestconf/.venv/lib/python3.12/site-packages/tempest/lib/services/network/networks_client.py", line 27, in create_network
    return self.create_resource(uri, post_data)
           ^^^^^^^^^^^^^^^^^^^^^^^^^^^^^^^^^^^^

      File "/home/stguser/devstack/python-tempestconf/.venv/lib/python3.12/site-packages/tempest/lib/services/network/base.py", line 62, in create_resource
    resp, body = self.post(req_uri, req_post_data)
                 ^^^^^^^^^^^^^^^^^^^^^^^^^^^^^^^^^

      File "/home/stguser/devstack/python-tempestconf/.venv/lib/python3.12/site-packages/tempest/lib/common/rest_client.py", line 314, in post
    resp_header, resp_body = self.request(
                             ^^^^^^^^^^^^^

      File "/home/stguser/devstack/python-tempestconf/.venv/lib/python3.12/site-packages/tempest/lib/common/rest_client.py", line 746, in request
    resp, resp_body = self._request(method, url, headers=headers,
                      ^^^^^^^^^^^^^^^^^^^^^^^^^^^^^^^^^^^^^^^^^^^

      File "/home/stguser/devstack/python-tempestconf/.venv/lib/python3.12/site-packages/tempest/lib/common/rest_client.py", line 612, in _request
    resp, resp_body = self.raw_request(
                      ^^^^^^^^^^^^^^^^^

      File "/home/stguser/devstack/python-tempestconf/.venv/lib/python3.12/site-packages/tempest/lib/common/rest_client.py", line 661, in raw_request
    resp, resp_body = self.http_obj.request(
                      ^^^^^^^^^^^^^^^^^^^^^^

      File "/home/stguser/devstack/python-tempestconf/.venv/lib/python3.12/site-packages/tempest/lib/common/http.py", line 123, in request
    r = super(ClosingHttp, self).request(method, url, retries=retry,
        ^^^^^^^^^^^^^^^^^^^^^^^^^^^^^^^^^^^^^^^^^^^^^^^^^^^^^^^^^^^^

      File "/home/stguser/devstack/python-tempestconf/.venv/lib/python3.12/site-packages/urllib3/_request_methods.py", line 143, in request
    return self.request_encode_body(
           ^^^^^^^^^^^^^^^^^^^^^^^^^

      File "/home/stguser/devstack/python-tempestconf/.venv/lib/python3.12/site-packages/urllib3/_request_methods.py", line 278, in request_encode_body
    return self.urlopen(method, url, **extra_kw)
           ^^^^^^^^^^^^^^^^^^^^^^^^^^^^^^^^^^^^^

      File "/home/stguser/devstack/python-tempestconf/.venv/lib/python3.12/site-packages/urllib3/poolmanager.py", line 459, in urlopen
    response = conn.urlopen(method, u.request_uri, **kw)
               ^^^^^^^^^^^^^^^^^^^^^^^^^^^^^^^^^^^^^^^^^

      File "/home/stguser/devstack/python-tempestconf/.venv/lib/python3.12/site-packages/urllib3/connectionpool.py", line 841, in urlopen
    retries = retries.increment(
              ^^^^^^^^^^^^^^^^^^

      File "/home/stguser/devstack/python-tempestconf/.venv/lib/python3.12/site-packages/urllib3/util/retry.py", line 474, in increment
    raise reraise(type(error), error, _stacktrace)
          ^^^^^^^^^^^^^^^^^^^^^^^^^^^^^^^^^^^^^^^^

      File "/home/stguser/devstack/python-tempestconf/.venv/lib/python3.12/site-packages/urllib3/util/util.py", line 39, in reraise
    raise value

      File "/home/stguser/devstack/python-tempestconf/.venv/lib/python3.12/site-packages/urllib3/connectionpool.py", line 787, in urlopen
    response = self._make_request(
               ^^^^^^^^^^^^^^^^^^^

      File "/home/stguser/devstack/python-tempestconf/.venv/lib/python3.12/site-packages/urllib3/connectionpool.py", line 536, in _make_request
    self._raise_timeout(err=e, url=url, timeout_value=read_timeout)

      File "/home/stguser/devstack/python-tempestconf/.venv/lib/python3.12/site-packages/urllib3/connectionpool.py", line 367, in _raise_timeout
    raise ReadTimeoutError(

    urllib3.exceptions.ReadTimeoutError: HTTPConnectionPool(host='9.180.170.14', port=9696): Read timed out. (read timeout=60)


setUpClass (tempest.api.volume.test_volumes_actions.VolumesActionsTest)
-----------------------------------------------------------------------

Captured traceback:
~~~~~~~~~~~~~~~~~~~
    Traceback (most recent call last):

      File "/home/stguser/devstack/python-tempestconf/.venv/lib/python3.12/site-packages/urllib3/connectionpool.py", line 534, in _make_request
    response = conn.getresponse()
               ^^^^^^^^^^^^^^^^^^

      File "/home/stguser/devstack/python-tempestconf/.venv/lib/python3.12/site-packages/urllib3/connection.py", line 565, in getresponse
    httplib_response = super().getresponse()
                       ^^^^^^^^^^^^^^^^^^^^^

      File "/usr/lib/python3.12/http/client.py", line 1428, in getresponse
    response.begin()

      File "/usr/lib/python3.12/http/client.py", line 331, in begin
    version, status, reason = self._read_status()
                              ^^^^^^^^^^^^^^^^^^^

      File "/usr/lib/python3.12/http/client.py", line 292, in _read_status
    line = str(self.fp.readline(_MAXLINE + 1), "iso-8859-1")
               ^^^^^^^^^^^^^^^^^^^^^^^^^^^^^^

      File "/usr/lib/python3.12/socket.py", line 707, in readinto
    return self._sock.recv_into(b)
           ^^^^^^^^^^^^^^^^^^^^^^^

    TimeoutError: timed out

    
The above exception was the direct cause of the following exception:


    Traceback (most recent call last):

      File "/home/stguser/devstack/python-tempestconf/.venv/lib/python3.12/site-packages/tempest/test.py", line 185, in setUpClass
    raise value.with_traceback(trace)

      File "/home/stguser/devstack/python-tempestconf/.venv/lib/python3.12/site-packages/tempest/test.py", line 170, in setUpClass
    cls.setup_credentials()

      File "/home/stguser/devstack/python-tempestconf/.venv/lib/python3.12/site-packages/tempest/api/volume/base.py", line 62, in setup_credentials
    super(BaseVolumeTest, cls).setup_credentials()

      File "/home/stguser/devstack/python-tempestconf/.venv/lib/python3.12/site-packages/tempest/test.py", line 398, in setup_credentials
    manager = cls.get_client_manager(
              ^^^^^^^^^^^^^^^^^^^^^^^

      File "/home/stguser/devstack/python-tempestconf/.venv/lib/python3.12/site-packages/tempest/test.py", line 743, in get_client_manager
    creds = getattr(cred_provider, credentials_method)()
            ^^^^^^^^^^^^^^^^^^^^^^^^^^^^^^^^^^^^^^^^^^^^

      File "/home/stguser/devstack/python-tempestconf/.venv/lib/python3.12/site-packages/tempest/lib/common/dynamic_creds.py", line 473, in get_primary_creds
    return self.get_project_member_creds()
           ^^^^^^^^^^^^^^^^^^^^^^^^^^^^^^^

      File "/home/stguser/devstack/python-tempestconf/.venv/lib/python3.12/site-packages/tempest/lib/common/dynamic_creds.py", line 514, in get_project_member_creds
    return self.get_credentials(['member'], scope='project')
           ^^^^^^^^^^^^^^^^^^^^^^^^^^^^^^^^^^^^^^^^^^^^^^^^^

      File "/home/stguser/devstack/python-tempestconf/.venv/lib/python3.12/site-packages/tempest/lib/common/dynamic_creds.py", line 459, in get_credentials
    network, subnet, router = self._create_network_resources(
                              ^^^^^^^^^^^^^^^^^^^^^^^^^^^^^^^

      File "/home/stguser/devstack/python-tempestconf/.venv/lib/python3.12/site-packages/tempest/lib/common/dynamic_creds.py", line 314, in _create_network_resources
    subnet = self._create_subnet(subnet_name, tenant_id,
             ^^^^^^^^^^^^^^^^^^^^^^^^^^^^^^^^^^^^^^^^^^^

      File "/home/stguser/devstack/python-tempestconf/.venv/lib/python3.12/site-packages/tempest/lib/common/dynamic_creds.py", line 349, in _create_subnet
    create_subnet(

      File "/home/stguser/devstack/python-tempestconf/.venv/lib/python3.12/site-packages/tempest/lib/services/network/subnets_client.py", line 27, in create_subnet
    return self.create_resource(uri, post_data)
           ^^^^^^^^^^^^^^^^^^^^^^^^^^^^^^^^^^^^

      File "/home/stguser/devstack/python-tempestconf/.venv/lib/python3.12/site-packages/tempest/lib/services/network/base.py", line 62, in create_resource
    resp, body = self.post(req_uri, req_post_data)
                 ^^^^^^^^^^^^^^^^^^^^^^^^^^^^^^^^^

      File "/home/stguser/devstack/python-tempestconf/.venv/lib/python3.12/site-packages/tempest/lib/common/rest_client.py", line 314, in post
    resp_header, resp_body = self.request(
                             ^^^^^^^^^^^^^

      File "/home/stguser/devstack/python-tempestconf/.venv/lib/python3.12/site-packages/tempest/lib/common/rest_client.py", line 746, in request
    resp, resp_body = self._request(method, url, headers=headers,
                      ^^^^^^^^^^^^^^^^^^^^^^^^^^^^^^^^^^^^^^^^^^^

      File "/home/stguser/devstack/python-tempestconf/.venv/lib/python3.12/site-packages/tempest/lib/common/rest_client.py", line 612, in _request
    resp, resp_body = self.raw_request(
                      ^^^^^^^^^^^^^^^^^

      File "/home/stguser/devstack/python-tempestconf/.venv/lib/python3.12/site-packages/tempest/lib/common/rest_client.py", line 661, in raw_request
    resp, resp_body = self.http_obj.request(
                      ^^^^^^^^^^^^^^^^^^^^^^

      File "/home/stguser/devstack/python-tempestconf/.venv/lib/python3.12/site-packages/tempest/lib/common/http.py", line 123, in request
    r = super(ClosingHttp, self).request(method, url, retries=retry,
        ^^^^^^^^^^^^^^^^^^^^^^^^^^^^^^^^^^^^^^^^^^^^^^^^^^^^^^^^^^^^

      File "/home/stguser/devstack/python-tempestconf/.venv/lib/python3.12/site-packages/urllib3/_request_methods.py", line 143, in request
    return self.request_encode_body(
           ^^^^^^^^^^^^^^^^^^^^^^^^^

      File "/home/stguser/devstack/python-tempestconf/.venv/lib/python3.12/site-packages/urllib3/_request_methods.py", line 278, in request_encode_body
    return self.urlopen(method, url, **extra_kw)
           ^^^^^^^^^^^^^^^^^^^^^^^^^^^^^^^^^^^^^

      File "/home/stguser/devstack/python-tempestconf/.venv/lib/python3.12/site-packages/urllib3/poolmanager.py", line 459, in urlopen
    response = conn.urlopen(method, u.request_uri, **kw)
               ^^^^^^^^^^^^^^^^^^^^^^^^^^^^^^^^^^^^^^^^^

      File "/home/stguser/devstack/python-tempestconf/.venv/lib/python3.12/site-packages/urllib3/connectionpool.py", line 841, in urlopen
    retries = retries.increment(
              ^^^^^^^^^^^^^^^^^^

      File "/home/stguser/devstack/python-tempestconf/.venv/lib/python3.12/site-packages/urllib3/util/retry.py", line 474, in increment
    raise reraise(type(error), error, _stacktrace)
          ^^^^^^^^^^^^^^^^^^^^^^^^^^^^^^^^^^^^^^^^

      File "/home/stguser/devstack/python-tempestconf/.venv/lib/python3.12/site-packages/urllib3/util/util.py", line 39, in reraise
    raise value

      File "/home/stguser/devstack/python-tempestconf/.venv/lib/python3.12/site-packages/urllib3/connectionpool.py", line 787, in urlopen
    response = self._make_request(
               ^^^^^^^^^^^^^^^^^^^

      File "/home/stguser/devstack/python-tempestconf/.venv/lib/python3.12/site-packages/urllib3/connectionpool.py", line 536, in _make_request
    self._raise_timeout(err=e, url=url, timeout_value=read_timeout)

      File "/home/stguser/devstack/python-tempestconf/.venv/lib/python3.12/site-packages/urllib3/connectionpool.py", line 367, in _raise_timeout
    raise ReadTimeoutError(

    urllib3.exceptions.ReadTimeoutError: HTTPConnectionPool(host='9.180.170.14', port=9696): Read timed out. (read timeout=60)


setUpClass (tempest.api.volume.admin.test_volume_retype.VolumeRetypeWithoutMigrationTest)
-----------------------------------------------------------------------------------------

Captured traceback:
~~~~~~~~~~~~~~~~~~~
    Traceback (most recent call last):

      File "/home/stguser/devstack/python-tempestconf/.venv/lib/python3.12/site-packages/tempest/test.py", line 185, in setUpClass
    raise value.with_traceback(trace)

      File "/home/stguser/devstack/python-tempestconf/.venv/lib/python3.12/site-packages/tempest/test.py", line 178, in setUpClass
    cls.resource_setup()

      File "/home/stguser/devstack/python-tempestconf/.venv/lib/python3.12/site-packages/tempest/api/volume/admin/test_volume_retype.py", line 172, in resource_setup
    cls.src_vol_type = cls.create_volume_type('volume-type-1')
                       ^^^^^^^^^^^^^^^^^^^^^^^^^^^^^^^^^^^^^^^

      File "/home/stguser/devstack/python-tempestconf/.venv/lib/python3.12/site-packages/tempest/api/volume/base.py", line 366, in create_volume_type
    volume_type = self.admin_volume_types_client.create_volume_type(
                  ^^^^^^^^^^^^^^^^^^^^^^^^^^^^^^^^^^^^^^^^^^^^^^^^^^

      File "/home/stguser/devstack/python-tempestconf/.venv/lib/python3.12/site-packages/tempest/lib/services/volume/v3/types_client.py", line 90, in create_volume_type
    resp, body = self.post('types', post_body)
                 ^^^^^^^^^^^^^^^^^^^^^^^^^^^^^

      File "/home/stguser/devstack/python-tempestconf/.venv/lib/python3.12/site-packages/tempest/lib/common/rest_client.py", line 314, in post
    resp_header, resp_body = self.request(
                             ^^^^^^^^^^^^^

      File "/home/stguser/devstack/python-tempestconf/.venv/lib/python3.12/site-packages/tempest/lib/common/rest_client.py", line 762, in request
    self._error_checker(resp, resp_body)

      File "/home/stguser/devstack/python-tempestconf/.venv/lib/python3.12/site-packages/tempest/lib/common/rest_client.py", line 892, in _error_checker
    raise exceptions.Conflict(resp_body, resp=resp)

    tempest.lib.exceptions.Conflict: Conflict with state of target resource
Details: {'code': 409, 'message': 'Volume Type volume-type-1 already exists.'}


setUpClass (tempest.api.volume.test_volumes_snapshots.VolumesSnapshotTestJSON)
------------------------------------------------------------------------------

Captured traceback:
~~~~~~~~~~~~~~~~~~~
    Traceback (most recent call last):

      File "/home/stguser/devstack/python-tempestconf/.venv/lib/python3.12/site-packages/urllib3/connectionpool.py", line 534, in _make_request
    response = conn.getresponse()
               ^^^^^^^^^^^^^^^^^^

      File "/home/stguser/devstack/python-tempestconf/.venv/lib/python3.12/site-packages/urllib3/connection.py", line 565, in getresponse
    httplib_response = super().getresponse()
                       ^^^^^^^^^^^^^^^^^^^^^

      File "/usr/lib/python3.12/http/client.py", line 1428, in getresponse
    response.begin()

      File "/usr/lib/python3.12/http/client.py", line 331, in begin
    version, status, reason = self._read_status()
                              ^^^^^^^^^^^^^^^^^^^

      File "/usr/lib/python3.12/http/client.py", line 292, in _read_status
    line = str(self.fp.readline(_MAXLINE + 1), "iso-8859-1")
               ^^^^^^^^^^^^^^^^^^^^^^^^^^^^^^

      File "/usr/lib/python3.12/socket.py", line 707, in readinto
    return self._sock.recv_into(b)
           ^^^^^^^^^^^^^^^^^^^^^^^

    TimeoutError: timed out

    
The above exception was the direct cause of the following exception:


    Traceback (most recent call last):

      File "/home/stguser/devstack/python-tempestconf/.venv/lib/python3.12/site-packages/tempest/test.py", line 185, in setUpClass
    raise value.with_traceback(trace)

      File "/home/stguser/devstack/python-tempestconf/.venv/lib/python3.12/site-packages/tempest/test.py", line 170, in setUpClass
    cls.setup_credentials()

      File "/home/stguser/devstack/python-tempestconf/.venv/lib/python3.12/site-packages/tempest/api/volume/base.py", line 62, in setup_credentials
    super(BaseVolumeTest, cls).setup_credentials()

      File "/home/stguser/devstack/python-tempestconf/.venv/lib/python3.12/site-packages/tempest/test.py", line 398, in setup_credentials
    manager = cls.get_client_manager(
              ^^^^^^^^^^^^^^^^^^^^^^^

      File "/home/stguser/devstack/python-tempestconf/.venv/lib/python3.12/site-packages/tempest/test.py", line 743, in get_client_manager
    creds = getattr(cred_provider, credentials_method)()
            ^^^^^^^^^^^^^^^^^^^^^^^^^^^^^^^^^^^^^^^^^^^^

      File "/home/stguser/devstack/python-tempestconf/.venv/lib/python3.12/site-packages/tempest/lib/common/dynamic_creds.py", line 473, in get_primary_creds
    return self.get_project_member_creds()
           ^^^^^^^^^^^^^^^^^^^^^^^^^^^^^^^

      File "/home/stguser/devstack/python-tempestconf/.venv/lib/python3.12/site-packages/tempest/lib/common/dynamic_creds.py", line 514, in get_project_member_creds
    return self.get_credentials(['member'], scope='project')
           ^^^^^^^^^^^^^^^^^^^^^^^^^^^^^^^^^^^^^^^^^^^^^^^^^

      File "/home/stguser/devstack/python-tempestconf/.venv/lib/python3.12/site-packages/tempest/lib/common/dynamic_creds.py", line 459, in get_credentials
    network, subnet, router = self._create_network_resources(
                              ^^^^^^^^^^^^^^^^^^^^^^^^^^^^^^^

      File "/home/stguser/devstack/python-tempestconf/.venv/lib/python3.12/site-packages/tempest/lib/common/dynamic_creds.py", line 318, in _create_network_resources
    router = self._create_router(router_name, tenant_id)
             ^^^^^^^^^^^^^^^^^^^^^^^^^^^^^^^^^^^^^^^^^^^

      File "/home/stguser/devstack/python-tempestconf/.venv/lib/python3.12/site-packages/tempest/lib/common/dynamic_creds.py", line 379, in _create_router
    resp_body = self.routers_admin_client.create_router(**kwargs)
                ^^^^^^^^^^^^^^^^^^^^^^^^^^^^^^^^^^^^^^^^^^^^^^^^^

      File "/home/stguser/devstack/python-tempestconf/.venv/lib/python3.12/site-packages/tempest/lib/services/network/routers_client.py", line 27, in create_router
    return self.create_resource(uri, post_body)
           ^^^^^^^^^^^^^^^^^^^^^^^^^^^^^^^^^^^^

      File "/home/stguser/devstack/python-tempestconf/.venv/lib/python3.12/site-packages/tempest/lib/services/network/base.py", line 62, in create_resource
    resp, body = self.post(req_uri, req_post_data)
                 ^^^^^^^^^^^^^^^^^^^^^^^^^^^^^^^^^

      File "/home/stguser/devstack/python-tempestconf/.venv/lib/python3.12/site-packages/tempest/lib/common/rest_client.py", line 314, in post
    resp_header, resp_body = self.request(
                             ^^^^^^^^^^^^^

      File "/home/stguser/devstack/python-tempestconf/.venv/lib/python3.12/site-packages/tempest/lib/common/rest_client.py", line 746, in request
    resp, resp_body = self._request(method, url, headers=headers,
                      ^^^^^^^^^^^^^^^^^^^^^^^^^^^^^^^^^^^^^^^^^^^

      File "/home/stguser/devstack/python-tempestconf/.venv/lib/python3.12/site-packages/tempest/lib/common/rest_client.py", line 612, in _request
    resp, resp_body = self.raw_request(
                      ^^^^^^^^^^^^^^^^^

      File "/home/stguser/devstack/python-tempestconf/.venv/lib/python3.12/site-packages/tempest/lib/common/rest_client.py", line 661, in raw_request
    resp, resp_body = self.http_obj.request(
                      ^^^^^^^^^^^^^^^^^^^^^^

      File "/home/stguser/devstack/python-tempestconf/.venv/lib/python3.12/site-packages/tempest/lib/common/http.py", line 123, in request
    r = super(ClosingHttp, self).request(method, url, retries=retry,
        ^^^^^^^^^^^^^^^^^^^^^^^^^^^^^^^^^^^^^^^^^^^^^^^^^^^^^^^^^^^^

      File "/home/stguser/devstack/python-tempestconf/.venv/lib/python3.12/site-packages/urllib3/_request_methods.py", line 143, in request
    return self.request_encode_body(
           ^^^^^^^^^^^^^^^^^^^^^^^^^

      File "/home/stguser/devstack/python-tempestconf/.venv/lib/python3.12/site-packages/urllib3/_request_methods.py", line 278, in request_encode_body
    return self.urlopen(method, url, **extra_kw)
           ^^^^^^^^^^^^^^^^^^^^^^^^^^^^^^^^^^^^^

      File "/home/stguser/devstack/python-tempestconf/.venv/lib/python3.12/site-packages/urllib3/poolmanager.py", line 459, in urlopen
    response = conn.urlopen(method, u.request_uri, **kw)
               ^^^^^^^^^^^^^^^^^^^^^^^^^^^^^^^^^^^^^^^^^

      File "/home/stguser/devstack/python-tempestconf/.venv/lib/python3.12/site-packages/urllib3/connectionpool.py", line 841, in urlopen
    retries = retries.increment(
              ^^^^^^^^^^^^^^^^^^

      File "/home/stguser/devstack/python-tempestconf/.venv/lib/python3.12/site-packages/urllib3/util/retry.py", line 474, in increment
    raise reraise(type(error), error, _stacktrace)
          ^^^^^^^^^^^^^^^^^^^^^^^^^^^^^^^^^^^^^^^^

      File "/home/stguser/devstack/python-tempestconf/.venv/lib/python3.12/site-packages/urllib3/util/util.py", line 39, in reraise
    raise value

      File "/home/stguser/devstack/python-tempestconf/.venv/lib/python3.12/site-packages/urllib3/connectionpool.py", line 787, in urlopen
    response = self._make_request(
               ^^^^^^^^^^^^^^^^^^^

      File "/home/stguser/devstack/python-tempestconf/.venv/lib/python3.12/site-packages/urllib3/connectionpool.py", line 536, in _make_request
    self._raise_timeout(err=e, url=url, timeout_value=read_timeout)

      File "/home/stguser/devstack/python-tempestconf/.venv/lib/python3.12/site-packages/urllib3/connectionpool.py", line 367, in _raise_timeout
    raise ReadTimeoutError(

    urllib3.exceptions.ReadTimeoutError: HTTPConnectionPool(host='9.180.170.14', port=9696): Read timed out. (read timeout=60)



======
Totals
======
Ran: 166 tests in 243.2132 sec.
 - Passed: 156
 - Skipped: 6
 - Expected Fail: 0
 - Unexpected Success: 0
 - Failed: 4
Sum of execute time for each test: 2692.4568 sec.

==============
Worker Balance
==============
 - Worker 0 (3 tests) => 0:03:57.413058
 - Worker 1 (2 tests) => 0:03:16.345201
 - Worker 2 (8 tests) => 0:03:14.455948
 - Worker 3 (2 tests) => 0:03:18.796155
 - Worker 4 (5 tests) => 0:02:57.132333
 - Worker 5 (3 tests) => 0:03:27.163325
 - Worker 6 (2 tests) => 0:02:32.564145
 - Worker 7 (2 tests) => 0:02:38.759623
 - Worker 8 (27 tests) => 0:02:14.378768
 - Worker 9 (2 tests) => 0:01:59.073569
 - Worker 10 (2 tests) => 0:01:54.537608
 - Worker 11 (1 tests) => 0:01:54.860472
 - Worker 12 (7 tests) => 0:01:39.453186
 - Worker 13 (5 tests) => 0:01:45.238406
 - Worker 14 (2 tests) => 0:01:34.289527
 - Worker 15 (1 tests) => 0:00:00
 - Worker 16 (6 tests) => 0:01:29.850304
 - Worker 17 (6 tests) => 0:01:16.163956
 - Worker 18 (1 tests) => 0:00:00
 - Worker 19 (3 tests) => 0:01:05.154172
 - Worker 20 (12 tests) => 0:00:44.711134
 - Worker 21 (2 tests) => 0:00:37.766720
 - Worker 22 (1 tests) => 0:00:00
 - Worker 23 (1 tests) => 0:00:00
 - Worker 24 (5 tests) => 0:00:31.513968
 - Worker 25 (2 tests) => 0:00:12.293967
 - Worker 26 (5 tests) => 0:00:08.102800
 - Worker 27 (2 tests) => 0:00:50.659329
 - Worker 28 (1 tests) => 0:00:18.672967
 - Worker 29 (2 tests) => 0:00:09.306125
 - Worker 30 (2 tests) => 0:00:11.057318
 - Worker 31 (2 tests) => 0:00:15.461596
 - Worker 32 (2 tests) => 0:00:05.228434
 - Worker 33 (1 tests) => 0:00:05.562924
 - Worker 34 (18 tests) => 0:00:04.389319
 - Worker 35 (2 tests) => 0:00:06.278743
 - Worker 36 (1 tests) => 0:00:05.006607
 - Worker 37 (1 tests) => 0:00:04.712521
 - Worker 38 (1 tests) => 0:00:03.616697
 - Worker 39 (13 tests) => 0:00:01.208920
