{5} setUpClass (tempest.api.volume.admin.test_volume_retype.VolumeRetypeWithMigrationTest) ... SKIPPED: Cinder multi-backend feature disabled
{1} setUpClass (tempest.api.volume.admin.test_encrypted_volumes_extend.EncryptedVolumesExtendAttachedTest) ... SKIPPED: Attached encrypted volume extend is disabled.
{4} setUpClass (tempest.api.volume.admin.test_multi_backend.VolumeMultiBackendTest) ... SKIPPED: Cinder multi-backend feature disabled
{0} setUpClass (tempest.api.volume.test_volumes_backup.VolumesBackupsTest) ... SKIPPED: Cinder backup feature disabled
{30} tempest.api.volume.test_versions.VersionsTest.test_list_versions [0.029776s] ... ok
{35} tempest.api.volume.test_availability_zone.AvailabilityZoneTestJSON.test_get_availability_zone_list [7.915428s] ... ok
{27} tempest.api.volume.test_volumes_snapshots_negative.VolumesSnapshotNegativeTestJSON.test_create_snapshot_with_nonexistent_volume_id [8.077326s] ... ok
{33} tempest.api.volume.test_extensions.ExtensionsTestJSON.test_list_extensions [8.723689s] ... ok
{32} tempest.api.volume.test_volumes_get.VolumesSummaryTest.test_show_volume_summary [9.302358s] ... ok
{27} tempest.api.volume.test_volumes_snapshots_negative.VolumesSnapshotNegativeTestJSON.test_create_snapshot_without_passing_volume_id [1.259321s] ... ok
{27} tempest.api.volume.test_volumes_snapshots_negative.VolumesSnapshotNegativeTestJSON.test_list_snapshot_invalid_param_limit [0.033308s] ... ok
{27} tempest.api.volume.test_volumes_snapshots_negative.VolumesSnapshotNegativeTestJSON.test_list_snapshots_invalid_param_marker [0.097050s] ... ok
{27} tempest.api.volume.test_volumes_snapshots_negative.VolumesSnapshotNegativeTestJSON.test_list_snapshots_invalid_param_sort [0.011386s] ... ok
{30} tempest.api.volume.test_versions.VersionsTest.test_show_version [11.450440s] ... ok
{23} tempest.api.volume.admin.test_volume_hosts.VolumeHostsAdminTestsJSON.test_list_hosts [2.897516s] ... ok
{28} tempest.api.volume.admin.test_volume_pools.VolumePoolsAdminTestsJSON.test_get_pools_with_details [6.317259s] ... ok
{22} tempest.api.volume.admin.test_volume_types_negative.VolumeTypesNegativeTest.test_create_volume_type_encryption_nonexistent_type_id [8.267986s] ... ok
{24} tempest.api.volume.admin.test_volume_services_negative.VolumeServicesNegativeTest.test_disable_log_reason_with_no_reason [1.354332s] ... ok
{9} tempest.api.volume.admin.test_volume_services.VolumesServicesTestJSON.test_get_service_by_host_name [1.692237s] ... ok
{20} tempest.api.volume.admin.test_volume_quota_classes.VolumeQuotaClassesTest.test_show_default_quota [2.277267s] ... ok
{28} tempest.api.volume.admin.test_volume_pools.VolumePoolsAdminTestsJSON.test_get_pools_without_details [1.793158s] ... ok
{26} tempest.api.volume.admin.test_volume_types_extra_specs_negative.ExtraSpecsNegativeTest.test_create_invalid_body [2.034192s] ... ok
{24} tempest.api.volume.admin.test_volume_services_negative.VolumeServicesNegativeTest.test_disable_service_with_invalid_binary [1.822879s] ... ok
{9} tempest.api.volume.admin.test_volume_services.VolumesServicesTestJSON.test_get_service_by_service_and_host_name [4.756786s] ... ok
{26} tempest.api.volume.admin.test_volume_types_extra_specs_negative.ExtraSpecsNegativeTest.test_create_none_body [6.183186s] ... ok
{25} tempest.api.volume.admin.test_backends_capabilities.BackendsCapabilitiesAdminTestsJSON.test_compare_volume_stats_values [8.622348s] ... ok
{24} tempest.api.volume.admin.test_volume_services_negative.VolumeServicesNegativeTest.test_enable_service_with_invalid_host [6.050274s] ... ok
{9} tempest.api.volume.admin.test_volume_services.VolumesServicesTestJSON.test_get_service_by_service_binary_name [4.927846s] ... ok
{26} tempest.api.volume.admin.test_volume_types_extra_specs_negative.ExtraSpecsNegativeTest.test_create_nonexistent_type_id [3.935283s] ... ok
{24} tempest.api.volume.admin.test_volume_services_negative.VolumeServicesNegativeTest.test_freeze_host_with_invalid_host [3.779018s] ... ok
{25} tempest.api.volume.admin.test_backends_capabilities.BackendsCapabilitiesAdminTestsJSON.test_get_capabilities_backend [4.294896s] ... ok
{24} tempest.api.volume.admin.test_volume_services_negative.VolumeServicesNegativeTest.test_thaw_host_with_invalid_host [6.146557s] ... ok
{26} tempest.api.volume.admin.test_volume_types_extra_specs_negative.ExtraSpecsNegativeTest.test_delete_nonexistent_volume_type_id [6.184405s] ... ok
{22} tempest.api.volume.admin.test_volume_types_negative.VolumeTypesNegativeTest.test_create_volume_with_private_volume_type [26.129796s] ... ok
{21} tempest.api.volume.admin.test_volume_types_extra_specs.VolumeTypesExtraSpecsTest.test_volume_type_extra_spec_create_get_delete [26.165883s] ... ok
{26} tempest.api.volume.admin.test_volume_types_extra_specs_negative.ExtraSpecsNegativeTest.test_get_nonexistent_extra_spec_name [8.048551s] ... ok
{22} tempest.api.volume.admin.test_volume_types_negative.VolumeTypesNegativeTest.test_create_with_empty_name [1.280608s] ... ok
{17} tempest.api.volume.admin.test_volume_types.VolumeTypesTest.test_volume_type_create_get_delete [29.508829s] ... ok
{26} tempest.api.volume.admin.test_volume_types_extra_specs_negative.ExtraSpecsNegativeTest.test_get_nonexistent_volume_type_id [1.926338s] ... ok
{23} tempest.api.volume.admin.test_volume_hosts.VolumeHostsAdminTestsJSON.test_show_host [31.837967s] ... ok
{26} tempest.api.volume.admin.test_volume_types_extra_specs_negative.ExtraSpecsNegativeTest.test_list_nonexistent_volume_type_id [3.517691s] ... ok
{26} tempest.api.volume.admin.test_volume_types_extra_specs_negative.ExtraSpecsNegativeTest.test_update_multiple_extra_spec [0.219943s] ... ok
{26} tempest.api.volume.admin.test_volume_types_extra_specs_negative.ExtraSpecsNegativeTest.test_update_no_body [0.014949s] ... ok
{26} tempest.api.volume.admin.test_volume_types_extra_specs_negative.ExtraSpecsNegativeTest.test_update_none_extra_spec_id [0.167108s] ... ok
{26} tempest.api.volume.admin.test_volume_types_extra_specs_negative.ExtraSpecsNegativeTest.test_update_nonexistent_extra_spec_id [0.071405s] ... ok
{26} tempest.api.volume.admin.test_volume_types_extra_specs_negative.ExtraSpecsNegativeTest.test_update_nonexistent_type_id [0.032989s] ... ok
{21} tempest.api.volume.admin.test_volume_types_extra_specs.VolumeTypesExtraSpecsTest.test_volume_type_extra_specs_list [8.398407s] ... ok
{22} tempest.api.volume.admin.test_volume_types_negative.VolumeTypesNegativeTest.test_create_with_repeated_name [15.324889s] ... ok
{22} tempest.api.volume.admin.test_volume_types_negative.VolumeTypesNegativeTest.test_delete_nonexistent_type_id [0.018147s] ... ok
{22} tempest.api.volume.admin.test_volume_types_negative.VolumeTypesNegativeTest.test_get_nonexistent_type_id [0.049591s] ... ok
{21} tempest.api.volume.admin.test_volume_types_extra_specs.VolumeTypesExtraSpecsTest.test_volume_type_extra_specs_update [10.660886s] ... ok
{17} tempest.api.volume.admin.test_volume_types.VolumeTypesTest.test_volume_type_encryption_create_get_update_delete [23.820556s] ... ok
{17} tempest.api.volume.admin.test_volume_types.VolumeTypesTest.test_volume_type_list [1.279312s] ... ok
{18} tempest.api.volume.admin.test_qos.QosSpecsTestJSON.test_associate_disassociate_qos [64.087248s] ... ok
{39} tempest.api.volume.test_volume_absolute_limits.AbsoluteLimitsTests.test_get_volume_absolute_limits [19.132366s] ... ok
{16} setUpClass (tempest.api.volume.test_volumes_snapshots.VolumesSnapshotTestJSON) [0.000000s] ... FAILED

Captured traceback:
~~~~~~~~~~~~~~~~~~~
    Traceback (most recent call last):

      File "/home/stguser/devstack/python-tempestconf/.venv/lib/python3.12/site-packages/urllib3/connectionpool.py", line 534, in _make_request
    response = conn.getresponse()
               ^^^^^^^^^^^^^^^^^^

      File "/home/stguser/devstack/python-tempestconf/.venv/lib/python3.12/site-packages/urllib3/connection.py", line 565, in getresponse
    httplib_response = super().getresponse()
                       ^^^^^^^^^^^^^^^^^^^^^

      File "/usr/lib/python3.12/http/client.py", line 1428, in getresponse
    response.begin()

      File "/usr/lib/python3.12/http/client.py", line 331, in begin
    version, status, reason = self._read_status()
                              ^^^^^^^^^^^^^^^^^^^

      File "/usr/lib/python3.12/http/client.py", line 292, in _read_status
    line = str(self.fp.readline(_MAXLINE + 1), "iso-8859-1")
               ^^^^^^^^^^^^^^^^^^^^^^^^^^^^^^

      File "/usr/lib/python3.12/socket.py", line 707, in readinto
    return self._sock.recv_into(b)
           ^^^^^^^^^^^^^^^^^^^^^^^

    TimeoutError: timed out

    
The above exception was the direct cause of the following exception:


    Traceback (most recent call last):

      File "/home/stguser/devstack/python-tempestconf/.venv/lib/python3.12/site-packages/tempest/test.py", line 185, in setUpClass
    raise value.with_traceback(trace)

      File "/home/stguser/devstack/python-tempestconf/.venv/lib/python3.12/site-packages/tempest/test.py", line 170, in setUpClass
    cls.setup_credentials()

      File "/home/stguser/devstack/python-tempestconf/.venv/lib/python3.12/site-packages/tempest/api/volume/base.py", line 62, in setup_credentials
    super(BaseVolumeTest, cls).setup_credentials()

      File "/home/stguser/devstack/python-tempestconf/.venv/lib/python3.12/site-packages/tempest/test.py", line 398, in setup_credentials
    manager = cls.get_client_manager(
              ^^^^^^^^^^^^^^^^^^^^^^^

      File "/home/stguser/devstack/python-tempestconf/.venv/lib/python3.12/site-packages/tempest/test.py", line 743, in get_client_manager
    creds = getattr(cred_provider, credentials_method)()
            ^^^^^^^^^^^^^^^^^^^^^^^^^^^^^^^^^^^^^^^^^^^^

      File "/home/stguser/devstack/python-tempestconf/.venv/lib/python3.12/site-packages/tempest/lib/common/dynamic_creds.py", line 473, in get_primary_creds
    return self.get_project_member_creds()
           ^^^^^^^^^^^^^^^^^^^^^^^^^^^^^^^

      File "/home/stguser/devstack/python-tempestconf/.venv/lib/python3.12/site-packages/tempest/lib/common/dynamic_creds.py", line 514, in get_project_member_creds
    return self.get_credentials(['member'], scope='project')
           ^^^^^^^^^^^^^^^^^^^^^^^^^^^^^^^^^^^^^^^^^^^^^^^^^

      File "/home/stguser/devstack/python-tempestconf/.venv/lib/python3.12/site-packages/tempest/lib/common/dynamic_creds.py", line 459, in get_credentials
    network, subnet, router = self._create_network_resources(
                              ^^^^^^^^^^^^^^^^^^^^^^^^^^^^^^^

      File "/home/stguser/devstack/python-tempestconf/.venv/lib/python3.12/site-packages/tempest/lib/common/dynamic_creds.py", line 310, in _create_network_resources
    network = self._create_network(network_name, tenant_id)
              ^^^^^^^^^^^^^^^^^^^^^^^^^^^^^^^^^^^^^^^^^^^^^

      File "/home/stguser/devstack/python-tempestconf/.venv/lib/python3.12/site-packages/tempest/lib/common/dynamic_creds.py", line 338, in _create_network
    resp_body = self.networks_admin_client.create_network(
                ^^^^^^^^^^^^^^^^^^^^^^^^^^^^^^^^^^^^^^^^^^

      File "/home/stguser/devstack/python-tempestconf/.venv/lib/python3.12/site-packages/tempest/lib/services/network/networks_client.py", line 27, in create_network
    return self.create_resource(uri, post_data)
           ^^^^^^^^^^^^^^^^^^^^^^^^^^^^^^^^^^^^

      File "/home/stguser/devstack/python-tempestconf/.venv/lib/python3.12/site-packages/tempest/lib/services/network/base.py", line 62, in create_resource
    resp, body = self.post(req_uri, req_post_data)
                 ^^^^^^^^^^^^^^^^^^^^^^^^^^^^^^^^^

      File "/home/stguser/devstack/python-tempestconf/.venv/lib/python3.12/site-packages/tempest/lib/common/rest_client.py", line 314, in post
    resp_header, resp_body = self.request(
                             ^^^^^^^^^^^^^

      File "/home/stguser/devstack/python-tempestconf/.venv/lib/python3.12/site-packages/tempest/lib/common/rest_client.py", line 746, in request
    resp, resp_body = self._request(method, url, headers=headers,
                      ^^^^^^^^^^^^^^^^^^^^^^^^^^^^^^^^^^^^^^^^^^^

      File "/home/stguser/devstack/python-tempestconf/.venv/lib/python3.12/site-packages/tempest/lib/common/rest_client.py", line 612, in _request
    resp, resp_body = self.raw_request(
                      ^^^^^^^^^^^^^^^^^

      File "/home/stguser/devstack/python-tempestconf/.venv/lib/python3.12/site-packages/tempest/lib/common/rest_client.py", line 661, in raw_request
    resp, resp_body = self.http_obj.request(
                      ^^^^^^^^^^^^^^^^^^^^^^

      File "/home/stguser/devstack/python-tempestconf/.venv/lib/python3.12/site-packages/tempest/lib/common/http.py", line 123, in request
    r = super(ClosingHttp, self).request(method, url, retries=retry,
        ^^^^^^^^^^^^^^^^^^^^^^^^^^^^^^^^^^^^^^^^^^^^^^^^^^^^^^^^^^^^

      File "/home/stguser/devstack/python-tempestconf/.venv/lib/python3.12/site-packages/urllib3/_request_methods.py", line 143, in request
    return self.request_encode_body(
           ^^^^^^^^^^^^^^^^^^^^^^^^^

      File "/home/stguser/devstack/python-tempestconf/.venv/lib/python3.12/site-packages/urllib3/_request_methods.py", line 278, in request_encode_body
    return self.urlopen(method, url, **extra_kw)
           ^^^^^^^^^^^^^^^^^^^^^^^^^^^^^^^^^^^^^

      File "/home/stguser/devstack/python-tempestconf/.venv/lib/python3.12/site-packages/urllib3/poolmanager.py", line 459, in urlopen
    response = conn.urlopen(method, u.request_uri, **kw)
               ^^^^^^^^^^^^^^^^^^^^^^^^^^^^^^^^^^^^^^^^^

      File "/home/stguser/devstack/python-tempestconf/.venv/lib/python3.12/site-packages/urllib3/connectionpool.py", line 841, in urlopen
    retries = retries.increment(
              ^^^^^^^^^^^^^^^^^^

      File "/home/stguser/devstack/python-tempestconf/.venv/lib/python3.12/site-packages/urllib3/util/retry.py", line 474, in increment
    raise reraise(type(error), error, _stacktrace)
          ^^^^^^^^^^^^^^^^^^^^^^^^^^^^^^^^^^^^^^^^

      File "/home/stguser/devstack/python-tempestconf/.venv/lib/python3.12/site-packages/urllib3/util/util.py", line 39, in reraise
    raise value

      File "/home/stguser/devstack/python-tempestconf/.venv/lib/python3.12/site-packages/urllib3/connectionpool.py", line 787, in urlopen
    response = self._make_request(
               ^^^^^^^^^^^^^^^^^^^

      File "/home/stguser/devstack/python-tempestconf/.venv/lib/python3.12/site-packages/urllib3/connectionpool.py", line 536, in _make_request
    self._raise_timeout(err=e, url=url, timeout_value=read_timeout)

      File "/home/stguser/devstack/python-tempestconf/.venv/lib/python3.12/site-packages/urllib3/connectionpool.py", line 367, in _raise_timeout
    raise ReadTimeoutError(

    urllib3.exceptions.ReadTimeoutError: HTTPConnectionPool(host='9.180.170.14', port=9696): Read timed out. (read timeout=60)

{36} tempest.api.volume.test_volume_metadata.VolumesMetadataTest.test_crud_volume_metadata [28.183091s] ... ok
{12} tempest.api.volume.admin.test_user_messages.UserMessagesTest.test_delete_message [103.506869s] ... ok
{29} tempest.api.volume.admin.test_volume_quotas_negative.VolumeQuotasNegativeTestJSON.test_quota_volume_gigabytes [16.841115s] ... ok
{20} tempest.api.volume.admin.test_volume_quota_classes.VolumeQuotaClassesTest.test_update_default_quota [104.251213s] ... ok
{10} tempest.api.volume.test_volumes_clone_negative.VolumesCloneNegativeTest.test_create_from_volume_decreasing_size [135.587817s] ... ok
{36} tempest.api.volume.test_volume_metadata.VolumesMetadataTest.test_update_show_volume_metadata_item [14.701385s] ... ok
{18} tempest.api.volume.admin.test_qos.QosSpecsTestJSON.test_create_delete_qos_with_back_end_consumer [46.247534s] ... ok
{29} tempest.api.volume.admin.test_volume_quotas_negative.VolumeQuotasNegativeTestJSON.test_quota_volumes [7.956245s] ... ok
{3} tempest.api.volume.admin.test_volume_quotas.VolumeQuotasAdminTestJSON.test_delete_quota [115.700223s] ... ok
{3} tempest.api.volume.admin.test_volume_quotas.VolumeQuotasAdminTestJSON.test_list_default_quotas [0.617339s] ... ok
{3} tempest.api.volume.admin.test_volume_quotas.VolumeQuotasAdminTestJSON.test_list_quotas [0.665090s] ... ok
{18} tempest.api.volume.admin.test_qos.QosSpecsTestJSON.test_create_delete_qos_with_both_consumer [6.763924s] ... ok
{13} setUpClass (tempest.api.volume.admin.test_volume_retype.VolumeRetypeWithoutMigrationTest) [0.000000s] ... FAILED

Captured traceback:
~~~~~~~~~~~~~~~~~~~
    Traceback (most recent call last):

      File "/home/stguser/devstack/python-tempestconf/.venv/lib/python3.12/site-packages/tempest/test.py", line 185, in setUpClass
    raise value.with_traceback(trace)

      File "/home/stguser/devstack/python-tempestconf/.venv/lib/python3.12/site-packages/tempest/test.py", line 178, in setUpClass
    cls.resource_setup()

      File "/home/stguser/devstack/python-tempestconf/.venv/lib/python3.12/site-packages/tempest/api/volume/admin/test_volume_retype.py", line 172, in resource_setup
    cls.src_vol_type = cls.create_volume_type('volume-type-1')
                       ^^^^^^^^^^^^^^^^^^^^^^^^^^^^^^^^^^^^^^^

      File "/home/stguser/devstack/python-tempestconf/.venv/lib/python3.12/site-packages/tempest/api/volume/base.py", line 366, in create_volume_type
    volume_type = self.admin_volume_types_client.create_volume_type(
                  ^^^^^^^^^^^^^^^^^^^^^^^^^^^^^^^^^^^^^^^^^^^^^^^^^^

      File "/home/stguser/devstack/python-tempestconf/.venv/lib/python3.12/site-packages/tempest/lib/services/volume/v3/types_client.py", line 90, in create_volume_type
    resp, body = self.post('types', post_body)
                 ^^^^^^^^^^^^^^^^^^^^^^^^^^^^^

      File "/home/stguser/devstack/python-tempestconf/.venv/lib/python3.12/site-packages/tempest/lib/common/rest_client.py", line 314, in post
    resp_header, resp_body = self.request(
                             ^^^^^^^^^^^^^

      File "/home/stguser/devstack/python-tempestconf/.venv/lib/python3.12/site-packages/tempest/lib/common/rest_client.py", line 762, in request
    self._error_checker(resp, resp_body)

      File "/home/stguser/devstack/python-tempestconf/.venv/lib/python3.12/site-packages/tempest/lib/common/rest_client.py", line 892, in _error_checker
    raise exceptions.Conflict(resp_body, resp=resp)

    tempest.lib.exceptions.Conflict: Conflict with state of target resource
Details: {'code': 409, 'message': 'Volume Type volume-type-1 already exists.'}

{37} tempest.api.volume.test_snapshot_metadata.SnapshotMetadataTestJSON.test_crud_snapshot_metadata [9.603533s] ... ok
{17} tempest.api.volume.admin.test_volume_types.VolumeTypesTest.test_volume_type_update [69.103433s] ... ok
{11} tempest.api.volume.admin.test_snapshots_actions.SnapshotsActionsTest.test_reset_snapshot_status [4.044065s] ... ok
{15} setUpClass (tempest.api.volume.test_volumes_actions.VolumesActionsTest) [0.000000s] ... FAILED

Captured traceback:
~~~~~~~~~~~~~~~~~~~
    Traceback (most recent call last):

      File "/home/stguser/devstack/python-tempestconf/.venv/lib/python3.12/site-packages/urllib3/connectionpool.py", line 534, in _make_request
    response = conn.getresponse()
               ^^^^^^^^^^^^^^^^^^

      File "/home/stguser/devstack/python-tempestconf/.venv/lib/python3.12/site-packages/urllib3/connection.py", line 565, in getresponse
    httplib_response = super().getresponse()
                       ^^^^^^^^^^^^^^^^^^^^^

      File "/usr/lib/python3.12/http/client.py", line 1428, in getresponse
    response.begin()

      File "/usr/lib/python3.12/http/client.py", line 331, in begin
    version, status, reason = self._read_status()
                              ^^^^^^^^^^^^^^^^^^^

      File "/usr/lib/python3.12/http/client.py", line 292, in _read_status
    line = str(self.fp.readline(_MAXLINE + 1), "iso-8859-1")
               ^^^^^^^^^^^^^^^^^^^^^^^^^^^^^^

      File "/usr/lib/python3.12/socket.py", line 707, in readinto
    return self._sock.recv_into(b)
           ^^^^^^^^^^^^^^^^^^^^^^^

    TimeoutError: timed out

    
The above exception was the direct cause of the following exception:


    Traceback (most recent call last):

      File "/home/stguser/devstack/python-tempestconf/.venv/lib/python3.12/site-packages/tempest/test.py", line 185, in setUpClass
    raise value.with_traceback(trace)

      File "/home/stguser/devstack/python-tempestconf/.venv/lib/python3.12/site-packages/tempest/test.py", line 170, in setUpClass
    cls.setup_credentials()

      File "/home/stguser/devstack/python-tempestconf/.venv/lib/python3.12/site-packages/tempest/api/volume/base.py", line 62, in setup_credentials
    super(BaseVolumeTest, cls).setup_credentials()

      File "/home/stguser/devstack/python-tempestconf/.venv/lib/python3.12/site-packages/tempest/test.py", line 398, in setup_credentials
    manager = cls.get_client_manager(
              ^^^^^^^^^^^^^^^^^^^^^^^

      File "/home/stguser/devstack/python-tempestconf/.venv/lib/python3.12/site-packages/tempest/test.py", line 743, in get_client_manager
    creds = getattr(cred_provider, credentials_method)()
            ^^^^^^^^^^^^^^^^^^^^^^^^^^^^^^^^^^^^^^^^^^^^

      File "/home/stguser/devstack/python-tempestconf/.venv/lib/python3.12/site-packages/tempest/lib/common/dynamic_creds.py", line 473, in get_primary_creds
    return self.get_project_member_creds()
           ^^^^^^^^^^^^^^^^^^^^^^^^^^^^^^^

      File "/home/stguser/devstack/python-tempestconf/.venv/lib/python3.12/site-packages/tempest/lib/common/dynamic_creds.py", line 514, in get_project_member_creds
    return self.get_credentials(['member'], scope='project')
           ^^^^^^^^^^^^^^^^^^^^^^^^^^^^^^^^^^^^^^^^^^^^^^^^^

      File "/home/stguser/devstack/python-tempestconf/.venv/lib/python3.12/site-packages/tempest/lib/common/dynamic_creds.py", line 459, in get_credentials
    network, subnet, router = self._create_network_resources(
                              ^^^^^^^^^^^^^^^^^^^^^^^^^^^^^^^

      File "/home/stguser/devstack/python-tempestconf/.venv/lib/python3.12/site-packages/tempest/lib/common/dynamic_creds.py", line 318, in _create_network_resources
    router = self._create_router(router_name, tenant_id)
             ^^^^^^^^^^^^^^^^^^^^^^^^^^^^^^^^^^^^^^^^^^^

      File "/home/stguser/devstack/python-tempestconf/.venv/lib/python3.12/site-packages/tempest/lib/common/dynamic_creds.py", line 379, in _create_router
    resp_body = self.routers_admin_client.create_router(**kwargs)
                ^^^^^^^^^^^^^^^^^^^^^^^^^^^^^^^^^^^^^^^^^^^^^^^^^

      File "/home/stguser/devstack/python-tempestconf/.venv/lib/python3.12/site-packages/tempest/lib/services/network/routers_client.py", line 27, in create_router
    return self.create_resource(uri, post_body)
           ^^^^^^^^^^^^^^^^^^^^^^^^^^^^^^^^^^^^

      File "/home/stguser/devstack/python-tempestconf/.venv/lib/python3.12/site-packages/tempest/lib/services/network/base.py", line 62, in create_resource
    resp, body = self.post(req_uri, req_post_data)
                 ^^^^^^^^^^^^^^^^^^^^^^^^^^^^^^^^^

      File "/home/stguser/devstack/python-tempestconf/.venv/lib/python3.12/site-packages/tempest/lib/common/rest_client.py", line 314, in post
    resp_header, resp_body = self.request(
                             ^^^^^^^^^^^^^

      File "/home/stguser/devstack/python-tempestconf/.venv/lib/python3.12/site-packages/tempest/lib/common/rest_client.py", line 746, in request
    resp, resp_body = self._request(method, url, headers=headers,
                      ^^^^^^^^^^^^^^^^^^^^^^^^^^^^^^^^^^^^^^^^^^^

      File "/home/stguser/devstack/python-tempestconf/.venv/lib/python3.12/site-packages/tempest/lib/common/rest_client.py", line 612, in _request
    resp, resp_body = self.raw_request(
                      ^^^^^^^^^^^^^^^^^

      File "/home/stguser/devstack/python-tempestconf/.venv/lib/python3.12/site-packages/tempest/lib/common/rest_client.py", line 661, in raw_request
    resp, resp_body = self.http_obj.request(
                      ^^^^^^^^^^^^^^^^^^^^^^

      File "/home/stguser/devstack/python-tempestconf/.venv/lib/python3.12/site-packages/tempest/lib/common/http.py", line 123, in request
    r = super(ClosingHttp, self).request(method, url, retries=retry,
        ^^^^^^^^^^^^^^^^^^^^^^^^^^^^^^^^^^^^^^^^^^^^^^^^^^^^^^^^^^^^

      File "/home/stguser/devstack/python-tempestconf/.venv/lib/python3.12/site-packages/urllib3/_request_methods.py", line 143, in request
    return self.request_encode_body(
           ^^^^^^^^^^^^^^^^^^^^^^^^^

      File "/home/stguser/devstack/python-tempestconf/.venv/lib/python3.12/site-packages/urllib3/_request_methods.py", line 278, in request_encode_body
    return self.urlopen(method, url, **extra_kw)
           ^^^^^^^^^^^^^^^^^^^^^^^^^^^^^^^^^^^^^

      File "/home/stguser/devstack/python-tempestconf/.venv/lib/python3.12/site-packages/urllib3/poolmanager.py", line 459, in urlopen
    response = conn.urlopen(method, u.request_uri, **kw)
               ^^^^^^^^^^^^^^^^^^^^^^^^^^^^^^^^^^^^^^^^^

      File "/home/stguser/devstack/python-tempestconf/.venv/lib/python3.12/site-packages/urllib3/connectionpool.py", line 841, in urlopen
    retries = retries.increment(
              ^^^^^^^^^^^^^^^^^^

      File "/home/stguser/devstack/python-tempestconf/.venv/lib/python3.12/site-packages/urllib3/util/retry.py", line 474, in increment
    raise reraise(type(error), error, _stacktrace)
          ^^^^^^^^^^^^^^^^^^^^^^^^^^^^^^^^^^^^^^^^

      File "/home/stguser/devstack/python-tempestconf/.venv/lib/python3.12/site-packages/urllib3/util/util.py", line 39, in reraise
    raise value

      File "/home/stguser/devstack/python-tempestconf/.venv/lib/python3.12/site-packages/urllib3/connectionpool.py", line 787, in urlopen
    response = self._make_request(
               ^^^^^^^^^^^^^^^^^^^

      File "/home/stguser/devstack/python-tempestconf/.venv/lib/python3.12/site-packages/urllib3/connectionpool.py", line 536, in _make_request
    self._raise_timeout(err=e, url=url, timeout_value=read_timeout)

      File "/home/stguser/devstack/python-tempestconf/.venv/lib/python3.12/site-packages/urllib3/connectionpool.py", line 367, in _raise_timeout
    raise ReadTimeoutError(

    urllib3.exceptions.ReadTimeoutError: HTTPConnectionPool(host='9.180.170.14', port=9696): Read timed out. (read timeout=60)

{9} tempest.api.volume.admin.test_volume_services.VolumesServicesTestJSON.test_get_service_by_volume_host_name [113.043022s] ... ok
{9} tempest.api.volume.admin.test_volume_services.VolumesServicesTestJSON.test_list_services [0.708163s] ... ok
{37} tempest.api.volume.test_snapshot_metadata.SnapshotMetadataTestJSON.test_update_show_snapshot_metadata_item [7.001698s] ... ok
{8} tempest.api.volume.admin.test_volume_type_access.VolumeTypesAccessTest.test_volume_type_access_add [127.300132s] ... ok
{12} tempest.api.volume.admin.test_user_messages.UserMessagesTest.test_list_show_messages [33.288886s] ... ok
{31} tempest.api.volume.admin.test_volume_snapshot_quotas_negative.VolumeSnapshotQuotasNegativeTestJSON.test_quota_volume_gigabytes_snapshots [4.178073s] ... ok
{31} tempest.api.volume.admin.test_volume_snapshot_quotas_negative.VolumeSnapshotQuotasNegativeTestJSON.test_quota_volume_snapshots [0.690073s] ... ok
{34} tempest.api.volume.test_volumes_list.VolumesListTestJSON.test_volume_list [0.204405s] ... ok
{34} tempest.api.volume.test_volumes_list.VolumesListTestJSON.test_volume_list_by_name [0.099170s] ... ok
{34} tempest.api.volume.test_volumes_list.VolumesListTestJSON.test_volume_list_details_by_name [0.087760s] ... ok
{34} tempest.api.volume.test_volumes_list.VolumesListTestJSON.test_volume_list_details_pagination [0.380089s] ... ok
{34} tempest.api.volume.test_volumes_list.VolumesListTestJSON.test_volume_list_details_with_multiple_params [0.643995s] ... ok
{34} tempest.api.volume.test_volumes_list.VolumesListTestJSON.test_volume_list_pagination [0.180296s] ... ok
{34} tempest.api.volume.test_volumes_list.VolumesListTestJSON.test_volume_list_param_display_name_and_status [0.080466s] ... ok
{34} tempest.api.volume.test_volumes_list.VolumesListTestJSON.test_volume_list_with_detail_param_display_name_and_status [0.090871s] ... ok
{34} tempest.api.volume.test_volumes_list.VolumesListTestJSON.test_volume_list_with_detail_param_marker [0.100143s] ... ok
{18} tempest.api.volume.admin.test_qos.QosSpecsTestJSON.test_create_delete_qos_with_front_end_consumer [12.962557s] ... ok
{18} tempest.api.volume.admin.test_qos.QosSpecsTestJSON.test_get_qos [0.041314s] ... ok
{34} tempest.api.volume.test_volumes_list.VolumesListTestJSON.test_volume_list_with_detail_param_metadata [0.468282s] ... ok
{34} tempest.api.volume.test_volumes_list.VolumesListTestJSON.test_volume_list_with_details [0.062712s] ... ok
{34} tempest.api.volume.test_volumes_list.VolumesListTestJSON.test_volume_list_with_param_metadata [0.094522s] ... ok
{34} tempest.api.volume.test_volumes_list.VolumesListTestJSON.test_volumes_list_by_availability_zone [0.152095s] ... ok
{34} tempest.api.volume.test_volumes_list.VolumesListTestJSON.test_volumes_list_by_bootable [0.156429s] ... ok
{8} tempest.api.volume.admin.test_volume_type_access.VolumeTypesAccessTest.test_volume_type_access_list [6.362409s] ... ok
{34} tempest.api.volume.test_volumes_list.VolumesListTestJSON.test_volumes_list_by_status [0.294697s] ... ok
{18} tempest.api.volume.admin.test_qos.QosSpecsTestJSON.test_list_qos [1.303251s] ... ok
{34} tempest.api.volume.test_volumes_list.VolumesListTestJSON.test_volumes_list_details_by_availability_zone [0.130552s] ... ok
{34} tempest.api.volume.test_volumes_list.VolumesListTestJSON.test_volumes_list_details_by_bootable [0.115057s] ... ok
{34} tempest.api.volume.test_volumes_list.VolumesListTestJSON.test_volumes_list_details_by_status [0.156683s] ... ok
{18} tempest.api.volume.admin.test_qos.QosSpecsTestJSON.test_set_unset_qos_key [1.853030s] ... ok
{4} tempest.api.volume.test_volume_transfers.VolumesTransfersTest.test_create_get_list_accept_volume_transfer [136.848382s] ... ok
{6} tempest.api.volume.test_volume_transfers.VolumesTransfersV357Test.test_create_get_list_accept_volume_transfer [137.365886s] ... ok
{38} tempest.api.volume.test_volumes_snapshots_list.VolumesSnapshotListTestJSON.test_snapshot_list_param_limit [0.041021s] ... ok
{38} tempest.api.volume.test_volumes_snapshots_list.VolumesSnapshotListTestJSON.test_snapshot_list_param_limit_equals_infinite [0.334736s] ... ok
{38} tempest.api.volume.test_volumes_snapshots_list.VolumesSnapshotListTestJSON.test_snapshot_list_param_limit_equals_zero [0.026819s] ... ok
{38} tempest.api.volume.test_volumes_snapshots_list.VolumesSnapshotListTestJSON.test_snapshot_list_param_marker [0.116678s] ... ok
{38} tempest.api.volume.test_volumes_snapshots_list.VolumesSnapshotListTestJSON.test_snapshot_list_param_offset [0.040003s] ... ok
{38} tempest.api.volume.test_volumes_snapshots_list.VolumesSnapshotListTestJSON.test_snapshot_list_param_sort_created_at_asc [0.051963s] ... ok
{38} tempest.api.volume.test_volumes_snapshots_list.VolumesSnapshotListTestJSON.test_snapshot_list_param_sort_created_at_desc [0.041554s] ... ok
{38} tempest.api.volume.test_volumes_snapshots_list.VolumesSnapshotListTestJSON.test_snapshot_list_param_sort_id_asc [0.048652s] ... ok
{38} tempest.api.volume.test_volumes_snapshots_list.VolumesSnapshotListTestJSON.test_snapshot_list_param_sort_id_desc [0.041593s] ... ok
{38} tempest.api.volume.test_volumes_snapshots_list.VolumesSnapshotListTestJSON.test_snapshot_list_param_sort_name_asc [0.042459s] ... ok
{38} tempest.api.volume.test_volumes_snapshots_list.VolumesSnapshotListTestJSON.test_snapshot_list_param_sort_name_desc [0.042940s] ... ok
{38} tempest.api.volume.test_volumes_snapshots_list.VolumesSnapshotListTestJSON.test_snapshots_list_details_with_params [0.221331s] ... ok
{7} setUpClass (tempest.api.volume.admin.test_volumes_actions.VolumesActionsTest) [0.000000s] ... FAILED

Captured traceback:
~~~~~~~~~~~~~~~~~~~
    Traceback (most recent call last):

      File "/home/stguser/devstack/python-tempestconf/.venv/lib/python3.12/site-packages/urllib3/connectionpool.py", line 534, in _make_request
    response = conn.getresponse()
               ^^^^^^^^^^^^^^^^^^

      File "/home/stguser/devstack/python-tempestconf/.venv/lib/python3.12/site-packages/urllib3/connection.py", line 565, in getresponse
    httplib_response = super().getresponse()
                       ^^^^^^^^^^^^^^^^^^^^^

      File "/usr/lib/python3.12/http/client.py", line 1428, in getresponse
    response.begin()

      File "/usr/lib/python3.12/http/client.py", line 331, in begin
    version, status, reason = self._read_status()
                              ^^^^^^^^^^^^^^^^^^^

      File "/usr/lib/python3.12/http/client.py", line 292, in _read_status
    line = str(self.fp.readline(_MAXLINE + 1), "iso-8859-1")
               ^^^^^^^^^^^^^^^^^^^^^^^^^^^^^^

      File "/usr/lib/python3.12/socket.py", line 707, in readinto
    return self._sock.recv_into(b)
           ^^^^^^^^^^^^^^^^^^^^^^^

    TimeoutError: timed out

    
The above exception was the direct cause of the following exception:


    Traceback (most recent call last):

      File "/home/stguser/devstack/python-tempestconf/.venv/lib/python3.12/site-packages/tempest/test.py", line 185, in setUpClass
    raise value.with_traceback(trace)

      File "/home/stguser/devstack/python-tempestconf/.venv/lib/python3.12/site-packages/tempest/test.py", line 170, in setUpClass
    cls.setup_credentials()

      File "/home/stguser/devstack/python-tempestconf/.venv/lib/python3.12/site-packages/tempest/api/volume/base.py", line 62, in setup_credentials
    super(BaseVolumeTest, cls).setup_credentials()

      File "/home/stguser/devstack/python-tempestconf/.venv/lib/python3.12/site-packages/tempest/test.py", line 398, in setup_credentials
    manager = cls.get_client_manager(
              ^^^^^^^^^^^^^^^^^^^^^^^

      File "/home/stguser/devstack/python-tempestconf/.venv/lib/python3.12/site-packages/tempest/test.py", line 743, in get_client_manager
    creds = getattr(cred_provider, credentials_method)()
            ^^^^^^^^^^^^^^^^^^^^^^^^^^^^^^^^^^^^^^^^^^^^

      File "/home/stguser/devstack/python-tempestconf/.venv/lib/python3.12/site-packages/tempest/lib/common/dynamic_creds.py", line 473, in get_primary_creds
    return self.get_project_member_creds()
           ^^^^^^^^^^^^^^^^^^^^^^^^^^^^^^^

      File "/home/stguser/devstack/python-tempestconf/.venv/lib/python3.12/site-packages/tempest/lib/common/dynamic_creds.py", line 514, in get_project_member_creds
    return self.get_credentials(['member'], scope='project')
           ^^^^^^^^^^^^^^^^^^^^^^^^^^^^^^^^^^^^^^^^^^^^^^^^^

      File "/home/stguser/devstack/python-tempestconf/.venv/lib/python3.12/site-packages/tempest/lib/common/dynamic_creds.py", line 459, in get_credentials
    network, subnet, router = self._create_network_resources(
                              ^^^^^^^^^^^^^^^^^^^^^^^^^^^^^^^

      File "/home/stguser/devstack/python-tempestconf/.venv/lib/python3.12/site-packages/tempest/lib/common/dynamic_creds.py", line 318, in _create_network_resources
    router = self._create_router(router_name, tenant_id)
             ^^^^^^^^^^^^^^^^^^^^^^^^^^^^^^^^^^^^^^^^^^^

      File "/home/stguser/devstack/python-tempestconf/.venv/lib/python3.12/site-packages/tempest/lib/common/dynamic_creds.py", line 379, in _create_router
    resp_body = self.routers_admin_client.create_router(**kwargs)
                ^^^^^^^^^^^^^^^^^^^^^^^^^^^^^^^^^^^^^^^^^^^^^^^^^

      File "/home/stguser/devstack/python-tempestconf/.venv/lib/python3.12/site-packages/tempest/lib/services/network/routers_client.py", line 27, in create_router
    return self.create_resource(uri, post_body)
           ^^^^^^^^^^^^^^^^^^^^^^^^^^^^^^^^^^^^

      File "/home/stguser/devstack/python-tempestconf/.venv/lib/python3.12/site-packages/tempest/lib/services/network/base.py", line 62, in create_resource
    resp, body = self.post(req_uri, req_post_data)
                 ^^^^^^^^^^^^^^^^^^^^^^^^^^^^^^^^^

      File "/home/stguser/devstack/python-tempestconf/.venv/lib/python3.12/site-packages/tempest/lib/common/rest_client.py", line 314, in post
    resp_header, resp_body = self.request(
                             ^^^^^^^^^^^^^

      File "/home/stguser/devstack/python-tempestconf/.venv/lib/python3.12/site-packages/tempest/lib/common/rest_client.py", line 746, in request
    resp, resp_body = self._request(method, url, headers=headers,
                      ^^^^^^^^^^^^^^^^^^^^^^^^^^^^^^^^^^^^^^^^^^^

      File "/home/stguser/devstack/python-tempestconf/.venv/lib/python3.12/site-packages/tempest/lib/common/rest_client.py", line 612, in _request
    resp, resp_body = self.raw_request(
                      ^^^^^^^^^^^^^^^^^

      File "/home/stguser/devstack/python-tempestconf/.venv/lib/python3.12/site-packages/tempest/lib/common/rest_client.py", line 661, in raw_request
    resp, resp_body = self.http_obj.request(
                      ^^^^^^^^^^^^^^^^^^^^^^

      File "/home/stguser/devstack/python-tempestconf/.venv/lib/python3.12/site-packages/tempest/lib/common/http.py", line 123, in request
    r = super(ClosingHttp, self).request(method, url, retries=retry,
        ^^^^^^^^^^^^^^^^^^^^^^^^^^^^^^^^^^^^^^^^^^^^^^^^^^^^^^^^^^^^

      File "/home/stguser/devstack/python-tempestconf/.venv/lib/python3.12/site-packages/urllib3/_request_methods.py", line 143, in request
    return self.request_encode_body(
           ^^^^^^^^^^^^^^^^^^^^^^^^^

      File "/home/stguser/devstack/python-tempestconf/.venv/lib/python3.12/site-packages/urllib3/_request_methods.py", line 278, in request_encode_body
    return self.urlopen(method, url, **extra_kw)
           ^^^^^^^^^^^^^^^^^^^^^^^^^^^^^^^^^^^^^

      File "/home/stguser/devstack/python-tempestconf/.venv/lib/python3.12/site-packages/urllib3/poolmanager.py", line 459, in urlopen
    response = conn.urlopen(method, u.request_uri, **kw)
               ^^^^^^^^^^^^^^^^^^^^^^^^^^^^^^^^^^^^^^^^^

      File "/home/stguser/devstack/python-tempestconf/.venv/lib/python3.12/site-packages/urllib3/connectionpool.py", line 841, in urlopen
    retries = retries.increment(
              ^^^^^^^^^^^^^^^^^^

      File "/home/stguser/devstack/python-tempestconf/.venv/lib/python3.12/site-packages/urllib3/util/retry.py", line 474, in increment
    raise reraise(type(error), error, _stacktrace)
          ^^^^^^^^^^^^^^^^^^^^^^^^^^^^^^^^^^^^^^^^

      File "/home/stguser/devstack/python-tempestconf/.venv/lib/python3.12/site-packages/urllib3/util/util.py", line 39, in reraise
    raise value

      File "/home/stguser/devstack/python-tempestconf/.venv/lib/python3.12/site-packages/urllib3/connectionpool.py", line 787, in urlopen
    response = self._make_request(
               ^^^^^^^^^^^^^^^^^^^

      File "/home/stguser/devstack/python-tempestconf/.venv/lib/python3.12/site-packages/urllib3/connectionpool.py", line 536, in _make_request
    self._raise_timeout(err=e, url=url, timeout_value=read_timeout)

      File "/home/stguser/devstack/python-tempestconf/.venv/lib/python3.12/site-packages/urllib3/connectionpool.py", line 367, in _raise_timeout
    raise ReadTimeoutError(

    urllib3.exceptions.ReadTimeoutError: HTTPConnectionPool(host='9.180.170.14', port=9696): Read timed out. (read timeout=60)

{38} tempest.api.volume.test_volumes_snapshots_list.VolumesSnapshotListTestJSON.test_snapshots_list_with_params [0.156924s] ... ok
{0} tempest.api.volume.test_volumes_get.VolumesGetTest.test_volume_create_get_update_delete [173.003261s] ... ok
{5} tempest.api.volume.test_volume_transfers.VolumesTransfersV355Test.test_create_get_list_accept_volume_transfer [145.925734s] ... ok
{19} tempest.api.volume.admin.test_volumes_list.VolumesListAdminTestJSON.test_volume_list_param_tenant [19.651052s] ... ok
{11} tempest.api.volume.admin.test_snapshots_actions.SnapshotsActionsTest.test_snapshot_force_delete_when_snapshot_is_creating [34.112638s] ... ok
{3} tempest.api.volume.admin.test_volume_quotas.VolumeQuotasAdminTestJSON.test_quota_usage [42.215717s] ... ok
{1} tempest.api.volume.test_volumes_clone.VolumesCloneTest.test_create_from_volume [195.167315s] ... ok
{6} tempest.api.volume.test_volume_transfers.VolumesTransfersV357Test.test_create_list_delete_volume_transfer [36.123581s] ... ok
{4} tempest.api.volume.test_volume_transfers.VolumesTransfersTest.test_create_list_delete_volume_transfer [36.960432s] ... ok
{2} tempest.api.volume.test_volume_delete_cascade.VolumesDeleteCascade.test_volume_delete_cascade [202.300716s] ... ok
{14} tempest.api.volume.test_volumes_negative.VolumesNegativeTest.test_attach_volumes_with_nonexistent_volume_id [125.367390s] ... ok
{5} tempest.api.volume.test_volume_transfers.VolumesTransfersV355Test.test_create_list_delete_volume_transfer [34.812327s] ... ok
{11} tempest.api.volume.admin.test_snapshots_actions.SnapshotsActionsTest.test_snapshot_force_delete_when_snapshot_is_deleting [31.239023s] ... ok
{2} setUpClass (tempest.api.volume.test_volumes_backup.VolumesBackupsV39Test) ... SKIPPED: Cinder backup feature disabled
{14} tempest.api.volume.test_volumes_negative.VolumesNegativeTest.test_create_volume_from_deactivated_image [10.546266s] ... ok
{14} tempest.api.volume.test_volumes_negative.VolumesNegativeTest.test_create_volume_from_image_with_decreasing_size [4.377997s] ... ok
{14} tempest.api.volume.test_volumes_negative.VolumesNegativeTest.test_create_volume_with_invalid_size [0.017504s] ... ok
{14} tempest.api.volume.test_volumes_negative.VolumesNegativeTest.test_create_volume_with_nonexistent_snapshot_id [0.112048s] ... ok
{14} tempest.api.volume.test_volumes_negative.VolumesNegativeTest.test_create_volume_with_nonexistent_source_volid [0.030887s] ... ok
{14} tempest.api.volume.test_volumes_negative.VolumesNegativeTest.test_create_volume_with_nonexistent_volume_type [0.098603s] ... ok
{14} tempest.api.volume.test_volumes_negative.VolumesNegativeTest.test_create_volume_with_size_negative [0.014096s] ... ok
{14} tempest.api.volume.test_volumes_negative.VolumesNegativeTest.test_create_volume_with_size_zero [0.017435s] ... ok
{14} tempest.api.volume.test_volumes_negative.VolumesNegativeTest.test_create_volume_without_passing_size [0.015065s] ... ok
{14} tempest.api.volume.test_volumes_negative.VolumesNegativeTest.test_delete_invalid_volume_id [0.023296s] ... ok
{14} tempest.api.volume.test_volumes_negative.VolumesNegativeTest.test_delete_volume_without_passing_volume_id [0.010956s] ... ok
{14} tempest.api.volume.test_volumes_negative.VolumesNegativeTest.test_detach_volumes_with_invalid_volume_id [0.025907s] ... ok
{14} tempest.api.volume.test_volumes_negative.VolumesNegativeTest.test_get_invalid_volume_id [0.030948s] ... ok
{14} tempest.api.volume.test_volumes_negative.VolumesNegativeTest.test_get_volume_without_passing_volume_id [0.011767s] ... ok
{14} tempest.api.volume.test_volumes_negative.VolumesNegativeTest.test_list_volumes_detail_with_invalid_status [0.123466s] ... ok
{14} tempest.api.volume.test_volumes_negative.VolumesNegativeTest.test_list_volumes_detail_with_nonexistent_name [0.083129s] ... ok
{14} tempest.api.volume.test_volumes_negative.VolumesNegativeTest.test_list_volumes_with_invalid_status [0.034629s] ... ok
{14} tempest.api.volume.test_volumes_negative.VolumesNegativeTest.test_list_volumes_with_nonexistent_name [0.022133s] ... ok
{14} tempest.api.volume.test_volumes_negative.VolumesNegativeTest.test_reserve_volume_with_negative_volume_status [0.450755s] ... ok
{14} tempest.api.volume.test_volumes_negative.VolumesNegativeTest.test_reserve_volume_with_nonexistent_volume_id [0.029929s] ... ok
{14} tempest.api.volume.test_volumes_negative.VolumesNegativeTest.test_unreserve_volume_with_nonexistent_volume_id [0.022661s] ... ok
{14} tempest.api.volume.test_volumes_negative.VolumesNegativeTest.test_update_volume_with_empty_volume_id [0.009708s] ... ok
{14} tempest.api.volume.test_volumes_negative.VolumesNegativeTest.test_update_volume_with_invalid_volume_id [0.025898s] ... ok
{14} tempest.api.volume.test_volumes_negative.VolumesNegativeTest.test_update_volume_with_nonexistent_volume_id [0.027901s] ... ok
{14} tempest.api.volume.test_volumes_negative.VolumesNegativeTest.test_volume_delete_nonexistent_volume_id [0.027887s] ... ok
{14} tempest.api.volume.test_volumes_negative.VolumesNegativeTest.test_volume_get_nonexistent_volume_id [0.033492s] ... ok
{11} tempest.api.volume.admin.test_snapshots_actions.SnapshotsActionsTest.test_snapshot_force_delete_when_snapshot_is_error [11.586149s] ... ok
{3} tempest.api.volume.admin.test_volume_quotas.VolumeQuotasAdminTestJSON.test_quota_usage_after_volume_transfer [37.664468s] ... ok
{3} tempest.api.volume.admin.test_volume_quotas.VolumeQuotasAdminTestJSON.test_show_quota_usage [0.573735s] ... ok
{3} tempest.api.volume.admin.test_volume_quotas.VolumeQuotasAdminTestJSON.test_update_all_quota_resources_for_tenant [4.420705s] ... ok
{11} tempest.api.volume.admin.test_snapshots_actions.SnapshotsActionsTest.test_snapshot_force_delete_when_snapshot_is_error_deleting [12.061637s] ... ok
{0} tempest.api.volume.test_volumes_get.VolumesGetTest.test_volume_create_get_update_delete_as_clone [66.317729s] ... ok
{11} tempest.api.volume.admin.test_snapshots_actions.SnapshotsActionsTest.test_update_snapshot_status [0.558106s] ... ok
{3} setUpClass (tempest.api.volume.admin.test_volumes_backup.VolumesBackupsAdminTest) ... SKIPPED: Cinder backup feature disabled
{19} tearDownClass (tempest.api.volume.admin.test_volumes_list.VolumesListAdminTestJSON) [0.000000s] ... FAILED

Captured traceback:
~~~~~~~~~~~~~~~~~~~
    Traceback (most recent call last):

      File "/home/stguser/devstack/python-tempestconf/.venv/lib/python3.12/site-packages/tempest/test.py", line 246, in tearDownClass
    raise value.with_traceback(trace)

      File "/home/stguser/devstack/python-tempestconf/.venv/lib/python3.12/site-packages/tempest/test.py", line 210, in tearDownClass
    teardown()

      File "/home/stguser/devstack/python-tempestconf/.venv/lib/python3.12/site-packages/tempest/test.py", line 757, in clear_credentials
    cls._creds_provider.clear_creds()

      File "/home/stguser/devstack/python-tempestconf/.venv/lib/python3.12/site-packages/tempest/lib/common/dynamic_creds.py", line 635, in clear_creds
    self.cleanup_default_secgroup(

      File "/home/stguser/devstack/python-tempestconf/.venv/lib/python3.12/site-packages/tempest/lib/common/cred_provider.py", line 145, in cleanup_default_secgroup
    security_group_client.delete_security_group(secgroup['id'])

      File "/home/stguser/devstack/python-tempestconf/.venv/lib/python3.12/site-packages/tempest/lib/services/network/security_groups_client.py", line 59, in delete_security_group
    return self.delete_resource(uri)
           ^^^^^^^^^^^^^^^^^^^^^^^^^

      File "/home/stguser/devstack/python-tempestconf/.venv/lib/python3.12/site-packages/tempest/lib/services/network/base.py", line 42, in delete_resource
    resp, body = self.delete(req_uri)
                 ^^^^^^^^^^^^^^^^^^^^

      File "/home/stguser/devstack/python-tempestconf/.venv/lib/python3.12/site-packages/tempest/lib/common/rest_client.py", line 359, in delete
    return self.request('DELETE', url, extra_headers, headers, body)
           ^^^^^^^^^^^^^^^^^^^^^^^^^^^^^^^^^^^^^^^^^^^^^^^^^^^^^^^^^

      File "/home/stguser/devstack/python-tempestconf/.venv/lib/python3.12/site-packages/tempest/lib/common/rest_client.py", line 762, in request
    self._error_checker(resp, resp_body)

      File "/home/stguser/devstack/python-tempestconf/.venv/lib/python3.12/site-packages/tempest/lib/common/rest_client.py", line 892, in _error_checker
    raise exceptions.Conflict(resp_body, resp=resp)

    tempest.lib.exceptions.Conflict: Conflict with state of target resource
Details: {'type': 'SecurityGroupInUse', 'message': 'Security Group None cannot perform precommit_delete due to Callback neutron.plugins.ml2.drivers.ovn.mech_driver.mech_driver.OVNMechanismDriver._delete_security_group_precommit-3946265 failed with "Port_Group pg_b687c7a3_9afe_4986_92fd_c1363eaec855 does not exist".', 'detail': ''}


==============================
Failed 5 tests - output below:
==============================

setUpClass (tempest.api.volume.test_volumes_snapshots.VolumesSnapshotTestJSON)
------------------------------------------------------------------------------

Captured traceback:
~~~~~~~~~~~~~~~~~~~
    Traceback (most recent call last):

      File "/home/stguser/devstack/python-tempestconf/.venv/lib/python3.12/site-packages/urllib3/connectionpool.py", line 534, in _make_request
    response = conn.getresponse()
               ^^^^^^^^^^^^^^^^^^

      File "/home/stguser/devstack/python-tempestconf/.venv/lib/python3.12/site-packages/urllib3/connection.py", line 565, in getresponse
    httplib_response = super().getresponse()
                       ^^^^^^^^^^^^^^^^^^^^^

      File "/usr/lib/python3.12/http/client.py", line 1428, in getresponse
    response.begin()

      File "/usr/lib/python3.12/http/client.py", line 331, in begin
    version, status, reason = self._read_status()
                              ^^^^^^^^^^^^^^^^^^^

      File "/usr/lib/python3.12/http/client.py", line 292, in _read_status
    line = str(self.fp.readline(_MAXLINE + 1), "iso-8859-1")
               ^^^^^^^^^^^^^^^^^^^^^^^^^^^^^^

      File "/usr/lib/python3.12/socket.py", line 707, in readinto
    return self._sock.recv_into(b)
           ^^^^^^^^^^^^^^^^^^^^^^^

    TimeoutError: timed out

    
The above exception was the direct cause of the following exception:


    Traceback (most recent call last):

      File "/home/stguser/devstack/python-tempestconf/.venv/lib/python3.12/site-packages/tempest/test.py", line 185, in setUpClass
    raise value.with_traceback(trace)

      File "/home/stguser/devstack/python-tempestconf/.venv/lib/python3.12/site-packages/tempest/test.py", line 170, in setUpClass
    cls.setup_credentials()

      File "/home/stguser/devstack/python-tempestconf/.venv/lib/python3.12/site-packages/tempest/api/volume/base.py", line 62, in setup_credentials
    super(BaseVolumeTest, cls).setup_credentials()

      File "/home/stguser/devstack/python-tempestconf/.venv/lib/python3.12/site-packages/tempest/test.py", line 398, in setup_credentials
    manager = cls.get_client_manager(
              ^^^^^^^^^^^^^^^^^^^^^^^

      File "/home/stguser/devstack/python-tempestconf/.venv/lib/python3.12/site-packages/tempest/test.py", line 743, in get_client_manager
    creds = getattr(cred_provider, credentials_method)()
            ^^^^^^^^^^^^^^^^^^^^^^^^^^^^^^^^^^^^^^^^^^^^

      File "/home/stguser/devstack/python-tempestconf/.venv/lib/python3.12/site-packages/tempest/lib/common/dynamic_creds.py", line 473, in get_primary_creds
    return self.get_project_member_creds()
           ^^^^^^^^^^^^^^^^^^^^^^^^^^^^^^^

      File "/home/stguser/devstack/python-tempestconf/.venv/lib/python3.12/site-packages/tempest/lib/common/dynamic_creds.py", line 514, in get_project_member_creds
    return self.get_credentials(['member'], scope='project')
           ^^^^^^^^^^^^^^^^^^^^^^^^^^^^^^^^^^^^^^^^^^^^^^^^^

      File "/home/stguser/devstack/python-tempestconf/.venv/lib/python3.12/site-packages/tempest/lib/common/dynamic_creds.py", line 459, in get_credentials
    network, subnet, router = self._create_network_resources(
                              ^^^^^^^^^^^^^^^^^^^^^^^^^^^^^^^

      File "/home/stguser/devstack/python-tempestconf/.venv/lib/python3.12/site-packages/tempest/lib/common/dynamic_creds.py", line 310, in _create_network_resources
    network = self._create_network(network_name, tenant_id)
              ^^^^^^^^^^^^^^^^^^^^^^^^^^^^^^^^^^^^^^^^^^^^^

      File "/home/stguser/devstack/python-tempestconf/.venv/lib/python3.12/site-packages/tempest/lib/common/dynamic_creds.py", line 338, in _create_network
    resp_body = self.networks_admin_client.create_network(
                ^^^^^^^^^^^^^^^^^^^^^^^^^^^^^^^^^^^^^^^^^^

      File "/home/stguser/devstack/python-tempestconf/.venv/lib/python3.12/site-packages/tempest/lib/services/network/networks_client.py", line 27, in create_network
    return self.create_resource(uri, post_data)
           ^^^^^^^^^^^^^^^^^^^^^^^^^^^^^^^^^^^^

      File "/home/stguser/devstack/python-tempestconf/.venv/lib/python3.12/site-packages/tempest/lib/services/network/base.py", line 62, in create_resource
    resp, body = self.post(req_uri, req_post_data)
                 ^^^^^^^^^^^^^^^^^^^^^^^^^^^^^^^^^

      File "/home/stguser/devstack/python-tempestconf/.venv/lib/python3.12/site-packages/tempest/lib/common/rest_client.py", line 314, in post
    resp_header, resp_body = self.request(
                             ^^^^^^^^^^^^^

      File "/home/stguser/devstack/python-tempestconf/.venv/lib/python3.12/site-packages/tempest/lib/common/rest_client.py", line 746, in request
    resp, resp_body = self._request(method, url, headers=headers,
                      ^^^^^^^^^^^^^^^^^^^^^^^^^^^^^^^^^^^^^^^^^^^

      File "/home/stguser/devstack/python-tempestconf/.venv/lib/python3.12/site-packages/tempest/lib/common/rest_client.py", line 612, in _request
    resp, resp_body = self.raw_request(
                      ^^^^^^^^^^^^^^^^^

      File "/home/stguser/devstack/python-tempestconf/.venv/lib/python3.12/site-packages/tempest/lib/common/rest_client.py", line 661, in raw_request
    resp, resp_body = self.http_obj.request(
                      ^^^^^^^^^^^^^^^^^^^^^^

      File "/home/stguser/devstack/python-tempestconf/.venv/lib/python3.12/site-packages/tempest/lib/common/http.py", line 123, in request
    r = super(ClosingHttp, self).request(method, url, retries=retry,
        ^^^^^^^^^^^^^^^^^^^^^^^^^^^^^^^^^^^^^^^^^^^^^^^^^^^^^^^^^^^^

      File "/home/stguser/devstack/python-tempestconf/.venv/lib/python3.12/site-packages/urllib3/_request_methods.py", line 143, in request
    return self.request_encode_body(
           ^^^^^^^^^^^^^^^^^^^^^^^^^

      File "/home/stguser/devstack/python-tempestconf/.venv/lib/python3.12/site-packages/urllib3/_request_methods.py", line 278, in request_encode_body
    return self.urlopen(method, url, **extra_kw)
           ^^^^^^^^^^^^^^^^^^^^^^^^^^^^^^^^^^^^^

      File "/home/stguser/devstack/python-tempestconf/.venv/lib/python3.12/site-packages/urllib3/poolmanager.py", line 459, in urlopen
    response = conn.urlopen(method, u.request_uri, **kw)
               ^^^^^^^^^^^^^^^^^^^^^^^^^^^^^^^^^^^^^^^^^

      File "/home/stguser/devstack/python-tempestconf/.venv/lib/python3.12/site-packages/urllib3/connectionpool.py", line 841, in urlopen
    retries = retries.increment(
              ^^^^^^^^^^^^^^^^^^

      File "/home/stguser/devstack/python-tempestconf/.venv/lib/python3.12/site-packages/urllib3/util/retry.py", line 474, in increment
    raise reraise(type(error), error, _stacktrace)
          ^^^^^^^^^^^^^^^^^^^^^^^^^^^^^^^^^^^^^^^^

      File "/home/stguser/devstack/python-tempestconf/.venv/lib/python3.12/site-packages/urllib3/util/util.py", line 39, in reraise
    raise value

      File "/home/stguser/devstack/python-tempestconf/.venv/lib/python3.12/site-packages/urllib3/connectionpool.py", line 787, in urlopen
    response = self._make_request(
               ^^^^^^^^^^^^^^^^^^^

      File "/home/stguser/devstack/python-tempestconf/.venv/lib/python3.12/site-packages/urllib3/connectionpool.py", line 536, in _make_request
    self._raise_timeout(err=e, url=url, timeout_value=read_timeout)

      File "/home/stguser/devstack/python-tempestconf/.venv/lib/python3.12/site-packages/urllib3/connectionpool.py", line 367, in _raise_timeout
    raise ReadTimeoutError(

    urllib3.exceptions.ReadTimeoutError: HTTPConnectionPool(host='9.180.170.14', port=9696): Read timed out. (read timeout=60)


setUpClass (tempest.api.volume.admin.test_volume_retype.VolumeRetypeWithoutMigrationTest)
-----------------------------------------------------------------------------------------

Captured traceback:
~~~~~~~~~~~~~~~~~~~
    Traceback (most recent call last):

      File "/home/stguser/devstack/python-tempestconf/.venv/lib/python3.12/site-packages/tempest/test.py", line 185, in setUpClass
    raise value.with_traceback(trace)

      File "/home/stguser/devstack/python-tempestconf/.venv/lib/python3.12/site-packages/tempest/test.py", line 178, in setUpClass
    cls.resource_setup()

      File "/home/stguser/devstack/python-tempestconf/.venv/lib/python3.12/site-packages/tempest/api/volume/admin/test_volume_retype.py", line 172, in resource_setup
    cls.src_vol_type = cls.create_volume_type('volume-type-1')
                       ^^^^^^^^^^^^^^^^^^^^^^^^^^^^^^^^^^^^^^^

      File "/home/stguser/devstack/python-tempestconf/.venv/lib/python3.12/site-packages/tempest/api/volume/base.py", line 366, in create_volume_type
    volume_type = self.admin_volume_types_client.create_volume_type(
                  ^^^^^^^^^^^^^^^^^^^^^^^^^^^^^^^^^^^^^^^^^^^^^^^^^^

      File "/home/stguser/devstack/python-tempestconf/.venv/lib/python3.12/site-packages/tempest/lib/services/volume/v3/types_client.py", line 90, in create_volume_type
    resp, body = self.post('types', post_body)
                 ^^^^^^^^^^^^^^^^^^^^^^^^^^^^^

      File "/home/stguser/devstack/python-tempestconf/.venv/lib/python3.12/site-packages/tempest/lib/common/rest_client.py", line 314, in post
    resp_header, resp_body = self.request(
                             ^^^^^^^^^^^^^

      File "/home/stguser/devstack/python-tempestconf/.venv/lib/python3.12/site-packages/tempest/lib/common/rest_client.py", line 762, in request
    self._error_checker(resp, resp_body)

      File "/home/stguser/devstack/python-tempestconf/.venv/lib/python3.12/site-packages/tempest/lib/common/rest_client.py", line 892, in _error_checker
    raise exceptions.Conflict(resp_body, resp=resp)

    tempest.lib.exceptions.Conflict: Conflict with state of target resource
Details: {'code': 409, 'message': 'Volume Type volume-type-1 already exists.'}


setUpClass (tempest.api.volume.test_volumes_actions.VolumesActionsTest)
-----------------------------------------------------------------------

Captured traceback:
~~~~~~~~~~~~~~~~~~~
    Traceback (most recent call last):

      File "/home/stguser/devstack/python-tempestconf/.venv/lib/python3.12/site-packages/urllib3/connectionpool.py", line 534, in _make_request
    response = conn.getresponse()
               ^^^^^^^^^^^^^^^^^^

      File "/home/stguser/devstack/python-tempestconf/.venv/lib/python3.12/site-packages/urllib3/connection.py", line 565, in getresponse
    httplib_response = super().getresponse()
                       ^^^^^^^^^^^^^^^^^^^^^

      File "/usr/lib/python3.12/http/client.py", line 1428, in getresponse
    response.begin()

      File "/usr/lib/python3.12/http/client.py", line 331, in begin
    version, status, reason = self._read_status()
                              ^^^^^^^^^^^^^^^^^^^

      File "/usr/lib/python3.12/http/client.py", line 292, in _read_status
    line = str(self.fp.readline(_MAXLINE + 1), "iso-8859-1")
               ^^^^^^^^^^^^^^^^^^^^^^^^^^^^^^

      File "/usr/lib/python3.12/socket.py", line 707, in readinto
    return self._sock.recv_into(b)
           ^^^^^^^^^^^^^^^^^^^^^^^

    TimeoutError: timed out

    
The above exception was the direct cause of the following exception:


    Traceback (most recent call last):

      File "/home/stguser/devstack/python-tempestconf/.venv/lib/python3.12/site-packages/tempest/test.py", line 185, in setUpClass
    raise value.with_traceback(trace)

      File "/home/stguser/devstack/python-tempestconf/.venv/lib/python3.12/site-packages/tempest/test.py", line 170, in setUpClass
    cls.setup_credentials()

      File "/home/stguser/devstack/python-tempestconf/.venv/lib/python3.12/site-packages/tempest/api/volume/base.py", line 62, in setup_credentials
    super(BaseVolumeTest, cls).setup_credentials()

      File "/home/stguser/devstack/python-tempestconf/.venv/lib/python3.12/site-packages/tempest/test.py", line 398, in setup_credentials
    manager = cls.get_client_manager(
              ^^^^^^^^^^^^^^^^^^^^^^^

      File "/home/stguser/devstack/python-tempestconf/.venv/lib/python3.12/site-packages/tempest/test.py", line 743, in get_client_manager
    creds = getattr(cred_provider, credentials_method)()
            ^^^^^^^^^^^^^^^^^^^^^^^^^^^^^^^^^^^^^^^^^^^^

      File "/home/stguser/devstack/python-tempestconf/.venv/lib/python3.12/site-packages/tempest/lib/common/dynamic_creds.py", line 473, in get_primary_creds
    return self.get_project_member_creds()
           ^^^^^^^^^^^^^^^^^^^^^^^^^^^^^^^

      File "/home/stguser/devstack/python-tempestconf/.venv/lib/python3.12/site-packages/tempest/lib/common/dynamic_creds.py", line 514, in get_project_member_creds
    return self.get_credentials(['member'], scope='project')
           ^^^^^^^^^^^^^^^^^^^^^^^^^^^^^^^^^^^^^^^^^^^^^^^^^

      File "/home/stguser/devstack/python-tempestconf/.venv/lib/python3.12/site-packages/tempest/lib/common/dynamic_creds.py", line 459, in get_credentials
    network, subnet, router = self._create_network_resources(
                              ^^^^^^^^^^^^^^^^^^^^^^^^^^^^^^^

      File "/home/stguser/devstack/python-tempestconf/.venv/lib/python3.12/site-packages/tempest/lib/common/dynamic_creds.py", line 318, in _create_network_resources
    router = self._create_router(router_name, tenant_id)
             ^^^^^^^^^^^^^^^^^^^^^^^^^^^^^^^^^^^^^^^^^^^

      File "/home/stguser/devstack/python-tempestconf/.venv/lib/python3.12/site-packages/tempest/lib/common/dynamic_creds.py", line 379, in _create_router
    resp_body = self.routers_admin_client.create_router(**kwargs)
                ^^^^^^^^^^^^^^^^^^^^^^^^^^^^^^^^^^^^^^^^^^^^^^^^^

      File "/home/stguser/devstack/python-tempestconf/.venv/lib/python3.12/site-packages/tempest/lib/services/network/routers_client.py", line 27, in create_router
    return self.create_resource(uri, post_body)
           ^^^^^^^^^^^^^^^^^^^^^^^^^^^^^^^^^^^^

      File "/home/stguser/devstack/python-tempestconf/.venv/lib/python3.12/site-packages/tempest/lib/services/network/base.py", line 62, in create_resource
    resp, body = self.post(req_uri, req_post_data)
                 ^^^^^^^^^^^^^^^^^^^^^^^^^^^^^^^^^

      File "/home/stguser/devstack/python-tempestconf/.venv/lib/python3.12/site-packages/tempest/lib/common/rest_client.py", line 314, in post
    resp_header, resp_body = self.request(
                             ^^^^^^^^^^^^^

      File "/home/stguser/devstack/python-tempestconf/.venv/lib/python3.12/site-packages/tempest/lib/common/rest_client.py", line 746, in request
    resp, resp_body = self._request(method, url, headers=headers,
                      ^^^^^^^^^^^^^^^^^^^^^^^^^^^^^^^^^^^^^^^^^^^

      File "/home/stguser/devstack/python-tempestconf/.venv/lib/python3.12/site-packages/tempest/lib/common/rest_client.py", line 612, in _request
    resp, resp_body = self.raw_request(
                      ^^^^^^^^^^^^^^^^^

      File "/home/stguser/devstack/python-tempestconf/.venv/lib/python3.12/site-packages/tempest/lib/common/rest_client.py", line 661, in raw_request
    resp, resp_body = self.http_obj.request(
                      ^^^^^^^^^^^^^^^^^^^^^^

      File "/home/stguser/devstack/python-tempestconf/.venv/lib/python3.12/site-packages/tempest/lib/common/http.py", line 123, in request
    r = super(ClosingHttp, self).request(method, url, retries=retry,
        ^^^^^^^^^^^^^^^^^^^^^^^^^^^^^^^^^^^^^^^^^^^^^^^^^^^^^^^^^^^^

      File "/home/stguser/devstack/python-tempestconf/.venv/lib/python3.12/site-packages/urllib3/_request_methods.py", line 143, in request
    return self.request_encode_body(
           ^^^^^^^^^^^^^^^^^^^^^^^^^

      File "/home/stguser/devstack/python-tempestconf/.venv/lib/python3.12/site-packages/urllib3/_request_methods.py", line 278, in request_encode_body
    return self.urlopen(method, url, **extra_kw)
           ^^^^^^^^^^^^^^^^^^^^^^^^^^^^^^^^^^^^^

      File "/home/stguser/devstack/python-tempestconf/.venv/lib/python3.12/site-packages/urllib3/poolmanager.py", line 459, in urlopen
    response = conn.urlopen(method, u.request_uri, **kw)
               ^^^^^^^^^^^^^^^^^^^^^^^^^^^^^^^^^^^^^^^^^

      File "/home/stguser/devstack/python-tempestconf/.venv/lib/python3.12/site-packages/urllib3/connectionpool.py", line 841, in urlopen
    retries = retries.increment(
              ^^^^^^^^^^^^^^^^^^

      File "/home/stguser/devstack/python-tempestconf/.venv/lib/python3.12/site-packages/urllib3/util/retry.py", line 474, in increment
    raise reraise(type(error), error, _stacktrace)
          ^^^^^^^^^^^^^^^^^^^^^^^^^^^^^^^^^^^^^^^^

      File "/home/stguser/devstack/python-tempestconf/.venv/lib/python3.12/site-packages/urllib3/util/util.py", line 39, in reraise
    raise value

      File "/home/stguser/devstack/python-tempestconf/.venv/lib/python3.12/site-packages/urllib3/connectionpool.py", line 787, in urlopen
    response = self._make_request(
               ^^^^^^^^^^^^^^^^^^^

      File "/home/stguser/devstack/python-tempestconf/.venv/lib/python3.12/site-packages/urllib3/connectionpool.py", line 536, in _make_request
    self._raise_timeout(err=e, url=url, timeout_value=read_timeout)

      File "/home/stguser/devstack/python-tempestconf/.venv/lib/python3.12/site-packages/urllib3/connectionpool.py", line 367, in _raise_timeout
    raise ReadTimeoutError(

    urllib3.exceptions.ReadTimeoutError: HTTPConnectionPool(host='9.180.170.14', port=9696): Read timed out. (read timeout=60)


setUpClass (tempest.api.volume.admin.test_volumes_actions.VolumesActionsTest)
-----------------------------------------------------------------------------

Captured traceback:
~~~~~~~~~~~~~~~~~~~
    Traceback (most recent call last):

      File "/home/stguser/devstack/python-tempestconf/.venv/lib/python3.12/site-packages/urllib3/connectionpool.py", line 534, in _make_request
    response = conn.getresponse()
               ^^^^^^^^^^^^^^^^^^

      File "/home/stguser/devstack/python-tempestconf/.venv/lib/python3.12/site-packages/urllib3/connection.py", line 565, in getresponse
    httplib_response = super().getresponse()
                       ^^^^^^^^^^^^^^^^^^^^^

      File "/usr/lib/python3.12/http/client.py", line 1428, in getresponse
    response.begin()

      File "/usr/lib/python3.12/http/client.py", line 331, in begin
    version, status, reason = self._read_status()
                              ^^^^^^^^^^^^^^^^^^^

      File "/usr/lib/python3.12/http/client.py", line 292, in _read_status
    line = str(self.fp.readline(_MAXLINE + 1), "iso-8859-1")
               ^^^^^^^^^^^^^^^^^^^^^^^^^^^^^^

      File "/usr/lib/python3.12/socket.py", line 707, in readinto
    return self._sock.recv_into(b)
           ^^^^^^^^^^^^^^^^^^^^^^^

    TimeoutError: timed out

    
The above exception was the direct cause of the following exception:


    Traceback (most recent call last):

      File "/home/stguser/devstack/python-tempestconf/.venv/lib/python3.12/site-packages/tempest/test.py", line 185, in setUpClass
    raise value.with_traceback(trace)

      File "/home/stguser/devstack/python-tempestconf/.venv/lib/python3.12/site-packages/tempest/test.py", line 170, in setUpClass
    cls.setup_credentials()

      File "/home/stguser/devstack/python-tempestconf/.venv/lib/python3.12/site-packages/tempest/api/volume/base.py", line 62, in setup_credentials
    super(BaseVolumeTest, cls).setup_credentials()

      File "/home/stguser/devstack/python-tempestconf/.venv/lib/python3.12/site-packages/tempest/test.py", line 398, in setup_credentials
    manager = cls.get_client_manager(
              ^^^^^^^^^^^^^^^^^^^^^^^

      File "/home/stguser/devstack/python-tempestconf/.venv/lib/python3.12/site-packages/tempest/test.py", line 743, in get_client_manager
    creds = getattr(cred_provider, credentials_method)()
            ^^^^^^^^^^^^^^^^^^^^^^^^^^^^^^^^^^^^^^^^^^^^

      File "/home/stguser/devstack/python-tempestconf/.venv/lib/python3.12/site-packages/tempest/lib/common/dynamic_creds.py", line 473, in get_primary_creds
    return self.get_project_member_creds()
           ^^^^^^^^^^^^^^^^^^^^^^^^^^^^^^^

      File "/home/stguser/devstack/python-tempestconf/.venv/lib/python3.12/site-packages/tempest/lib/common/dynamic_creds.py", line 514, in get_project_member_creds
    return self.get_credentials(['member'], scope='project')
           ^^^^^^^^^^^^^^^^^^^^^^^^^^^^^^^^^^^^^^^^^^^^^^^^^

      File "/home/stguser/devstack/python-tempestconf/.venv/lib/python3.12/site-packages/tempest/lib/common/dynamic_creds.py", line 459, in get_credentials
    network, subnet, router = self._create_network_resources(
                              ^^^^^^^^^^^^^^^^^^^^^^^^^^^^^^^

      File "/home/stguser/devstack/python-tempestconf/.venv/lib/python3.12/site-packages/tempest/lib/common/dynamic_creds.py", line 318, in _create_network_resources
    router = self._create_router(router_name, tenant_id)
             ^^^^^^^^^^^^^^^^^^^^^^^^^^^^^^^^^^^^^^^^^^^

      File "/home/stguser/devstack/python-tempestconf/.venv/lib/python3.12/site-packages/tempest/lib/common/dynamic_creds.py", line 379, in _create_router
    resp_body = self.routers_admin_client.create_router(**kwargs)
                ^^^^^^^^^^^^^^^^^^^^^^^^^^^^^^^^^^^^^^^^^^^^^^^^^

      File "/home/stguser/devstack/python-tempestconf/.venv/lib/python3.12/site-packages/tempest/lib/services/network/routers_client.py", line 27, in create_router
    return self.create_resource(uri, post_body)
           ^^^^^^^^^^^^^^^^^^^^^^^^^^^^^^^^^^^^

      File "/home/stguser/devstack/python-tempestconf/.venv/lib/python3.12/site-packages/tempest/lib/services/network/base.py", line 62, in create_resource
    resp, body = self.post(req_uri, req_post_data)
                 ^^^^^^^^^^^^^^^^^^^^^^^^^^^^^^^^^

      File "/home/stguser/devstack/python-tempestconf/.venv/lib/python3.12/site-packages/tempest/lib/common/rest_client.py", line 314, in post
    resp_header, resp_body = self.request(
                             ^^^^^^^^^^^^^

      File "/home/stguser/devstack/python-tempestconf/.venv/lib/python3.12/site-packages/tempest/lib/common/rest_client.py", line 746, in request
    resp, resp_body = self._request(method, url, headers=headers,
                      ^^^^^^^^^^^^^^^^^^^^^^^^^^^^^^^^^^^^^^^^^^^

      File "/home/stguser/devstack/python-tempestconf/.venv/lib/python3.12/site-packages/tempest/lib/common/rest_client.py", line 612, in _request
    resp, resp_body = self.raw_request(
                      ^^^^^^^^^^^^^^^^^

      File "/home/stguser/devstack/python-tempestconf/.venv/lib/python3.12/site-packages/tempest/lib/common/rest_client.py", line 661, in raw_request
    resp, resp_body = self.http_obj.request(
                      ^^^^^^^^^^^^^^^^^^^^^^

      File "/home/stguser/devstack/python-tempestconf/.venv/lib/python3.12/site-packages/tempest/lib/common/http.py", line 123, in request
    r = super(ClosingHttp, self).request(method, url, retries=retry,
        ^^^^^^^^^^^^^^^^^^^^^^^^^^^^^^^^^^^^^^^^^^^^^^^^^^^^^^^^^^^^

      File "/home/stguser/devstack/python-tempestconf/.venv/lib/python3.12/site-packages/urllib3/_request_methods.py", line 143, in request
    return self.request_encode_body(
           ^^^^^^^^^^^^^^^^^^^^^^^^^

      File "/home/stguser/devstack/python-tempestconf/.venv/lib/python3.12/site-packages/urllib3/_request_methods.py", line 278, in request_encode_body
    return self.urlopen(method, url, **extra_kw)
           ^^^^^^^^^^^^^^^^^^^^^^^^^^^^^^^^^^^^^

      File "/home/stguser/devstack/python-tempestconf/.venv/lib/python3.12/site-packages/urllib3/poolmanager.py", line 459, in urlopen
    response = conn.urlopen(method, u.request_uri, **kw)
               ^^^^^^^^^^^^^^^^^^^^^^^^^^^^^^^^^^^^^^^^^

      File "/home/stguser/devstack/python-tempestconf/.venv/lib/python3.12/site-packages/urllib3/connectionpool.py", line 841, in urlopen
    retries = retries.increment(
              ^^^^^^^^^^^^^^^^^^

      File "/home/stguser/devstack/python-tempestconf/.venv/lib/python3.12/site-packages/urllib3/util/retry.py", line 474, in increment
    raise reraise(type(error), error, _stacktrace)
          ^^^^^^^^^^^^^^^^^^^^^^^^^^^^^^^^^^^^^^^^

      File "/home/stguser/devstack/python-tempestconf/.venv/lib/python3.12/site-packages/urllib3/util/util.py", line 39, in reraise
    raise value

      File "/home/stguser/devstack/python-tempestconf/.venv/lib/python3.12/site-packages/urllib3/connectionpool.py", line 787, in urlopen
    response = self._make_request(
               ^^^^^^^^^^^^^^^^^^^

      File "/home/stguser/devstack/python-tempestconf/.venv/lib/python3.12/site-packages/urllib3/connectionpool.py", line 536, in _make_request
    self._raise_timeout(err=e, url=url, timeout_value=read_timeout)

      File "/home/stguser/devstack/python-tempestconf/.venv/lib/python3.12/site-packages/urllib3/connectionpool.py", line 367, in _raise_timeout
    raise ReadTimeoutError(

    urllib3.exceptions.ReadTimeoutError: HTTPConnectionPool(host='9.180.170.14', port=9696): Read timed out. (read timeout=60)


tearDownClass (tempest.api.volume.admin.test_volumes_list.VolumesListAdminTestJSON)
-----------------------------------------------------------------------------------

Captured traceback:
~~~~~~~~~~~~~~~~~~~
    Traceback (most recent call last):

      File "/home/stguser/devstack/python-tempestconf/.venv/lib/python3.12/site-packages/tempest/test.py", line 246, in tearDownClass
    raise value.with_traceback(trace)

      File "/home/stguser/devstack/python-tempestconf/.venv/lib/python3.12/site-packages/tempest/test.py", line 210, in tearDownClass
    teardown()

      File "/home/stguser/devstack/python-tempestconf/.venv/lib/python3.12/site-packages/tempest/test.py", line 757, in clear_credentials
    cls._creds_provider.clear_creds()

      File "/home/stguser/devstack/python-tempestconf/.venv/lib/python3.12/site-packages/tempest/lib/common/dynamic_creds.py", line 635, in clear_creds
    self.cleanup_default_secgroup(

      File "/home/stguser/devstack/python-tempestconf/.venv/lib/python3.12/site-packages/tempest/lib/common/cred_provider.py", line 145, in cleanup_default_secgroup
    security_group_client.delete_security_group(secgroup['id'])

      File "/home/stguser/devstack/python-tempestconf/.venv/lib/python3.12/site-packages/tempest/lib/services/network/security_groups_client.py", line 59, in delete_security_group
    return self.delete_resource(uri)
           ^^^^^^^^^^^^^^^^^^^^^^^^^

      File "/home/stguser/devstack/python-tempestconf/.venv/lib/python3.12/site-packages/tempest/lib/services/network/base.py", line 42, in delete_resource
    resp, body = self.delete(req_uri)
                 ^^^^^^^^^^^^^^^^^^^^

      File "/home/stguser/devstack/python-tempestconf/.venv/lib/python3.12/site-packages/tempest/lib/common/rest_client.py", line 359, in delete
    return self.request('DELETE', url, extra_headers, headers, body)
           ^^^^^^^^^^^^^^^^^^^^^^^^^^^^^^^^^^^^^^^^^^^^^^^^^^^^^^^^^

      File "/home/stguser/devstack/python-tempestconf/.venv/lib/python3.12/site-packages/tempest/lib/common/rest_client.py", line 762, in request
    self._error_checker(resp, resp_body)

      File "/home/stguser/devstack/python-tempestconf/.venv/lib/python3.12/site-packages/tempest/lib/common/rest_client.py", line 892, in _error_checker
    raise exceptions.Conflict(resp_body, resp=resp)

    tempest.lib.exceptions.Conflict: Conflict with state of target resource
Details: {'type': 'SecurityGroupInUse', 'message': 'Security Group None cannot perform precommit_delete due to Callback neutron.plugins.ml2.drivers.ovn.mech_driver.mech_driver.OVNMechanismDriver._delete_security_group_precommit-3946265 failed with "Port_Group pg_b687c7a3_9afe_4986_92fd_c1363eaec855 does not exist".', 'detail': ''}



======
Totals
======
Ran: 167 tests in 293.7427 sec.
 - Passed: 156
 - Skipped: 6
 - Expected Fail: 0
 - Unexpected Success: 0
 - Failed: 5
Sum of execute time for each test: 2879.6417 sec.

==============
Worker Balance
==============
 - Worker 0 (3 tests) => 0:04:10.516192
 - Worker 1 (2 tests) => 0:03:22.623219
 - Worker 2 (2 tests) => 0:03:34.651766
 - Worker 3 (8 tests) => 0:03:36.410407
 - Worker 4 (3 tests) => 0:03:32.978399
 - Worker 5 (3 tests) => 0:03:40.028155
 - Worker 6 (2 tests) => 0:02:53.514559
 - Worker 7 (1 tests) => 0:00:00
 - Worker 8 (2 tests) => 0:02:13.677390
 - Worker 9 (5 tests) => 0:02:05.143380
 - Worker 10 (1 tests) => 0:02:15.587817
 - Worker 11 (6 tests) => 0:01:33.619038
 - Worker 12 (2 tests) => 0:02:16.807063
 - Worker 13 (1 tests) => 0:00:00
 - Worker 14 (27 tests) => 0:02:21.641867
 - Worker 15 (1 tests) => 0:00:00
 - Worker 16 (1 tests) => 0:00:00
 - Worker 17 (4 tests) => 0:02:03.725637
 - Worker 18 (7 tests) => 0:02:13.281394
 - Worker 19 (2 tests) => 0:02:02.665483
 - Worker 20 (2 tests) => 0:01:46.538877
 - Worker 21 (3 tests) => 0:00:45.237195
 - Worker 22 (6 tests) => 0:00:51.086624
 - Worker 23 (2 tests) => 0:00:34.747568
 - Worker 24 (5 tests) => 0:00:19.166543
 - Worker 25 (2 tests) => 0:00:12.927889
 - Worker 26 (12 tests) => 0:00:32.355662
 - Worker 27 (5 tests) => 0:00:09.495587
 - Worker 28 (2 tests) => 0:00:08.125595
 - Worker 29 (2 tests) => 0:00:24.807992
 - Worker 30 (2 tests) => 0:00:11.490734
 - Worker 31 (2 tests) => 0:00:04.874225
 - Worker 32 (1 tests) => 0:00:09.302358
 - Worker 33 (1 tests) => 0:00:08.723689
 - Worker 34 (18 tests) => 0:00:03.528069
 - Worker 35 (1 tests) => 0:00:07.915428
 - Worker 36 (2 tests) => 0:00:42.899475
 - Worker 37 (2 tests) => 0:00:16.624083
 - Worker 38 (13 tests) => 0:00:01.227774
 - Worker 39 (1 tests) => 0:00:19.132366
