{4} setUpClass (tempest.api.volume.admin.test_encrypted_volumes_extend.EncryptedVolumesExtendAttachedTest) ... SKIPPED: Attached encrypted volume extend is disabled.
{2} setUpClass (tempest.api.volume.admin.test_multi_backend.VolumeMultiBackendTest) ... SKIPPED: Cinder multi-backend feature disabled
{0} setUpClass (tempest.api.volume.admin.test_volume_retype.VolumeRetypeWithMigrationTest) ... SKIPPED: Cinder multi-backend feature disabled
{3} setUpClass (tempest.api.volume.test_volumes_backup.VolumesBackupsTest) ... SKIPPED: Cinder backup feature disabled
{38} tempest.api.volume.test_availability_zone.AvailabilityZoneTestJSON.test_get_availability_zone_list [5.930874s] ... ok
{37} tempest.api.volume.test_versions.VersionsTest.test_list_versions [4.146692s] ... ok
{36} tempest.api.volume.test_extensions.ExtensionsTestJSON.test_list_extensions [5.073980s] ... ok
{35} tempest.api.volume.test_volumes_snapshots_negative.VolumesSnapshotNegativeTestJSON.test_create_snapshot_with_nonexistent_volume_id [4.243743s] ... ok
{35} tempest.api.volume.test_volumes_snapshots_negative.VolumesSnapshotNegativeTestJSON.test_create_snapshot_without_passing_volume_id [0.211422s] ... ok
{35} tempest.api.volume.test_volumes_snapshots_negative.VolumesSnapshotNegativeTestJSON.test_list_snapshot_invalid_param_limit [3.397530s] ... ok
{34} tempest.api.volume.test_volumes_get.VolumesSummaryTest.test_show_volume_summary [7.860561s] ... ok
{35} tempest.api.volume.test_volumes_snapshots_negative.VolumesSnapshotNegativeTestJSON.test_list_snapshots_invalid_param_marker [0.480927s] ... ok
{37} tempest.api.volume.test_versions.VersionsTest.test_show_version [4.796827s] ... ok
{35} tempest.api.volume.test_volumes_snapshots_negative.VolumesSnapshotNegativeTestJSON.test_list_snapshots_invalid_param_sort [3.893654s] ... ok
{8} tempest.api.volume.admin.test_volume_services.VolumesServicesTestJSON.test_get_service_by_host_name [0.750236s] ... ok
{8} tempest.api.volume.admin.test_volume_services.VolumesServicesTestJSON.test_get_service_by_service_and_host_name [0.030663s] ... ok
{8} tempest.api.volume.admin.test_volume_services.VolumesServicesTestJSON.test_get_service_by_service_binary_name [0.021624s] ... ok
{19} tempest.api.volume.admin.test_volume_types_extra_specs_negative.ExtraSpecsNegativeTest.test_create_invalid_body [0.137293s] ... ok
{19} tempest.api.volume.admin.test_volume_types_extra_specs_negative.ExtraSpecsNegativeTest.test_create_none_body [0.080925s] ... ok
{19} tempest.api.volume.admin.test_volume_types_extra_specs_negative.ExtraSpecsNegativeTest.test_create_nonexistent_type_id [6.593646s] ... ok
{19} tempest.api.volume.admin.test_volume_types_extra_specs_negative.ExtraSpecsNegativeTest.test_delete_nonexistent_volume_type_id [3.721100s] ... ok
{27} tempest.api.volume.admin.test_volume_pools.VolumePoolsAdminTestsJSON.test_get_pools_with_details [5.263850s] ... ok
{22} tempest.api.volume.admin.test_volume_hosts.VolumeHostsAdminTestsJSON.test_list_hosts [3.195523s] ... ok
{12} tempest.api.volume.admin.test_volume_quota_classes.VolumeQuotaClassesTest.test_show_default_quota [3.851567s] ... ok
{4} tempest.api.volume.admin.test_volume_types.VolumeTypesTest.test_volume_type_create_get_delete [17.863293s] ... ok
{19} tempest.api.volume.admin.test_volume_types_extra_specs_negative.ExtraSpecsNegativeTest.test_get_nonexistent_extra_spec_name [1.817196s] ... ok
{16} tempest.api.volume.admin.test_volume_types_negative.VolumeTypesNegativeTest.test_create_volume_type_encryption_nonexistent_type_id [6.255909s] ... ok
{27} tempest.api.volume.admin.test_volume_pools.VolumePoolsAdminTestsJSON.test_get_pools_without_details [5.672929s] ... ok
{19} tempest.api.volume.admin.test_volume_types_extra_specs_negative.ExtraSpecsNegativeTest.test_get_nonexistent_volume_type_id [14.690298s] ... ok
{23} tempest.api.volume.admin.test_volume_services_negative.VolumeServicesNegativeTest.test_disable_log_reason_with_no_reason [13.916370s] ... ok
{15} tempest.api.volume.admin.test_volume_types_extra_specs.VolumeTypesExtraSpecsTest.test_volume_type_extra_spec_create_get_delete [27.586398s] ... ok
{26} tempest.api.volume.admin.test_backends_capabilities.BackendsCapabilitiesAdminTestsJSON.test_compare_volume_stats_values [26.698047s] ... ok
{19} tempest.api.volume.admin.test_volume_types_extra_specs_negative.ExtraSpecsNegativeTest.test_list_nonexistent_volume_type_id [17.926811s] ... ok
{23} tempest.api.volume.admin.test_volume_services_negative.VolumeServicesNegativeTest.test_disable_service_with_invalid_binary [17.987765s] ... ok
{19} tempest.api.volume.admin.test_volume_types_extra_specs_negative.ExtraSpecsNegativeTest.test_update_multiple_extra_spec [2.429595s] ... ok
{23} tempest.api.volume.admin.test_volume_services_negative.VolumeServicesNegativeTest.test_enable_service_with_invalid_host [2.346130s] ... ok
{26} tempest.api.volume.admin.test_backends_capabilities.BackendsCapabilitiesAdminTestsJSON.test_get_capabilities_backend [10.268528s] ... ok
{19} tempest.api.volume.admin.test_volume_types_extra_specs_negative.ExtraSpecsNegativeTest.test_update_no_body [2.218235s] ... ok
{23} tempest.api.volume.admin.test_volume_services_negative.VolumeServicesNegativeTest.test_freeze_host_with_invalid_host [2.242267s] ... ok
{22} tempest.api.volume.admin.test_volume_hosts.VolumeHostsAdminTestsJSON.test_show_host [41.607683s] ... ok
{19} tempest.api.volume.admin.test_volume_types_extra_specs_negative.ExtraSpecsNegativeTest.test_update_none_extra_spec_id [4.019617s] ... ok
{23} tempest.api.volume.admin.test_volume_services_negative.VolumeServicesNegativeTest.test_thaw_host_with_invalid_host [3.995563s] ... ok
{15} tempest.api.volume.admin.test_volume_types_extra_specs.VolumeTypesExtraSpecsTest.test_volume_type_extra_specs_list [23.480744s] ... ok
{19} tempest.api.volume.admin.test_volume_types_extra_specs_negative.ExtraSpecsNegativeTest.test_update_nonexistent_extra_spec_id [1.857457s] ... ok
{16} tempest.api.volume.admin.test_volume_types_negative.VolumeTypesNegativeTest.test_create_volume_with_private_volume_type [43.306733s] ... ok
{19} tempest.api.volume.admin.test_volume_types_extra_specs_negative.ExtraSpecsNegativeTest.test_update_nonexistent_type_id [2.868505s] ... ok
{16} tempest.api.volume.admin.test_volume_types_negative.VolumeTypesNegativeTest.test_create_with_empty_name [1.359822s] ... ok
{16} tempest.api.volume.admin.test_volume_types_negative.VolumeTypesNegativeTest.test_create_with_repeated_name [36.214353s] ... ok
{15} tempest.api.volume.admin.test_volume_types_extra_specs.VolumeTypesExtraSpecsTest.test_volume_type_extra_specs_update [41.270671s] ... ok
{31} tempest.api.volume.test_volume_absolute_limits.AbsoluteLimitsTests.test_get_volume_absolute_limits [20.299189s] ... ok
{24} tempest.api.volume.test_volume_metadata.VolumesMetadataTest.test_crud_volume_metadata [51.443306s] ... ok
{16} tempest.api.volume.admin.test_volume_types_negative.VolumeTypesNegativeTest.test_delete_nonexistent_type_id [6.130859s] ... ok
{4} tempest.api.volume.admin.test_volume_types.VolumeTypesTest.test_volume_type_encryption_create_get_update_delete [91.549984s] ... ok
{16} tempest.api.volume.admin.test_volume_types_negative.VolumeTypesNegativeTest.test_get_nonexistent_type_id [3.005675s] ... ok
{14} tempest.api.volume.test_volumes_clone_negative.VolumesCloneNegativeTest.test_create_from_volume_decreasing_size [127.091245s] ... ok
{4} tempest.api.volume.admin.test_volume_types.VolumeTypesTest.test_volume_type_list [1.211344s] ... ok
{28} tempest.api.volume.admin.test_volume_quotas_negative.VolumeQuotasNegativeTestJSON.test_quota_volume_gigabytes [13.881791s] ... ok
{20} setUpClass (tempest.api.volume.test_volumes_actions.VolumesActionsTest) [0.000000s] ... FAILED

Captured traceback:
~~~~~~~~~~~~~~~~~~~
    Traceback (most recent call last):

      File "/home/stguser/devstack/python-tempestconf/.venv/lib/python3.12/site-packages/urllib3/connectionpool.py", line 534, in _make_request
    response = conn.getresponse()
               ^^^^^^^^^^^^^^^^^^

      File "/home/stguser/devstack/python-tempestconf/.venv/lib/python3.12/site-packages/urllib3/connection.py", line 565, in getresponse
    httplib_response = super().getresponse()
                       ^^^^^^^^^^^^^^^^^^^^^

      File "/usr/lib/python3.12/http/client.py", line 1428, in getresponse
    response.begin()

      File "/usr/lib/python3.12/http/client.py", line 331, in begin
    version, status, reason = self._read_status()
                              ^^^^^^^^^^^^^^^^^^^

      File "/usr/lib/python3.12/http/client.py", line 292, in _read_status
    line = str(self.fp.readline(_MAXLINE + 1), "iso-8859-1")
               ^^^^^^^^^^^^^^^^^^^^^^^^^^^^^^

      File "/usr/lib/python3.12/socket.py", line 707, in readinto
    return self._sock.recv_into(b)
           ^^^^^^^^^^^^^^^^^^^^^^^

    TimeoutError: timed out

    
The above exception was the direct cause of the following exception:


    Traceback (most recent call last):

      File "/home/stguser/devstack/python-tempestconf/.venv/lib/python3.12/site-packages/tempest/test.py", line 185, in setUpClass
    raise value.with_traceback(trace)

      File "/home/stguser/devstack/python-tempestconf/.venv/lib/python3.12/site-packages/tempest/test.py", line 170, in setUpClass
    cls.setup_credentials()

      File "/home/stguser/devstack/python-tempestconf/.venv/lib/python3.12/site-packages/tempest/api/volume/base.py", line 62, in setup_credentials
    super(BaseVolumeTest, cls).setup_credentials()

      File "/home/stguser/devstack/python-tempestconf/.venv/lib/python3.12/site-packages/tempest/test.py", line 398, in setup_credentials
    manager = cls.get_client_manager(
              ^^^^^^^^^^^^^^^^^^^^^^^

      File "/home/stguser/devstack/python-tempestconf/.venv/lib/python3.12/site-packages/tempest/test.py", line 743, in get_client_manager
    creds = getattr(cred_provider, credentials_method)()
            ^^^^^^^^^^^^^^^^^^^^^^^^^^^^^^^^^^^^^^^^^^^^

      File "/home/stguser/devstack/python-tempestconf/.venv/lib/python3.12/site-packages/tempest/lib/common/dynamic_creds.py", line 473, in get_primary_creds
    return self.get_project_member_creds()
           ^^^^^^^^^^^^^^^^^^^^^^^^^^^^^^^

      File "/home/stguser/devstack/python-tempestconf/.venv/lib/python3.12/site-packages/tempest/lib/common/dynamic_creds.py", line 514, in get_project_member_creds
    return self.get_credentials(['member'], scope='project')
           ^^^^^^^^^^^^^^^^^^^^^^^^^^^^^^^^^^^^^^^^^^^^^^^^^

      File "/home/stguser/devstack/python-tempestconf/.venv/lib/python3.12/site-packages/tempest/lib/common/dynamic_creds.py", line 459, in get_credentials
    network, subnet, router = self._create_network_resources(
                              ^^^^^^^^^^^^^^^^^^^^^^^^^^^^^^^

      File "/home/stguser/devstack/python-tempestconf/.venv/lib/python3.12/site-packages/tempest/lib/common/dynamic_creds.py", line 310, in _create_network_resources
    network = self._create_network(network_name, tenant_id)
              ^^^^^^^^^^^^^^^^^^^^^^^^^^^^^^^^^^^^^^^^^^^^^

      File "/home/stguser/devstack/python-tempestconf/.venv/lib/python3.12/site-packages/tempest/lib/common/dynamic_creds.py", line 338, in _create_network
    resp_body = self.networks_admin_client.create_network(
                ^^^^^^^^^^^^^^^^^^^^^^^^^^^^^^^^^^^^^^^^^^

      File "/home/stguser/devstack/python-tempestconf/.venv/lib/python3.12/site-packages/tempest/lib/services/network/networks_client.py", line 27, in create_network
    return self.create_resource(uri, post_data)
           ^^^^^^^^^^^^^^^^^^^^^^^^^^^^^^^^^^^^

      File "/home/stguser/devstack/python-tempestconf/.venv/lib/python3.12/site-packages/tempest/lib/services/network/base.py", line 62, in create_resource
    resp, body = self.post(req_uri, req_post_data)
                 ^^^^^^^^^^^^^^^^^^^^^^^^^^^^^^^^^

      File "/home/stguser/devstack/python-tempestconf/.venv/lib/python3.12/site-packages/tempest/lib/common/rest_client.py", line 314, in post
    resp_header, resp_body = self.request(
                             ^^^^^^^^^^^^^

      File "/home/stguser/devstack/python-tempestconf/.venv/lib/python3.12/site-packages/tempest/lib/common/rest_client.py", line 746, in request
    resp, resp_body = self._request(method, url, headers=headers,
                      ^^^^^^^^^^^^^^^^^^^^^^^^^^^^^^^^^^^^^^^^^^^

      File "/home/stguser/devstack/python-tempestconf/.venv/lib/python3.12/site-packages/tempest/lib/common/rest_client.py", line 612, in _request
    resp, resp_body = self.raw_request(
                      ^^^^^^^^^^^^^^^^^

      File "/home/stguser/devstack/python-tempestconf/.venv/lib/python3.12/site-packages/tempest/lib/common/rest_client.py", line 661, in raw_request
    resp, resp_body = self.http_obj.request(
                      ^^^^^^^^^^^^^^^^^^^^^^

      File "/home/stguser/devstack/python-tempestconf/.venv/lib/python3.12/site-packages/tempest/lib/common/http.py", line 123, in request
    r = super(ClosingHttp, self).request(method, url, retries=retry,
        ^^^^^^^^^^^^^^^^^^^^^^^^^^^^^^^^^^^^^^^^^^^^^^^^^^^^^^^^^^^^

      File "/home/stguser/devstack/python-tempestconf/.venv/lib/python3.12/site-packages/urllib3/_request_methods.py", line 143, in request
    return self.request_encode_body(
           ^^^^^^^^^^^^^^^^^^^^^^^^^

      File "/home/stguser/devstack/python-tempestconf/.venv/lib/python3.12/site-packages/urllib3/_request_methods.py", line 278, in request_encode_body
    return self.urlopen(method, url, **extra_kw)
           ^^^^^^^^^^^^^^^^^^^^^^^^^^^^^^^^^^^^^

      File "/home/stguser/devstack/python-tempestconf/.venv/lib/python3.12/site-packages/urllib3/poolmanager.py", line 459, in urlopen
    response = conn.urlopen(method, u.request_uri, **kw)
               ^^^^^^^^^^^^^^^^^^^^^^^^^^^^^^^^^^^^^^^^^

      File "/home/stguser/devstack/python-tempestconf/.venv/lib/python3.12/site-packages/urllib3/connectionpool.py", line 841, in urlopen
    retries = retries.increment(
              ^^^^^^^^^^^^^^^^^^

      File "/home/stguser/devstack/python-tempestconf/.venv/lib/python3.12/site-packages/urllib3/util/retry.py", line 474, in increment
    raise reraise(type(error), error, _stacktrace)
          ^^^^^^^^^^^^^^^^^^^^^^^^^^^^^^^^^^^^^^^^

      File "/home/stguser/devstack/python-tempestconf/.venv/lib/python3.12/site-packages/urllib3/util/util.py", line 39, in reraise
    raise value

      File "/home/stguser/devstack/python-tempestconf/.venv/lib/python3.12/site-packages/urllib3/connectionpool.py", line 787, in urlopen
    response = self._make_request(
               ^^^^^^^^^^^^^^^^^^^

      File "/home/stguser/devstack/python-tempestconf/.venv/lib/python3.12/site-packages/urllib3/connectionpool.py", line 536, in _make_request
    self._raise_timeout(err=e, url=url, timeout_value=read_timeout)

      File "/home/stguser/devstack/python-tempestconf/.venv/lib/python3.12/site-packages/urllib3/connectionpool.py", line 367, in _raise_timeout
    raise ReadTimeoutError(

    urllib3.exceptions.ReadTimeoutError: HTTPConnectionPool(host='9.180.170.14', port=9696): Read timed out. (read timeout=60)

{24} tempest.api.volume.test_volume_metadata.VolumesMetadataTest.test_update_show_volume_metadata_item [9.163063s] ... ok
{17} setUpClass (tempest.api.volume.admin.test_volumes_actions.VolumesActionsTest) [0.000000s] ... FAILED

Captured traceback:
~~~~~~~~~~~~~~~~~~~
    Traceback (most recent call last):

      File "/home/stguser/devstack/python-tempestconf/.venv/lib/python3.12/site-packages/urllib3/connectionpool.py", line 534, in _make_request
    response = conn.getresponse()
               ^^^^^^^^^^^^^^^^^^

      File "/home/stguser/devstack/python-tempestconf/.venv/lib/python3.12/site-packages/urllib3/connection.py", line 565, in getresponse
    httplib_response = super().getresponse()
                       ^^^^^^^^^^^^^^^^^^^^^

      File "/usr/lib/python3.12/http/client.py", line 1428, in getresponse
    response.begin()

      File "/usr/lib/python3.12/http/client.py", line 331, in begin
    version, status, reason = self._read_status()
                              ^^^^^^^^^^^^^^^^^^^

      File "/usr/lib/python3.12/http/client.py", line 292, in _read_status
    line = str(self.fp.readline(_MAXLINE + 1), "iso-8859-1")
               ^^^^^^^^^^^^^^^^^^^^^^^^^^^^^^

      File "/usr/lib/python3.12/socket.py", line 707, in readinto
    return self._sock.recv_into(b)
           ^^^^^^^^^^^^^^^^^^^^^^^

    TimeoutError: timed out

    
The above exception was the direct cause of the following exception:


    Traceback (most recent call last):

      File "/home/stguser/devstack/python-tempestconf/.venv/lib/python3.12/site-packages/tempest/test.py", line 185, in setUpClass
    raise value.with_traceback(trace)

      File "/home/stguser/devstack/python-tempestconf/.venv/lib/python3.12/site-packages/tempest/test.py", line 170, in setUpClass
    cls.setup_credentials()

      File "/home/stguser/devstack/python-tempestconf/.venv/lib/python3.12/site-packages/tempest/api/volume/base.py", line 62, in setup_credentials
    super(BaseVolumeTest, cls).setup_credentials()

      File "/home/stguser/devstack/python-tempestconf/.venv/lib/python3.12/site-packages/tempest/test.py", line 398, in setup_credentials
    manager = cls.get_client_manager(
              ^^^^^^^^^^^^^^^^^^^^^^^

      File "/home/stguser/devstack/python-tempestconf/.venv/lib/python3.12/site-packages/tempest/test.py", line 743, in get_client_manager
    creds = getattr(cred_provider, credentials_method)()
            ^^^^^^^^^^^^^^^^^^^^^^^^^^^^^^^^^^^^^^^^^^^^

      File "/home/stguser/devstack/python-tempestconf/.venv/lib/python3.12/site-packages/tempest/lib/common/dynamic_creds.py", line 473, in get_primary_creds
    return self.get_project_member_creds()
           ^^^^^^^^^^^^^^^^^^^^^^^^^^^^^^^

      File "/home/stguser/devstack/python-tempestconf/.venv/lib/python3.12/site-packages/tempest/lib/common/dynamic_creds.py", line 514, in get_project_member_creds
    return self.get_credentials(['member'], scope='project')
           ^^^^^^^^^^^^^^^^^^^^^^^^^^^^^^^^^^^^^^^^^^^^^^^^^

      File "/home/stguser/devstack/python-tempestconf/.venv/lib/python3.12/site-packages/tempest/lib/common/dynamic_creds.py", line 459, in get_credentials
    network, subnet, router = self._create_network_resources(
                              ^^^^^^^^^^^^^^^^^^^^^^^^^^^^^^^

      File "/home/stguser/devstack/python-tempestconf/.venv/lib/python3.12/site-packages/tempest/lib/common/dynamic_creds.py", line 310, in _create_network_resources
    network = self._create_network(network_name, tenant_id)
              ^^^^^^^^^^^^^^^^^^^^^^^^^^^^^^^^^^^^^^^^^^^^^

      File "/home/stguser/devstack/python-tempestconf/.venv/lib/python3.12/site-packages/tempest/lib/common/dynamic_creds.py", line 338, in _create_network
    resp_body = self.networks_admin_client.create_network(
                ^^^^^^^^^^^^^^^^^^^^^^^^^^^^^^^^^^^^^^^^^^

      File "/home/stguser/devstack/python-tempestconf/.venv/lib/python3.12/site-packages/tempest/lib/services/network/networks_client.py", line 27, in create_network
    return self.create_resource(uri, post_data)
           ^^^^^^^^^^^^^^^^^^^^^^^^^^^^^^^^^^^^

      File "/home/stguser/devstack/python-tempestconf/.venv/lib/python3.12/site-packages/tempest/lib/services/network/base.py", line 62, in create_resource
    resp, body = self.post(req_uri, req_post_data)
                 ^^^^^^^^^^^^^^^^^^^^^^^^^^^^^^^^^

      File "/home/stguser/devstack/python-tempestconf/.venv/lib/python3.12/site-packages/tempest/lib/common/rest_client.py", line 314, in post
    resp_header, resp_body = self.request(
                             ^^^^^^^^^^^^^

      File "/home/stguser/devstack/python-tempestconf/.venv/lib/python3.12/site-packages/tempest/lib/common/rest_client.py", line 746, in request
    resp, resp_body = self._request(method, url, headers=headers,
                      ^^^^^^^^^^^^^^^^^^^^^^^^^^^^^^^^^^^^^^^^^^^

      File "/home/stguser/devstack/python-tempestconf/.venv/lib/python3.12/site-packages/tempest/lib/common/rest_client.py", line 612, in _request
    resp, resp_body = self.raw_request(
                      ^^^^^^^^^^^^^^^^^

      File "/home/stguser/devstack/python-tempestconf/.venv/lib/python3.12/site-packages/tempest/lib/common/rest_client.py", line 661, in raw_request
    resp, resp_body = self.http_obj.request(
                      ^^^^^^^^^^^^^^^^^^^^^^

      File "/home/stguser/devstack/python-tempestconf/.venv/lib/python3.12/site-packages/tempest/lib/common/http.py", line 123, in request
    r = super(ClosingHttp, self).request(method, url, retries=retry,
        ^^^^^^^^^^^^^^^^^^^^^^^^^^^^^^^^^^^^^^^^^^^^^^^^^^^^^^^^^^^^

      File "/home/stguser/devstack/python-tempestconf/.venv/lib/python3.12/site-packages/urllib3/_request_methods.py", line 143, in request
    return self.request_encode_body(
           ^^^^^^^^^^^^^^^^^^^^^^^^^

      File "/home/stguser/devstack/python-tempestconf/.venv/lib/python3.12/site-packages/urllib3/_request_methods.py", line 278, in request_encode_body
    return self.urlopen(method, url, **extra_kw)
           ^^^^^^^^^^^^^^^^^^^^^^^^^^^^^^^^^^^^^

      File "/home/stguser/devstack/python-tempestconf/.venv/lib/python3.12/site-packages/urllib3/poolmanager.py", line 459, in urlopen
    response = conn.urlopen(method, u.request_uri, **kw)
               ^^^^^^^^^^^^^^^^^^^^^^^^^^^^^^^^^^^^^^^^^

      File "/home/stguser/devstack/python-tempestconf/.venv/lib/python3.12/site-packages/urllib3/connectionpool.py", line 841, in urlopen
    retries = retries.increment(
              ^^^^^^^^^^^^^^^^^^

      File "/home/stguser/devstack/python-tempestconf/.venv/lib/python3.12/site-packages/urllib3/util/retry.py", line 474, in increment
    raise reraise(type(error), error, _stacktrace)
          ^^^^^^^^^^^^^^^^^^^^^^^^^^^^^^^^^^^^^^^^

      File "/home/stguser/devstack/python-tempestconf/.venv/lib/python3.12/site-packages/urllib3/util/util.py", line 39, in reraise
    raise value

      File "/home/stguser/devstack/python-tempestconf/.venv/lib/python3.12/site-packages/urllib3/connectionpool.py", line 787, in urlopen
    response = self._make_request(
               ^^^^^^^^^^^^^^^^^^^

      File "/home/stguser/devstack/python-tempestconf/.venv/lib/python3.12/site-packages/urllib3/connectionpool.py", line 536, in _make_request
    self._raise_timeout(err=e, url=url, timeout_value=read_timeout)

      File "/home/stguser/devstack/python-tempestconf/.venv/lib/python3.12/site-packages/urllib3/connectionpool.py", line 367, in _raise_timeout
    raise ReadTimeoutError(

    urllib3.exceptions.ReadTimeoutError: HTTPConnectionPool(host='9.180.170.14', port=9696): Read timed out. (read timeout=60)

{28} tempest.api.volume.admin.test_volume_quotas_negative.VolumeQuotasNegativeTestJSON.test_quota_volumes [4.340684s] ... ok
{12} tempest.api.volume.admin.test_volume_quota_classes.VolumeQuotaClassesTest.test_update_default_quota [100.425168s] ... ok
{7} tempest.api.volume.admin.test_user_messages.UserMessagesTest.test_delete_message [106.501916s] ... ok
{9} tempest.api.volume.admin.test_qos.QosSpecsTestJSON.test_associate_disassociate_qos [69.282224s] ... ok
{30} tempest.api.volume.test_snapshot_metadata.SnapshotMetadataTestJSON.test_crud_snapshot_metadata [5.009500s] ... ok
{8} tempest.api.volume.admin.test_volume_services.VolumesServicesTestJSON.test_get_service_by_volume_host_name [120.495649s] ... ok
{1} tempest.api.volume.admin.test_volume_quotas.VolumeQuotasAdminTestJSON.test_delete_quota [83.130834s] ... ok
{8} tempest.api.volume.admin.test_volume_services.VolumesServicesTestJSON.test_list_services [0.340901s] ... ok
{1} tempest.api.volume.admin.test_volume_quotas.VolumeQuotasAdminTestJSON.test_list_default_quotas [0.552126s] ... ok
{1} tempest.api.volume.admin.test_volume_quotas.VolumeQuotasAdminTestJSON.test_list_quotas [0.340971s] ... ok
{30} tempest.api.volume.test_snapshot_metadata.SnapshotMetadataTestJSON.test_update_show_snapshot_metadata_item [6.051344s] ... ok
{18} tempest.api.volume.admin.test_snapshots_actions.SnapshotsActionsTest.test_reset_snapshot_status [3.220994s] ... ok
{21} setUpClass (tempest.api.volume.admin.test_volume_retype.VolumeRetypeWithoutMigrationTest) [0.000000s] ... FAILED

Captured traceback:
~~~~~~~~~~~~~~~~~~~
    Traceback (most recent call last):

      File "/home/stguser/devstack/python-tempestconf/.venv/lib/python3.12/site-packages/tempest/test.py", line 185, in setUpClass
    raise value.with_traceback(trace)

      File "/home/stguser/devstack/python-tempestconf/.venv/lib/python3.12/site-packages/tempest/test.py", line 178, in setUpClass
    cls.resource_setup()

      File "/home/stguser/devstack/python-tempestconf/.venv/lib/python3.12/site-packages/tempest/api/volume/admin/test_volume_retype.py", line 172, in resource_setup
    cls.src_vol_type = cls.create_volume_type('volume-type-1')
                       ^^^^^^^^^^^^^^^^^^^^^^^^^^^^^^^^^^^^^^^

      File "/home/stguser/devstack/python-tempestconf/.venv/lib/python3.12/site-packages/tempest/api/volume/base.py", line 366, in create_volume_type
    volume_type = self.admin_volume_types_client.create_volume_type(
                  ^^^^^^^^^^^^^^^^^^^^^^^^^^^^^^^^^^^^^^^^^^^^^^^^^^

      File "/home/stguser/devstack/python-tempestconf/.venv/lib/python3.12/site-packages/tempest/lib/services/volume/v3/types_client.py", line 90, in create_volume_type
    resp, body = self.post('types', post_body)
                 ^^^^^^^^^^^^^^^^^^^^^^^^^^^^^

      File "/home/stguser/devstack/python-tempestconf/.venv/lib/python3.12/site-packages/tempest/lib/common/rest_client.py", line 314, in post
    resp_header, resp_body = self.request(
                             ^^^^^^^^^^^^^

      File "/home/stguser/devstack/python-tempestconf/.venv/lib/python3.12/site-packages/tempest/lib/common/rest_client.py", line 762, in request
    self._error_checker(resp, resp_body)

      File "/home/stguser/devstack/python-tempestconf/.venv/lib/python3.12/site-packages/tempest/lib/common/rest_client.py", line 892, in _error_checker
    raise exceptions.Conflict(resp_body, resp=resp)

    tempest.lib.exceptions.Conflict: Conflict with state of target resource
Details: {'code': 409, 'message': 'Volume Type volume-type-1 already exists.'}

{9} tempest.api.volume.admin.test_qos.QosSpecsTestJSON.test_create_delete_qos_with_back_end_consumer [12.518414s] ... ok
{7} tempest.api.volume.admin.test_user_messages.UserMessagesTest.test_list_show_messages [18.884381s] ... ok
{10} tempest.api.volume.admin.test_volume_type_access.VolumeTypesAccessTest.test_volume_type_access_add [121.622306s] ... ok
{33} tempest.api.volume.test_volumes_list.VolumesListTestJSON.test_volume_list [0.618620s] ... ok
{33} tempest.api.volume.test_volumes_list.VolumesListTestJSON.test_volume_list_by_name [0.076876s] ... ok
{33} tempest.api.volume.test_volumes_list.VolumesListTestJSON.test_volume_list_details_by_name [0.091860s] ... ok
{33} tempest.api.volume.test_volumes_list.VolumesListTestJSON.test_volume_list_details_pagination [0.573104s] ... ok
{33} tempest.api.volume.test_volumes_list.VolumesListTestJSON.test_volume_list_details_with_multiple_params [0.519890s] ... ok
{33} tempest.api.volume.test_volumes_list.VolumesListTestJSON.test_volume_list_pagination [0.509760s] ... ok
{33} tempest.api.volume.test_volumes_list.VolumesListTestJSON.test_volume_list_param_display_name_and_status [0.099467s] ... ok
{33} tempest.api.volume.test_volumes_list.VolumesListTestJSON.test_volume_list_with_detail_param_display_name_and_status [0.095823s] ... ok
{33} tempest.api.volume.test_volumes_list.VolumesListTestJSON.test_volume_list_with_detail_param_marker [0.314730s] ... ok
{33} tempest.api.volume.test_volumes_list.VolumesListTestJSON.test_volume_list_with_detail_param_metadata [0.099715s] ... ok
{33} tempest.api.volume.test_volumes_list.VolumesListTestJSON.test_volume_list_with_details [0.117834s] ... ok
{33} tempest.api.volume.test_volumes_list.VolumesListTestJSON.test_volume_list_with_param_metadata [0.091752s] ... ok
{33} tempest.api.volume.test_volumes_list.VolumesListTestJSON.test_volumes_list_by_availability_zone [0.144177s] ... ok
{33} tempest.api.volume.test_volumes_list.VolumesListTestJSON.test_volumes_list_by_bootable [0.130059s] ... ok
{33} tempest.api.volume.test_volumes_list.VolumesListTestJSON.test_volumes_list_by_status [0.121285s] ... ok
{33} tempest.api.volume.test_volumes_list.VolumesListTestJSON.test_volumes_list_details_by_availability_zone [0.092141s] ... ok
{33} tempest.api.volume.test_volumes_list.VolumesListTestJSON.test_volumes_list_details_by_bootable [0.097478s] ... ok
{33} tempest.api.volume.test_volumes_list.VolumesListTestJSON.test_volumes_list_details_by_status [0.058570s] ... ok
{9} tempest.api.volume.admin.test_qos.QosSpecsTestJSON.test_create_delete_qos_with_both_consumer [7.724160s] ... ok
{10} tempest.api.volume.admin.test_volume_type_access.VolumeTypesAccessTest.test_volume_type_access_list [5.387914s] ... ok
{25} setUpClass (tempest.api.volume.test_volumes_snapshots.VolumesSnapshotTestJSON) [0.000000s] ... FAILED

Captured traceback:
~~~~~~~~~~~~~~~~~~~
    Traceback (most recent call last):

      File "/home/stguser/devstack/python-tempestconf/.venv/lib/python3.12/site-packages/urllib3/connectionpool.py", line 534, in _make_request
    response = conn.getresponse()
               ^^^^^^^^^^^^^^^^^^

      File "/home/stguser/devstack/python-tempestconf/.venv/lib/python3.12/site-packages/urllib3/connection.py", line 565, in getresponse
    httplib_response = super().getresponse()
                       ^^^^^^^^^^^^^^^^^^^^^

      File "/usr/lib/python3.12/http/client.py", line 1428, in getresponse
    response.begin()

      File "/usr/lib/python3.12/http/client.py", line 331, in begin
    version, status, reason = self._read_status()
                              ^^^^^^^^^^^^^^^^^^^

      File "/usr/lib/python3.12/http/client.py", line 292, in _read_status
    line = str(self.fp.readline(_MAXLINE + 1), "iso-8859-1")
               ^^^^^^^^^^^^^^^^^^^^^^^^^^^^^^

      File "/usr/lib/python3.12/socket.py", line 707, in readinto
    return self._sock.recv_into(b)
           ^^^^^^^^^^^^^^^^^^^^^^^

    TimeoutError: timed out

    
The above exception was the direct cause of the following exception:


    Traceback (most recent call last):

      File "/home/stguser/devstack/python-tempestconf/.venv/lib/python3.12/site-packages/tempest/test.py", line 185, in setUpClass
    raise value.with_traceback(trace)

      File "/home/stguser/devstack/python-tempestconf/.venv/lib/python3.12/site-packages/tempest/test.py", line 170, in setUpClass
    cls.setup_credentials()

      File "/home/stguser/devstack/python-tempestconf/.venv/lib/python3.12/site-packages/tempest/api/volume/base.py", line 62, in setup_credentials
    super(BaseVolumeTest, cls).setup_credentials()

      File "/home/stguser/devstack/python-tempestconf/.venv/lib/python3.12/site-packages/tempest/test.py", line 398, in setup_credentials
    manager = cls.get_client_manager(
              ^^^^^^^^^^^^^^^^^^^^^^^

      File "/home/stguser/devstack/python-tempestconf/.venv/lib/python3.12/site-packages/tempest/test.py", line 743, in get_client_manager
    creds = getattr(cred_provider, credentials_method)()
            ^^^^^^^^^^^^^^^^^^^^^^^^^^^^^^^^^^^^^^^^^^^^

      File "/home/stguser/devstack/python-tempestconf/.venv/lib/python3.12/site-packages/tempest/lib/common/dynamic_creds.py", line 473, in get_primary_creds
    return self.get_project_member_creds()
           ^^^^^^^^^^^^^^^^^^^^^^^^^^^^^^^

      File "/home/stguser/devstack/python-tempestconf/.venv/lib/python3.12/site-packages/tempest/lib/common/dynamic_creds.py", line 514, in get_project_member_creds
    return self.get_credentials(['member'], scope='project')
           ^^^^^^^^^^^^^^^^^^^^^^^^^^^^^^^^^^^^^^^^^^^^^^^^^

      File "/home/stguser/devstack/python-tempestconf/.venv/lib/python3.12/site-packages/tempest/lib/common/dynamic_creds.py", line 459, in get_credentials
    network, subnet, router = self._create_network_resources(
                              ^^^^^^^^^^^^^^^^^^^^^^^^^^^^^^^

      File "/home/stguser/devstack/python-tempestconf/.venv/lib/python3.12/site-packages/tempest/lib/common/dynamic_creds.py", line 314, in _create_network_resources
    subnet = self._create_subnet(subnet_name, tenant_id,
             ^^^^^^^^^^^^^^^^^^^^^^^^^^^^^^^^^^^^^^^^^^^

      File "/home/stguser/devstack/python-tempestconf/.venv/lib/python3.12/site-packages/tempest/lib/common/dynamic_creds.py", line 349, in _create_subnet
    create_subnet(

      File "/home/stguser/devstack/python-tempestconf/.venv/lib/python3.12/site-packages/tempest/lib/services/network/subnets_client.py", line 27, in create_subnet
    return self.create_resource(uri, post_data)
           ^^^^^^^^^^^^^^^^^^^^^^^^^^^^^^^^^^^^

      File "/home/stguser/devstack/python-tempestconf/.venv/lib/python3.12/site-packages/tempest/lib/services/network/base.py", line 62, in create_resource
    resp, body = self.post(req_uri, req_post_data)
                 ^^^^^^^^^^^^^^^^^^^^^^^^^^^^^^^^^

      File "/home/stguser/devstack/python-tempestconf/.venv/lib/python3.12/site-packages/tempest/lib/common/rest_client.py", line 314, in post
    resp_header, resp_body = self.request(
                             ^^^^^^^^^^^^^

      File "/home/stguser/devstack/python-tempestconf/.venv/lib/python3.12/site-packages/tempest/lib/common/rest_client.py", line 746, in request
    resp, resp_body = self._request(method, url, headers=headers,
                      ^^^^^^^^^^^^^^^^^^^^^^^^^^^^^^^^^^^^^^^^^^^

      File "/home/stguser/devstack/python-tempestconf/.venv/lib/python3.12/site-packages/tempest/lib/common/rest_client.py", line 612, in _request
    resp, resp_body = self.raw_request(
                      ^^^^^^^^^^^^^^^^^

      File "/home/stguser/devstack/python-tempestconf/.venv/lib/python3.12/site-packages/tempest/lib/common/rest_client.py", line 661, in raw_request
    resp, resp_body = self.http_obj.request(
                      ^^^^^^^^^^^^^^^^^^^^^^

      File "/home/stguser/devstack/python-tempestconf/.venv/lib/python3.12/site-packages/tempest/lib/common/http.py", line 123, in request
    r = super(ClosingHttp, self).request(method, url, retries=retry,
        ^^^^^^^^^^^^^^^^^^^^^^^^^^^^^^^^^^^^^^^^^^^^^^^^^^^^^^^^^^^^

      File "/home/stguser/devstack/python-tempestconf/.venv/lib/python3.12/site-packages/urllib3/_request_methods.py", line 143, in request
    return self.request_encode_body(
           ^^^^^^^^^^^^^^^^^^^^^^^^^

      File "/home/stguser/devstack/python-tempestconf/.venv/lib/python3.12/site-packages/urllib3/_request_methods.py", line 278, in request_encode_body
    return self.urlopen(method, url, **extra_kw)
           ^^^^^^^^^^^^^^^^^^^^^^^^^^^^^^^^^^^^^

      File "/home/stguser/devstack/python-tempestconf/.venv/lib/python3.12/site-packages/urllib3/poolmanager.py", line 459, in urlopen
    response = conn.urlopen(method, u.request_uri, **kw)
               ^^^^^^^^^^^^^^^^^^^^^^^^^^^^^^^^^^^^^^^^^

      File "/home/stguser/devstack/python-tempestconf/.venv/lib/python3.12/site-packages/urllib3/connectionpool.py", line 841, in urlopen
    retries = retries.increment(
              ^^^^^^^^^^^^^^^^^^

      File "/home/stguser/devstack/python-tempestconf/.venv/lib/python3.12/site-packages/urllib3/util/retry.py", line 474, in increment
    raise reraise(type(error), error, _stacktrace)
          ^^^^^^^^^^^^^^^^^^^^^^^^^^^^^^^^^^^^^^^^

      File "/home/stguser/devstack/python-tempestconf/.venv/lib/python3.12/site-packages/urllib3/util/util.py", line 39, in reraise
    raise value

      File "/home/stguser/devstack/python-tempestconf/.venv/lib/python3.12/site-packages/urllib3/connectionpool.py", line 787, in urlopen
    response = self._make_request(
               ^^^^^^^^^^^^^^^^^^^

      File "/home/stguser/devstack/python-tempestconf/.venv/lib/python3.12/site-packages/urllib3/connectionpool.py", line 536, in _make_request
    self._raise_timeout(err=e, url=url, timeout_value=read_timeout)

      File "/home/stguser/devstack/python-tempestconf/.venv/lib/python3.12/site-packages/urllib3/connectionpool.py", line 367, in _raise_timeout
    raise ReadTimeoutError(

    urllib3.exceptions.ReadTimeoutError: HTTPConnectionPool(host='9.180.170.14', port=9696): Read timed out. (read timeout=60)

{5} tempest.api.volume.test_volume_transfers.VolumesTransfersTest.test_create_get_list_accept_volume_transfer [128.820659s] ... ok
{6} tempest.api.volume.test_volume_transfers.VolumesTransfersV355Test.test_create_get_list_accept_volume_transfer [128.820567s] ... ok
{9} tempest.api.volume.admin.test_qos.QosSpecsTestJSON.test_create_delete_qos_with_front_end_consumer [4.205726s] ... ok
{9} tempest.api.volume.admin.test_qos.QosSpecsTestJSON.test_get_qos [0.102881s] ... ok
{32} tempest.api.volume.admin.test_volume_snapshot_quotas_negative.VolumeSnapshotQuotasNegativeTestJSON.test_quota_volume_gigabytes_snapshots [6.649241s] ... ok
{32} tempest.api.volume.admin.test_volume_snapshot_quotas_negative.VolumeSnapshotQuotasNegativeTestJSON.test_quota_volume_snapshots [0.653034s] ... ok
{11} tempest.api.volume.test_volume_transfers.VolumesTransfersV357Test.test_create_get_list_accept_volume_transfer [130.743307s] ... ok
{9} tempest.api.volume.admin.test_qos.QosSpecsTestJSON.test_list_qos [2.289697s] ... ok
{9} tempest.api.volume.admin.test_qos.QosSpecsTestJSON.test_set_unset_qos_key [1.348018s] ... ok
{39} tempest.api.volume.test_volumes_snapshots_list.VolumesSnapshotListTestJSON.test_snapshot_list_param_limit [0.093662s] ... ok
{39} tempest.api.volume.test_volumes_snapshots_list.VolumesSnapshotListTestJSON.test_snapshot_list_param_limit_equals_infinite [0.234668s] ... ok
{39} tempest.api.volume.test_volumes_snapshots_list.VolumesSnapshotListTestJSON.test_snapshot_list_param_limit_equals_zero [0.043598s] ... ok
{39} tempest.api.volume.test_volumes_snapshots_list.VolumesSnapshotListTestJSON.test_snapshot_list_param_marker [0.114969s] ... ok
{39} tempest.api.volume.test_volumes_snapshots_list.VolumesSnapshotListTestJSON.test_snapshot_list_param_offset [0.044179s] ... ok
{39} tempest.api.volume.test_volumes_snapshots_list.VolumesSnapshotListTestJSON.test_snapshot_list_param_sort_created_at_asc [0.040846s] ... ok
{39} tempest.api.volume.test_volumes_snapshots_list.VolumesSnapshotListTestJSON.test_snapshot_list_param_sort_created_at_desc [0.029000s] ... ok
{39} tempest.api.volume.test_volumes_snapshots_list.VolumesSnapshotListTestJSON.test_snapshot_list_param_sort_id_asc [0.040711s] ... ok
{39} tempest.api.volume.test_volumes_snapshots_list.VolumesSnapshotListTestJSON.test_snapshot_list_param_sort_id_desc [0.038947s] ... ok
{39} tempest.api.volume.test_volumes_snapshots_list.VolumesSnapshotListTestJSON.test_snapshot_list_param_sort_name_asc [0.042804s] ... ok
{39} tempest.api.volume.test_volumes_snapshots_list.VolumesSnapshotListTestJSON.test_snapshot_list_param_sort_name_desc [0.041493s] ... ok
{39} tempest.api.volume.test_volumes_snapshots_list.VolumesSnapshotListTestJSON.test_snapshots_list_details_with_params [0.145123s] ... ok
{39} tempest.api.volume.test_volumes_snapshots_list.VolumesSnapshotListTestJSON.test_snapshots_list_with_params [0.120072s] ... ok
{0} tempest.api.volume.test_volumes_get.VolumesGetTest.test_volume_create_get_update_delete [171.289534s] ... ok
{1} tempest.api.volume.admin.test_volume_quotas.VolumeQuotasAdminTestJSON.test_quota_usage [37.187289s] ... ok
{18} tempest.api.volume.admin.test_snapshots_actions.SnapshotsActionsTest.test_snapshot_force_delete_when_snapshot_is_creating [36.176154s] ... ok
{29} tempest.api.volume.admin.test_volumes_list.VolumesListAdminTestJSON.test_volume_list_param_tenant [20.982592s] ... ok
{4} tempest.api.volume.admin.test_volume_types.VolumeTypesTest.test_volume_type_update [64.705838s] ... ok
{5} tempest.api.volume.test_volume_transfers.VolumesTransfersTest.test_create_list_delete_volume_transfer [32.435945s] ... ok
{6} tempest.api.volume.test_volume_transfers.VolumesTransfersV355Test.test_create_list_delete_volume_transfer [33.742667s] ... ok
{13} tempest.api.volume.test_volumes_negative.VolumesNegativeTest.test_attach_volumes_with_nonexistent_volume_id [131.396501s] ... ok
{11} tempest.api.volume.test_volume_transfers.VolumesTransfersV357Test.test_create_list_delete_volume_transfer [37.497473s] ... ok
{3} tempest.api.volume.test_volumes_clone.VolumesCloneTest.test_create_from_volume [202.295237s] ... ok
{2} tempest.api.volume.test_volume_delete_cascade.VolumesDeleteCascade.test_volume_delete_cascade [207.736956s] ... ok
{13} tempest.api.volume.test_volumes_negative.VolumesNegativeTest.test_create_volume_from_deactivated_image [8.139882s] ... ok
{18} tempest.api.volume.admin.test_snapshots_actions.SnapshotsActionsTest.test_snapshot_force_delete_when_snapshot_is_deleting [27.825667s] ... ok
{1} tempest.api.volume.admin.test_volume_quotas.VolumeQuotasAdminTestJSON.test_quota_usage_after_volume_transfer [34.570491s] ... ok
{1} tempest.api.volume.admin.test_volume_quotas.VolumeQuotasAdminTestJSON.test_show_quota_usage [0.535521s] ... ok
{13} tempest.api.volume.test_volumes_negative.VolumesNegativeTest.test_create_volume_from_image_with_decreasing_size [6.020017s] ... ok
{13} tempest.api.volume.test_volumes_negative.VolumesNegativeTest.test_create_volume_with_invalid_size [0.015454s] ... ok
{13} tempest.api.volume.test_volumes_negative.VolumesNegativeTest.test_create_volume_with_nonexistent_snapshot_id [0.090400s] ... ok
{13} tempest.api.volume.test_volumes_negative.VolumesNegativeTest.test_create_volume_with_nonexistent_source_volid [0.171831s] ... ok
{13} tempest.api.volume.test_volumes_negative.VolumesNegativeTest.test_create_volume_with_nonexistent_volume_type [0.043642s] ... ok
{13} tempest.api.volume.test_volumes_negative.VolumesNegativeTest.test_create_volume_with_size_negative [0.011953s] ... ok
{13} tempest.api.volume.test_volumes_negative.VolumesNegativeTest.test_create_volume_with_size_zero [0.011816s] ... ok
{13} tempest.api.volume.test_volumes_negative.VolumesNegativeTest.test_create_volume_without_passing_size [0.022541s] ... ok
{13} tempest.api.volume.test_volumes_negative.VolumesNegativeTest.test_delete_invalid_volume_id [0.065172s] ... ok
{13} tempest.api.volume.test_volumes_negative.VolumesNegativeTest.test_delete_volume_without_passing_volume_id [0.022238s] ... ok
{13} tempest.api.volume.test_volumes_negative.VolumesNegativeTest.test_detach_volumes_with_invalid_volume_id [0.099183s] ... ok
{13} tempest.api.volume.test_volumes_negative.VolumesNegativeTest.test_get_invalid_volume_id [0.025360s] ... ok
{13} tempest.api.volume.test_volumes_negative.VolumesNegativeTest.test_get_volume_without_passing_volume_id [0.010935s] ... ok
{13} tempest.api.volume.test_volumes_negative.VolumesNegativeTest.test_list_volumes_detail_with_invalid_status [0.323563s] ... ok
{13} tempest.api.volume.test_volumes_negative.VolumesNegativeTest.test_list_volumes_detail_with_nonexistent_name [0.105625s] ... ok
{13} tempest.api.volume.test_volumes_negative.VolumesNegativeTest.test_list_volumes_with_invalid_status [0.073436s] ... ok
{13} tempest.api.volume.test_volumes_negative.VolumesNegativeTest.test_list_volumes_with_nonexistent_name [0.097981s] ... ok
{13} tempest.api.volume.test_volumes_negative.VolumesNegativeTest.test_reserve_volume_with_negative_volume_status [0.780395s] ... ok
{13} tempest.api.volume.test_volumes_negative.VolumesNegativeTest.test_reserve_volume_with_nonexistent_volume_id [0.024699s] ... ok
{13} tempest.api.volume.test_volumes_negative.VolumesNegativeTest.test_unreserve_volume_with_nonexistent_volume_id [0.131155s] ... ok
{13} tempest.api.volume.test_volumes_negative.VolumesNegativeTest.test_update_volume_with_empty_volume_id [0.011611s] ... ok
{13} tempest.api.volume.test_volumes_negative.VolumesNegativeTest.test_update_volume_with_invalid_volume_id [0.094773s] ... ok
{13} tempest.api.volume.test_volumes_negative.VolumesNegativeTest.test_update_volume_with_nonexistent_volume_id [0.160199s] ... ok
{13} tempest.api.volume.test_volumes_negative.VolumesNegativeTest.test_volume_delete_nonexistent_volume_id [0.153143s] ... ok
{13} tempest.api.volume.test_volumes_negative.VolumesNegativeTest.test_volume_get_nonexistent_volume_id [0.134486s] ... ok
{5} setUpClass (tempest.api.volume.test_volumes_backup.VolumesBackupsV39Test) ... SKIPPED: Cinder backup feature disabled
{1} tempest.api.volume.admin.test_volume_quotas.VolumeQuotasAdminTestJSON.test_update_all_quota_resources_for_tenant [6.664010s] ... ok
{18} tempest.api.volume.admin.test_snapshots_actions.SnapshotsActionsTest.test_snapshot_force_delete_when_snapshot_is_error [11.315909s] ... ok
{18} tempest.api.volume.admin.test_snapshots_actions.SnapshotsActionsTest.test_snapshot_force_delete_when_snapshot_is_error_deleting [11.750924s] ... ok
{18} tempest.api.volume.admin.test_snapshots_actions.SnapshotsActionsTest.test_update_snapshot_status [0.699552s] ... ok
{1} setUpClass (tempest.api.volume.admin.test_volumes_backup.VolumesBackupsAdminTest) ... SKIPPED: Cinder backup feature disabled
{0} tempest.api.volume.test_volumes_get.VolumesGetTest.test_volume_create_get_update_delete_as_clone [70.148048s] ... ok
{0} tearDownClass (tempest.api.volume.test_volumes_get.VolumesGetTest) [0.000000s] ... FAILED

Captured traceback:
~~~~~~~~~~~~~~~~~~~
    Traceback (most recent call last):

      File "/home/stguser/devstack/python-tempestconf/.venv/lib/python3.12/site-packages/tempest/test.py", line 246, in tearDownClass
    raise value.with_traceback(trace)

      File "/home/stguser/devstack/python-tempestconf/.venv/lib/python3.12/site-packages/tempest/test.py", line 210, in tearDownClass
    teardown()

      File "/home/stguser/devstack/python-tempestconf/.venv/lib/python3.12/site-packages/tempest/test.py", line 757, in clear_credentials
    cls._creds_provider.clear_creds()

      File "/home/stguser/devstack/python-tempestconf/.venv/lib/python3.12/site-packages/tempest/lib/common/dynamic_creds.py", line 635, in clear_creds
    self.cleanup_default_secgroup(

      File "/home/stguser/devstack/python-tempestconf/.venv/lib/python3.12/site-packages/tempest/lib/common/cred_provider.py", line 145, in cleanup_default_secgroup
    security_group_client.delete_security_group(secgroup['id'])

      File "/home/stguser/devstack/python-tempestconf/.venv/lib/python3.12/site-packages/tempest/lib/services/network/security_groups_client.py", line 59, in delete_security_group
    return self.delete_resource(uri)
           ^^^^^^^^^^^^^^^^^^^^^^^^^

      File "/home/stguser/devstack/python-tempestconf/.venv/lib/python3.12/site-packages/tempest/lib/services/network/base.py", line 42, in delete_resource
    resp, body = self.delete(req_uri)
                 ^^^^^^^^^^^^^^^^^^^^

      File "/home/stguser/devstack/python-tempestconf/.venv/lib/python3.12/site-packages/tempest/lib/common/rest_client.py", line 359, in delete
    return self.request('DELETE', url, extra_headers, headers, body)
           ^^^^^^^^^^^^^^^^^^^^^^^^^^^^^^^^^^^^^^^^^^^^^^^^^^^^^^^^^

      File "/home/stguser/devstack/python-tempestconf/.venv/lib/python3.12/site-packages/tempest/lib/common/rest_client.py", line 762, in request
    self._error_checker(resp, resp_body)

      File "/home/stguser/devstack/python-tempestconf/.venv/lib/python3.12/site-packages/tempest/lib/common/rest_client.py", line 892, in _error_checker
    raise exceptions.Conflict(resp_body, resp=resp)

    tempest.lib.exceptions.Conflict: Conflict with state of target resource
Details: {'type': 'SecurityGroupInUse', 'message': 'Security Group None cannot perform precommit_delete due to Callback neutron.plugins.ml2.drivers.ovn.mech_driver.mech_driver.OVNMechanismDriver._delete_security_group_precommit-3946265 failed with "Port_Group pg_04579a8f_30ef_4040_ba9b_d19116dcd9b2 does not exist".', 'detail': ''}

{6} tearDownClass (tempest.api.volume.test_volume_transfers.VolumesTransfersV355Test) [0.000000s] ... FAILED

Captured traceback:
~~~~~~~~~~~~~~~~~~~
    Traceback (most recent call last):

      File "/home/stguser/devstack/python-tempestconf/.venv/lib/python3.12/site-packages/tempest/test.py", line 246, in tearDownClass
    raise value.with_traceback(trace)

      File "/home/stguser/devstack/python-tempestconf/.venv/lib/python3.12/site-packages/tempest/test.py", line 210, in tearDownClass
    teardown()

      File "/home/stguser/devstack/python-tempestconf/.venv/lib/python3.12/site-packages/tempest/test.py", line 757, in clear_credentials
    cls._creds_provider.clear_creds()

      File "/home/stguser/devstack/python-tempestconf/.venv/lib/python3.12/site-packages/tempest/lib/common/dynamic_creds.py", line 635, in clear_creds
    self.cleanup_default_secgroup(

      File "/home/stguser/devstack/python-tempestconf/.venv/lib/python3.12/site-packages/tempest/lib/common/cred_provider.py", line 145, in cleanup_default_secgroup
    security_group_client.delete_security_group(secgroup['id'])

      File "/home/stguser/devstack/python-tempestconf/.venv/lib/python3.12/site-packages/tempest/lib/services/network/security_groups_client.py", line 59, in delete_security_group
    return self.delete_resource(uri)
           ^^^^^^^^^^^^^^^^^^^^^^^^^

      File "/home/stguser/devstack/python-tempestconf/.venv/lib/python3.12/site-packages/tempest/lib/services/network/base.py", line 42, in delete_resource
    resp, body = self.delete(req_uri)
                 ^^^^^^^^^^^^^^^^^^^^

      File "/home/stguser/devstack/python-tempestconf/.venv/lib/python3.12/site-packages/tempest/lib/common/rest_client.py", line 359, in delete
    return self.request('DELETE', url, extra_headers, headers, body)
           ^^^^^^^^^^^^^^^^^^^^^^^^^^^^^^^^^^^^^^^^^^^^^^^^^^^^^^^^^

      File "/home/stguser/devstack/python-tempestconf/.venv/lib/python3.12/site-packages/tempest/lib/common/rest_client.py", line 762, in request
    self._error_checker(resp, resp_body)

      File "/home/stguser/devstack/python-tempestconf/.venv/lib/python3.12/site-packages/tempest/lib/common/rest_client.py", line 892, in _error_checker
    raise exceptions.Conflict(resp_body, resp=resp)

    tempest.lib.exceptions.Conflict: Conflict with state of target resource
Details: {'type': 'SecurityGroupInUse', 'message': 'Security Group None cannot perform precommit_delete due to Callback neutron.plugins.ml2.drivers.ovn.mech_driver.mech_driver.OVNMechanismDriver._delete_security_group_precommit-3946265 failed with "Port_Group pg_80db68d2_48b9_4348_ae4c_be543fd0e635 does not exist".', 'detail': ''}

{18} tearDownClass (tempest.api.volume.admin.test_snapshots_actions.SnapshotsActionsTest) [0.000000s] ... FAILED

Captured traceback:
~~~~~~~~~~~~~~~~~~~
    Traceback (most recent call last):

      File "/home/stguser/devstack/python-tempestconf/.venv/lib/python3.12/site-packages/tempest/test.py", line 246, in tearDownClass
    raise value.with_traceback(trace)

      File "/home/stguser/devstack/python-tempestconf/.venv/lib/python3.12/site-packages/tempest/test.py", line 210, in tearDownClass
    teardown()

      File "/home/stguser/devstack/python-tempestconf/.venv/lib/python3.12/site-packages/tempest/test.py", line 757, in clear_credentials
    cls._creds_provider.clear_creds()

      File "/home/stguser/devstack/python-tempestconf/.venv/lib/python3.12/site-packages/tempest/lib/common/dynamic_creds.py", line 635, in clear_creds
    self.cleanup_default_secgroup(

      File "/home/stguser/devstack/python-tempestconf/.venv/lib/python3.12/site-packages/tempest/lib/common/cred_provider.py", line 145, in cleanup_default_secgroup
    security_group_client.delete_security_group(secgroup['id'])

      File "/home/stguser/devstack/python-tempestconf/.venv/lib/python3.12/site-packages/tempest/lib/services/network/security_groups_client.py", line 59, in delete_security_group
    return self.delete_resource(uri)
           ^^^^^^^^^^^^^^^^^^^^^^^^^

      File "/home/stguser/devstack/python-tempestconf/.venv/lib/python3.12/site-packages/tempest/lib/services/network/base.py", line 42, in delete_resource
    resp, body = self.delete(req_uri)
                 ^^^^^^^^^^^^^^^^^^^^

      File "/home/stguser/devstack/python-tempestconf/.venv/lib/python3.12/site-packages/tempest/lib/common/rest_client.py", line 359, in delete
    return self.request('DELETE', url, extra_headers, headers, body)
           ^^^^^^^^^^^^^^^^^^^^^^^^^^^^^^^^^^^^^^^^^^^^^^^^^^^^^^^^^

      File "/home/stguser/devstack/python-tempestconf/.venv/lib/python3.12/site-packages/tempest/lib/common/rest_client.py", line 762, in request
    self._error_checker(resp, resp_body)

      File "/home/stguser/devstack/python-tempestconf/.venv/lib/python3.12/site-packages/tempest/lib/common/rest_client.py", line 892, in _error_checker
    raise exceptions.Conflict(resp_body, resp=resp)

    tempest.lib.exceptions.Conflict: Conflict with state of target resource
Details: {'type': 'SecurityGroupInUse', 'message': 'Security Group None cannot perform precommit_delete due to Callback neutron.plugins.ml2.drivers.ovn.mech_driver.mech_driver.OVNMechanismDriver._delete_security_group_precommit-3946265 failed with "Port_Group pg_b97ea8ce_15c7_4a6b_a305_f66bfebd6813 does not exist".', 'detail': ''}


==============================
Failed 7 tests - output below:
==============================

setUpClass (tempest.api.volume.test_volumes_actions.VolumesActionsTest)
-----------------------------------------------------------------------

Captured traceback:
~~~~~~~~~~~~~~~~~~~
    Traceback (most recent call last):

      File "/home/stguser/devstack/python-tempestconf/.venv/lib/python3.12/site-packages/urllib3/connectionpool.py", line 534, in _make_request
    response = conn.getresponse()
               ^^^^^^^^^^^^^^^^^^

      File "/home/stguser/devstack/python-tempestconf/.venv/lib/python3.12/site-packages/urllib3/connection.py", line 565, in getresponse
    httplib_response = super().getresponse()
                       ^^^^^^^^^^^^^^^^^^^^^

      File "/usr/lib/python3.12/http/client.py", line 1428, in getresponse
    response.begin()

      File "/usr/lib/python3.12/http/client.py", line 331, in begin
    version, status, reason = self._read_status()
                              ^^^^^^^^^^^^^^^^^^^

      File "/usr/lib/python3.12/http/client.py", line 292, in _read_status
    line = str(self.fp.readline(_MAXLINE + 1), "iso-8859-1")
               ^^^^^^^^^^^^^^^^^^^^^^^^^^^^^^

      File "/usr/lib/python3.12/socket.py", line 707, in readinto
    return self._sock.recv_into(b)
           ^^^^^^^^^^^^^^^^^^^^^^^

    TimeoutError: timed out

    
The above exception was the direct cause of the following exception:


    Traceback (most recent call last):

      File "/home/stguser/devstack/python-tempestconf/.venv/lib/python3.12/site-packages/tempest/test.py", line 185, in setUpClass
    raise value.with_traceback(trace)

      File "/home/stguser/devstack/python-tempestconf/.venv/lib/python3.12/site-packages/tempest/test.py", line 170, in setUpClass
    cls.setup_credentials()

      File "/home/stguser/devstack/python-tempestconf/.venv/lib/python3.12/site-packages/tempest/api/volume/base.py", line 62, in setup_credentials
    super(BaseVolumeTest, cls).setup_credentials()

      File "/home/stguser/devstack/python-tempestconf/.venv/lib/python3.12/site-packages/tempest/test.py", line 398, in setup_credentials
    manager = cls.get_client_manager(
              ^^^^^^^^^^^^^^^^^^^^^^^

      File "/home/stguser/devstack/python-tempestconf/.venv/lib/python3.12/site-packages/tempest/test.py", line 743, in get_client_manager
    creds = getattr(cred_provider, credentials_method)()
            ^^^^^^^^^^^^^^^^^^^^^^^^^^^^^^^^^^^^^^^^^^^^

      File "/home/stguser/devstack/python-tempestconf/.venv/lib/python3.12/site-packages/tempest/lib/common/dynamic_creds.py", line 473, in get_primary_creds
    return self.get_project_member_creds()
           ^^^^^^^^^^^^^^^^^^^^^^^^^^^^^^^

      File "/home/stguser/devstack/python-tempestconf/.venv/lib/python3.12/site-packages/tempest/lib/common/dynamic_creds.py", line 514, in get_project_member_creds
    return self.get_credentials(['member'], scope='project')
           ^^^^^^^^^^^^^^^^^^^^^^^^^^^^^^^^^^^^^^^^^^^^^^^^^

      File "/home/stguser/devstack/python-tempestconf/.venv/lib/python3.12/site-packages/tempest/lib/common/dynamic_creds.py", line 459, in get_credentials
    network, subnet, router = self._create_network_resources(
                              ^^^^^^^^^^^^^^^^^^^^^^^^^^^^^^^

      File "/home/stguser/devstack/python-tempestconf/.venv/lib/python3.12/site-packages/tempest/lib/common/dynamic_creds.py", line 310, in _create_network_resources
    network = self._create_network(network_name, tenant_id)
              ^^^^^^^^^^^^^^^^^^^^^^^^^^^^^^^^^^^^^^^^^^^^^

      File "/home/stguser/devstack/python-tempestconf/.venv/lib/python3.12/site-packages/tempest/lib/common/dynamic_creds.py", line 338, in _create_network
    resp_body = self.networks_admin_client.create_network(
                ^^^^^^^^^^^^^^^^^^^^^^^^^^^^^^^^^^^^^^^^^^

      File "/home/stguser/devstack/python-tempestconf/.venv/lib/python3.12/site-packages/tempest/lib/services/network/networks_client.py", line 27, in create_network
    return self.create_resource(uri, post_data)
           ^^^^^^^^^^^^^^^^^^^^^^^^^^^^^^^^^^^^

      File "/home/stguser/devstack/python-tempestconf/.venv/lib/python3.12/site-packages/tempest/lib/services/network/base.py", line 62, in create_resource
    resp, body = self.post(req_uri, req_post_data)
                 ^^^^^^^^^^^^^^^^^^^^^^^^^^^^^^^^^

      File "/home/stguser/devstack/python-tempestconf/.venv/lib/python3.12/site-packages/tempest/lib/common/rest_client.py", line 314, in post
    resp_header, resp_body = self.request(
                             ^^^^^^^^^^^^^

      File "/home/stguser/devstack/python-tempestconf/.venv/lib/python3.12/site-packages/tempest/lib/common/rest_client.py", line 746, in request
    resp, resp_body = self._request(method, url, headers=headers,
                      ^^^^^^^^^^^^^^^^^^^^^^^^^^^^^^^^^^^^^^^^^^^

      File "/home/stguser/devstack/python-tempestconf/.venv/lib/python3.12/site-packages/tempest/lib/common/rest_client.py", line 612, in _request
    resp, resp_body = self.raw_request(
                      ^^^^^^^^^^^^^^^^^

      File "/home/stguser/devstack/python-tempestconf/.venv/lib/python3.12/site-packages/tempest/lib/common/rest_client.py", line 661, in raw_request
    resp, resp_body = self.http_obj.request(
                      ^^^^^^^^^^^^^^^^^^^^^^

      File "/home/stguser/devstack/python-tempestconf/.venv/lib/python3.12/site-packages/tempest/lib/common/http.py", line 123, in request
    r = super(ClosingHttp, self).request(method, url, retries=retry,
        ^^^^^^^^^^^^^^^^^^^^^^^^^^^^^^^^^^^^^^^^^^^^^^^^^^^^^^^^^^^^

      File "/home/stguser/devstack/python-tempestconf/.venv/lib/python3.12/site-packages/urllib3/_request_methods.py", line 143, in request
    return self.request_encode_body(
           ^^^^^^^^^^^^^^^^^^^^^^^^^

      File "/home/stguser/devstack/python-tempestconf/.venv/lib/python3.12/site-packages/urllib3/_request_methods.py", line 278, in request_encode_body
    return self.urlopen(method, url, **extra_kw)
           ^^^^^^^^^^^^^^^^^^^^^^^^^^^^^^^^^^^^^

      File "/home/stguser/devstack/python-tempestconf/.venv/lib/python3.12/site-packages/urllib3/poolmanager.py", line 459, in urlopen
    response = conn.urlopen(method, u.request_uri, **kw)
               ^^^^^^^^^^^^^^^^^^^^^^^^^^^^^^^^^^^^^^^^^

      File "/home/stguser/devstack/python-tempestconf/.venv/lib/python3.12/site-packages/urllib3/connectionpool.py", line 841, in urlopen
    retries = retries.increment(
              ^^^^^^^^^^^^^^^^^^

      File "/home/stguser/devstack/python-tempestconf/.venv/lib/python3.12/site-packages/urllib3/util/retry.py", line 474, in increment
    raise reraise(type(error), error, _stacktrace)
          ^^^^^^^^^^^^^^^^^^^^^^^^^^^^^^^^^^^^^^^^

      File "/home/stguser/devstack/python-tempestconf/.venv/lib/python3.12/site-packages/urllib3/util/util.py", line 39, in reraise
    raise value

      File "/home/stguser/devstack/python-tempestconf/.venv/lib/python3.12/site-packages/urllib3/connectionpool.py", line 787, in urlopen
    response = self._make_request(
               ^^^^^^^^^^^^^^^^^^^

      File "/home/stguser/devstack/python-tempestconf/.venv/lib/python3.12/site-packages/urllib3/connectionpool.py", line 536, in _make_request
    self._raise_timeout(err=e, url=url, timeout_value=read_timeout)

      File "/home/stguser/devstack/python-tempestconf/.venv/lib/python3.12/site-packages/urllib3/connectionpool.py", line 367, in _raise_timeout
    raise ReadTimeoutError(

    urllib3.exceptions.ReadTimeoutError: HTTPConnectionPool(host='9.180.170.14', port=9696): Read timed out. (read timeout=60)


setUpClass (tempest.api.volume.admin.test_volumes_actions.VolumesActionsTest)
-----------------------------------------------------------------------------

Captured traceback:
~~~~~~~~~~~~~~~~~~~
    Traceback (most recent call last):

      File "/home/stguser/devstack/python-tempestconf/.venv/lib/python3.12/site-packages/urllib3/connectionpool.py", line 534, in _make_request
    response = conn.getresponse()
               ^^^^^^^^^^^^^^^^^^

      File "/home/stguser/devstack/python-tempestconf/.venv/lib/python3.12/site-packages/urllib3/connection.py", line 565, in getresponse
    httplib_response = super().getresponse()
                       ^^^^^^^^^^^^^^^^^^^^^

      File "/usr/lib/python3.12/http/client.py", line 1428, in getresponse
    response.begin()

      File "/usr/lib/python3.12/http/client.py", line 331, in begin
    version, status, reason = self._read_status()
                              ^^^^^^^^^^^^^^^^^^^

      File "/usr/lib/python3.12/http/client.py", line 292, in _read_status
    line = str(self.fp.readline(_MAXLINE + 1), "iso-8859-1")
               ^^^^^^^^^^^^^^^^^^^^^^^^^^^^^^

      File "/usr/lib/python3.12/socket.py", line 707, in readinto
    return self._sock.recv_into(b)
           ^^^^^^^^^^^^^^^^^^^^^^^

    TimeoutError: timed out

    
The above exception was the direct cause of the following exception:


    Traceback (most recent call last):

      File "/home/stguser/devstack/python-tempestconf/.venv/lib/python3.12/site-packages/tempest/test.py", line 185, in setUpClass
    raise value.with_traceback(trace)

      File "/home/stguser/devstack/python-tempestconf/.venv/lib/python3.12/site-packages/tempest/test.py", line 170, in setUpClass
    cls.setup_credentials()

      File "/home/stguser/devstack/python-tempestconf/.venv/lib/python3.12/site-packages/tempest/api/volume/base.py", line 62, in setup_credentials
    super(BaseVolumeTest, cls).setup_credentials()

      File "/home/stguser/devstack/python-tempestconf/.venv/lib/python3.12/site-packages/tempest/test.py", line 398, in setup_credentials
    manager = cls.get_client_manager(
              ^^^^^^^^^^^^^^^^^^^^^^^

      File "/home/stguser/devstack/python-tempestconf/.venv/lib/python3.12/site-packages/tempest/test.py", line 743, in get_client_manager
    creds = getattr(cred_provider, credentials_method)()
            ^^^^^^^^^^^^^^^^^^^^^^^^^^^^^^^^^^^^^^^^^^^^

      File "/home/stguser/devstack/python-tempestconf/.venv/lib/python3.12/site-packages/tempest/lib/common/dynamic_creds.py", line 473, in get_primary_creds
    return self.get_project_member_creds()
           ^^^^^^^^^^^^^^^^^^^^^^^^^^^^^^^

      File "/home/stguser/devstack/python-tempestconf/.venv/lib/python3.12/site-packages/tempest/lib/common/dynamic_creds.py", line 514, in get_project_member_creds
    return self.get_credentials(['member'], scope='project')
           ^^^^^^^^^^^^^^^^^^^^^^^^^^^^^^^^^^^^^^^^^^^^^^^^^

      File "/home/stguser/devstack/python-tempestconf/.venv/lib/python3.12/site-packages/tempest/lib/common/dynamic_creds.py", line 459, in get_credentials
    network, subnet, router = self._create_network_resources(
                              ^^^^^^^^^^^^^^^^^^^^^^^^^^^^^^^

      File "/home/stguser/devstack/python-tempestconf/.venv/lib/python3.12/site-packages/tempest/lib/common/dynamic_creds.py", line 310, in _create_network_resources
    network = self._create_network(network_name, tenant_id)
              ^^^^^^^^^^^^^^^^^^^^^^^^^^^^^^^^^^^^^^^^^^^^^

      File "/home/stguser/devstack/python-tempestconf/.venv/lib/python3.12/site-packages/tempest/lib/common/dynamic_creds.py", line 338, in _create_network
    resp_body = self.networks_admin_client.create_network(
                ^^^^^^^^^^^^^^^^^^^^^^^^^^^^^^^^^^^^^^^^^^

      File "/home/stguser/devstack/python-tempestconf/.venv/lib/python3.12/site-packages/tempest/lib/services/network/networks_client.py", line 27, in create_network
    return self.create_resource(uri, post_data)
           ^^^^^^^^^^^^^^^^^^^^^^^^^^^^^^^^^^^^

      File "/home/stguser/devstack/python-tempestconf/.venv/lib/python3.12/site-packages/tempest/lib/services/network/base.py", line 62, in create_resource
    resp, body = self.post(req_uri, req_post_data)
                 ^^^^^^^^^^^^^^^^^^^^^^^^^^^^^^^^^

      File "/home/stguser/devstack/python-tempestconf/.venv/lib/python3.12/site-packages/tempest/lib/common/rest_client.py", line 314, in post
    resp_header, resp_body = self.request(
                             ^^^^^^^^^^^^^

      File "/home/stguser/devstack/python-tempestconf/.venv/lib/python3.12/site-packages/tempest/lib/common/rest_client.py", line 746, in request
    resp, resp_body = self._request(method, url, headers=headers,
                      ^^^^^^^^^^^^^^^^^^^^^^^^^^^^^^^^^^^^^^^^^^^

      File "/home/stguser/devstack/python-tempestconf/.venv/lib/python3.12/site-packages/tempest/lib/common/rest_client.py", line 612, in _request
    resp, resp_body = self.raw_request(
                      ^^^^^^^^^^^^^^^^^

      File "/home/stguser/devstack/python-tempestconf/.venv/lib/python3.12/site-packages/tempest/lib/common/rest_client.py", line 661, in raw_request
    resp, resp_body = self.http_obj.request(
                      ^^^^^^^^^^^^^^^^^^^^^^

      File "/home/stguser/devstack/python-tempestconf/.venv/lib/python3.12/site-packages/tempest/lib/common/http.py", line 123, in request
    r = super(ClosingHttp, self).request(method, url, retries=retry,
        ^^^^^^^^^^^^^^^^^^^^^^^^^^^^^^^^^^^^^^^^^^^^^^^^^^^^^^^^^^^^

      File "/home/stguser/devstack/python-tempestconf/.venv/lib/python3.12/site-packages/urllib3/_request_methods.py", line 143, in request
    return self.request_encode_body(
           ^^^^^^^^^^^^^^^^^^^^^^^^^

      File "/home/stguser/devstack/python-tempestconf/.venv/lib/python3.12/site-packages/urllib3/_request_methods.py", line 278, in request_encode_body
    return self.urlopen(method, url, **extra_kw)
           ^^^^^^^^^^^^^^^^^^^^^^^^^^^^^^^^^^^^^

      File "/home/stguser/devstack/python-tempestconf/.venv/lib/python3.12/site-packages/urllib3/poolmanager.py", line 459, in urlopen
    response = conn.urlopen(method, u.request_uri, **kw)
               ^^^^^^^^^^^^^^^^^^^^^^^^^^^^^^^^^^^^^^^^^

      File "/home/stguser/devstack/python-tempestconf/.venv/lib/python3.12/site-packages/urllib3/connectionpool.py", line 841, in urlopen
    retries = retries.increment(
              ^^^^^^^^^^^^^^^^^^

      File "/home/stguser/devstack/python-tempestconf/.venv/lib/python3.12/site-packages/urllib3/util/retry.py", line 474, in increment
    raise reraise(type(error), error, _stacktrace)
          ^^^^^^^^^^^^^^^^^^^^^^^^^^^^^^^^^^^^^^^^

      File "/home/stguser/devstack/python-tempestconf/.venv/lib/python3.12/site-packages/urllib3/util/util.py", line 39, in reraise
    raise value

      File "/home/stguser/devstack/python-tempestconf/.venv/lib/python3.12/site-packages/urllib3/connectionpool.py", line 787, in urlopen
    response = self._make_request(
               ^^^^^^^^^^^^^^^^^^^

      File "/home/stguser/devstack/python-tempestconf/.venv/lib/python3.12/site-packages/urllib3/connectionpool.py", line 536, in _make_request
    self._raise_timeout(err=e, url=url, timeout_value=read_timeout)

      File "/home/stguser/devstack/python-tempestconf/.venv/lib/python3.12/site-packages/urllib3/connectionpool.py", line 367, in _raise_timeout
    raise ReadTimeoutError(

    urllib3.exceptions.ReadTimeoutError: HTTPConnectionPool(host='9.180.170.14', port=9696): Read timed out. (read timeout=60)


setUpClass (tempest.api.volume.admin.test_volume_retype.VolumeRetypeWithoutMigrationTest)
-----------------------------------------------------------------------------------------

Captured traceback:
~~~~~~~~~~~~~~~~~~~
    Traceback (most recent call last):

      File "/home/stguser/devstack/python-tempestconf/.venv/lib/python3.12/site-packages/tempest/test.py", line 185, in setUpClass
    raise value.with_traceback(trace)

      File "/home/stguser/devstack/python-tempestconf/.venv/lib/python3.12/site-packages/tempest/test.py", line 178, in setUpClass
    cls.resource_setup()

      File "/home/stguser/devstack/python-tempestconf/.venv/lib/python3.12/site-packages/tempest/api/volume/admin/test_volume_retype.py", line 172, in resource_setup
    cls.src_vol_type = cls.create_volume_type('volume-type-1')
                       ^^^^^^^^^^^^^^^^^^^^^^^^^^^^^^^^^^^^^^^

      File "/home/stguser/devstack/python-tempestconf/.venv/lib/python3.12/site-packages/tempest/api/volume/base.py", line 366, in create_volume_type
    volume_type = self.admin_volume_types_client.create_volume_type(
                  ^^^^^^^^^^^^^^^^^^^^^^^^^^^^^^^^^^^^^^^^^^^^^^^^^^

      File "/home/stguser/devstack/python-tempestconf/.venv/lib/python3.12/site-packages/tempest/lib/services/volume/v3/types_client.py", line 90, in create_volume_type
    resp, body = self.post('types', post_body)
                 ^^^^^^^^^^^^^^^^^^^^^^^^^^^^^

      File "/home/stguser/devstack/python-tempestconf/.venv/lib/python3.12/site-packages/tempest/lib/common/rest_client.py", line 314, in post
    resp_header, resp_body = self.request(
                             ^^^^^^^^^^^^^

      File "/home/stguser/devstack/python-tempestconf/.venv/lib/python3.12/site-packages/tempest/lib/common/rest_client.py", line 762, in request
    self._error_checker(resp, resp_body)

      File "/home/stguser/devstack/python-tempestconf/.venv/lib/python3.12/site-packages/tempest/lib/common/rest_client.py", line 892, in _error_checker
    raise exceptions.Conflict(resp_body, resp=resp)

    tempest.lib.exceptions.Conflict: Conflict with state of target resource
Details: {'code': 409, 'message': 'Volume Type volume-type-1 already exists.'}


setUpClass (tempest.api.volume.test_volumes_snapshots.VolumesSnapshotTestJSON)
------------------------------------------------------------------------------

Captured traceback:
~~~~~~~~~~~~~~~~~~~
    Traceback (most recent call last):

      File "/home/stguser/devstack/python-tempestconf/.venv/lib/python3.12/site-packages/urllib3/connectionpool.py", line 534, in _make_request
    response = conn.getresponse()
               ^^^^^^^^^^^^^^^^^^

      File "/home/stguser/devstack/python-tempestconf/.venv/lib/python3.12/site-packages/urllib3/connection.py", line 565, in getresponse
    httplib_response = super().getresponse()
                       ^^^^^^^^^^^^^^^^^^^^^

      File "/usr/lib/python3.12/http/client.py", line 1428, in getresponse
    response.begin()

      File "/usr/lib/python3.12/http/client.py", line 331, in begin
    version, status, reason = self._read_status()
                              ^^^^^^^^^^^^^^^^^^^

      File "/usr/lib/python3.12/http/client.py", line 292, in _read_status
    line = str(self.fp.readline(_MAXLINE + 1), "iso-8859-1")
               ^^^^^^^^^^^^^^^^^^^^^^^^^^^^^^

      File "/usr/lib/python3.12/socket.py", line 707, in readinto
    return self._sock.recv_into(b)
           ^^^^^^^^^^^^^^^^^^^^^^^

    TimeoutError: timed out

    
The above exception was the direct cause of the following exception:


    Traceback (most recent call last):

      File "/home/stguser/devstack/python-tempestconf/.venv/lib/python3.12/site-packages/tempest/test.py", line 185, in setUpClass
    raise value.with_traceback(trace)

      File "/home/stguser/devstack/python-tempestconf/.venv/lib/python3.12/site-packages/tempest/test.py", line 170, in setUpClass
    cls.setup_credentials()

      File "/home/stguser/devstack/python-tempestconf/.venv/lib/python3.12/site-packages/tempest/api/volume/base.py", line 62, in setup_credentials
    super(BaseVolumeTest, cls).setup_credentials()

      File "/home/stguser/devstack/python-tempestconf/.venv/lib/python3.12/site-packages/tempest/test.py", line 398, in setup_credentials
    manager = cls.get_client_manager(
              ^^^^^^^^^^^^^^^^^^^^^^^

      File "/home/stguser/devstack/python-tempestconf/.venv/lib/python3.12/site-packages/tempest/test.py", line 743, in get_client_manager
    creds = getattr(cred_provider, credentials_method)()
            ^^^^^^^^^^^^^^^^^^^^^^^^^^^^^^^^^^^^^^^^^^^^

      File "/home/stguser/devstack/python-tempestconf/.venv/lib/python3.12/site-packages/tempest/lib/common/dynamic_creds.py", line 473, in get_primary_creds
    return self.get_project_member_creds()
           ^^^^^^^^^^^^^^^^^^^^^^^^^^^^^^^

      File "/home/stguser/devstack/python-tempestconf/.venv/lib/python3.12/site-packages/tempest/lib/common/dynamic_creds.py", line 514, in get_project_member_creds
    return self.get_credentials(['member'], scope='project')
           ^^^^^^^^^^^^^^^^^^^^^^^^^^^^^^^^^^^^^^^^^^^^^^^^^

      File "/home/stguser/devstack/python-tempestconf/.venv/lib/python3.12/site-packages/tempest/lib/common/dynamic_creds.py", line 459, in get_credentials
    network, subnet, router = self._create_network_resources(
                              ^^^^^^^^^^^^^^^^^^^^^^^^^^^^^^^

      File "/home/stguser/devstack/python-tempestconf/.venv/lib/python3.12/site-packages/tempest/lib/common/dynamic_creds.py", line 314, in _create_network_resources
    subnet = self._create_subnet(subnet_name, tenant_id,
             ^^^^^^^^^^^^^^^^^^^^^^^^^^^^^^^^^^^^^^^^^^^

      File "/home/stguser/devstack/python-tempestconf/.venv/lib/python3.12/site-packages/tempest/lib/common/dynamic_creds.py", line 349, in _create_subnet
    create_subnet(

      File "/home/stguser/devstack/python-tempestconf/.venv/lib/python3.12/site-packages/tempest/lib/services/network/subnets_client.py", line 27, in create_subnet
    return self.create_resource(uri, post_data)
           ^^^^^^^^^^^^^^^^^^^^^^^^^^^^^^^^^^^^

      File "/home/stguser/devstack/python-tempestconf/.venv/lib/python3.12/site-packages/tempest/lib/services/network/base.py", line 62, in create_resource
    resp, body = self.post(req_uri, req_post_data)
                 ^^^^^^^^^^^^^^^^^^^^^^^^^^^^^^^^^

      File "/home/stguser/devstack/python-tempestconf/.venv/lib/python3.12/site-packages/tempest/lib/common/rest_client.py", line 314, in post
    resp_header, resp_body = self.request(
                             ^^^^^^^^^^^^^

      File "/home/stguser/devstack/python-tempestconf/.venv/lib/python3.12/site-packages/tempest/lib/common/rest_client.py", line 746, in request
    resp, resp_body = self._request(method, url, headers=headers,
                      ^^^^^^^^^^^^^^^^^^^^^^^^^^^^^^^^^^^^^^^^^^^

      File "/home/stguser/devstack/python-tempestconf/.venv/lib/python3.12/site-packages/tempest/lib/common/rest_client.py", line 612, in _request
    resp, resp_body = self.raw_request(
                      ^^^^^^^^^^^^^^^^^

      File "/home/stguser/devstack/python-tempestconf/.venv/lib/python3.12/site-packages/tempest/lib/common/rest_client.py", line 661, in raw_request
    resp, resp_body = self.http_obj.request(
                      ^^^^^^^^^^^^^^^^^^^^^^

      File "/home/stguser/devstack/python-tempestconf/.venv/lib/python3.12/site-packages/tempest/lib/common/http.py", line 123, in request
    r = super(ClosingHttp, self).request(method, url, retries=retry,
        ^^^^^^^^^^^^^^^^^^^^^^^^^^^^^^^^^^^^^^^^^^^^^^^^^^^^^^^^^^^^

      File "/home/stguser/devstack/python-tempestconf/.venv/lib/python3.12/site-packages/urllib3/_request_methods.py", line 143, in request
    return self.request_encode_body(
           ^^^^^^^^^^^^^^^^^^^^^^^^^

      File "/home/stguser/devstack/python-tempestconf/.venv/lib/python3.12/site-packages/urllib3/_request_methods.py", line 278, in request_encode_body
    return self.urlopen(method, url, **extra_kw)
           ^^^^^^^^^^^^^^^^^^^^^^^^^^^^^^^^^^^^^

      File "/home/stguser/devstack/python-tempestconf/.venv/lib/python3.12/site-packages/urllib3/poolmanager.py", line 459, in urlopen
    response = conn.urlopen(method, u.request_uri, **kw)
               ^^^^^^^^^^^^^^^^^^^^^^^^^^^^^^^^^^^^^^^^^

      File "/home/stguser/devstack/python-tempestconf/.venv/lib/python3.12/site-packages/urllib3/connectionpool.py", line 841, in urlopen
    retries = retries.increment(
              ^^^^^^^^^^^^^^^^^^

      File "/home/stguser/devstack/python-tempestconf/.venv/lib/python3.12/site-packages/urllib3/util/retry.py", line 474, in increment
    raise reraise(type(error), error, _stacktrace)
          ^^^^^^^^^^^^^^^^^^^^^^^^^^^^^^^^^^^^^^^^

      File "/home/stguser/devstack/python-tempestconf/.venv/lib/python3.12/site-packages/urllib3/util/util.py", line 39, in reraise
    raise value

      File "/home/stguser/devstack/python-tempestconf/.venv/lib/python3.12/site-packages/urllib3/connectionpool.py", line 787, in urlopen
    response = self._make_request(
               ^^^^^^^^^^^^^^^^^^^

      File "/home/stguser/devstack/python-tempestconf/.venv/lib/python3.12/site-packages/urllib3/connectionpool.py", line 536, in _make_request
    self._raise_timeout(err=e, url=url, timeout_value=read_timeout)

      File "/home/stguser/devstack/python-tempestconf/.venv/lib/python3.12/site-packages/urllib3/connectionpool.py", line 367, in _raise_timeout
    raise ReadTimeoutError(

    urllib3.exceptions.ReadTimeoutError: HTTPConnectionPool(host='9.180.170.14', port=9696): Read timed out. (read timeout=60)


tearDownClass (tempest.api.volume.test_volumes_get.VolumesGetTest)
------------------------------------------------------------------

Captured traceback:
~~~~~~~~~~~~~~~~~~~
    Traceback (most recent call last):

      File "/home/stguser/devstack/python-tempestconf/.venv/lib/python3.12/site-packages/tempest/test.py", line 246, in tearDownClass
    raise value.with_traceback(trace)

      File "/home/stguser/devstack/python-tempestconf/.venv/lib/python3.12/site-packages/tempest/test.py", line 210, in tearDownClass
    teardown()

      File "/home/stguser/devstack/python-tempestconf/.venv/lib/python3.12/site-packages/tempest/test.py", line 757, in clear_credentials
    cls._creds_provider.clear_creds()

      File "/home/stguser/devstack/python-tempestconf/.venv/lib/python3.12/site-packages/tempest/lib/common/dynamic_creds.py", line 635, in clear_creds
    self.cleanup_default_secgroup(

      File "/home/stguser/devstack/python-tempestconf/.venv/lib/python3.12/site-packages/tempest/lib/common/cred_provider.py", line 145, in cleanup_default_secgroup
    security_group_client.delete_security_group(secgroup['id'])

      File "/home/stguser/devstack/python-tempestconf/.venv/lib/python3.12/site-packages/tempest/lib/services/network/security_groups_client.py", line 59, in delete_security_group
    return self.delete_resource(uri)
           ^^^^^^^^^^^^^^^^^^^^^^^^^

      File "/home/stguser/devstack/python-tempestconf/.venv/lib/python3.12/site-packages/tempest/lib/services/network/base.py", line 42, in delete_resource
    resp, body = self.delete(req_uri)
                 ^^^^^^^^^^^^^^^^^^^^

      File "/home/stguser/devstack/python-tempestconf/.venv/lib/python3.12/site-packages/tempest/lib/common/rest_client.py", line 359, in delete
    return self.request('DELETE', url, extra_headers, headers, body)
           ^^^^^^^^^^^^^^^^^^^^^^^^^^^^^^^^^^^^^^^^^^^^^^^^^^^^^^^^^

      File "/home/stguser/devstack/python-tempestconf/.venv/lib/python3.12/site-packages/tempest/lib/common/rest_client.py", line 762, in request
    self._error_checker(resp, resp_body)

      File "/home/stguser/devstack/python-tempestconf/.venv/lib/python3.12/site-packages/tempest/lib/common/rest_client.py", line 892, in _error_checker
    raise exceptions.Conflict(resp_body, resp=resp)

    tempest.lib.exceptions.Conflict: Conflict with state of target resource
Details: {'type': 'SecurityGroupInUse', 'message': 'Security Group None cannot perform precommit_delete due to Callback neutron.plugins.ml2.drivers.ovn.mech_driver.mech_driver.OVNMechanismDriver._delete_security_group_precommit-3946265 failed with "Port_Group pg_04579a8f_30ef_4040_ba9b_d19116dcd9b2 does not exist".', 'detail': ''}


tearDownClass (tempest.api.volume.test_volume_transfers.VolumesTransfersV355Test)
---------------------------------------------------------------------------------

Captured traceback:
~~~~~~~~~~~~~~~~~~~
    Traceback (most recent call last):

      File "/home/stguser/devstack/python-tempestconf/.venv/lib/python3.12/site-packages/tempest/test.py", line 246, in tearDownClass
    raise value.with_traceback(trace)

      File "/home/stguser/devstack/python-tempestconf/.venv/lib/python3.12/site-packages/tempest/test.py", line 210, in tearDownClass
    teardown()

      File "/home/stguser/devstack/python-tempestconf/.venv/lib/python3.12/site-packages/tempest/test.py", line 757, in clear_credentials
    cls._creds_provider.clear_creds()

      File "/home/stguser/devstack/python-tempestconf/.venv/lib/python3.12/site-packages/tempest/lib/common/dynamic_creds.py", line 635, in clear_creds
    self.cleanup_default_secgroup(

      File "/home/stguser/devstack/python-tempestconf/.venv/lib/python3.12/site-packages/tempest/lib/common/cred_provider.py", line 145, in cleanup_default_secgroup
    security_group_client.delete_security_group(secgroup['id'])

      File "/home/stguser/devstack/python-tempestconf/.venv/lib/python3.12/site-packages/tempest/lib/services/network/security_groups_client.py", line 59, in delete_security_group
    return self.delete_resource(uri)
           ^^^^^^^^^^^^^^^^^^^^^^^^^

      File "/home/stguser/devstack/python-tempestconf/.venv/lib/python3.12/site-packages/tempest/lib/services/network/base.py", line 42, in delete_resource
    resp, body = self.delete(req_uri)
                 ^^^^^^^^^^^^^^^^^^^^

      File "/home/stguser/devstack/python-tempestconf/.venv/lib/python3.12/site-packages/tempest/lib/common/rest_client.py", line 359, in delete
    return self.request('DELETE', url, extra_headers, headers, body)
           ^^^^^^^^^^^^^^^^^^^^^^^^^^^^^^^^^^^^^^^^^^^^^^^^^^^^^^^^^

      File "/home/stguser/devstack/python-tempestconf/.venv/lib/python3.12/site-packages/tempest/lib/common/rest_client.py", line 762, in request
    self._error_checker(resp, resp_body)

      File "/home/stguser/devstack/python-tempestconf/.venv/lib/python3.12/site-packages/tempest/lib/common/rest_client.py", line 892, in _error_checker
    raise exceptions.Conflict(resp_body, resp=resp)

    tempest.lib.exceptions.Conflict: Conflict with state of target resource
Details: {'type': 'SecurityGroupInUse', 'message': 'Security Group None cannot perform precommit_delete due to Callback neutron.plugins.ml2.drivers.ovn.mech_driver.mech_driver.OVNMechanismDriver._delete_security_group_precommit-3946265 failed with "Port_Group pg_80db68d2_48b9_4348_ae4c_be543fd0e635 does not exist".', 'detail': ''}


tearDownClass (tempest.api.volume.admin.test_snapshots_actions.SnapshotsActionsTest)
------------------------------------------------------------------------------------

Captured traceback:
~~~~~~~~~~~~~~~~~~~
    Traceback (most recent call last):

      File "/home/stguser/devstack/python-tempestconf/.venv/lib/python3.12/site-packages/tempest/test.py", line 246, in tearDownClass
    raise value.with_traceback(trace)

      File "/home/stguser/devstack/python-tempestconf/.venv/lib/python3.12/site-packages/tempest/test.py", line 210, in tearDownClass
    teardown()

      File "/home/stguser/devstack/python-tempestconf/.venv/lib/python3.12/site-packages/tempest/test.py", line 757, in clear_credentials
    cls._creds_provider.clear_creds()

      File "/home/stguser/devstack/python-tempestconf/.venv/lib/python3.12/site-packages/tempest/lib/common/dynamic_creds.py", line 635, in clear_creds
    self.cleanup_default_secgroup(

      File "/home/stguser/devstack/python-tempestconf/.venv/lib/python3.12/site-packages/tempest/lib/common/cred_provider.py", line 145, in cleanup_default_secgroup
    security_group_client.delete_security_group(secgroup['id'])

      File "/home/stguser/devstack/python-tempestconf/.venv/lib/python3.12/site-packages/tempest/lib/services/network/security_groups_client.py", line 59, in delete_security_group
    return self.delete_resource(uri)
           ^^^^^^^^^^^^^^^^^^^^^^^^^

      File "/home/stguser/devstack/python-tempestconf/.venv/lib/python3.12/site-packages/tempest/lib/services/network/base.py", line 42, in delete_resource
    resp, body = self.delete(req_uri)
                 ^^^^^^^^^^^^^^^^^^^^

      File "/home/stguser/devstack/python-tempestconf/.venv/lib/python3.12/site-packages/tempest/lib/common/rest_client.py", line 359, in delete
    return self.request('DELETE', url, extra_headers, headers, body)
           ^^^^^^^^^^^^^^^^^^^^^^^^^^^^^^^^^^^^^^^^^^^^^^^^^^^^^^^^^

      File "/home/stguser/devstack/python-tempestconf/.venv/lib/python3.12/site-packages/tempest/lib/common/rest_client.py", line 762, in request
    self._error_checker(resp, resp_body)

      File "/home/stguser/devstack/python-tempestconf/.venv/lib/python3.12/site-packages/tempest/lib/common/rest_client.py", line 892, in _error_checker
    raise exceptions.Conflict(resp_body, resp=resp)

    tempest.lib.exceptions.Conflict: Conflict with state of target resource
Details: {'type': 'SecurityGroupInUse', 'message': 'Security Group None cannot perform precommit_delete due to Callback neutron.plugins.ml2.drivers.ovn.mech_driver.mech_driver.OVNMechanismDriver._delete_security_group_precommit-3946265 failed with "Port_Group pg_b97ea8ce_15c7_4a6b_a305_f66bfebd6813 does not exist".', 'detail': ''}



======
Totals
======
Ran: 169 tests in 313.8554 sec.
 - Passed: 156
 - Skipped: 6
 - Expected Fail: 0
 - Unexpected Success: 0
 - Failed: 7
Sum of execute time for each test: 2987.5036 sec.

==============
Worker Balance
==============
 - Worker 0 (4 tests) => 0:05:11.084690
 - Worker 1 (8 tests) => 0:02:58.730218
 - Worker 2 (2 tests) => 0:03:35.855571
 - Worker 3 (2 tests) => 0:03:34.830149
 - Worker 4 (5 tests) => 0:03:20.435832
 - Worker 5 (3 tests) => 0:03:08.099116
 - Worker 6 (3 tests) => 0:04:30.500369
 - Worker 7 (2 tests) => 0:02:05.396721
 - Worker 8 (5 tests) => 0:02:01.659777
 - Worker 9 (7 tests) => 0:01:37.493984
 - Worker 10 (2 tests) => 0:02:07.021895
 - Worker 11 (2 tests) => 0:02:48.261484
 - Worker 12 (2 tests) => 0:01:44.286828
 - Worker 13 (27 tests) => 0:02:28.281544
 - Worker 14 (1 tests) => 0:02:07.091245
 - Worker 15 (3 tests) => 0:01:32.349851
 - Worker 16 (6 tests) => 0:01:36.288636
 - Worker 17 (1 tests) => 0:00:00
 - Worker 18 (7 tests) => 0:02:41.113788
 - Worker 19 (12 tests) => 0:00:58.381045
 - Worker 20 (1 tests) => 0:00:00
 - Worker 21 (1 tests) => 0:00:00
 - Worker 22 (2 tests) => 0:00:44.814208
 - Worker 23 (5 tests) => 0:00:40.502360
 - Worker 24 (2 tests) => 0:01:00.617310
 - Worker 25 (1 tests) => 0:00:00
 - Worker 26 (2 tests) => 0:00:36.977204
 - Worker 27 (2 tests) => 0:00:10.947506
 - Worker 28 (2 tests) => 0:00:18.232835
 - Worker 29 (1 tests) => 0:00:20.982592
 - Worker 30 (2 tests) => 0:00:11.071869
 - Worker 31 (1 tests) => 0:00:20.299189
 - Worker 32 (2 tests) => 0:00:07.312261
 - Worker 33 (18 tests) => 0:00:03.879031
 - Worker 34 (1 tests) => 0:00:07.860561
 - Worker 35 (5 tests) => 0:00:12.240739
 - Worker 36 (1 tests) => 0:00:05.073980
 - Worker 37 (2 tests) => 0:00:08.953768
 - Worker 38 (1 tests) => 0:00:05.930874
 - Worker 39 (13 tests) => 0:00:01.048224
