{2} setUpClass (tempest.api.volume.admin.test_encrypted_volumes_extend.EncryptedVolumesExtendAttachedTest) ... SKIPPED: Attached encrypted volume extend is disabled.
{0} setUpClass (tempest.api.volume.test_volumes_backup.VolumesBackupsTest) ... SKIPPED: Cinder backup feature disabled
{1} setUpClass (tempest.api.volume.admin.test_volumes_backup.VolumesBackupsAdminTest) ... SKIPPED: Cinder backup feature disabled
{3} setUpClass (tempest.api.volume.admin.test_multi_backend.VolumeMultiBackendTest) ... SKIPPED: Cinder multi-backend feature disabled
{27} tempest.api.volume.test_volumes_snapshots_negative.VolumesSnapshotNegativeTestJSON.test_create_snapshot_with_nonexistent_volume_id [2.438670s] ... ok
{33} tempest.api.volume.test_volumes_get.VolumesSummaryTest.test_show_volume_summary [1.937887s] ... ok
{36} tempest.api.volume.test_versions.VersionsTest.test_list_versions [1.792200s] ... ok
{27} tempest.api.volume.test_volumes_snapshots_negative.VolumesSnapshotNegativeTestJSON.test_create_snapshot_without_passing_volume_id [0.596256s] ... ok
{32} tempest.api.volume.test_availability_zone.AvailabilityZoneTestJSON.test_get_availability_zone_list [5.042668s] ... ok
{27} tempest.api.volume.test_volumes_snapshots_negative.VolumesSnapshotNegativeTestJSON.test_list_snapshot_invalid_param_limit [3.716932s] ... ok
{35} tempest.api.volume.test_extensions.ExtensionsTestJSON.test_list_extensions [5.878205s] ... ok
{36} tempest.api.volume.test_versions.VersionsTest.test_show_version [7.652662s] ... ok
{27} tempest.api.volume.test_volumes_snapshots_negative.VolumesSnapshotNegativeTestJSON.test_list_snapshots_invalid_param_marker [4.806996s] ... ok
{23} tempest.api.volume.admin.test_volume_hosts.VolumeHostsAdminTestsJSON.test_list_hosts [8.116559s] ... ok
{27} tempest.api.volume.test_volumes_snapshots_negative.VolumesSnapshotNegativeTestJSON.test_list_snapshots_invalid_param_sort [5.864518s] ... ok
{19} tempest.api.volume.admin.test_volume_quota_classes.VolumeQuotaClassesTest.test_show_default_quota [5.868156s] ... ok
{12} tempest.api.volume.admin.test_volume_services.VolumesServicesTestJSON.test_get_service_by_host_name [4.584632s] ... ok
{26} tempest.api.volume.admin.test_backends_capabilities.BackendsCapabilitiesAdminTestsJSON.test_compare_volume_stats_values [9.164027s] ... ok
{25} tempest.api.volume.admin.test_volume_services_negative.VolumeServicesNegativeTest.test_disable_log_reason_with_no_reason [3.375019s] ... ok
{29} tempest.api.volume.admin.test_volume_pools.VolumePoolsAdminTestsJSON.test_get_pools_with_details [4.665937s] ... ok
{21} tempest.api.volume.admin.test_volume_types_negative.VolumeTypesNegativeTest.test_create_volume_type_encryption_nonexistent_type_id [9.573106s] ... ok
{12} tempest.api.volume.admin.test_volume_services.VolumesServicesTestJSON.test_get_service_by_service_and_host_name [5.000242s] ... ok
{26} tempest.api.volume.admin.test_backends_capabilities.BackendsCapabilitiesAdminTestsJSON.test_get_capabilities_backend [5.122965s] ... ok
{25} tempest.api.volume.admin.test_volume_services_negative.VolumeServicesNegativeTest.test_disable_service_with_invalid_binary [4.901547s] ... ok
{29} tempest.api.volume.admin.test_volume_pools.VolumePoolsAdminTestsJSON.test_get_pools_without_details [5.476346s] ... ok
{12} tempest.api.volume.admin.test_volume_services.VolumesServicesTestJSON.test_get_service_by_service_binary_name [6.127164s] ... ok
{24} tempest.api.volume.admin.test_volume_types_extra_specs_negative.ExtraSpecsNegativeTest.test_create_invalid_body [7.693498s] ... ok
{25} tempest.api.volume.admin.test_volume_services_negative.VolumeServicesNegativeTest.test_enable_service_with_invalid_host [6.975782s] ... ok
{24} tempest.api.volume.admin.test_volume_types_extra_specs_negative.ExtraSpecsNegativeTest.test_create_none_body [12.780108s] ... ok
{25} tempest.api.volume.admin.test_volume_services_negative.VolumeServicesNegativeTest.test_freeze_host_with_invalid_host [13.370322s] ... ok
{23} tempest.api.volume.admin.test_volume_hosts.VolumeHostsAdminTestsJSON.test_show_host [34.780988s] ... ok
{24} tempest.api.volume.admin.test_volume_types_extra_specs_negative.ExtraSpecsNegativeTest.test_create_nonexistent_type_id [7.388289s] ... ok
{25} tempest.api.volume.admin.test_volume_services_negative.VolumeServicesNegativeTest.test_thaw_host_with_invalid_host [6.880346s] ... ok
{24} tempest.api.volume.admin.test_volume_types_extra_specs_negative.ExtraSpecsNegativeTest.test_delete_nonexistent_volume_type_id [3.066325s] ... ok
{17} tempest.api.volume.admin.test_volume_types.VolumeTypesTest.test_volume_type_create_get_delete [39.861838s] ... ok
{22} tempest.api.volume.admin.test_volume_types_extra_specs.VolumeTypesExtraSpecsTest.test_volume_type_extra_spec_create_get_delete [38.848148s] ... ok
{24} tempest.api.volume.admin.test_volume_types_extra_specs_negative.ExtraSpecsNegativeTest.test_get_nonexistent_extra_spec_name [0.312612s] ... ok
{24} tempest.api.volume.admin.test_volume_types_extra_specs_negative.ExtraSpecsNegativeTest.test_get_nonexistent_volume_type_id [0.197426s] ... ok
{24} tempest.api.volume.admin.test_volume_types_extra_specs_negative.ExtraSpecsNegativeTest.test_list_nonexistent_volume_type_id [0.021591s] ... ok
{24} tempest.api.volume.admin.test_volume_types_extra_specs_negative.ExtraSpecsNegativeTest.test_update_multiple_extra_spec [0.024860s] ... ok
{24} tempest.api.volume.admin.test_volume_types_extra_specs_negative.ExtraSpecsNegativeTest.test_update_no_body [0.014468s] ... ok
{24} tempest.api.volume.admin.test_volume_types_extra_specs_negative.ExtraSpecsNegativeTest.test_update_none_extra_spec_id [0.677748s] ... ok
{24} tempest.api.volume.admin.test_volume_types_extra_specs_negative.ExtraSpecsNegativeTest.test_update_nonexistent_extra_spec_id [1.402567s] ... ok
{24} tempest.api.volume.admin.test_volume_types_extra_specs_negative.ExtraSpecsNegativeTest.test_update_nonexistent_type_id [0.724724s] ... ok
{21} tempest.api.volume.admin.test_volume_types_negative.VolumeTypesNegativeTest.test_create_volume_with_private_volume_type [41.036946s] ... ok
{22} tempest.api.volume.admin.test_volume_types_extra_specs.VolumeTypesExtraSpecsTest.test_volume_type_extra_specs_list [8.795916s] ... ok
{21} tempest.api.volume.admin.test_volume_types_negative.VolumeTypesNegativeTest.test_create_with_empty_name [0.024546s] ... ok
{21} tempest.api.volume.admin.test_volume_types_negative.VolumeTypesNegativeTest.test_create_with_repeated_name [11.658834s] ... ok
{21} tempest.api.volume.admin.test_volume_types_negative.VolumeTypesNegativeTest.test_delete_nonexistent_type_id [0.014759s] ... ok
{21} tempest.api.volume.admin.test_volume_types_negative.VolumeTypesNegativeTest.test_get_nonexistent_type_id [0.015031s] ... ok
{22} tempest.api.volume.admin.test_volume_types_extra_specs.VolumeTypesExtraSpecsTest.test_volume_type_extra_specs_update [11.959388s] ... ok
{17} tempest.api.volume.admin.test_volume_types.VolumeTypesTest.test_volume_type_encryption_create_get_update_delete [29.729094s] ... ok
{17} tempest.api.volume.admin.test_volume_types.VolumeTypesTest.test_volume_type_list [1.896780s] ... ok
{31} tempest.api.volume.admin.test_volume_quotas_negative.VolumeQuotasNegativeTestJSON.test_quota_volume_gigabytes [12.224880s] ... ok
{15} tempest.api.volume.admin.test_user_messages.UserMessagesTest.test_delete_message [94.202954s] ... ok
{39} tempest.api.volume.test_volume_absolute_limits.AbsoluteLimitsTests.test_get_volume_absolute_limits [1.925974s] ... ok
{31} tempest.api.volume.admin.test_volume_quotas_negative.VolumeQuotasNegativeTestJSON.test_quota_volumes [18.571347s] ... ok
{19} tempest.api.volume.admin.test_volume_quota_classes.VolumeQuotaClassesTest.test_update_default_quota [95.723432s] ... ok
{37} tempest.api.volume.test_volume_metadata.VolumesMetadataTest.test_crud_volume_metadata [28.645905s] ... ok
{37} tempest.api.volume.test_volume_metadata.VolumesMetadataTest.test_update_show_volume_metadata_item [14.066391s] ... ok
{18} tempest.api.volume.admin.test_qos.QosSpecsTestJSON.test_associate_disassociate_qos [86.252936s] ... ok
{9} tempest.api.volume.admin.test_snapshots_actions.SnapshotsActionsTest.test_reset_snapshot_status [4.665100s] ... ok
{4} tempest.api.volume.admin.test_volume_quotas.VolumeQuotasAdminTestJSON.test_delete_quota [104.247853s] ... ok
{4} tempest.api.volume.admin.test_volume_quotas.VolumeQuotasAdminTestJSON.test_list_default_quotas [0.435606s] ... ok
{4} tempest.api.volume.admin.test_volume_quotas.VolumeQuotasAdminTestJSON.test_list_quotas [0.283040s] ... ok
{8} tempest.api.volume.test_volumes_clone_negative.VolumesCloneNegativeTest.test_create_from_volume_decreasing_size [143.896526s] ... ok
{15} tempest.api.volume.admin.test_user_messages.UserMessagesTest.test_list_show_messages [43.226745s] ... ok
{18} tempest.api.volume.admin.test_qos.QosSpecsTestJSON.test_create_delete_qos_with_back_end_consumer [11.616383s] ... ok
{12} tempest.api.volume.admin.test_volume_services.VolumesServicesTestJSON.test_get_service_by_volume_host_name [114.454194s] ... ok
{12} tempest.api.volume.admin.test_volume_services.VolumesServicesTestJSON.test_list_services [0.029741s] ... ok
{13} setUpClass (tempest.api.volume.test_volumes_actions.VolumesActionsTest) [0.000000s] ... FAILED

Captured traceback:
~~~~~~~~~~~~~~~~~~~
    Traceback (most recent call last):

      File "/home/stguser/devstack/python-tempestconf/.venv/lib/python3.12/site-packages/urllib3/connectionpool.py", line 534, in _make_request
    response = conn.getresponse()
               ^^^^^^^^^^^^^^^^^^

      File "/home/stguser/devstack/python-tempestconf/.venv/lib/python3.12/site-packages/urllib3/connection.py", line 565, in getresponse
    httplib_response = super().getresponse()
                       ^^^^^^^^^^^^^^^^^^^^^

      File "/usr/lib/python3.12/http/client.py", line 1428, in getresponse
    response.begin()

      File "/usr/lib/python3.12/http/client.py", line 331, in begin
    version, status, reason = self._read_status()
                              ^^^^^^^^^^^^^^^^^^^

      File "/usr/lib/python3.12/http/client.py", line 292, in _read_status
    line = str(self.fp.readline(_MAXLINE + 1), "iso-8859-1")
               ^^^^^^^^^^^^^^^^^^^^^^^^^^^^^^

      File "/usr/lib/python3.12/socket.py", line 707, in readinto
    return self._sock.recv_into(b)
           ^^^^^^^^^^^^^^^^^^^^^^^

    TimeoutError: timed out

    
The above exception was the direct cause of the following exception:


    Traceback (most recent call last):

      File "/home/stguser/devstack/python-tempestconf/.venv/lib/python3.12/site-packages/tempest/test.py", line 185, in setUpClass
    raise value.with_traceback(trace)

      File "/home/stguser/devstack/python-tempestconf/.venv/lib/python3.12/site-packages/tempest/test.py", line 170, in setUpClass
    cls.setup_credentials()

      File "/home/stguser/devstack/python-tempestconf/.venv/lib/python3.12/site-packages/tempest/api/volume/base.py", line 62, in setup_credentials
    super(BaseVolumeTest, cls).setup_credentials()

      File "/home/stguser/devstack/python-tempestconf/.venv/lib/python3.12/site-packages/tempest/test.py", line 398, in setup_credentials
    manager = cls.get_client_manager(
              ^^^^^^^^^^^^^^^^^^^^^^^

      File "/home/stguser/devstack/python-tempestconf/.venv/lib/python3.12/site-packages/tempest/test.py", line 743, in get_client_manager
    creds = getattr(cred_provider, credentials_method)()
            ^^^^^^^^^^^^^^^^^^^^^^^^^^^^^^^^^^^^^^^^^^^^

      File "/home/stguser/devstack/python-tempestconf/.venv/lib/python3.12/site-packages/tempest/lib/common/dynamic_creds.py", line 473, in get_primary_creds
    return self.get_project_member_creds()
           ^^^^^^^^^^^^^^^^^^^^^^^^^^^^^^^

      File "/home/stguser/devstack/python-tempestconf/.venv/lib/python3.12/site-packages/tempest/lib/common/dynamic_creds.py", line 514, in get_project_member_creds
    return self.get_credentials(['member'], scope='project')
           ^^^^^^^^^^^^^^^^^^^^^^^^^^^^^^^^^^^^^^^^^^^^^^^^^

      File "/home/stguser/devstack/python-tempestconf/.venv/lib/python3.12/site-packages/tempest/lib/common/dynamic_creds.py", line 459, in get_credentials
    network, subnet, router = self._create_network_resources(
                              ^^^^^^^^^^^^^^^^^^^^^^^^^^^^^^^

      File "/home/stguser/devstack/python-tempestconf/.venv/lib/python3.12/site-packages/tempest/lib/common/dynamic_creds.py", line 314, in _create_network_resources
    subnet = self._create_subnet(subnet_name, tenant_id,
             ^^^^^^^^^^^^^^^^^^^^^^^^^^^^^^^^^^^^^^^^^^^

      File "/home/stguser/devstack/python-tempestconf/.venv/lib/python3.12/site-packages/tempest/lib/common/dynamic_creds.py", line 349, in _create_subnet
    create_subnet(

      File "/home/stguser/devstack/python-tempestconf/.venv/lib/python3.12/site-packages/tempest/lib/services/network/subnets_client.py", line 27, in create_subnet
    return self.create_resource(uri, post_data)
           ^^^^^^^^^^^^^^^^^^^^^^^^^^^^^^^^^^^^

      File "/home/stguser/devstack/python-tempestconf/.venv/lib/python3.12/site-packages/tempest/lib/services/network/base.py", line 62, in create_resource
    resp, body = self.post(req_uri, req_post_data)
                 ^^^^^^^^^^^^^^^^^^^^^^^^^^^^^^^^^

      File "/home/stguser/devstack/python-tempestconf/.venv/lib/python3.12/site-packages/tempest/lib/common/rest_client.py", line 314, in post
    resp_header, resp_body = self.request(
                             ^^^^^^^^^^^^^

      File "/home/stguser/devstack/python-tempestconf/.venv/lib/python3.12/site-packages/tempest/lib/common/rest_client.py", line 746, in request
    resp, resp_body = self._request(method, url, headers=headers,
                      ^^^^^^^^^^^^^^^^^^^^^^^^^^^^^^^^^^^^^^^^^^^

      File "/home/stguser/devstack/python-tempestconf/.venv/lib/python3.12/site-packages/tempest/lib/common/rest_client.py", line 612, in _request
    resp, resp_body = self.raw_request(
                      ^^^^^^^^^^^^^^^^^

      File "/home/stguser/devstack/python-tempestconf/.venv/lib/python3.12/site-packages/tempest/lib/common/rest_client.py", line 661, in raw_request
    resp, resp_body = self.http_obj.request(
                      ^^^^^^^^^^^^^^^^^^^^^^

      File "/home/stguser/devstack/python-tempestconf/.venv/lib/python3.12/site-packages/tempest/lib/common/http.py", line 123, in request
    r = super(ClosingHttp, self).request(method, url, retries=retry,
        ^^^^^^^^^^^^^^^^^^^^^^^^^^^^^^^^^^^^^^^^^^^^^^^^^^^^^^^^^^^^

      File "/home/stguser/devstack/python-tempestconf/.venv/lib/python3.12/site-packages/urllib3/_request_methods.py", line 143, in request
    return self.request_encode_body(
           ^^^^^^^^^^^^^^^^^^^^^^^^^

      File "/home/stguser/devstack/python-tempestconf/.venv/lib/python3.12/site-packages/urllib3/_request_methods.py", line 278, in request_encode_body
    return self.urlopen(method, url, **extra_kw)
           ^^^^^^^^^^^^^^^^^^^^^^^^^^^^^^^^^^^^^

      File "/home/stguser/devstack/python-tempestconf/.venv/lib/python3.12/site-packages/urllib3/poolmanager.py", line 459, in urlopen
    response = conn.urlopen(method, u.request_uri, **kw)
               ^^^^^^^^^^^^^^^^^^^^^^^^^^^^^^^^^^^^^^^^^

      File "/home/stguser/devstack/python-tempestconf/.venv/lib/python3.12/site-packages/urllib3/connectionpool.py", line 841, in urlopen
    retries = retries.increment(
              ^^^^^^^^^^^^^^^^^^

      File "/home/stguser/devstack/python-tempestconf/.venv/lib/python3.12/site-packages/urllib3/util/retry.py", line 474, in increment
    raise reraise(type(error), error, _stacktrace)
          ^^^^^^^^^^^^^^^^^^^^^^^^^^^^^^^^^^^^^^^^

      File "/home/stguser/devstack/python-tempestconf/.venv/lib/python3.12/site-packages/urllib3/util/util.py", line 39, in reraise
    raise value

      File "/home/stguser/devstack/python-tempestconf/.venv/lib/python3.12/site-packages/urllib3/connectionpool.py", line 787, in urlopen
    response = self._make_request(
               ^^^^^^^^^^^^^^^^^^^

      File "/home/stguser/devstack/python-tempestconf/.venv/lib/python3.12/site-packages/urllib3/connectionpool.py", line 536, in _make_request
    self._raise_timeout(err=e, url=url, timeout_value=read_timeout)

      File "/home/stguser/devstack/python-tempestconf/.venv/lib/python3.12/site-packages/urllib3/connectionpool.py", line 367, in _raise_timeout
    raise ReadTimeoutError(

    urllib3.exceptions.ReadTimeoutError: HTTPConnectionPool(host='9.180.170.14', port=9696): Read timed out. (read timeout=60)

{28} tempest.api.volume.test_snapshot_metadata.SnapshotMetadataTestJSON.test_crud_snapshot_metadata [7.036210s] ... ok
{10} tempest.api.volume.admin.test_volume_type_access.VolumeTypesAccessTest.test_volume_type_access_add [124.850392s] ... ok
{14} setUpClass (tempest.api.volume.admin.test_volume_retype.VolumeRetypeWithoutMigrationTest) [0.000000s] ... FAILED

Captured traceback:
~~~~~~~~~~~~~~~~~~~
    Traceback (most recent call last):

      File "/home/stguser/devstack/python-tempestconf/.venv/lib/python3.12/site-packages/tempest/test.py", line 185, in setUpClass
    raise value.with_traceback(trace)

      File "/home/stguser/devstack/python-tempestconf/.venv/lib/python3.12/site-packages/tempest/test.py", line 178, in setUpClass
    cls.resource_setup()

      File "/home/stguser/devstack/python-tempestconf/.venv/lib/python3.12/site-packages/tempest/api/volume/admin/test_volume_retype.py", line 172, in resource_setup
    cls.src_vol_type = cls.create_volume_type('volume-type-1')
                       ^^^^^^^^^^^^^^^^^^^^^^^^^^^^^^^^^^^^^^^

      File "/home/stguser/devstack/python-tempestconf/.venv/lib/python3.12/site-packages/tempest/api/volume/base.py", line 366, in create_volume_type
    volume_type = self.admin_volume_types_client.create_volume_type(
                  ^^^^^^^^^^^^^^^^^^^^^^^^^^^^^^^^^^^^^^^^^^^^^^^^^^

      File "/home/stguser/devstack/python-tempestconf/.venv/lib/python3.12/site-packages/tempest/lib/services/volume/v3/types_client.py", line 90, in create_volume_type
    resp, body = self.post('types', post_body)
                 ^^^^^^^^^^^^^^^^^^^^^^^^^^^^^

      File "/home/stguser/devstack/python-tempestconf/.venv/lib/python3.12/site-packages/tempest/lib/common/rest_client.py", line 314, in post
    resp_header, resp_body = self.request(
                             ^^^^^^^^^^^^^

      File "/home/stguser/devstack/python-tempestconf/.venv/lib/python3.12/site-packages/tempest/lib/common/rest_client.py", line 762, in request
    self._error_checker(resp, resp_body)

      File "/home/stguser/devstack/python-tempestconf/.venv/lib/python3.12/site-packages/tempest/lib/common/rest_client.py", line 892, in _error_checker
    raise exceptions.Conflict(resp_body, resp=resp)

    tempest.lib.exceptions.Conflict: Conflict with state of target resource
Details: {'code': 409, 'message': 'Volume Type volume-type-1 already exists.'}

{34} tempest.api.volume.test_volumes_list.VolumesListTestJSON.test_volume_list [1.144193s] ... ok
{34} tempest.api.volume.test_volumes_list.VolumesListTestJSON.test_volume_list_by_name [0.071256s] ... ok
{34} tempest.api.volume.test_volumes_list.VolumesListTestJSON.test_volume_list_details_by_name [0.079822s] ... ok
{34} tempest.api.volume.test_volumes_list.VolumesListTestJSON.test_volume_list_details_pagination [0.498206s] ... ok
{18} tempest.api.volume.admin.test_qos.QosSpecsTestJSON.test_create_delete_qos_with_both_consumer [8.027843s] ... ok
{34} tempest.api.volume.test_volumes_list.VolumesListTestJSON.test_volume_list_details_with_multiple_params [0.703926s] ... ok
{34} tempest.api.volume.test_volumes_list.VolumesListTestJSON.test_volume_list_pagination [0.460124s] ... ok
{34} tempest.api.volume.test_volumes_list.VolumesListTestJSON.test_volume_list_param_display_name_and_status [0.072662s] ... ok
{34} tempest.api.volume.test_volumes_list.VolumesListTestJSON.test_volume_list_with_detail_param_display_name_and_status [0.088897s] ... ok
{34} tempest.api.volume.test_volumes_list.VolumesListTestJSON.test_volume_list_with_detail_param_marker [0.081583s] ... ok
{28} tempest.api.volume.test_snapshot_metadata.SnapshotMetadataTestJSON.test_update_show_snapshot_metadata_item [7.071859s] ... ok
{16} setUpClass (tempest.api.volume.test_volumes_snapshots.VolumesSnapshotTestJSON) [0.000000s] ... FAILED

Captured traceback:
~~~~~~~~~~~~~~~~~~~
    Traceback (most recent call last):

      File "/home/stguser/devstack/python-tempestconf/.venv/lib/python3.12/site-packages/urllib3/connectionpool.py", line 534, in _make_request
    response = conn.getresponse()
               ^^^^^^^^^^^^^^^^^^

      File "/home/stguser/devstack/python-tempestconf/.venv/lib/python3.12/site-packages/urllib3/connection.py", line 565, in getresponse
    httplib_response = super().getresponse()
                       ^^^^^^^^^^^^^^^^^^^^^

      File "/usr/lib/python3.12/http/client.py", line 1428, in getresponse
    response.begin()

      File "/usr/lib/python3.12/http/client.py", line 331, in begin
    version, status, reason = self._read_status()
                              ^^^^^^^^^^^^^^^^^^^

      File "/usr/lib/python3.12/http/client.py", line 292, in _read_status
    line = str(self.fp.readline(_MAXLINE + 1), "iso-8859-1")
               ^^^^^^^^^^^^^^^^^^^^^^^^^^^^^^

      File "/usr/lib/python3.12/socket.py", line 707, in readinto
    return self._sock.recv_into(b)
           ^^^^^^^^^^^^^^^^^^^^^^^

    TimeoutError: timed out

    
The above exception was the direct cause of the following exception:


    Traceback (most recent call last):

      File "/home/stguser/devstack/python-tempestconf/.venv/lib/python3.12/site-packages/tempest/test.py", line 185, in setUpClass
    raise value.with_traceback(trace)

      File "/home/stguser/devstack/python-tempestconf/.venv/lib/python3.12/site-packages/tempest/test.py", line 170, in setUpClass
    cls.setup_credentials()

      File "/home/stguser/devstack/python-tempestconf/.venv/lib/python3.12/site-packages/tempest/api/volume/base.py", line 62, in setup_credentials
    super(BaseVolumeTest, cls).setup_credentials()

      File "/home/stguser/devstack/python-tempestconf/.venv/lib/python3.12/site-packages/tempest/test.py", line 398, in setup_credentials
    manager = cls.get_client_manager(
              ^^^^^^^^^^^^^^^^^^^^^^^

      File "/home/stguser/devstack/python-tempestconf/.venv/lib/python3.12/site-packages/tempest/test.py", line 743, in get_client_manager
    creds = getattr(cred_provider, credentials_method)()
            ^^^^^^^^^^^^^^^^^^^^^^^^^^^^^^^^^^^^^^^^^^^^

      File "/home/stguser/devstack/python-tempestconf/.venv/lib/python3.12/site-packages/tempest/lib/common/dynamic_creds.py", line 473, in get_primary_creds
    return self.get_project_member_creds()
           ^^^^^^^^^^^^^^^^^^^^^^^^^^^^^^^

      File "/home/stguser/devstack/python-tempestconf/.venv/lib/python3.12/site-packages/tempest/lib/common/dynamic_creds.py", line 514, in get_project_member_creds
    return self.get_credentials(['member'], scope='project')
           ^^^^^^^^^^^^^^^^^^^^^^^^^^^^^^^^^^^^^^^^^^^^^^^^^

      File "/home/stguser/devstack/python-tempestconf/.venv/lib/python3.12/site-packages/tempest/lib/common/dynamic_creds.py", line 459, in get_credentials
    network, subnet, router = self._create_network_resources(
                              ^^^^^^^^^^^^^^^^^^^^^^^^^^^^^^^

      File "/home/stguser/devstack/python-tempestconf/.venv/lib/python3.12/site-packages/tempest/lib/common/dynamic_creds.py", line 318, in _create_network_resources
    router = self._create_router(router_name, tenant_id)
             ^^^^^^^^^^^^^^^^^^^^^^^^^^^^^^^^^^^^^^^^^^^

      File "/home/stguser/devstack/python-tempestconf/.venv/lib/python3.12/site-packages/tempest/lib/common/dynamic_creds.py", line 379, in _create_router
    resp_body = self.routers_admin_client.create_router(**kwargs)
                ^^^^^^^^^^^^^^^^^^^^^^^^^^^^^^^^^^^^^^^^^^^^^^^^^

      File "/home/stguser/devstack/python-tempestconf/.venv/lib/python3.12/site-packages/tempest/lib/services/network/routers_client.py", line 27, in create_router
    return self.create_resource(uri, post_body)
           ^^^^^^^^^^^^^^^^^^^^^^^^^^^^^^^^^^^^

      File "/home/stguser/devstack/python-tempestconf/.venv/lib/python3.12/site-packages/tempest/lib/services/network/base.py", line 62, in create_resource
    resp, body = self.post(req_uri, req_post_data)
                 ^^^^^^^^^^^^^^^^^^^^^^^^^^^^^^^^^

      File "/home/stguser/devstack/python-tempestconf/.venv/lib/python3.12/site-packages/tempest/lib/common/rest_client.py", line 314, in post
    resp_header, resp_body = self.request(
                             ^^^^^^^^^^^^^

      File "/home/stguser/devstack/python-tempestconf/.venv/lib/python3.12/site-packages/tempest/lib/common/rest_client.py", line 746, in request
    resp, resp_body = self._request(method, url, headers=headers,
                      ^^^^^^^^^^^^^^^^^^^^^^^^^^^^^^^^^^^^^^^^^^^

      File "/home/stguser/devstack/python-tempestconf/.venv/lib/python3.12/site-packages/tempest/lib/common/rest_client.py", line 612, in _request
    resp, resp_body = self.raw_request(
                      ^^^^^^^^^^^^^^^^^

      File "/home/stguser/devstack/python-tempestconf/.venv/lib/python3.12/site-packages/tempest/lib/common/rest_client.py", line 661, in raw_request
    resp, resp_body = self.http_obj.request(
                      ^^^^^^^^^^^^^^^^^^^^^^

      File "/home/stguser/devstack/python-tempestconf/.venv/lib/python3.12/site-packages/tempest/lib/common/http.py", line 123, in request
    r = super(ClosingHttp, self).request(method, url, retries=retry,
        ^^^^^^^^^^^^^^^^^^^^^^^^^^^^^^^^^^^^^^^^^^^^^^^^^^^^^^^^^^^^

      File "/home/stguser/devstack/python-tempestconf/.venv/lib/python3.12/site-packages/urllib3/_request_methods.py", line 143, in request
    return self.request_encode_body(
           ^^^^^^^^^^^^^^^^^^^^^^^^^

      File "/home/stguser/devstack/python-tempestconf/.venv/lib/python3.12/site-packages/urllib3/_request_methods.py", line 278, in request_encode_body
    return self.urlopen(method, url, **extra_kw)
           ^^^^^^^^^^^^^^^^^^^^^^^^^^^^^^^^^^^^^

      File "/home/stguser/devstack/python-tempestconf/.venv/lib/python3.12/site-packages/urllib3/poolmanager.py", line 459, in urlopen
    response = conn.urlopen(method, u.request_uri, **kw)
               ^^^^^^^^^^^^^^^^^^^^^^^^^^^^^^^^^^^^^^^^^

      File "/home/stguser/devstack/python-tempestconf/.venv/lib/python3.12/site-packages/urllib3/connectionpool.py", line 841, in urlopen
    retries = retries.increment(
              ^^^^^^^^^^^^^^^^^^

      File "/home/stguser/devstack/python-tempestconf/.venv/lib/python3.12/site-packages/urllib3/util/retry.py", line 474, in increment
    raise reraise(type(error), error, _stacktrace)
          ^^^^^^^^^^^^^^^^^^^^^^^^^^^^^^^^^^^^^^^^

      File "/home/stguser/devstack/python-tempestconf/.venv/lib/python3.12/site-packages/urllib3/util/util.py", line 39, in reraise
    raise value

      File "/home/stguser/devstack/python-tempestconf/.venv/lib/python3.12/site-packages/urllib3/connectionpool.py", line 787, in urlopen
    response = self._make_request(
               ^^^^^^^^^^^^^^^^^^^

      File "/home/stguser/devstack/python-tempestconf/.venv/lib/python3.12/site-packages/urllib3/connectionpool.py", line 536, in _make_request
    self._raise_timeout(err=e, url=url, timeout_value=read_timeout)

      File "/home/stguser/devstack/python-tempestconf/.venv/lib/python3.12/site-packages/urllib3/connectionpool.py", line 367, in _raise_timeout
    raise ReadTimeoutError(

    urllib3.exceptions.ReadTimeoutError: HTTPConnectionPool(host='9.180.170.14', port=9696): Read timed out. (read timeout=60)

{34} tempest.api.volume.test_volumes_list.VolumesListTestJSON.test_volume_list_with_detail_param_metadata [0.111956s] ... ok
{34} tempest.api.volume.test_volumes_list.VolumesListTestJSON.test_volume_list_with_details [0.046316s] ... ok
{34} tempest.api.volume.test_volumes_list.VolumesListTestJSON.test_volume_list_with_param_metadata [0.087163s] ... ok
{34} tempest.api.volume.test_volumes_list.VolumesListTestJSON.test_volumes_list_by_availability_zone [0.148451s] ... ok
{34} tempest.api.volume.test_volumes_list.VolumesListTestJSON.test_volumes_list_by_bootable [0.145799s] ... ok
{34} tempest.api.volume.test_volumes_list.VolumesListTestJSON.test_volumes_list_by_status [0.184037s] ... ok
{34} tempest.api.volume.test_volumes_list.VolumesListTestJSON.test_volumes_list_details_by_availability_zone [0.183537s] ... ok
{34} tempest.api.volume.test_volumes_list.VolumesListTestJSON.test_volumes_list_details_by_bootable [0.104076s] ... ok
{34} tempest.api.volume.test_volumes_list.VolumesListTestJSON.test_volumes_list_details_by_status [0.092943s] ... ok
{17} tempest.api.volume.admin.test_volume_types.VolumeTypesTest.test_volume_type_update [67.494237s] ... ok
{10} tempest.api.volume.admin.test_volume_type_access.VolumeTypesAccessTest.test_volume_type_access_list [6.997288s] ... ok
{18} tempest.api.volume.admin.test_qos.QosSpecsTestJSON.test_create_delete_qos_with_front_end_consumer [6.849863s] ... ok
{18} tempest.api.volume.admin.test_qos.QosSpecsTestJSON.test_get_qos [0.114689s] ... ok
{3} tempest.api.volume.test_volume_transfers.VolumesTransfersV357Test.test_create_get_list_accept_volume_transfer [133.580360s] ... ok
{30} setUpClass (tempest.api.volume.admin.test_volume_snapshot_quotas_negative.VolumeSnapshotQuotasNegativeTestJSON) [0.000000s] ... FAILED

Captured traceback:
~~~~~~~~~~~~~~~~~~~
    Traceback (most recent call last):

      File "/home/stguser/devstack/python-tempestconf/.venv/lib/python3.12/site-packages/urllib3/connectionpool.py", line 534, in _make_request
    response = conn.getresponse()
               ^^^^^^^^^^^^^^^^^^

      File "/home/stguser/devstack/python-tempestconf/.venv/lib/python3.12/site-packages/urllib3/connection.py", line 565, in getresponse
    httplib_response = super().getresponse()
                       ^^^^^^^^^^^^^^^^^^^^^

      File "/usr/lib/python3.12/http/client.py", line 1428, in getresponse
    response.begin()

      File "/usr/lib/python3.12/http/client.py", line 331, in begin
    version, status, reason = self._read_status()
                              ^^^^^^^^^^^^^^^^^^^

      File "/usr/lib/python3.12/http/client.py", line 292, in _read_status
    line = str(self.fp.readline(_MAXLINE + 1), "iso-8859-1")
               ^^^^^^^^^^^^^^^^^^^^^^^^^^^^^^

      File "/usr/lib/python3.12/socket.py", line 707, in readinto
    return self._sock.recv_into(b)
           ^^^^^^^^^^^^^^^^^^^^^^^

    TimeoutError: timed out

    
The above exception was the direct cause of the following exception:


    Traceback (most recent call last):

      File "/home/stguser/devstack/python-tempestconf/.venv/lib/python3.12/site-packages/tempest/test.py", line 185, in setUpClass
    raise value.with_traceback(trace)

      File "/home/stguser/devstack/python-tempestconf/.venv/lib/python3.12/site-packages/tempest/test.py", line 178, in setUpClass
    cls.resource_setup()

      File "/home/stguser/devstack/python-tempestconf/.venv/lib/python3.12/site-packages/tempest/api/volume/admin/test_volume_snapshot_quotas_negative.py", line 65, in resource_setup
    cls.volume = cls.create_volume()
                 ^^^^^^^^^^^^^^^^^^^

      File "/home/stguser/devstack/python-tempestconf/.venv/lib/python3.12/site-packages/tempest/api/volume/base.py", line 139, in create_volume
    volume = self.volumes_client.create_volume(**kwargs)['volume']
             ^^^^^^^^^^^^^^^^^^^^^^^^^^^^^^^^^^^^^^^^^^^

      File "/home/stguser/devstack/python-tempestconf/.venv/lib/python3.12/site-packages/tempest/lib/services/volume/v3/volumes_client.py", line 116, in create_volume
    resp, body = self.post('volumes', post_body)
                 ^^^^^^^^^^^^^^^^^^^^^^^^^^^^^^^

      File "/home/stguser/devstack/python-tempestconf/.venv/lib/python3.12/site-packages/tempest/lib/common/rest_client.py", line 314, in post
    resp_header, resp_body = self.request(
                             ^^^^^^^^^^^^^

      File "/home/stguser/devstack/python-tempestconf/.venv/lib/python3.12/site-packages/tempest/lib/services/volume/base_client.py", line 39, in request
    resp, resp_body = super(BaseClient, self).request(
                      ^^^^^^^^^^^^^^^^^^^^^^^^^^^^^^^^

      File "/home/stguser/devstack/python-tempestconf/.venv/lib/python3.12/site-packages/tempest/lib/common/rest_client.py", line 746, in request
    resp, resp_body = self._request(method, url, headers=headers,
                      ^^^^^^^^^^^^^^^^^^^^^^^^^^^^^^^^^^^^^^^^^^^

      File "/home/stguser/devstack/python-tempestconf/.venv/lib/python3.12/site-packages/tempest/lib/common/rest_client.py", line 612, in _request
    resp, resp_body = self.raw_request(
                      ^^^^^^^^^^^^^^^^^

      File "/home/stguser/devstack/python-tempestconf/.venv/lib/python3.12/site-packages/tempest/lib/common/rest_client.py", line 661, in raw_request
    resp, resp_body = self.http_obj.request(
                      ^^^^^^^^^^^^^^^^^^^^^^

      File "/home/stguser/devstack/python-tempestconf/.venv/lib/python3.12/site-packages/tempest/lib/common/http.py", line 123, in request
    r = super(ClosingHttp, self).request(method, url, retries=retry,
        ^^^^^^^^^^^^^^^^^^^^^^^^^^^^^^^^^^^^^^^^^^^^^^^^^^^^^^^^^^^^

      File "/home/stguser/devstack/python-tempestconf/.venv/lib/python3.12/site-packages/urllib3/_request_methods.py", line 143, in request
    return self.request_encode_body(
           ^^^^^^^^^^^^^^^^^^^^^^^^^

      File "/home/stguser/devstack/python-tempestconf/.venv/lib/python3.12/site-packages/urllib3/_request_methods.py", line 278, in request_encode_body
    return self.urlopen(method, url, **extra_kw)
           ^^^^^^^^^^^^^^^^^^^^^^^^^^^^^^^^^^^^^

      File "/home/stguser/devstack/python-tempestconf/.venv/lib/python3.12/site-packages/urllib3/poolmanager.py", line 459, in urlopen
    response = conn.urlopen(method, u.request_uri, **kw)
               ^^^^^^^^^^^^^^^^^^^^^^^^^^^^^^^^^^^^^^^^^

      File "/home/stguser/devstack/python-tempestconf/.venv/lib/python3.12/site-packages/urllib3/connectionpool.py", line 841, in urlopen
    retries = retries.increment(
              ^^^^^^^^^^^^^^^^^^

      File "/home/stguser/devstack/python-tempestconf/.venv/lib/python3.12/site-packages/urllib3/util/retry.py", line 474, in increment
    raise reraise(type(error), error, _stacktrace)
          ^^^^^^^^^^^^^^^^^^^^^^^^^^^^^^^^^^^^^^^^

      File "/home/stguser/devstack/python-tempestconf/.venv/lib/python3.12/site-packages/urllib3/util/util.py", line 39, in reraise
    raise value

      File "/home/stguser/devstack/python-tempestconf/.venv/lib/python3.12/site-packages/urllib3/connectionpool.py", line 787, in urlopen
    response = self._make_request(
               ^^^^^^^^^^^^^^^^^^^

      File "/home/stguser/devstack/python-tempestconf/.venv/lib/python3.12/site-packages/urllib3/connectionpool.py", line 536, in _make_request
    self._raise_timeout(err=e, url=url, timeout_value=read_timeout)

      File "/home/stguser/devstack/python-tempestconf/.venv/lib/python3.12/site-packages/urllib3/connectionpool.py", line 367, in _raise_timeout
    raise ReadTimeoutError(

    urllib3.exceptions.ReadTimeoutError: HTTPConnectionPool(host='9.180.170.14', port=80): Read timed out. (read timeout=60)

{18} tempest.api.volume.admin.test_qos.QosSpecsTestJSON.test_list_qos [3.469029s] ... ok
{18} tempest.api.volume.admin.test_qos.QosSpecsTestJSON.test_set_unset_qos_key [1.196206s] ... ok
{6} tempest.api.volume.test_volume_transfers.VolumesTransfersTest.test_create_get_list_accept_volume_transfer [139.754545s] ... ok
{5} tempest.api.volume.test_volume_transfers.VolumesTransfersV355Test.test_create_get_list_accept_volume_transfer [135.810925s] ... ok
{38} tempest.api.volume.test_volumes_snapshots_list.VolumesSnapshotListTestJSON.test_snapshot_list_param_limit [0.114346s] ... ok
{38} tempest.api.volume.test_volumes_snapshots_list.VolumesSnapshotListTestJSON.test_snapshot_list_param_limit_equals_infinite [0.417862s] ... ok
{38} tempest.api.volume.test_volumes_snapshots_list.VolumesSnapshotListTestJSON.test_snapshot_list_param_limit_equals_zero [0.040355s] ... ok
{38} tempest.api.volume.test_volumes_snapshots_list.VolumesSnapshotListTestJSON.test_snapshot_list_param_marker [0.132329s] ... ok
{38} tempest.api.volume.test_volumes_snapshots_list.VolumesSnapshotListTestJSON.test_snapshot_list_param_offset [0.034163s] ... ok
{38} tempest.api.volume.test_volumes_snapshots_list.VolumesSnapshotListTestJSON.test_snapshot_list_param_sort_created_at_asc [0.027915s] ... ok
{38} tempest.api.volume.test_volumes_snapshots_list.VolumesSnapshotListTestJSON.test_snapshot_list_param_sort_created_at_desc [0.032746s] ... ok
{38} tempest.api.volume.test_volumes_snapshots_list.VolumesSnapshotListTestJSON.test_snapshot_list_param_sort_id_asc [0.042245s] ... ok
{38} tempest.api.volume.test_volumes_snapshots_list.VolumesSnapshotListTestJSON.test_snapshot_list_param_sort_id_desc [0.043852s] ... ok
{38} tempest.api.volume.test_volumes_snapshots_list.VolumesSnapshotListTestJSON.test_snapshot_list_param_sort_name_asc [0.041116s] ... ok
{38} tempest.api.volume.test_volumes_snapshots_list.VolumesSnapshotListTestJSON.test_snapshot_list_param_sort_name_desc [0.043175s] ... ok
{38} tempest.api.volume.test_volumes_snapshots_list.VolumesSnapshotListTestJSON.test_snapshots_list_details_with_params [0.143479s] ... ok
{9} tempest.api.volume.admin.test_snapshots_actions.SnapshotsActionsTest.test_snapshot_force_delete_when_snapshot_is_creating [32.299382s] ... ok
{38} tempest.api.volume.test_volumes_snapshots_list.VolumesSnapshotListTestJSON.test_snapshots_list_with_params [0.108737s] ... ok
{7} setUpClass (tempest.api.volume.admin.test_volumes_actions.VolumesActionsTest) [0.000000s] ... FAILED

Captured traceback:
~~~~~~~~~~~~~~~~~~~
    Traceback (most recent call last):

      File "/home/stguser/devstack/python-tempestconf/.venv/lib/python3.12/site-packages/urllib3/connectionpool.py", line 534, in _make_request
    response = conn.getresponse()
               ^^^^^^^^^^^^^^^^^^

      File "/home/stguser/devstack/python-tempestconf/.venv/lib/python3.12/site-packages/urllib3/connection.py", line 565, in getresponse
    httplib_response = super().getresponse()
                       ^^^^^^^^^^^^^^^^^^^^^

      File "/usr/lib/python3.12/http/client.py", line 1428, in getresponse
    response.begin()

      File "/usr/lib/python3.12/http/client.py", line 331, in begin
    version, status, reason = self._read_status()
                              ^^^^^^^^^^^^^^^^^^^

      File "/usr/lib/python3.12/http/client.py", line 292, in _read_status
    line = str(self.fp.readline(_MAXLINE + 1), "iso-8859-1")
               ^^^^^^^^^^^^^^^^^^^^^^^^^^^^^^

      File "/usr/lib/python3.12/socket.py", line 707, in readinto
    return self._sock.recv_into(b)
           ^^^^^^^^^^^^^^^^^^^^^^^

    TimeoutError: timed out

    
The above exception was the direct cause of the following exception:


    Traceback (most recent call last):

      File "/home/stguser/devstack/python-tempestconf/.venv/lib/python3.12/site-packages/tempest/test.py", line 185, in setUpClass
    raise value.with_traceback(trace)

      File "/home/stguser/devstack/python-tempestconf/.venv/lib/python3.12/site-packages/tempest/test.py", line 170, in setUpClass
    cls.setup_credentials()

      File "/home/stguser/devstack/python-tempestconf/.venv/lib/python3.12/site-packages/tempest/api/volume/base.py", line 62, in setup_credentials
    super(BaseVolumeTest, cls).setup_credentials()

      File "/home/stguser/devstack/python-tempestconf/.venv/lib/python3.12/site-packages/tempest/test.py", line 398, in setup_credentials
    manager = cls.get_client_manager(
              ^^^^^^^^^^^^^^^^^^^^^^^

      File "/home/stguser/devstack/python-tempestconf/.venv/lib/python3.12/site-packages/tempest/test.py", line 743, in get_client_manager
    creds = getattr(cred_provider, credentials_method)()
            ^^^^^^^^^^^^^^^^^^^^^^^^^^^^^^^^^^^^^^^^^^^^

      File "/home/stguser/devstack/python-tempestconf/.venv/lib/python3.12/site-packages/tempest/lib/common/dynamic_creds.py", line 473, in get_primary_creds
    return self.get_project_member_creds()
           ^^^^^^^^^^^^^^^^^^^^^^^^^^^^^^^

      File "/home/stguser/devstack/python-tempestconf/.venv/lib/python3.12/site-packages/tempest/lib/common/dynamic_creds.py", line 514, in get_project_member_creds
    return self.get_credentials(['member'], scope='project')
           ^^^^^^^^^^^^^^^^^^^^^^^^^^^^^^^^^^^^^^^^^^^^^^^^^

      File "/home/stguser/devstack/python-tempestconf/.venv/lib/python3.12/site-packages/tempest/lib/common/dynamic_creds.py", line 459, in get_credentials
    network, subnet, router = self._create_network_resources(
                              ^^^^^^^^^^^^^^^^^^^^^^^^^^^^^^^

      File "/home/stguser/devstack/python-tempestconf/.venv/lib/python3.12/site-packages/tempest/lib/common/dynamic_creds.py", line 318, in _create_network_resources
    router = self._create_router(router_name, tenant_id)
             ^^^^^^^^^^^^^^^^^^^^^^^^^^^^^^^^^^^^^^^^^^^

      File "/home/stguser/devstack/python-tempestconf/.venv/lib/python3.12/site-packages/tempest/lib/common/dynamic_creds.py", line 379, in _create_router
    resp_body = self.routers_admin_client.create_router(**kwargs)
                ^^^^^^^^^^^^^^^^^^^^^^^^^^^^^^^^^^^^^^^^^^^^^^^^^

      File "/home/stguser/devstack/python-tempestconf/.venv/lib/python3.12/site-packages/tempest/lib/services/network/routers_client.py", line 27, in create_router
    return self.create_resource(uri, post_body)
           ^^^^^^^^^^^^^^^^^^^^^^^^^^^^^^^^^^^^

      File "/home/stguser/devstack/python-tempestconf/.venv/lib/python3.12/site-packages/tempest/lib/services/network/base.py", line 62, in create_resource
    resp, body = self.post(req_uri, req_post_data)
                 ^^^^^^^^^^^^^^^^^^^^^^^^^^^^^^^^^

      File "/home/stguser/devstack/python-tempestconf/.venv/lib/python3.12/site-packages/tempest/lib/common/rest_client.py", line 314, in post
    resp_header, resp_body = self.request(
                             ^^^^^^^^^^^^^

      File "/home/stguser/devstack/python-tempestconf/.venv/lib/python3.12/site-packages/tempest/lib/common/rest_client.py", line 746, in request
    resp, resp_body = self._request(method, url, headers=headers,
                      ^^^^^^^^^^^^^^^^^^^^^^^^^^^^^^^^^^^^^^^^^^^

      File "/home/stguser/devstack/python-tempestconf/.venv/lib/python3.12/site-packages/tempest/lib/common/rest_client.py", line 612, in _request
    resp, resp_body = self.raw_request(
                      ^^^^^^^^^^^^^^^^^

      File "/home/stguser/devstack/python-tempestconf/.venv/lib/python3.12/site-packages/tempest/lib/common/rest_client.py", line 661, in raw_request
    resp, resp_body = self.http_obj.request(
                      ^^^^^^^^^^^^^^^^^^^^^^

      File "/home/stguser/devstack/python-tempestconf/.venv/lib/python3.12/site-packages/tempest/lib/common/http.py", line 123, in request
    r = super(ClosingHttp, self).request(method, url, retries=retry,
        ^^^^^^^^^^^^^^^^^^^^^^^^^^^^^^^^^^^^^^^^^^^^^^^^^^^^^^^^^^^^

      File "/home/stguser/devstack/python-tempestconf/.venv/lib/python3.12/site-packages/urllib3/_request_methods.py", line 143, in request
    return self.request_encode_body(
           ^^^^^^^^^^^^^^^^^^^^^^^^^

      File "/home/stguser/devstack/python-tempestconf/.venv/lib/python3.12/site-packages/urllib3/_request_methods.py", line 278, in request_encode_body
    return self.urlopen(method, url, **extra_kw)
           ^^^^^^^^^^^^^^^^^^^^^^^^^^^^^^^^^^^^^

      File "/home/stguser/devstack/python-tempestconf/.venv/lib/python3.12/site-packages/urllib3/poolmanager.py", line 459, in urlopen
    response = conn.urlopen(method, u.request_uri, **kw)
               ^^^^^^^^^^^^^^^^^^^^^^^^^^^^^^^^^^^^^^^^^

      File "/home/stguser/devstack/python-tempestconf/.venv/lib/python3.12/site-packages/urllib3/connectionpool.py", line 841, in urlopen
    retries = retries.increment(
              ^^^^^^^^^^^^^^^^^^

      File "/home/stguser/devstack/python-tempestconf/.venv/lib/python3.12/site-packages/urllib3/util/retry.py", line 474, in increment
    raise reraise(type(error), error, _stacktrace)
          ^^^^^^^^^^^^^^^^^^^^^^^^^^^^^^^^^^^^^^^^

      File "/home/stguser/devstack/python-tempestconf/.venv/lib/python3.12/site-packages/urllib3/util/util.py", line 39, in reraise
    raise value

      File "/home/stguser/devstack/python-tempestconf/.venv/lib/python3.12/site-packages/urllib3/connectionpool.py", line 787, in urlopen
    response = self._make_request(
               ^^^^^^^^^^^^^^^^^^^

      File "/home/stguser/devstack/python-tempestconf/.venv/lib/python3.12/site-packages/urllib3/connectionpool.py", line 536, in _make_request
    self._raise_timeout(err=e, url=url, timeout_value=read_timeout)

      File "/home/stguser/devstack/python-tempestconf/.venv/lib/python3.12/site-packages/urllib3/connectionpool.py", line 367, in _raise_timeout
    raise ReadTimeoutError(

    urllib3.exceptions.ReadTimeoutError: HTTPConnectionPool(host='9.180.170.14', port=9696): Read timed out. (read timeout=60)

{0} tempest.api.volume.test_volumes_get.VolumesGetTest.test_volume_create_get_update_delete [172.560966s] ... ok
{4} tempest.api.volume.admin.test_volume_quotas.VolumeQuotasAdminTestJSON.test_quota_usage [35.573007s] ... ok
{20} tempest.api.volume.admin.test_volumes_list.VolumesListAdminTestJSON.test_volume_list_param_tenant [19.925915s] ... ok
{2} tempest.api.volume.test_volume_delete_cascade.VolumesDeleteCascade.test_volume_delete_cascade [190.872500s] ... ok
{1} tempest.api.volume.test_volumes_clone.VolumesCloneTest.test_create_from_volume [192.150091s] ... ok
{9} tempest.api.volume.admin.test_snapshots_actions.SnapshotsActionsTest.test_snapshot_force_delete_when_snapshot_is_deleting [27.437727s] ... ok
{3} tempest.api.volume.test_volume_transfers.VolumesTransfersV357Test.test_create_list_delete_volume_transfer [35.818504s] ... ok
{5} tempest.api.volume.test_volume_transfers.VolumesTransfersV355Test.test_create_list_delete_volume_transfer [30.635660s] ... ok
{6} tempest.api.volume.test_volume_transfers.VolumesTransfersTest.test_create_list_delete_volume_transfer [35.093653s] ... ok
{4} tempest.api.volume.admin.test_volume_quotas.VolumeQuotasAdminTestJSON.test_quota_usage_after_volume_transfer [33.225845s] ... ok
{4} tempest.api.volume.admin.test_volume_quotas.VolumeQuotasAdminTestJSON.test_show_quota_usage [0.824255s] ... ok
{4} tempest.api.volume.admin.test_volume_quotas.VolumeQuotasAdminTestJSON.test_update_all_quota_resources_for_tenant [6.175152s] ... ok
{9} tempest.api.volume.admin.test_snapshots_actions.SnapshotsActionsTest.test_snapshot_force_delete_when_snapshot_is_error [18.178119s] ... ok
{5} setUpClass (tempest.api.volume.test_volumes_backup.VolumesBackupsV39Test) ... SKIPPED: Cinder backup feature disabled
{9} tempest.api.volume.admin.test_snapshots_actions.SnapshotsActionsTest.test_snapshot_force_delete_when_snapshot_is_error_deleting [9.516952s] ... ok
{11} tempest.api.volume.test_volumes_negative.VolumesNegativeTest.test_attach_volumes_with_nonexistent_volume_id [133.207170s] ... ok
{9} tempest.api.volume.admin.test_snapshots_actions.SnapshotsActionsTest.test_update_snapshot_status [0.740121s] ... ok
{11} tempest.api.volume.test_volumes_negative.VolumesNegativeTest.test_create_volume_from_deactivated_image [8.122248s] ... ok
{0} tempest.api.volume.test_volumes_get.VolumesGetTest.test_volume_create_get_update_delete_as_clone [63.046842s] ... ok
{11} tempest.api.volume.test_volumes_negative.VolumesNegativeTest.test_create_volume_from_image_with_decreasing_size [3.894476s] ... ok
{11} tempest.api.volume.test_volumes_negative.VolumesNegativeTest.test_create_volume_with_invalid_size [0.017829s] ... ok
{11} tempest.api.volume.test_volumes_negative.VolumesNegativeTest.test_create_volume_with_nonexistent_snapshot_id [0.103315s] ... ok
{11} tempest.api.volume.test_volumes_negative.VolumesNegativeTest.test_create_volume_with_nonexistent_source_volid [0.029692s] ... ok
{11} tempest.api.volume.test_volumes_negative.VolumesNegativeTest.test_create_volume_with_nonexistent_volume_type [0.057996s] ... ok
{11} tempest.api.volume.test_volumes_negative.VolumesNegativeTest.test_create_volume_with_size_negative [0.018184s] ... ok
{11} tempest.api.volume.test_volumes_negative.VolumesNegativeTest.test_create_volume_with_size_zero [0.016777s] ... ok
{11} tempest.api.volume.test_volumes_negative.VolumesNegativeTest.test_create_volume_without_passing_size [0.016661s] ... ok
{11} tempest.api.volume.test_volumes_negative.VolumesNegativeTest.test_delete_invalid_volume_id [0.027076s] ... ok
{11} tempest.api.volume.test_volumes_negative.VolumesNegativeTest.test_delete_volume_without_passing_volume_id [0.011864s] ... ok
{11} tempest.api.volume.test_volumes_negative.VolumesNegativeTest.test_detach_volumes_with_invalid_volume_id [0.030821s] ... ok
{11} tempest.api.volume.test_volumes_negative.VolumesNegativeTest.test_get_invalid_volume_id [0.029919s] ... ok
{11} tempest.api.volume.test_volumes_negative.VolumesNegativeTest.test_get_volume_without_passing_volume_id [0.010507s] ... ok
{11} tempest.api.volume.test_volumes_negative.VolumesNegativeTest.test_list_volumes_detail_with_invalid_status [0.093817s] ... ok
{11} tempest.api.volume.test_volumes_negative.VolumesNegativeTest.test_list_volumes_detail_with_nonexistent_name [0.090943s] ... ok
{11} tempest.api.volume.test_volumes_negative.VolumesNegativeTest.test_list_volumes_with_invalid_status [0.035112s] ... ok
{11} tempest.api.volume.test_volumes_negative.VolumesNegativeTest.test_list_volumes_with_nonexistent_name [0.033798s] ... ok
{11} tempest.api.volume.test_volumes_negative.VolumesNegativeTest.test_reserve_volume_with_negative_volume_status [0.457333s] ... ok
{11} tempest.api.volume.test_volumes_negative.VolumesNegativeTest.test_reserve_volume_with_nonexistent_volume_id [0.049771s] ... ok
{11} tempest.api.volume.test_volumes_negative.VolumesNegativeTest.test_unreserve_volume_with_nonexistent_volume_id [0.031040s] ... ok
{11} tempest.api.volume.test_volumes_negative.VolumesNegativeTest.test_update_volume_with_empty_volume_id [0.011207s] ... ok
{11} tempest.api.volume.test_volumes_negative.VolumesNegativeTest.test_update_volume_with_invalid_volume_id [0.028226s] ... ok
{11} tempest.api.volume.test_volumes_negative.VolumesNegativeTest.test_update_volume_with_nonexistent_volume_id [0.050332s] ... ok
{11} tempest.api.volume.test_volumes_negative.VolumesNegativeTest.test_volume_delete_nonexistent_volume_id [0.076831s] ... ok
{11} tempest.api.volume.test_volumes_negative.VolumesNegativeTest.test_volume_get_nonexistent_volume_id [0.025590s] ... ok
{4} setUpClass (tempest.api.volume.admin.test_volume_retype.VolumeRetypeWithMigrationTest) ... SKIPPED: Cinder multi-backend feature disabled

==============================
Failed 5 tests - output below:
==============================

setUpClass (tempest.api.volume.test_volumes_actions.VolumesActionsTest)
-----------------------------------------------------------------------

Captured traceback:
~~~~~~~~~~~~~~~~~~~
    Traceback (most recent call last):

      File "/home/stguser/devstack/python-tempestconf/.venv/lib/python3.12/site-packages/urllib3/connectionpool.py", line 534, in _make_request
    response = conn.getresponse()
               ^^^^^^^^^^^^^^^^^^

      File "/home/stguser/devstack/python-tempestconf/.venv/lib/python3.12/site-packages/urllib3/connection.py", line 565, in getresponse
    httplib_response = super().getresponse()
                       ^^^^^^^^^^^^^^^^^^^^^

      File "/usr/lib/python3.12/http/client.py", line 1428, in getresponse
    response.begin()

      File "/usr/lib/python3.12/http/client.py", line 331, in begin
    version, status, reason = self._read_status()
                              ^^^^^^^^^^^^^^^^^^^

      File "/usr/lib/python3.12/http/client.py", line 292, in _read_status
    line = str(self.fp.readline(_MAXLINE + 1), "iso-8859-1")
               ^^^^^^^^^^^^^^^^^^^^^^^^^^^^^^

      File "/usr/lib/python3.12/socket.py", line 707, in readinto
    return self._sock.recv_into(b)
           ^^^^^^^^^^^^^^^^^^^^^^^

    TimeoutError: timed out

    
The above exception was the direct cause of the following exception:


    Traceback (most recent call last):

      File "/home/stguser/devstack/python-tempestconf/.venv/lib/python3.12/site-packages/tempest/test.py", line 185, in setUpClass
    raise value.with_traceback(trace)

      File "/home/stguser/devstack/python-tempestconf/.venv/lib/python3.12/site-packages/tempest/test.py", line 170, in setUpClass
    cls.setup_credentials()

      File "/home/stguser/devstack/python-tempestconf/.venv/lib/python3.12/site-packages/tempest/api/volume/base.py", line 62, in setup_credentials
    super(BaseVolumeTest, cls).setup_credentials()

      File "/home/stguser/devstack/python-tempestconf/.venv/lib/python3.12/site-packages/tempest/test.py", line 398, in setup_credentials
    manager = cls.get_client_manager(
              ^^^^^^^^^^^^^^^^^^^^^^^

      File "/home/stguser/devstack/python-tempestconf/.venv/lib/python3.12/site-packages/tempest/test.py", line 743, in get_client_manager
    creds = getattr(cred_provider, credentials_method)()
            ^^^^^^^^^^^^^^^^^^^^^^^^^^^^^^^^^^^^^^^^^^^^

      File "/home/stguser/devstack/python-tempestconf/.venv/lib/python3.12/site-packages/tempest/lib/common/dynamic_creds.py", line 473, in get_primary_creds
    return self.get_project_member_creds()
           ^^^^^^^^^^^^^^^^^^^^^^^^^^^^^^^

      File "/home/stguser/devstack/python-tempestconf/.venv/lib/python3.12/site-packages/tempest/lib/common/dynamic_creds.py", line 514, in get_project_member_creds
    return self.get_credentials(['member'], scope='project')
           ^^^^^^^^^^^^^^^^^^^^^^^^^^^^^^^^^^^^^^^^^^^^^^^^^

      File "/home/stguser/devstack/python-tempestconf/.venv/lib/python3.12/site-packages/tempest/lib/common/dynamic_creds.py", line 459, in get_credentials
    network, subnet, router = self._create_network_resources(
                              ^^^^^^^^^^^^^^^^^^^^^^^^^^^^^^^

      File "/home/stguser/devstack/python-tempestconf/.venv/lib/python3.12/site-packages/tempest/lib/common/dynamic_creds.py", line 314, in _create_network_resources
    subnet = self._create_subnet(subnet_name, tenant_id,
             ^^^^^^^^^^^^^^^^^^^^^^^^^^^^^^^^^^^^^^^^^^^

      File "/home/stguser/devstack/python-tempestconf/.venv/lib/python3.12/site-packages/tempest/lib/common/dynamic_creds.py", line 349, in _create_subnet
    create_subnet(

      File "/home/stguser/devstack/python-tempestconf/.venv/lib/python3.12/site-packages/tempest/lib/services/network/subnets_client.py", line 27, in create_subnet
    return self.create_resource(uri, post_data)
           ^^^^^^^^^^^^^^^^^^^^^^^^^^^^^^^^^^^^

      File "/home/stguser/devstack/python-tempestconf/.venv/lib/python3.12/site-packages/tempest/lib/services/network/base.py", line 62, in create_resource
    resp, body = self.post(req_uri, req_post_data)
                 ^^^^^^^^^^^^^^^^^^^^^^^^^^^^^^^^^

      File "/home/stguser/devstack/python-tempestconf/.venv/lib/python3.12/site-packages/tempest/lib/common/rest_client.py", line 314, in post
    resp_header, resp_body = self.request(
                             ^^^^^^^^^^^^^

      File "/home/stguser/devstack/python-tempestconf/.venv/lib/python3.12/site-packages/tempest/lib/common/rest_client.py", line 746, in request
    resp, resp_body = self._request(method, url, headers=headers,
                      ^^^^^^^^^^^^^^^^^^^^^^^^^^^^^^^^^^^^^^^^^^^

      File "/home/stguser/devstack/python-tempestconf/.venv/lib/python3.12/site-packages/tempest/lib/common/rest_client.py", line 612, in _request
    resp, resp_body = self.raw_request(
                      ^^^^^^^^^^^^^^^^^

      File "/home/stguser/devstack/python-tempestconf/.venv/lib/python3.12/site-packages/tempest/lib/common/rest_client.py", line 661, in raw_request
    resp, resp_body = self.http_obj.request(
                      ^^^^^^^^^^^^^^^^^^^^^^

      File "/home/stguser/devstack/python-tempestconf/.venv/lib/python3.12/site-packages/tempest/lib/common/http.py", line 123, in request
    r = super(ClosingHttp, self).request(method, url, retries=retry,
        ^^^^^^^^^^^^^^^^^^^^^^^^^^^^^^^^^^^^^^^^^^^^^^^^^^^^^^^^^^^^

      File "/home/stguser/devstack/python-tempestconf/.venv/lib/python3.12/site-packages/urllib3/_request_methods.py", line 143, in request
    return self.request_encode_body(
           ^^^^^^^^^^^^^^^^^^^^^^^^^

      File "/home/stguser/devstack/python-tempestconf/.venv/lib/python3.12/site-packages/urllib3/_request_methods.py", line 278, in request_encode_body
    return self.urlopen(method, url, **extra_kw)
           ^^^^^^^^^^^^^^^^^^^^^^^^^^^^^^^^^^^^^

      File "/home/stguser/devstack/python-tempestconf/.venv/lib/python3.12/site-packages/urllib3/poolmanager.py", line 459, in urlopen
    response = conn.urlopen(method, u.request_uri, **kw)
               ^^^^^^^^^^^^^^^^^^^^^^^^^^^^^^^^^^^^^^^^^

      File "/home/stguser/devstack/python-tempestconf/.venv/lib/python3.12/site-packages/urllib3/connectionpool.py", line 841, in urlopen
    retries = retries.increment(
              ^^^^^^^^^^^^^^^^^^

      File "/home/stguser/devstack/python-tempestconf/.venv/lib/python3.12/site-packages/urllib3/util/retry.py", line 474, in increment
    raise reraise(type(error), error, _stacktrace)
          ^^^^^^^^^^^^^^^^^^^^^^^^^^^^^^^^^^^^^^^^

      File "/home/stguser/devstack/python-tempestconf/.venv/lib/python3.12/site-packages/urllib3/util/util.py", line 39, in reraise
    raise value

      File "/home/stguser/devstack/python-tempestconf/.venv/lib/python3.12/site-packages/urllib3/connectionpool.py", line 787, in urlopen
    response = self._make_request(
               ^^^^^^^^^^^^^^^^^^^

      File "/home/stguser/devstack/python-tempestconf/.venv/lib/python3.12/site-packages/urllib3/connectionpool.py", line 536, in _make_request
    self._raise_timeout(err=e, url=url, timeout_value=read_timeout)

      File "/home/stguser/devstack/python-tempestconf/.venv/lib/python3.12/site-packages/urllib3/connectionpool.py", line 367, in _raise_timeout
    raise ReadTimeoutError(

    urllib3.exceptions.ReadTimeoutError: HTTPConnectionPool(host='9.180.170.14', port=9696): Read timed out. (read timeout=60)


setUpClass (tempest.api.volume.admin.test_volume_retype.VolumeRetypeWithoutMigrationTest)
-----------------------------------------------------------------------------------------

Captured traceback:
~~~~~~~~~~~~~~~~~~~
    Traceback (most recent call last):

      File "/home/stguser/devstack/python-tempestconf/.venv/lib/python3.12/site-packages/tempest/test.py", line 185, in setUpClass
    raise value.with_traceback(trace)

      File "/home/stguser/devstack/python-tempestconf/.venv/lib/python3.12/site-packages/tempest/test.py", line 178, in setUpClass
    cls.resource_setup()

      File "/home/stguser/devstack/python-tempestconf/.venv/lib/python3.12/site-packages/tempest/api/volume/admin/test_volume_retype.py", line 172, in resource_setup
    cls.src_vol_type = cls.create_volume_type('volume-type-1')
                       ^^^^^^^^^^^^^^^^^^^^^^^^^^^^^^^^^^^^^^^

      File "/home/stguser/devstack/python-tempestconf/.venv/lib/python3.12/site-packages/tempest/api/volume/base.py", line 366, in create_volume_type
    volume_type = self.admin_volume_types_client.create_volume_type(
                  ^^^^^^^^^^^^^^^^^^^^^^^^^^^^^^^^^^^^^^^^^^^^^^^^^^

      File "/home/stguser/devstack/python-tempestconf/.venv/lib/python3.12/site-packages/tempest/lib/services/volume/v3/types_client.py", line 90, in create_volume_type
    resp, body = self.post('types', post_body)
                 ^^^^^^^^^^^^^^^^^^^^^^^^^^^^^

      File "/home/stguser/devstack/python-tempestconf/.venv/lib/python3.12/site-packages/tempest/lib/common/rest_client.py", line 314, in post
    resp_header, resp_body = self.request(
                             ^^^^^^^^^^^^^

      File "/home/stguser/devstack/python-tempestconf/.venv/lib/python3.12/site-packages/tempest/lib/common/rest_client.py", line 762, in request
    self._error_checker(resp, resp_body)

      File "/home/stguser/devstack/python-tempestconf/.venv/lib/python3.12/site-packages/tempest/lib/common/rest_client.py", line 892, in _error_checker
    raise exceptions.Conflict(resp_body, resp=resp)

    tempest.lib.exceptions.Conflict: Conflict with state of target resource
Details: {'code': 409, 'message': 'Volume Type volume-type-1 already exists.'}


setUpClass (tempest.api.volume.test_volumes_snapshots.VolumesSnapshotTestJSON)
------------------------------------------------------------------------------

Captured traceback:
~~~~~~~~~~~~~~~~~~~
    Traceback (most recent call last):

      File "/home/stguser/devstack/python-tempestconf/.venv/lib/python3.12/site-packages/urllib3/connectionpool.py", line 534, in _make_request
    response = conn.getresponse()
               ^^^^^^^^^^^^^^^^^^

      File "/home/stguser/devstack/python-tempestconf/.venv/lib/python3.12/site-packages/urllib3/connection.py", line 565, in getresponse
    httplib_response = super().getresponse()
                       ^^^^^^^^^^^^^^^^^^^^^

      File "/usr/lib/python3.12/http/client.py", line 1428, in getresponse
    response.begin()

      File "/usr/lib/python3.12/http/client.py", line 331, in begin
    version, status, reason = self._read_status()
                              ^^^^^^^^^^^^^^^^^^^

      File "/usr/lib/python3.12/http/client.py", line 292, in _read_status
    line = str(self.fp.readline(_MAXLINE + 1), "iso-8859-1")
               ^^^^^^^^^^^^^^^^^^^^^^^^^^^^^^

      File "/usr/lib/python3.12/socket.py", line 707, in readinto
    return self._sock.recv_into(b)
           ^^^^^^^^^^^^^^^^^^^^^^^

    TimeoutError: timed out

    
The above exception was the direct cause of the following exception:


    Traceback (most recent call last):

      File "/home/stguser/devstack/python-tempestconf/.venv/lib/python3.12/site-packages/tempest/test.py", line 185, in setUpClass
    raise value.with_traceback(trace)

      File "/home/stguser/devstack/python-tempestconf/.venv/lib/python3.12/site-packages/tempest/test.py", line 170, in setUpClass
    cls.setup_credentials()

      File "/home/stguser/devstack/python-tempestconf/.venv/lib/python3.12/site-packages/tempest/api/volume/base.py", line 62, in setup_credentials
    super(BaseVolumeTest, cls).setup_credentials()

      File "/home/stguser/devstack/python-tempestconf/.venv/lib/python3.12/site-packages/tempest/test.py", line 398, in setup_credentials
    manager = cls.get_client_manager(
              ^^^^^^^^^^^^^^^^^^^^^^^

      File "/home/stguser/devstack/python-tempestconf/.venv/lib/python3.12/site-packages/tempest/test.py", line 743, in get_client_manager
    creds = getattr(cred_provider, credentials_method)()
            ^^^^^^^^^^^^^^^^^^^^^^^^^^^^^^^^^^^^^^^^^^^^

      File "/home/stguser/devstack/python-tempestconf/.venv/lib/python3.12/site-packages/tempest/lib/common/dynamic_creds.py", line 473, in get_primary_creds
    return self.get_project_member_creds()
           ^^^^^^^^^^^^^^^^^^^^^^^^^^^^^^^

      File "/home/stguser/devstack/python-tempestconf/.venv/lib/python3.12/site-packages/tempest/lib/common/dynamic_creds.py", line 514, in get_project_member_creds
    return self.get_credentials(['member'], scope='project')
           ^^^^^^^^^^^^^^^^^^^^^^^^^^^^^^^^^^^^^^^^^^^^^^^^^

      File "/home/stguser/devstack/python-tempestconf/.venv/lib/python3.12/site-packages/tempest/lib/common/dynamic_creds.py", line 459, in get_credentials
    network, subnet, router = self._create_network_resources(
                              ^^^^^^^^^^^^^^^^^^^^^^^^^^^^^^^

      File "/home/stguser/devstack/python-tempestconf/.venv/lib/python3.12/site-packages/tempest/lib/common/dynamic_creds.py", line 318, in _create_network_resources
    router = self._create_router(router_name, tenant_id)
             ^^^^^^^^^^^^^^^^^^^^^^^^^^^^^^^^^^^^^^^^^^^

      File "/home/stguser/devstack/python-tempestconf/.venv/lib/python3.12/site-packages/tempest/lib/common/dynamic_creds.py", line 379, in _create_router
    resp_body = self.routers_admin_client.create_router(**kwargs)
                ^^^^^^^^^^^^^^^^^^^^^^^^^^^^^^^^^^^^^^^^^^^^^^^^^

      File "/home/stguser/devstack/python-tempestconf/.venv/lib/python3.12/site-packages/tempest/lib/services/network/routers_client.py", line 27, in create_router
    return self.create_resource(uri, post_body)
           ^^^^^^^^^^^^^^^^^^^^^^^^^^^^^^^^^^^^

      File "/home/stguser/devstack/python-tempestconf/.venv/lib/python3.12/site-packages/tempest/lib/services/network/base.py", line 62, in create_resource
    resp, body = self.post(req_uri, req_post_data)
                 ^^^^^^^^^^^^^^^^^^^^^^^^^^^^^^^^^

      File "/home/stguser/devstack/python-tempestconf/.venv/lib/python3.12/site-packages/tempest/lib/common/rest_client.py", line 314, in post
    resp_header, resp_body = self.request(
                             ^^^^^^^^^^^^^

      File "/home/stguser/devstack/python-tempestconf/.venv/lib/python3.12/site-packages/tempest/lib/common/rest_client.py", line 746, in request
    resp, resp_body = self._request(method, url, headers=headers,
                      ^^^^^^^^^^^^^^^^^^^^^^^^^^^^^^^^^^^^^^^^^^^

      File "/home/stguser/devstack/python-tempestconf/.venv/lib/python3.12/site-packages/tempest/lib/common/rest_client.py", line 612, in _request
    resp, resp_body = self.raw_request(
                      ^^^^^^^^^^^^^^^^^

      File "/home/stguser/devstack/python-tempestconf/.venv/lib/python3.12/site-packages/tempest/lib/common/rest_client.py", line 661, in raw_request
    resp, resp_body = self.http_obj.request(
                      ^^^^^^^^^^^^^^^^^^^^^^

      File "/home/stguser/devstack/python-tempestconf/.venv/lib/python3.12/site-packages/tempest/lib/common/http.py", line 123, in request
    r = super(ClosingHttp, self).request(method, url, retries=retry,
        ^^^^^^^^^^^^^^^^^^^^^^^^^^^^^^^^^^^^^^^^^^^^^^^^^^^^^^^^^^^^

      File "/home/stguser/devstack/python-tempestconf/.venv/lib/python3.12/site-packages/urllib3/_request_methods.py", line 143, in request
    return self.request_encode_body(
           ^^^^^^^^^^^^^^^^^^^^^^^^^

      File "/home/stguser/devstack/python-tempestconf/.venv/lib/python3.12/site-packages/urllib3/_request_methods.py", line 278, in request_encode_body
    return self.urlopen(method, url, **extra_kw)
           ^^^^^^^^^^^^^^^^^^^^^^^^^^^^^^^^^^^^^

      File "/home/stguser/devstack/python-tempestconf/.venv/lib/python3.12/site-packages/urllib3/poolmanager.py", line 459, in urlopen
    response = conn.urlopen(method, u.request_uri, **kw)
               ^^^^^^^^^^^^^^^^^^^^^^^^^^^^^^^^^^^^^^^^^

      File "/home/stguser/devstack/python-tempestconf/.venv/lib/python3.12/site-packages/urllib3/connectionpool.py", line 841, in urlopen
    retries = retries.increment(
              ^^^^^^^^^^^^^^^^^^

      File "/home/stguser/devstack/python-tempestconf/.venv/lib/python3.12/site-packages/urllib3/util/retry.py", line 474, in increment
    raise reraise(type(error), error, _stacktrace)
          ^^^^^^^^^^^^^^^^^^^^^^^^^^^^^^^^^^^^^^^^

      File "/home/stguser/devstack/python-tempestconf/.venv/lib/python3.12/site-packages/urllib3/util/util.py", line 39, in reraise
    raise value

      File "/home/stguser/devstack/python-tempestconf/.venv/lib/python3.12/site-packages/urllib3/connectionpool.py", line 787, in urlopen
    response = self._make_request(
               ^^^^^^^^^^^^^^^^^^^

      File "/home/stguser/devstack/python-tempestconf/.venv/lib/python3.12/site-packages/urllib3/connectionpool.py", line 536, in _make_request
    self._raise_timeout(err=e, url=url, timeout_value=read_timeout)

      File "/home/stguser/devstack/python-tempestconf/.venv/lib/python3.12/site-packages/urllib3/connectionpool.py", line 367, in _raise_timeout
    raise ReadTimeoutError(

    urllib3.exceptions.ReadTimeoutError: HTTPConnectionPool(host='9.180.170.14', port=9696): Read timed out. (read timeout=60)


setUpClass (tempest.api.volume.admin.test_volume_snapshot_quotas_negative.VolumeSnapshotQuotasNegativeTestJSON)
---------------------------------------------------------------------------------------------------------------

Captured traceback:
~~~~~~~~~~~~~~~~~~~
    Traceback (most recent call last):

      File "/home/stguser/devstack/python-tempestconf/.venv/lib/python3.12/site-packages/urllib3/connectionpool.py", line 534, in _make_request
    response = conn.getresponse()
               ^^^^^^^^^^^^^^^^^^

      File "/home/stguser/devstack/python-tempestconf/.venv/lib/python3.12/site-packages/urllib3/connection.py", line 565, in getresponse
    httplib_response = super().getresponse()
                       ^^^^^^^^^^^^^^^^^^^^^

      File "/usr/lib/python3.12/http/client.py", line 1428, in getresponse
    response.begin()

      File "/usr/lib/python3.12/http/client.py", line 331, in begin
    version, status, reason = self._read_status()
                              ^^^^^^^^^^^^^^^^^^^

      File "/usr/lib/python3.12/http/client.py", line 292, in _read_status
    line = str(self.fp.readline(_MAXLINE + 1), "iso-8859-1")
               ^^^^^^^^^^^^^^^^^^^^^^^^^^^^^^

      File "/usr/lib/python3.12/socket.py", line 707, in readinto
    return self._sock.recv_into(b)
           ^^^^^^^^^^^^^^^^^^^^^^^

    TimeoutError: timed out

    
The above exception was the direct cause of the following exception:


    Traceback (most recent call last):

      File "/home/stguser/devstack/python-tempestconf/.venv/lib/python3.12/site-packages/tempest/test.py", line 185, in setUpClass
    raise value.with_traceback(trace)

      File "/home/stguser/devstack/python-tempestconf/.venv/lib/python3.12/site-packages/tempest/test.py", line 178, in setUpClass
    cls.resource_setup()

      File "/home/stguser/devstack/python-tempestconf/.venv/lib/python3.12/site-packages/tempest/api/volume/admin/test_volume_snapshot_quotas_negative.py", line 65, in resource_setup
    cls.volume = cls.create_volume()
                 ^^^^^^^^^^^^^^^^^^^

      File "/home/stguser/devstack/python-tempestconf/.venv/lib/python3.12/site-packages/tempest/api/volume/base.py", line 139, in create_volume
    volume = self.volumes_client.create_volume(**kwargs)['volume']
             ^^^^^^^^^^^^^^^^^^^^^^^^^^^^^^^^^^^^^^^^^^^

      File "/home/stguser/devstack/python-tempestconf/.venv/lib/python3.12/site-packages/tempest/lib/services/volume/v3/volumes_client.py", line 116, in create_volume
    resp, body = self.post('volumes', post_body)
                 ^^^^^^^^^^^^^^^^^^^^^^^^^^^^^^^

      File "/home/stguser/devstack/python-tempestconf/.venv/lib/python3.12/site-packages/tempest/lib/common/rest_client.py", line 314, in post
    resp_header, resp_body = self.request(
                             ^^^^^^^^^^^^^

      File "/home/stguser/devstack/python-tempestconf/.venv/lib/python3.12/site-packages/tempest/lib/services/volume/base_client.py", line 39, in request
    resp, resp_body = super(BaseClient, self).request(
                      ^^^^^^^^^^^^^^^^^^^^^^^^^^^^^^^^

      File "/home/stguser/devstack/python-tempestconf/.venv/lib/python3.12/site-packages/tempest/lib/common/rest_client.py", line 746, in request
    resp, resp_body = self._request(method, url, headers=headers,
                      ^^^^^^^^^^^^^^^^^^^^^^^^^^^^^^^^^^^^^^^^^^^

      File "/home/stguser/devstack/python-tempestconf/.venv/lib/python3.12/site-packages/tempest/lib/common/rest_client.py", line 612, in _request
    resp, resp_body = self.raw_request(
                      ^^^^^^^^^^^^^^^^^

      File "/home/stguser/devstack/python-tempestconf/.venv/lib/python3.12/site-packages/tempest/lib/common/rest_client.py", line 661, in raw_request
    resp, resp_body = self.http_obj.request(
                      ^^^^^^^^^^^^^^^^^^^^^^

      File "/home/stguser/devstack/python-tempestconf/.venv/lib/python3.12/site-packages/tempest/lib/common/http.py", line 123, in request
    r = super(ClosingHttp, self).request(method, url, retries=retry,
        ^^^^^^^^^^^^^^^^^^^^^^^^^^^^^^^^^^^^^^^^^^^^^^^^^^^^^^^^^^^^

      File "/home/stguser/devstack/python-tempestconf/.venv/lib/python3.12/site-packages/urllib3/_request_methods.py", line 143, in request
    return self.request_encode_body(
           ^^^^^^^^^^^^^^^^^^^^^^^^^

      File "/home/stguser/devstack/python-tempestconf/.venv/lib/python3.12/site-packages/urllib3/_request_methods.py", line 278, in request_encode_body
    return self.urlopen(method, url, **extra_kw)
           ^^^^^^^^^^^^^^^^^^^^^^^^^^^^^^^^^^^^^

      File "/home/stguser/devstack/python-tempestconf/.venv/lib/python3.12/site-packages/urllib3/poolmanager.py", line 459, in urlopen
    response = conn.urlopen(method, u.request_uri, **kw)
               ^^^^^^^^^^^^^^^^^^^^^^^^^^^^^^^^^^^^^^^^^

      File "/home/stguser/devstack/python-tempestconf/.venv/lib/python3.12/site-packages/urllib3/connectionpool.py", line 841, in urlopen
    retries = retries.increment(
              ^^^^^^^^^^^^^^^^^^

      File "/home/stguser/devstack/python-tempestconf/.venv/lib/python3.12/site-packages/urllib3/util/retry.py", line 474, in increment
    raise reraise(type(error), error, _stacktrace)
          ^^^^^^^^^^^^^^^^^^^^^^^^^^^^^^^^^^^^^^^^

      File "/home/stguser/devstack/python-tempestconf/.venv/lib/python3.12/site-packages/urllib3/util/util.py", line 39, in reraise
    raise value

      File "/home/stguser/devstack/python-tempestconf/.venv/lib/python3.12/site-packages/urllib3/connectionpool.py", line 787, in urlopen
    response = self._make_request(
               ^^^^^^^^^^^^^^^^^^^

      File "/home/stguser/devstack/python-tempestconf/.venv/lib/python3.12/site-packages/urllib3/connectionpool.py", line 536, in _make_request
    self._raise_timeout(err=e, url=url, timeout_value=read_timeout)

      File "/home/stguser/devstack/python-tempestconf/.venv/lib/python3.12/site-packages/urllib3/connectionpool.py", line 367, in _raise_timeout
    raise ReadTimeoutError(

    urllib3.exceptions.ReadTimeoutError: HTTPConnectionPool(host='9.180.170.14', port=80): Read timed out. (read timeout=60)


setUpClass (tempest.api.volume.admin.test_volumes_actions.VolumesActionsTest)
-----------------------------------------------------------------------------

Captured traceback:
~~~~~~~~~~~~~~~~~~~
    Traceback (most recent call last):

      File "/home/stguser/devstack/python-tempestconf/.venv/lib/python3.12/site-packages/urllib3/connectionpool.py", line 534, in _make_request
    response = conn.getresponse()
               ^^^^^^^^^^^^^^^^^^

      File "/home/stguser/devstack/python-tempestconf/.venv/lib/python3.12/site-packages/urllib3/connection.py", line 565, in getresponse
    httplib_response = super().getresponse()
                       ^^^^^^^^^^^^^^^^^^^^^

      File "/usr/lib/python3.12/http/client.py", line 1428, in getresponse
    response.begin()

      File "/usr/lib/python3.12/http/client.py", line 331, in begin
    version, status, reason = self._read_status()
                              ^^^^^^^^^^^^^^^^^^^

      File "/usr/lib/python3.12/http/client.py", line 292, in _read_status
    line = str(self.fp.readline(_MAXLINE + 1), "iso-8859-1")
               ^^^^^^^^^^^^^^^^^^^^^^^^^^^^^^

      File "/usr/lib/python3.12/socket.py", line 707, in readinto
    return self._sock.recv_into(b)
           ^^^^^^^^^^^^^^^^^^^^^^^

    TimeoutError: timed out

    
The above exception was the direct cause of the following exception:


    Traceback (most recent call last):

      File "/home/stguser/devstack/python-tempestconf/.venv/lib/python3.12/site-packages/tempest/test.py", line 185, in setUpClass
    raise value.with_traceback(trace)

      File "/home/stguser/devstack/python-tempestconf/.venv/lib/python3.12/site-packages/tempest/test.py", line 170, in setUpClass
    cls.setup_credentials()

      File "/home/stguser/devstack/python-tempestconf/.venv/lib/python3.12/site-packages/tempest/api/volume/base.py", line 62, in setup_credentials
    super(BaseVolumeTest, cls).setup_credentials()

      File "/home/stguser/devstack/python-tempestconf/.venv/lib/python3.12/site-packages/tempest/test.py", line 398, in setup_credentials
    manager = cls.get_client_manager(
              ^^^^^^^^^^^^^^^^^^^^^^^

      File "/home/stguser/devstack/python-tempestconf/.venv/lib/python3.12/site-packages/tempest/test.py", line 743, in get_client_manager
    creds = getattr(cred_provider, credentials_method)()
            ^^^^^^^^^^^^^^^^^^^^^^^^^^^^^^^^^^^^^^^^^^^^

      File "/home/stguser/devstack/python-tempestconf/.venv/lib/python3.12/site-packages/tempest/lib/common/dynamic_creds.py", line 473, in get_primary_creds
    return self.get_project_member_creds()
           ^^^^^^^^^^^^^^^^^^^^^^^^^^^^^^^

      File "/home/stguser/devstack/python-tempestconf/.venv/lib/python3.12/site-packages/tempest/lib/common/dynamic_creds.py", line 514, in get_project_member_creds
    return self.get_credentials(['member'], scope='project')
           ^^^^^^^^^^^^^^^^^^^^^^^^^^^^^^^^^^^^^^^^^^^^^^^^^

      File "/home/stguser/devstack/python-tempestconf/.venv/lib/python3.12/site-packages/tempest/lib/common/dynamic_creds.py", line 459, in get_credentials
    network, subnet, router = self._create_network_resources(
                              ^^^^^^^^^^^^^^^^^^^^^^^^^^^^^^^

      File "/home/stguser/devstack/python-tempestconf/.venv/lib/python3.12/site-packages/tempest/lib/common/dynamic_creds.py", line 318, in _create_network_resources
    router = self._create_router(router_name, tenant_id)
             ^^^^^^^^^^^^^^^^^^^^^^^^^^^^^^^^^^^^^^^^^^^

      File "/home/stguser/devstack/python-tempestconf/.venv/lib/python3.12/site-packages/tempest/lib/common/dynamic_creds.py", line 379, in _create_router
    resp_body = self.routers_admin_client.create_router(**kwargs)
                ^^^^^^^^^^^^^^^^^^^^^^^^^^^^^^^^^^^^^^^^^^^^^^^^^

      File "/home/stguser/devstack/python-tempestconf/.venv/lib/python3.12/site-packages/tempest/lib/services/network/routers_client.py", line 27, in create_router
    return self.create_resource(uri, post_body)
           ^^^^^^^^^^^^^^^^^^^^^^^^^^^^^^^^^^^^

      File "/home/stguser/devstack/python-tempestconf/.venv/lib/python3.12/site-packages/tempest/lib/services/network/base.py", line 62, in create_resource
    resp, body = self.post(req_uri, req_post_data)
                 ^^^^^^^^^^^^^^^^^^^^^^^^^^^^^^^^^

      File "/home/stguser/devstack/python-tempestconf/.venv/lib/python3.12/site-packages/tempest/lib/common/rest_client.py", line 314, in post
    resp_header, resp_body = self.request(
                             ^^^^^^^^^^^^^

      File "/home/stguser/devstack/python-tempestconf/.venv/lib/python3.12/site-packages/tempest/lib/common/rest_client.py", line 746, in request
    resp, resp_body = self._request(method, url, headers=headers,
                      ^^^^^^^^^^^^^^^^^^^^^^^^^^^^^^^^^^^^^^^^^^^

      File "/home/stguser/devstack/python-tempestconf/.venv/lib/python3.12/site-packages/tempest/lib/common/rest_client.py", line 612, in _request
    resp, resp_body = self.raw_request(
                      ^^^^^^^^^^^^^^^^^

      File "/home/stguser/devstack/python-tempestconf/.venv/lib/python3.12/site-packages/tempest/lib/common/rest_client.py", line 661, in raw_request
    resp, resp_body = self.http_obj.request(
                      ^^^^^^^^^^^^^^^^^^^^^^

      File "/home/stguser/devstack/python-tempestconf/.venv/lib/python3.12/site-packages/tempest/lib/common/http.py", line 123, in request
    r = super(ClosingHttp, self).request(method, url, retries=retry,
        ^^^^^^^^^^^^^^^^^^^^^^^^^^^^^^^^^^^^^^^^^^^^^^^^^^^^^^^^^^^^

      File "/home/stguser/devstack/python-tempestconf/.venv/lib/python3.12/site-packages/urllib3/_request_methods.py", line 143, in request
    return self.request_encode_body(
           ^^^^^^^^^^^^^^^^^^^^^^^^^

      File "/home/stguser/devstack/python-tempestconf/.venv/lib/python3.12/site-packages/urllib3/_request_methods.py", line 278, in request_encode_body
    return self.urlopen(method, url, **extra_kw)
           ^^^^^^^^^^^^^^^^^^^^^^^^^^^^^^^^^^^^^

      File "/home/stguser/devstack/python-tempestconf/.venv/lib/python3.12/site-packages/urllib3/poolmanager.py", line 459, in urlopen
    response = conn.urlopen(method, u.request_uri, **kw)
               ^^^^^^^^^^^^^^^^^^^^^^^^^^^^^^^^^^^^^^^^^

      File "/home/stguser/devstack/python-tempestconf/.venv/lib/python3.12/site-packages/urllib3/connectionpool.py", line 841, in urlopen
    retries = retries.increment(
              ^^^^^^^^^^^^^^^^^^

      File "/home/stguser/devstack/python-tempestconf/.venv/lib/python3.12/site-packages/urllib3/util/retry.py", line 474, in increment
    raise reraise(type(error), error, _stacktrace)
          ^^^^^^^^^^^^^^^^^^^^^^^^^^^^^^^^^^^^^^^^

      File "/home/stguser/devstack/python-tempestconf/.venv/lib/python3.12/site-packages/urllib3/util/util.py", line 39, in reraise
    raise value

      File "/home/stguser/devstack/python-tempestconf/.venv/lib/python3.12/site-packages/urllib3/connectionpool.py", line 787, in urlopen
    response = self._make_request(
               ^^^^^^^^^^^^^^^^^^^

      File "/home/stguser/devstack/python-tempestconf/.venv/lib/python3.12/site-packages/urllib3/connectionpool.py", line 536, in _make_request
    self._raise_timeout(err=e, url=url, timeout_value=read_timeout)

      File "/home/stguser/devstack/python-tempestconf/.venv/lib/python3.12/site-packages/urllib3/connectionpool.py", line 367, in _raise_timeout
    raise ReadTimeoutError(

    urllib3.exceptions.ReadTimeoutError: HTTPConnectionPool(host='9.180.170.14', port=9696): Read timed out. (read timeout=60)



======
Totals
======
Ran: 165 tests in 288.2701 sec.
 - Passed: 154
 - Skipped: 6
 - Expected Fail: 0
 - Unexpected Success: 0
 - Failed: 5
Sum of execute time for each test: 2864.7586 sec.

==============
Worker Balance
==============
 - Worker 0 (3 tests) => 0:03:59.753922
 - Worker 1 (2 tests) => 0:03:17.337382
 - Worker 2 (2 tests) => 0:03:14.236612
 - Worker 3 (3 tests) => 0:03:23.255885
 - Worker 4 (8 tests) => 0:04:09.158005
 - Worker 5 (3 tests) => 0:03:10.485607
 - Worker 6 (2 tests) => 0:02:54.867275
 - Worker 7 (1 tests) => 0:00:00
 - Worker 8 (1 tests) => 0:02:23.896526
 - Worker 9 (6 tests) => 0:01:32.860411
 - Worker 10 (2 tests) => 0:02:11.862836
 - Worker 11 (27 tests) => 0:02:26.622131
 - Worker 12 (5 tests) => 0:02:10.214041
 - Worker 13 (1 tests) => 0:00:00
 - Worker 14 (1 tests) => 0:00:00
 - Worker 15 (2 tests) => 0:02:17.441416
 - Worker 16 (1 tests) => 0:00:00
 - Worker 17 (4 tests) => 0:02:18.994611
 - Worker 18 (7 tests) => 0:01:57.542652
 - Worker 19 (2 tests) => 0:01:41.601819
 - Worker 20 (1 tests) => 0:00:19.925915
 - Worker 21 (6 tests) => 0:01:02.337646
 - Worker 22 (3 tests) => 0:00:59.615797
 - Worker 23 (2 tests) => 0:00:42.907978
 - Worker 24 (12 tests) => 0:00:34.331379
 - Worker 25 (5 tests) => 0:00:35.518802
 - Worker 26 (2 tests) => 0:00:14.298018
 - Worker 27 (5 tests) => 0:00:17.436343
 - Worker 28 (2 tests) => 0:00:14.128328
 - Worker 29 (2 tests) => 0:00:10.153155
 - Worker 30 (1 tests) => 0:00:00
 - Worker 31 (2 tests) => 0:00:30.808620
 - Worker 32 (1 tests) => 0:00:05.042668
 - Worker 33 (1 tests) => 0:00:01.937887
 - Worker 34 (18 tests) => 0:00:04.335561
 - Worker 35 (1 tests) => 0:00:05.878205
 - Worker 36 (2 tests) => 0:00:09.451451
 - Worker 37 (2 tests) => 0:00:42.724817
 - Worker 38 (13 tests) => 0:00:01.244165
 - Worker 39 (1 tests) => 0:00:01.925974
