{2} setUpClass (tempest.api.volume.admin.test_encrypted_volumes_extend.EncryptedVolumesExtendAttachedTest) ... SKIPPED: Attached encrypted volume extend is disabled.
{5} setUpClass (tempest.api.volume.admin.test_volume_retype.VolumeRetypeWithMigrationTest) ... SKIPPED: Cinder multi-backend feature disabled
{3} setUpClass (tempest.api.volume.test_volumes_backup.VolumesBackupsTest) ... SKIPPED: Cinder backup feature disabled
{0} setUpClass (tempest.api.volume.admin.test_volumes_backup.VolumesBackupsAdminTest) ... SKIPPED: Cinder backup feature disabled
{1} setUpClass (tempest.api.volume.admin.test_multi_backend.VolumeMultiBackendTest) ... SKIPPED: Cinder multi-backend feature disabled
{31} tempest.api.volume.test_versions.VersionsTest.test_list_versions [0.035973s] ... ok
{31} tempest.api.volume.test_versions.VersionsTest.test_show_version [15.697709s] ... ok
{33} tempest.api.volume.test_extensions.ExtensionsTestJSON.test_list_extensions [16.718504s] ... ok
{34} tempest.api.volume.test_volumes_get.VolumesSummaryTest.test_show_volume_summary [21.942126s] ... ok
{35} tempest.api.volume.test_availability_zone.AvailabilityZoneTestJSON.test_get_availability_zone_list [18.880540s] ... ok
{32} tempest.api.volume.test_volumes_snapshots_negative.VolumesSnapshotNegativeTestJSON.test_create_snapshot_with_nonexistent_volume_id [17.870115s] ... ok
{32} tempest.api.volume.test_volumes_snapshots_negative.VolumesSnapshotNegativeTestJSON.test_create_snapshot_without_passing_volume_id [2.137857s] ... ok
{32} tempest.api.volume.test_volumes_snapshots_negative.VolumesSnapshotNegativeTestJSON.test_list_snapshot_invalid_param_limit [0.084755s] ... ok
{32} tempest.api.volume.test_volumes_snapshots_negative.VolumesSnapshotNegativeTestJSON.test_list_snapshots_invalid_param_marker [0.290616s] ... ok
{32} tempest.api.volume.test_volumes_snapshots_negative.VolumesSnapshotNegativeTestJSON.test_list_snapshots_invalid_param_sort [0.043270s] ... ok
{18} tempest.api.volume.admin.test_volume_types_extra_specs_negative.ExtraSpecsNegativeTest.test_create_invalid_body [0.019491s] ... ok
{18} tempest.api.volume.admin.test_volume_types_extra_specs_negative.ExtraSpecsNegativeTest.test_create_none_body [0.017173s] ... ok
{14} tempest.api.volume.admin.test_volume_quota_classes.VolumeQuotaClassesTest.test_show_default_quota [4.398522s] ... ok
{18} tempest.api.volume.admin.test_volume_types_extra_specs_negative.ExtraSpecsNegativeTest.test_create_nonexistent_type_id [7.928544s] ... ok
{16} tempest.api.volume.admin.test_volume_types_negative.VolumeTypesNegativeTest.test_create_volume_type_encryption_nonexistent_type_id [8.051644s] ... ok
{21} tempest.api.volume.admin.test_volume_hosts.VolumeHostsAdminTestsJSON.test_list_hosts [4.343778s] ... ok
{18} tempest.api.volume.admin.test_volume_types_extra_specs_negative.ExtraSpecsNegativeTest.test_delete_nonexistent_volume_type_id [3.697622s] ... ok
{28} tempest.api.volume.admin.test_volume_pools.VolumePoolsAdminTestsJSON.test_get_pools_with_details [4.857266s] ... ok
{24} tempest.api.volume.admin.test_volume_services_negative.VolumeServicesNegativeTest.test_disable_log_reason_with_no_reason [3.165194s] ... ok
{12} tempest.api.volume.admin.test_volume_services.VolumesServicesTestJSON.test_get_service_by_host_name [3.174484s] ... ok
{26} tempest.api.volume.admin.test_backends_capabilities.BackendsCapabilitiesAdminTestsJSON.test_compare_volume_stats_values [9.453371s] ... ok
{18} tempest.api.volume.admin.test_volume_types_extra_specs_negative.ExtraSpecsNegativeTest.test_get_nonexistent_extra_spec_name [3.901243s] ... ok
{28} tempest.api.volume.admin.test_volume_pools.VolumePoolsAdminTestsJSON.test_get_pools_without_details [4.410650s] ... ok
{24} tempest.api.volume.admin.test_volume_services_negative.VolumeServicesNegativeTest.test_disable_service_with_invalid_binary [6.655387s] ... ok
{12} tempest.api.volume.admin.test_volume_services.VolumesServicesTestJSON.test_get_service_by_service_and_host_name [6.671322s] ... ok
{26} tempest.api.volume.admin.test_backends_capabilities.BackendsCapabilitiesAdminTestsJSON.test_get_capabilities_backend [10.703733s] ... ok
{18} tempest.api.volume.admin.test_volume_types_extra_specs_negative.ExtraSpecsNegativeTest.test_get_nonexistent_volume_type_id [15.008775s] ... ok
{24} tempest.api.volume.admin.test_volume_services_negative.VolumeServicesNegativeTest.test_enable_service_with_invalid_host [11.507760s] ... ok
{12} tempest.api.volume.admin.test_volume_services.VolumesServicesTestJSON.test_get_service_by_service_binary_name [11.485382s] ... ok
{18} tempest.api.volume.admin.test_volume_types_extra_specs_negative.ExtraSpecsNegativeTest.test_list_nonexistent_volume_type_id [0.840882s] ... ok
{24} tempest.api.volume.admin.test_volume_services_negative.VolumeServicesNegativeTest.test_freeze_host_with_invalid_host [1.195819s] ... ok
{18} tempest.api.volume.admin.test_volume_types_extra_specs_negative.ExtraSpecsNegativeTest.test_update_multiple_extra_spec [1.945392s] ... ok
{24} tempest.api.volume.admin.test_volume_services_negative.VolumeServicesNegativeTest.test_thaw_host_with_invalid_host [2.507927s] ... ok
{17} tempest.api.volume.admin.test_volume_types_extra_specs.VolumeTypesExtraSpecsTest.test_volume_type_extra_spec_create_get_delete [34.558614s] ... ok
{18} tempest.api.volume.admin.test_volume_types_extra_specs_negative.ExtraSpecsNegativeTest.test_update_no_body [1.304873s] ... ok
{18} tempest.api.volume.admin.test_volume_types_extra_specs_negative.ExtraSpecsNegativeTest.test_update_none_extra_spec_id [3.443688s] ... ok
{7} tempest.api.volume.admin.test_volume_types.VolumeTypesTest.test_volume_type_create_get_delete [36.121360s] ... ok
{18} tempest.api.volume.admin.test_volume_types_extra_specs_negative.ExtraSpecsNegativeTest.test_update_nonexistent_extra_spec_id [1.370351s] ... ok
{21} tempest.api.volume.admin.test_volume_hosts.VolumeHostsAdminTestsJSON.test_show_host [29.487831s] ... ok
{16} tempest.api.volume.admin.test_volume_types_negative.VolumeTypesNegativeTest.test_create_volume_with_private_volume_type [32.781729s] ... ok
{18} tempest.api.volume.admin.test_volume_types_extra_specs_negative.ExtraSpecsNegativeTest.test_update_nonexistent_type_id [1.310657s] ... ok
{16} tempest.api.volume.admin.test_volume_types_negative.VolumeTypesNegativeTest.test_create_with_empty_name [0.511202s] ... ok
{17} tempest.api.volume.admin.test_volume_types_extra_specs.VolumeTypesExtraSpecsTest.test_volume_type_extra_specs_list [7.468584s] ... ok
{16} tempest.api.volume.admin.test_volume_types_negative.VolumeTypesNegativeTest.test_create_with_repeated_name [15.600080s] ... ok
{19} tempest.api.volume.test_volume_metadata.VolumesMetadataTest.test_crud_volume_metadata [35.825503s] ... ok
{16} tempest.api.volume.admin.test_volume_types_negative.VolumeTypesNegativeTest.test_delete_nonexistent_type_id [15.337102s] ... ok
{6} tempest.api.volume.test_volume_transfers.VolumesTransfersTest.test_create_get_list_accept_volume_transfer [60.073951s] ... FAILED

Captured traceback:
~~~~~~~~~~~~~~~~~~~
    Traceback (most recent call last):

      File "/home/stguser/devstack/python-tempestconf/.venv/lib/python3.12/site-packages/urllib3/connectionpool.py", line 534, in _make_request
    response = conn.getresponse()
               ^^^^^^^^^^^^^^^^^^

      File "/home/stguser/devstack/python-tempestconf/.venv/lib/python3.12/site-packages/urllib3/connection.py", line 565, in getresponse
    httplib_response = super().getresponse()
                       ^^^^^^^^^^^^^^^^^^^^^

      File "/usr/lib/python3.12/http/client.py", line 1428, in getresponse
    response.begin()

      File "/usr/lib/python3.12/http/client.py", line 331, in begin
    version, status, reason = self._read_status()
                              ^^^^^^^^^^^^^^^^^^^

      File "/usr/lib/python3.12/http/client.py", line 292, in _read_status
    line = str(self.fp.readline(_MAXLINE + 1), "iso-8859-1")
               ^^^^^^^^^^^^^^^^^^^^^^^^^^^^^^

      File "/usr/lib/python3.12/socket.py", line 707, in readinto
    return self._sock.recv_into(b)
           ^^^^^^^^^^^^^^^^^^^^^^^

    TimeoutError: timed out

    
The above exception was the direct cause of the following exception:


    Traceback (most recent call last):

      File "/home/stguser/devstack/python-tempestconf/.venv/lib/python3.12/site-packages/tempest/api/volume/test_volume_transfers.py", line 40, in test_create_get_list_accept_volume_transfer
    volume = self.create_volume()
             ^^^^^^^^^^^^^^^^^^^^

      File "/home/stguser/devstack/python-tempestconf/.venv/lib/python3.12/site-packages/tempest/api/volume/base.py", line 139, in create_volume
    volume = self.volumes_client.create_volume(**kwargs)['volume']
             ^^^^^^^^^^^^^^^^^^^^^^^^^^^^^^^^^^^^^^^^^^^

      File "/home/stguser/devstack/python-tempestconf/.venv/lib/python3.12/site-packages/tempest/lib/services/volume/v3/volumes_client.py", line 116, in create_volume
    resp, body = self.post('volumes', post_body)
                 ^^^^^^^^^^^^^^^^^^^^^^^^^^^^^^^

      File "/home/stguser/devstack/python-tempestconf/.venv/lib/python3.12/site-packages/tempest/lib/common/rest_client.py", line 314, in post
    resp_header, resp_body = self.request(
                             ^^^^^^^^^^^^^

      File "/home/stguser/devstack/python-tempestconf/.venv/lib/python3.12/site-packages/tempest/lib/services/volume/base_client.py", line 39, in request
    resp, resp_body = super(BaseClient, self).request(
                      ^^^^^^^^^^^^^^^^^^^^^^^^^^^^^^^^

      File "/home/stguser/devstack/python-tempestconf/.venv/lib/python3.12/site-packages/tempest/lib/common/rest_client.py", line 746, in request
    resp, resp_body = self._request(method, url, headers=headers,
                      ^^^^^^^^^^^^^^^^^^^^^^^^^^^^^^^^^^^^^^^^^^^

      File "/home/stguser/devstack/python-tempestconf/.venv/lib/python3.12/site-packages/tempest/lib/common/rest_client.py", line 612, in _request
    resp, resp_body = self.raw_request(
                      ^^^^^^^^^^^^^^^^^

      File "/home/stguser/devstack/python-tempestconf/.venv/lib/python3.12/site-packages/tempest/lib/common/rest_client.py", line 661, in raw_request
    resp, resp_body = self.http_obj.request(
                      ^^^^^^^^^^^^^^^^^^^^^^

      File "/home/stguser/devstack/python-tempestconf/.venv/lib/python3.12/site-packages/tempest/lib/common/http.py", line 123, in request
    r = super(ClosingHttp, self).request(method, url, retries=retry,
        ^^^^^^^^^^^^^^^^^^^^^^^^^^^^^^^^^^^^^^^^^^^^^^^^^^^^^^^^^^^^

      File "/home/stguser/devstack/python-tempestconf/.venv/lib/python3.12/site-packages/urllib3/_request_methods.py", line 143, in request
    return self.request_encode_body(
           ^^^^^^^^^^^^^^^^^^^^^^^^^

      File "/home/stguser/devstack/python-tempestconf/.venv/lib/python3.12/site-packages/urllib3/_request_methods.py", line 278, in request_encode_body
    return self.urlopen(method, url, **extra_kw)
           ^^^^^^^^^^^^^^^^^^^^^^^^^^^^^^^^^^^^^

      File "/home/stguser/devstack/python-tempestconf/.venv/lib/python3.12/site-packages/urllib3/poolmanager.py", line 459, in urlopen
    response = conn.urlopen(method, u.request_uri, **kw)
               ^^^^^^^^^^^^^^^^^^^^^^^^^^^^^^^^^^^^^^^^^

      File "/home/stguser/devstack/python-tempestconf/.venv/lib/python3.12/site-packages/urllib3/connectionpool.py", line 841, in urlopen
    retries = retries.increment(
              ^^^^^^^^^^^^^^^^^^

      File "/home/stguser/devstack/python-tempestconf/.venv/lib/python3.12/site-packages/urllib3/util/retry.py", line 474, in increment
    raise reraise(type(error), error, _stacktrace)
          ^^^^^^^^^^^^^^^^^^^^^^^^^^^^^^^^^^^^^^^^

      File "/home/stguser/devstack/python-tempestconf/.venv/lib/python3.12/site-packages/urllib3/util/util.py", line 39, in reraise
    raise value

      File "/home/stguser/devstack/python-tempestconf/.venv/lib/python3.12/site-packages/urllib3/connectionpool.py", line 787, in urlopen
    response = self._make_request(
               ^^^^^^^^^^^^^^^^^^^

      File "/home/stguser/devstack/python-tempestconf/.venv/lib/python3.12/site-packages/urllib3/connectionpool.py", line 536, in _make_request
    self._raise_timeout(err=e, url=url, timeout_value=read_timeout)

      File "/home/stguser/devstack/python-tempestconf/.venv/lib/python3.12/site-packages/urllib3/connectionpool.py", line 367, in _raise_timeout
    raise ReadTimeoutError(

    urllib3.exceptions.ReadTimeoutError: HTTPConnectionPool(host='9.180.170.14', port=80): Read timed out. (read timeout=60)

{16} tempest.api.volume.admin.test_volume_types_negative.VolumeTypesNegativeTest.test_get_nonexistent_type_id [11.541015s] ... ok
{20} setUpClass (tempest.api.volume.test_volumes_actions.VolumesActionsTest) [0.000000s] ... FAILED

Captured traceback:
~~~~~~~~~~~~~~~~~~~
    Traceback (most recent call last):

      File "/home/stguser/devstack/python-tempestconf/.venv/lib/python3.12/site-packages/urllib3/connectionpool.py", line 534, in _make_request
    response = conn.getresponse()
               ^^^^^^^^^^^^^^^^^^

      File "/home/stguser/devstack/python-tempestconf/.venv/lib/python3.12/site-packages/urllib3/connection.py", line 565, in getresponse
    httplib_response = super().getresponse()
                       ^^^^^^^^^^^^^^^^^^^^^

      File "/usr/lib/python3.12/http/client.py", line 1428, in getresponse
    response.begin()

      File "/usr/lib/python3.12/http/client.py", line 331, in begin
    version, status, reason = self._read_status()
                              ^^^^^^^^^^^^^^^^^^^

      File "/usr/lib/python3.12/http/client.py", line 292, in _read_status
    line = str(self.fp.readline(_MAXLINE + 1), "iso-8859-1")
               ^^^^^^^^^^^^^^^^^^^^^^^^^^^^^^

      File "/usr/lib/python3.12/socket.py", line 707, in readinto
    return self._sock.recv_into(b)
           ^^^^^^^^^^^^^^^^^^^^^^^

    TimeoutError: timed out

    
The above exception was the direct cause of the following exception:


    Traceback (most recent call last):

      File "/home/stguser/devstack/python-tempestconf/.venv/lib/python3.12/site-packages/tempest/test.py", line 185, in setUpClass
    raise value.with_traceback(trace)

      File "/home/stguser/devstack/python-tempestconf/.venv/lib/python3.12/site-packages/tempest/test.py", line 170, in setUpClass
    cls.setup_credentials()

      File "/home/stguser/devstack/python-tempestconf/.venv/lib/python3.12/site-packages/tempest/api/volume/base.py", line 62, in setup_credentials
    super(BaseVolumeTest, cls).setup_credentials()

      File "/home/stguser/devstack/python-tempestconf/.venv/lib/python3.12/site-packages/tempest/test.py", line 398, in setup_credentials
    manager = cls.get_client_manager(
              ^^^^^^^^^^^^^^^^^^^^^^^

      File "/home/stguser/devstack/python-tempestconf/.venv/lib/python3.12/site-packages/tempest/test.py", line 743, in get_client_manager
    creds = getattr(cred_provider, credentials_method)()
            ^^^^^^^^^^^^^^^^^^^^^^^^^^^^^^^^^^^^^^^^^^^^

      File "/home/stguser/devstack/python-tempestconf/.venv/lib/python3.12/site-packages/tempest/lib/common/dynamic_creds.py", line 473, in get_primary_creds
    return self.get_project_member_creds()
           ^^^^^^^^^^^^^^^^^^^^^^^^^^^^^^^

      File "/home/stguser/devstack/python-tempestconf/.venv/lib/python3.12/site-packages/tempest/lib/common/dynamic_creds.py", line 514, in get_project_member_creds
    return self.get_credentials(['member'], scope='project')
           ^^^^^^^^^^^^^^^^^^^^^^^^^^^^^^^^^^^^^^^^^^^^^^^^^

      File "/home/stguser/devstack/python-tempestconf/.venv/lib/python3.12/site-packages/tempest/lib/common/dynamic_creds.py", line 459, in get_credentials
    network, subnet, router = self._create_network_resources(
                              ^^^^^^^^^^^^^^^^^^^^^^^^^^^^^^^

      File "/home/stguser/devstack/python-tempestconf/.venv/lib/python3.12/site-packages/tempest/lib/common/dynamic_creds.py", line 310, in _create_network_resources
    network = self._create_network(network_name, tenant_id)
              ^^^^^^^^^^^^^^^^^^^^^^^^^^^^^^^^^^^^^^^^^^^^^

      File "/home/stguser/devstack/python-tempestconf/.venv/lib/python3.12/site-packages/tempest/lib/common/dynamic_creds.py", line 338, in _create_network
    resp_body = self.networks_admin_client.create_network(
                ^^^^^^^^^^^^^^^^^^^^^^^^^^^^^^^^^^^^^^^^^^

      File "/home/stguser/devstack/python-tempestconf/.venv/lib/python3.12/site-packages/tempest/lib/services/network/networks_client.py", line 27, in create_network
    return self.create_resource(uri, post_data)
           ^^^^^^^^^^^^^^^^^^^^^^^^^^^^^^^^^^^^

      File "/home/stguser/devstack/python-tempestconf/.venv/lib/python3.12/site-packages/tempest/lib/services/network/base.py", line 62, in create_resource
    resp, body = self.post(req_uri, req_post_data)
                 ^^^^^^^^^^^^^^^^^^^^^^^^^^^^^^^^^

      File "/home/stguser/devstack/python-tempestconf/.venv/lib/python3.12/site-packages/tempest/lib/common/rest_client.py", line 314, in post
    resp_header, resp_body = self.request(
                             ^^^^^^^^^^^^^

      File "/home/stguser/devstack/python-tempestconf/.venv/lib/python3.12/site-packages/tempest/lib/common/rest_client.py", line 746, in request
    resp, resp_body = self._request(method, url, headers=headers,
                      ^^^^^^^^^^^^^^^^^^^^^^^^^^^^^^^^^^^^^^^^^^^

      File "/home/stguser/devstack/python-tempestconf/.venv/lib/python3.12/site-packages/tempest/lib/common/rest_client.py", line 612, in _request
    resp, resp_body = self.raw_request(
                      ^^^^^^^^^^^^^^^^^

      File "/home/stguser/devstack/python-tempestconf/.venv/lib/python3.12/site-packages/tempest/lib/common/rest_client.py", line 661, in raw_request
    resp, resp_body = self.http_obj.request(
                      ^^^^^^^^^^^^^^^^^^^^^^

      File "/home/stguser/devstack/python-tempestconf/.venv/lib/python3.12/site-packages/tempest/lib/common/http.py", line 123, in request
    r = super(ClosingHttp, self).request(method, url, retries=retry,
        ^^^^^^^^^^^^^^^^^^^^^^^^^^^^^^^^^^^^^^^^^^^^^^^^^^^^^^^^^^^^

      File "/home/stguser/devstack/python-tempestconf/.venv/lib/python3.12/site-packages/urllib3/_request_methods.py", line 143, in request
    return self.request_encode_body(
           ^^^^^^^^^^^^^^^^^^^^^^^^^

      File "/home/stguser/devstack/python-tempestconf/.venv/lib/python3.12/site-packages/urllib3/_request_methods.py", line 278, in request_encode_body
    return self.urlopen(method, url, **extra_kw)
           ^^^^^^^^^^^^^^^^^^^^^^^^^^^^^^^^^^^^^

      File "/home/stguser/devstack/python-tempestconf/.venv/lib/python3.12/site-packages/urllib3/poolmanager.py", line 459, in urlopen
    response = conn.urlopen(method, u.request_uri, **kw)
               ^^^^^^^^^^^^^^^^^^^^^^^^^^^^^^^^^^^^^^^^^

      File "/home/stguser/devstack/python-tempestconf/.venv/lib/python3.12/site-packages/urllib3/connectionpool.py", line 841, in urlopen
    retries = retries.increment(
              ^^^^^^^^^^^^^^^^^^

      File "/home/stguser/devstack/python-tempestconf/.venv/lib/python3.12/site-packages/urllib3/util/retry.py", line 474, in increment
    raise reraise(type(error), error, _stacktrace)
          ^^^^^^^^^^^^^^^^^^^^^^^^^^^^^^^^^^^^^^^^

      File "/home/stguser/devstack/python-tempestconf/.venv/lib/python3.12/site-packages/urllib3/util/util.py", line 39, in reraise
    raise value

      File "/home/stguser/devstack/python-tempestconf/.venv/lib/python3.12/site-packages/urllib3/connectionpool.py", line 787, in urlopen
    response = self._make_request(
               ^^^^^^^^^^^^^^^^^^^

      File "/home/stguser/devstack/python-tempestconf/.venv/lib/python3.12/site-packages/urllib3/connectionpool.py", line 536, in _make_request
    self._raise_timeout(err=e, url=url, timeout_value=read_timeout)

      File "/home/stguser/devstack/python-tempestconf/.venv/lib/python3.12/site-packages/urllib3/connectionpool.py", line 367, in _raise_timeout
    raise ReadTimeoutError(

    urllib3.exceptions.ReadTimeoutError: HTTPConnectionPool(host='9.180.170.14', port=9696): Read timed out. (read timeout=60)

{37} tempest.api.volume.test_volume_absolute_limits.AbsoluteLimitsTests.test_get_volume_absolute_limits [6.585303s] ... ok
{10} tempest.api.volume.test_volumes_clone_negative.VolumesCloneNegativeTest.test_create_from_volume_decreasing_size [129.255338s] ... ok
{17} tempest.api.volume.admin.test_volume_types_extra_specs.VolumeTypesExtraSpecsTest.test_volume_type_extra_specs_update [50.993492s] ... ok
{14} tempest.api.volume.admin.test_volume_quota_classes.VolumeQuotaClassesTest.test_update_default_quota [95.207659s] ... ok
{27} tempest.api.volume.admin.test_volume_quotas_negative.VolumeQuotasNegativeTestJSON.test_quota_volume_gigabytes [26.134948s] ... ok
{9} tempest.api.volume.admin.test_user_messages.UserMessagesTest.test_delete_message [114.676612s] ... ok
{19} tempest.api.volume.test_volume_metadata.VolumesMetadataTest.test_update_show_volume_metadata_item [39.507941s] ... ok
{27} tempest.api.volume.admin.test_volume_quotas_negative.VolumeQuotasNegativeTestJSON.test_quota_volumes [13.637517s] ... ok
{7} tempest.api.volume.admin.test_volume_types.VolumeTypesTest.test_volume_type_encryption_create_get_update_delete [74.952913s] ... ok
{23} setUpClass (tempest.api.volume.admin.test_volumes_actions.VolumesActionsTest) [0.000000s] ... FAILED

Captured traceback:
~~~~~~~~~~~~~~~~~~~
    Traceback (most recent call last):

      File "/home/stguser/devstack/python-tempestconf/.venv/lib/python3.12/site-packages/tempest/test.py", line 185, in setUpClass
    raise value.with_traceback(trace)

      File "/home/stguser/devstack/python-tempestconf/.venv/lib/python3.12/site-packages/tempest/test.py", line 170, in setUpClass
    cls.setup_credentials()

      File "/home/stguser/devstack/python-tempestconf/.venv/lib/python3.12/site-packages/tempest/api/volume/base.py", line 62, in setup_credentials
    super(BaseVolumeTest, cls).setup_credentials()

      File "/home/stguser/devstack/python-tempestconf/.venv/lib/python3.12/site-packages/tempest/test.py", line 398, in setup_credentials
    manager = cls.get_client_manager(
              ^^^^^^^^^^^^^^^^^^^^^^^

      File "/home/stguser/devstack/python-tempestconf/.venv/lib/python3.12/site-packages/tempest/test.py", line 743, in get_client_manager
    creds = getattr(cred_provider, credentials_method)()
            ^^^^^^^^^^^^^^^^^^^^^^^^^^^^^^^^^^^^^^^^^^^^

      File "/home/stguser/devstack/python-tempestconf/.venv/lib/python3.12/site-packages/tempest/lib/common/dynamic_creds.py", line 473, in get_primary_creds
    return self.get_project_member_creds()
           ^^^^^^^^^^^^^^^^^^^^^^^^^^^^^^^

      File "/home/stguser/devstack/python-tempestconf/.venv/lib/python3.12/site-packages/tempest/lib/common/dynamic_creds.py", line 514, in get_project_member_creds
    return self.get_credentials(['member'], scope='project')
           ^^^^^^^^^^^^^^^^^^^^^^^^^^^^^^^^^^^^^^^^^^^^^^^^^

      File "/home/stguser/devstack/python-tempestconf/.venv/lib/python3.12/site-packages/tempest/lib/common/dynamic_creds.py", line 459, in get_credentials
    network, subnet, router = self._create_network_resources(
                              ^^^^^^^^^^^^^^^^^^^^^^^^^^^^^^^

      File "/home/stguser/devstack/python-tempestconf/.venv/lib/python3.12/site-packages/tempest/lib/common/dynamic_creds.py", line 318, in _create_network_resources
    router = self._create_router(router_name, tenant_id)
             ^^^^^^^^^^^^^^^^^^^^^^^^^^^^^^^^^^^^^^^^^^^

      File "/home/stguser/devstack/python-tempestconf/.venv/lib/python3.12/site-packages/tempest/lib/common/dynamic_creds.py", line 379, in _create_router
    resp_body = self.routers_admin_client.create_router(**kwargs)
                ^^^^^^^^^^^^^^^^^^^^^^^^^^^^^^^^^^^^^^^^^^^^^^^^^

      File "/home/stguser/devstack/python-tempestconf/.venv/lib/python3.12/site-packages/tempest/lib/services/network/routers_client.py", line 27, in create_router
    return self.create_resource(uri, post_body)
           ^^^^^^^^^^^^^^^^^^^^^^^^^^^^^^^^^^^^

      File "/home/stguser/devstack/python-tempestconf/.venv/lib/python3.12/site-packages/tempest/lib/services/network/base.py", line 62, in create_resource
    resp, body = self.post(req_uri, req_post_data)
                 ^^^^^^^^^^^^^^^^^^^^^^^^^^^^^^^^^

      File "/home/stguser/devstack/python-tempestconf/.venv/lib/python3.12/site-packages/tempest/lib/common/rest_client.py", line 314, in post
    resp_header, resp_body = self.request(
                             ^^^^^^^^^^^^^

      File "/home/stguser/devstack/python-tempestconf/.venv/lib/python3.12/site-packages/tempest/lib/common/rest_client.py", line 762, in request
    self._error_checker(resp, resp_body)

      File "/home/stguser/devstack/python-tempestconf/.venv/lib/python3.12/site-packages/tempest/lib/common/rest_client.py", line 892, in _error_checker
    raise exceptions.Conflict(resp_body, resp=resp)

    tempest.lib.exceptions.Conflict: Conflict with state of target resource
Details: {'type': 'IpAddressGenerationFailure', 'message': 'No more IP addresses available on network 0cdb1fc2-5ef2-42d1-9505-33350276d87e.', 'detail': ''}

{7} tempest.api.volume.admin.test_volume_types.VolumeTypesTest.test_volume_type_list [0.826824s] ... ok
{22} setUpClass (tempest.api.volume.admin.test_volume_retype.VolumeRetypeWithoutMigrationTest) [0.000000s] ... FAILED

Captured traceback:
~~~~~~~~~~~~~~~~~~~
    Traceback (most recent call last):

      File "/home/stguser/devstack/python-tempestconf/.venv/lib/python3.12/site-packages/tempest/test.py", line 185, in setUpClass
    raise value.with_traceback(trace)

      File "/home/stguser/devstack/python-tempestconf/.venv/lib/python3.12/site-packages/tempest/test.py", line 178, in setUpClass
    cls.resource_setup()

      File "/home/stguser/devstack/python-tempestconf/.venv/lib/python3.12/site-packages/tempest/api/volume/admin/test_volume_retype.py", line 172, in resource_setup
    cls.src_vol_type = cls.create_volume_type('volume-type-1')
                       ^^^^^^^^^^^^^^^^^^^^^^^^^^^^^^^^^^^^^^^

      File "/home/stguser/devstack/python-tempestconf/.venv/lib/python3.12/site-packages/tempest/api/volume/base.py", line 366, in create_volume_type
    volume_type = self.admin_volume_types_client.create_volume_type(
                  ^^^^^^^^^^^^^^^^^^^^^^^^^^^^^^^^^^^^^^^^^^^^^^^^^^

      File "/home/stguser/devstack/python-tempestconf/.venv/lib/python3.12/site-packages/tempest/lib/services/volume/v3/types_client.py", line 90, in create_volume_type
    resp, body = self.post('types', post_body)
                 ^^^^^^^^^^^^^^^^^^^^^^^^^^^^^

      File "/home/stguser/devstack/python-tempestconf/.venv/lib/python3.12/site-packages/tempest/lib/common/rest_client.py", line 314, in post
    resp_header, resp_body = self.request(
                             ^^^^^^^^^^^^^

      File "/home/stguser/devstack/python-tempestconf/.venv/lib/python3.12/site-packages/tempest/lib/common/rest_client.py", line 762, in request
    self._error_checker(resp, resp_body)

      File "/home/stguser/devstack/python-tempestconf/.venv/lib/python3.12/site-packages/tempest/lib/common/rest_client.py", line 892, in _error_checker
    raise exceptions.Conflict(resp_body, resp=resp)

    tempest.lib.exceptions.Conflict: Conflict with state of target resource
Details: {'code': 409, 'message': 'Volume Type volume-type-1 already exists.'}

{30} tempest.api.volume.test_snapshot_metadata.SnapshotMetadataTestJSON.test_crud_snapshot_metadata [8.848074s] ... ok
{2} tempest.api.volume.admin.test_volume_quotas.VolumeQuotasAdminTestJSON.test_delete_quota [108.119673s] ... ok
{2} tempest.api.volume.admin.test_volume_quotas.VolumeQuotasAdminTestJSON.test_list_default_quotas [0.487132s] ... ok
{15} tempest.api.volume.admin.test_snapshots_actions.SnapshotsActionsTest.test_reset_snapshot_status [1.719741s] ... ok
{30} tempest.api.volume.test_snapshot_metadata.SnapshotMetadataTestJSON.test_update_show_snapshot_metadata_item [3.058269s] ... ok
{2} tempest.api.volume.admin.test_volume_quotas.VolumeQuotasAdminTestJSON.test_list_quotas [0.536514s] ... ok
{13} tempest.api.volume.admin.test_qos.QosSpecsTestJSON.test_associate_disassociate_qos [91.621138s] ... ok
{9} tempest.api.volume.admin.test_user_messages.UserMessagesTest.test_list_show_messages [19.111310s] ... ok
{13} tempest.api.volume.admin.test_qos.QosSpecsTestJSON.test_create_delete_qos_with_back_end_consumer [9.801229s] ... ok
{38} tempest.api.volume.test_volumes_list.VolumesListTestJSON.test_volume_list [1.495208s] ... ok
{38} tempest.api.volume.test_volumes_list.VolumesListTestJSON.test_volume_list_by_name [0.091133s] ... ok
{38} tempest.api.volume.test_volumes_list.VolumesListTestJSON.test_volume_list_details_by_name [0.198897s] ... ok
{38} tempest.api.volume.test_volumes_list.VolumesListTestJSON.test_volume_list_details_pagination [1.356403s] ... ok
{13} tempest.api.volume.admin.test_qos.QosSpecsTestJSON.test_create_delete_qos_with_both_consumer [3.344110s] ... ok
{38} tempest.api.volume.test_volumes_list.VolumesListTestJSON.test_volume_list_details_with_multiple_params [0.487220s] ... ok
{38} tempest.api.volume.test_volumes_list.VolumesListTestJSON.test_volume_list_pagination [0.477296s] ... ok
{36} tempest.api.volume.admin.test_volume_snapshot_quotas_negative.VolumeSnapshotQuotasNegativeTestJSON.test_quota_volume_gigabytes_snapshots [6.494774s] ... ok
{38} tempest.api.volume.test_volumes_list.VolumesListTestJSON.test_volume_list_param_display_name_and_status [0.175710s] ... ok
{38} tempest.api.volume.test_volumes_list.VolumesListTestJSON.test_volume_list_with_detail_param_display_name_and_status [0.172554s] ... ok
{38} tempest.api.volume.test_volumes_list.VolumesListTestJSON.test_volume_list_with_detail_param_marker [0.091459s] ... ok
{36} tempest.api.volume.admin.test_volume_snapshot_quotas_negative.VolumeSnapshotQuotasNegativeTestJSON.test_quota_volume_snapshots [0.468794s] ... ok
{38} tempest.api.volume.test_volumes_list.VolumesListTestJSON.test_volume_list_with_detail_param_metadata [0.322910s] ... ok
{38} tempest.api.volume.test_volumes_list.VolumesListTestJSON.test_volume_list_with_details [0.125914s] ... ok
{38} tempest.api.volume.test_volumes_list.VolumesListTestJSON.test_volume_list_with_param_metadata [0.078248s] ... ok
{25} setUpClass (tempest.api.volume.test_volumes_snapshots.VolumesSnapshotTestJSON) [0.000000s] ... FAILED

Captured traceback:
~~~~~~~~~~~~~~~~~~~
    Traceback (most recent call last):

      File "/home/stguser/devstack/python-tempestconf/.venv/lib/python3.12/site-packages/tempest/test.py", line 185, in setUpClass
    raise value.with_traceback(trace)

      File "/home/stguser/devstack/python-tempestconf/.venv/lib/python3.12/site-packages/tempest/test.py", line 170, in setUpClass
    cls.setup_credentials()

      File "/home/stguser/devstack/python-tempestconf/.venv/lib/python3.12/site-packages/tempest/api/volume/base.py", line 62, in setup_credentials
    super(BaseVolumeTest, cls).setup_credentials()

      File "/home/stguser/devstack/python-tempestconf/.venv/lib/python3.12/site-packages/tempest/test.py", line 398, in setup_credentials
    manager = cls.get_client_manager(
              ^^^^^^^^^^^^^^^^^^^^^^^

      File "/home/stguser/devstack/python-tempestconf/.venv/lib/python3.12/site-packages/tempest/test.py", line 743, in get_client_manager
    creds = getattr(cred_provider, credentials_method)()
            ^^^^^^^^^^^^^^^^^^^^^^^^^^^^^^^^^^^^^^^^^^^^

      File "/home/stguser/devstack/python-tempestconf/.venv/lib/python3.12/site-packages/tempest/lib/common/dynamic_creds.py", line 473, in get_primary_creds
    return self.get_project_member_creds()
           ^^^^^^^^^^^^^^^^^^^^^^^^^^^^^^^

      File "/home/stguser/devstack/python-tempestconf/.venv/lib/python3.12/site-packages/tempest/lib/common/dynamic_creds.py", line 514, in get_project_member_creds
    return self.get_credentials(['member'], scope='project')
           ^^^^^^^^^^^^^^^^^^^^^^^^^^^^^^^^^^^^^^^^^^^^^^^^^

      File "/home/stguser/devstack/python-tempestconf/.venv/lib/python3.12/site-packages/tempest/lib/common/dynamic_creds.py", line 459, in get_credentials
    network, subnet, router = self._create_network_resources(
                              ^^^^^^^^^^^^^^^^^^^^^^^^^^^^^^^

      File "/home/stguser/devstack/python-tempestconf/.venv/lib/python3.12/site-packages/tempest/lib/common/dynamic_creds.py", line 318, in _create_network_resources
    router = self._create_router(router_name, tenant_id)
             ^^^^^^^^^^^^^^^^^^^^^^^^^^^^^^^^^^^^^^^^^^^

      File "/home/stguser/devstack/python-tempestconf/.venv/lib/python3.12/site-packages/tempest/lib/common/dynamic_creds.py", line 379, in _create_router
    resp_body = self.routers_admin_client.create_router(**kwargs)
                ^^^^^^^^^^^^^^^^^^^^^^^^^^^^^^^^^^^^^^^^^^^^^^^^^

      File "/home/stguser/devstack/python-tempestconf/.venv/lib/python3.12/site-packages/tempest/lib/services/network/routers_client.py", line 27, in create_router
    return self.create_resource(uri, post_body)
           ^^^^^^^^^^^^^^^^^^^^^^^^^^^^^^^^^^^^

      File "/home/stguser/devstack/python-tempestconf/.venv/lib/python3.12/site-packages/tempest/lib/services/network/base.py", line 62, in create_resource
    resp, body = self.post(req_uri, req_post_data)
                 ^^^^^^^^^^^^^^^^^^^^^^^^^^^^^^^^^

      File "/home/stguser/devstack/python-tempestconf/.venv/lib/python3.12/site-packages/tempest/lib/common/rest_client.py", line 314, in post
    resp_header, resp_body = self.request(
                             ^^^^^^^^^^^^^

      File "/home/stguser/devstack/python-tempestconf/.venv/lib/python3.12/site-packages/tempest/lib/common/rest_client.py", line 762, in request
    self._error_checker(resp, resp_body)

      File "/home/stguser/devstack/python-tempestconf/.venv/lib/python3.12/site-packages/tempest/lib/common/rest_client.py", line 892, in _error_checker
    raise exceptions.Conflict(resp_body, resp=resp)

    tempest.lib.exceptions.Conflict: Conflict with state of target resource
Details: {'type': 'IpAddressGenerationFailure', 'message': 'No more IP addresses available on network 0cdb1fc2-5ef2-42d1-9505-33350276d87e.', 'detail': ''}

{38} tempest.api.volume.test_volumes_list.VolumesListTestJSON.test_volumes_list_by_availability_zone [0.186951s] ... ok
{38} tempest.api.volume.test_volumes_list.VolumesListTestJSON.test_volumes_list_by_bootable [0.337333s] ... ok
{38} tempest.api.volume.test_volumes_list.VolumesListTestJSON.test_volumes_list_by_status [0.161239s] ... ok
{38} tempest.api.volume.test_volumes_list.VolumesListTestJSON.test_volumes_list_details_by_availability_zone [0.247718s] ... ok
{38} tempest.api.volume.test_volumes_list.VolumesListTestJSON.test_volumes_list_details_by_bootable [0.125095s] ... ok
{38} tempest.api.volume.test_volumes_list.VolumesListTestJSON.test_volumes_list_details_by_status [0.100394s] ... ok
{13} tempest.api.volume.admin.test_qos.QosSpecsTestJSON.test_create_delete_qos_with_front_end_consumer [3.400880s] ... ok
{13} tempest.api.volume.admin.test_qos.QosSpecsTestJSON.test_get_qos [0.030811s] ... ok
{12} tempest.api.volume.admin.test_volume_services.VolumesServicesTestJSON.test_get_service_by_volume_host_name [108.679203s] ... ok
{12} tempest.api.volume.admin.test_volume_services.VolumesServicesTestJSON.test_list_services [0.026745s] ... ok
{11} tempest.api.volume.admin.test_volume_type_access.VolumeTypesAccessTest.test_volume_type_access_add [126.808761s] ... ok
{13} tempest.api.volume.admin.test_qos.QosSpecsTestJSON.test_list_qos [1.813495s] ... ok
{13} tempest.api.volume.admin.test_qos.QosSpecsTestJSON.test_set_unset_qos_key [0.734909s] ... ok
{11} tempest.api.volume.admin.test_volume_type_access.VolumeTypesAccessTest.test_volume_type_access_list [4.955896s] ... ok
{4} tempest.api.volume.test_volume_transfers.VolumesTransfersV357Test.test_create_get_list_accept_volume_transfer [135.718872s] ... ok
{5} tempest.api.volume.test_volume_transfers.VolumesTransfersV355Test.test_create_get_list_accept_volume_transfer [137.831205s] ... ok
{6} tempest.api.volume.test_volume_transfers.VolumesTransfersTest.test_create_list_delete_volume_transfer [77.274604s] ... ok
{39} tempest.api.volume.test_volumes_snapshots_list.VolumesSnapshotListTestJSON.test_snapshot_list_param_limit [0.201920s] ... ok
{39} tempest.api.volume.test_volumes_snapshots_list.VolumesSnapshotListTestJSON.test_snapshot_list_param_limit_equals_infinite [0.407207s] ... ok
{39} tempest.api.volume.test_volumes_snapshots_list.VolumesSnapshotListTestJSON.test_snapshot_list_param_limit_equals_zero [0.038067s] ... ok
{39} tempest.api.volume.test_volumes_snapshots_list.VolumesSnapshotListTestJSON.test_snapshot_list_param_marker [0.118013s] ... ok
{39} tempest.api.volume.test_volumes_snapshots_list.VolumesSnapshotListTestJSON.test_snapshot_list_param_offset [0.043240s] ... ok
{39} tempest.api.volume.test_volumes_snapshots_list.VolumesSnapshotListTestJSON.test_snapshot_list_param_sort_created_at_asc [0.048548s] ... ok
{39} tempest.api.volume.test_volumes_snapshots_list.VolumesSnapshotListTestJSON.test_snapshot_list_param_sort_created_at_desc [0.029575s] ... ok
{39} tempest.api.volume.test_volumes_snapshots_list.VolumesSnapshotListTestJSON.test_snapshot_list_param_sort_id_asc [0.053272s] ... ok
{39} tempest.api.volume.test_volumes_snapshots_list.VolumesSnapshotListTestJSON.test_snapshot_list_param_sort_id_desc [0.037836s] ... ok
{39} tempest.api.volume.test_volumes_snapshots_list.VolumesSnapshotListTestJSON.test_snapshot_list_param_sort_name_asc [0.045243s] ... ok
{39} tempest.api.volume.test_volumes_snapshots_list.VolumesSnapshotListTestJSON.test_snapshot_list_param_sort_name_desc [0.042699s] ... ok
{39} tempest.api.volume.test_volumes_snapshots_list.VolumesSnapshotListTestJSON.test_snapshots_list_details_with_params [0.224446s] ... ok
{39} tempest.api.volume.test_volumes_snapshots_list.VolumesSnapshotListTestJSON.test_snapshots_list_with_params [0.230760s] ... ok
{15} tempest.api.volume.admin.test_snapshots_actions.SnapshotsActionsTest.test_snapshot_force_delete_when_snapshot_is_creating [41.942746s] ... ok
{0} tempest.api.volume.test_volumes_get.VolumesGetTest.test_volume_create_get_update_delete [202.603647s] ... ok
{2} tempest.api.volume.admin.test_volume_quotas.VolumeQuotasAdminTestJSON.test_quota_usage [46.463381s] ... ok
{7} tempest.api.volume.admin.test_volume_types.VolumeTypesTest.test_volume_type_update [58.338286s] ... ok
{29} tempest.api.volume.admin.test_volumes_list.VolumesListAdminTestJSON.test_volume_list_param_tenant [24.077217s] ... ok
{4} tempest.api.volume.test_volume_transfers.VolumesTransfersV357Test.test_create_list_delete_volume_transfer [34.535234s] ... ok
{5} tempest.api.volume.test_volume_transfers.VolumesTransfersV355Test.test_create_list_delete_volume_transfer [36.099355s] ... ok
{1} tempest.api.volume.test_volume_delete_cascade.VolumesDeleteCascade.test_volume_delete_cascade [217.331140s] ... ok
{3} tempest.api.volume.test_volumes_clone.VolumesCloneTest.test_create_from_volume [223.143137s] ... ok
{8} tempest.api.volume.test_volumes_negative.VolumesNegativeTest.test_attach_volumes_with_nonexistent_volume_id [116.138655s] ... ok
{8} tempest.api.volume.test_volumes_negative.VolumesNegativeTest.test_create_volume_from_deactivated_image [6.104077s] ... ok
{15} tempest.api.volume.admin.test_snapshots_actions.SnapshotsActionsTest.test_snapshot_force_delete_when_snapshot_is_deleting [31.791668s] ... ok
{8} tempest.api.volume.test_volumes_negative.VolumesNegativeTest.test_create_volume_from_image_with_decreasing_size [4.405442s] ... ok
{8} tempest.api.volume.test_volumes_negative.VolumesNegativeTest.test_create_volume_with_invalid_size [0.016299s] ... ok
{8} tempest.api.volume.test_volumes_negative.VolumesNegativeTest.test_create_volume_with_nonexistent_snapshot_id [0.116507s] ... ok
{8} tempest.api.volume.test_volumes_negative.VolumesNegativeTest.test_create_volume_with_nonexistent_source_volid [0.108958s] ... ok
{8} tempest.api.volume.test_volumes_negative.VolumesNegativeTest.test_create_volume_with_nonexistent_volume_type [0.044101s] ... ok
{8} tempest.api.volume.test_volumes_negative.VolumesNegativeTest.test_create_volume_with_size_negative [0.012683s] ... ok
{8} tempest.api.volume.test_volumes_negative.VolumesNegativeTest.test_create_volume_with_size_zero [0.027287s] ... ok
{8} tempest.api.volume.test_volumes_negative.VolumesNegativeTest.test_create_volume_without_passing_size [0.028369s] ... ok
{8} tempest.api.volume.test_volumes_negative.VolumesNegativeTest.test_delete_invalid_volume_id [0.093172s] ... ok
{8} tempest.api.volume.test_volumes_negative.VolumesNegativeTest.test_delete_volume_without_passing_volume_id [0.011402s] ... ok
{8} tempest.api.volume.test_volumes_negative.VolumesNegativeTest.test_detach_volumes_with_invalid_volume_id [0.026484s] ... ok
{8} tempest.api.volume.test_volumes_negative.VolumesNegativeTest.test_get_invalid_volume_id [0.033319s] ... ok
{8} tempest.api.volume.test_volumes_negative.VolumesNegativeTest.test_get_volume_without_passing_volume_id [0.010684s] ... ok
{8} tempest.api.volume.test_volumes_negative.VolumesNegativeTest.test_list_volumes_detail_with_invalid_status [0.223434s] ... ok
{8} tempest.api.volume.test_volumes_negative.VolumesNegativeTest.test_list_volumes_detail_with_nonexistent_name [0.047044s] ... ok
{8} tempest.api.volume.test_volumes_negative.VolumesNegativeTest.test_list_volumes_with_invalid_status [0.031564s] ... ok
{8} tempest.api.volume.test_volumes_negative.VolumesNegativeTest.test_list_volumes_with_nonexistent_name [0.067461s] ... ok
{8} tempest.api.volume.test_volumes_negative.VolumesNegativeTest.test_reserve_volume_with_negative_volume_status [1.228932s] ... ok
{8} tempest.api.volume.test_volumes_negative.VolumesNegativeTest.test_reserve_volume_with_nonexistent_volume_id [0.105413s] ... ok
{8} tempest.api.volume.test_volumes_negative.VolumesNegativeTest.test_unreserve_volume_with_nonexistent_volume_id [0.229726s] ... ok
{8} tempest.api.volume.test_volumes_negative.VolumesNegativeTest.test_update_volume_with_empty_volume_id [0.019549s] ... ok
{8} tempest.api.volume.test_volumes_negative.VolumesNegativeTest.test_update_volume_with_invalid_volume_id [0.124072s] ... ok
{8} tempest.api.volume.test_volumes_negative.VolumesNegativeTest.test_update_volume_with_nonexistent_volume_id [0.132751s] ... ok
{8} tempest.api.volume.test_volumes_negative.VolumesNegativeTest.test_volume_delete_nonexistent_volume_id [0.185377s] ... ok
{8} tempest.api.volume.test_volumes_negative.VolumesNegativeTest.test_volume_get_nonexistent_volume_id [0.110544s] ... ok
{4} setUpClass (tempest.api.volume.test_volumes_backup.VolumesBackupsV39Test) ... SKIPPED: Cinder backup feature disabled
{2} tempest.api.volume.admin.test_volume_quotas.VolumeQuotasAdminTestJSON.test_quota_usage_after_volume_transfer [35.993055s] ... ok
{2} tempest.api.volume.admin.test_volume_quotas.VolumeQuotasAdminTestJSON.test_show_quota_usage [0.893467s] ... ok
{15} tempest.api.volume.admin.test_snapshots_actions.SnapshotsActionsTest.test_snapshot_force_delete_when_snapshot_is_error [13.414764s] ... ok
{2} tempest.api.volume.admin.test_volume_quotas.VolumeQuotasAdminTestJSON.test_update_all_quota_resources_for_tenant [5.978695s] ... ok
{15} tempest.api.volume.admin.test_snapshots_actions.SnapshotsActionsTest.test_snapshot_force_delete_when_snapshot_is_error_deleting [11.318025s] ... ok
{15} tempest.api.volume.admin.test_snapshots_actions.SnapshotsActionsTest.test_update_snapshot_status [0.713782s] ... ok
{0} tempest.api.volume.test_volumes_get.VolumesGetTest.test_volume_create_get_update_delete_as_clone [61.473011s] ... ok

==============================
Failed 5 tests - output below:
==============================

tempest.api.volume.test_volume_transfers.VolumesTransfersTest.test_create_get_list_accept_volume_transfer[id-4d75b645-a478-48b1-97c8-503f64242f1a]
--------------------------------------------------------------------------------------------------------------------------------------------------

Captured traceback:
~~~~~~~~~~~~~~~~~~~
    Traceback (most recent call last):

      File "/home/stguser/devstack/python-tempestconf/.venv/lib/python3.12/site-packages/urllib3/connectionpool.py", line 534, in _make_request
    response = conn.getresponse()
               ^^^^^^^^^^^^^^^^^^

      File "/home/stguser/devstack/python-tempestconf/.venv/lib/python3.12/site-packages/urllib3/connection.py", line 565, in getresponse
    httplib_response = super().getresponse()
                       ^^^^^^^^^^^^^^^^^^^^^

      File "/usr/lib/python3.12/http/client.py", line 1428, in getresponse
    response.begin()

      File "/usr/lib/python3.12/http/client.py", line 331, in begin
    version, status, reason = self._read_status()
                              ^^^^^^^^^^^^^^^^^^^

      File "/usr/lib/python3.12/http/client.py", line 292, in _read_status
    line = str(self.fp.readline(_MAXLINE + 1), "iso-8859-1")
               ^^^^^^^^^^^^^^^^^^^^^^^^^^^^^^

      File "/usr/lib/python3.12/socket.py", line 707, in readinto
    return self._sock.recv_into(b)
           ^^^^^^^^^^^^^^^^^^^^^^^

    TimeoutError: timed out

    
The above exception was the direct cause of the following exception:


    Traceback (most recent call last):

      File "/home/stguser/devstack/python-tempestconf/.venv/lib/python3.12/site-packages/tempest/api/volume/test_volume_transfers.py", line 40, in test_create_get_list_accept_volume_transfer
    volume = self.create_volume()
             ^^^^^^^^^^^^^^^^^^^^

      File "/home/stguser/devstack/python-tempestconf/.venv/lib/python3.12/site-packages/tempest/api/volume/base.py", line 139, in create_volume
    volume = self.volumes_client.create_volume(**kwargs)['volume']
             ^^^^^^^^^^^^^^^^^^^^^^^^^^^^^^^^^^^^^^^^^^^

      File "/home/stguser/devstack/python-tempestconf/.venv/lib/python3.12/site-packages/tempest/lib/services/volume/v3/volumes_client.py", line 116, in create_volume
    resp, body = self.post('volumes', post_body)
                 ^^^^^^^^^^^^^^^^^^^^^^^^^^^^^^^

      File "/home/stguser/devstack/python-tempestconf/.venv/lib/python3.12/site-packages/tempest/lib/common/rest_client.py", line 314, in post
    resp_header, resp_body = self.request(
                             ^^^^^^^^^^^^^

      File "/home/stguser/devstack/python-tempestconf/.venv/lib/python3.12/site-packages/tempest/lib/services/volume/base_client.py", line 39, in request
    resp, resp_body = super(BaseClient, self).request(
                      ^^^^^^^^^^^^^^^^^^^^^^^^^^^^^^^^

      File "/home/stguser/devstack/python-tempestconf/.venv/lib/python3.12/site-packages/tempest/lib/common/rest_client.py", line 746, in request
    resp, resp_body = self._request(method, url, headers=headers,
                      ^^^^^^^^^^^^^^^^^^^^^^^^^^^^^^^^^^^^^^^^^^^

      File "/home/stguser/devstack/python-tempestconf/.venv/lib/python3.12/site-packages/tempest/lib/common/rest_client.py", line 612, in _request
    resp, resp_body = self.raw_request(
                      ^^^^^^^^^^^^^^^^^

      File "/home/stguser/devstack/python-tempestconf/.venv/lib/python3.12/site-packages/tempest/lib/common/rest_client.py", line 661, in raw_request
    resp, resp_body = self.http_obj.request(
                      ^^^^^^^^^^^^^^^^^^^^^^

      File "/home/stguser/devstack/python-tempestconf/.venv/lib/python3.12/site-packages/tempest/lib/common/http.py", line 123, in request
    r = super(ClosingHttp, self).request(method, url, retries=retry,
        ^^^^^^^^^^^^^^^^^^^^^^^^^^^^^^^^^^^^^^^^^^^^^^^^^^^^^^^^^^^^

      File "/home/stguser/devstack/python-tempestconf/.venv/lib/python3.12/site-packages/urllib3/_request_methods.py", line 143, in request
    return self.request_encode_body(
           ^^^^^^^^^^^^^^^^^^^^^^^^^

      File "/home/stguser/devstack/python-tempestconf/.venv/lib/python3.12/site-packages/urllib3/_request_methods.py", line 278, in request_encode_body
    return self.urlopen(method, url, **extra_kw)
           ^^^^^^^^^^^^^^^^^^^^^^^^^^^^^^^^^^^^^

      File "/home/stguser/devstack/python-tempestconf/.venv/lib/python3.12/site-packages/urllib3/poolmanager.py", line 459, in urlopen
    response = conn.urlopen(method, u.request_uri, **kw)
               ^^^^^^^^^^^^^^^^^^^^^^^^^^^^^^^^^^^^^^^^^

      File "/home/stguser/devstack/python-tempestconf/.venv/lib/python3.12/site-packages/urllib3/connectionpool.py", line 841, in urlopen
    retries = retries.increment(
              ^^^^^^^^^^^^^^^^^^

      File "/home/stguser/devstack/python-tempestconf/.venv/lib/python3.12/site-packages/urllib3/util/retry.py", line 474, in increment
    raise reraise(type(error), error, _stacktrace)
          ^^^^^^^^^^^^^^^^^^^^^^^^^^^^^^^^^^^^^^^^

      File "/home/stguser/devstack/python-tempestconf/.venv/lib/python3.12/site-packages/urllib3/util/util.py", line 39, in reraise
    raise value

      File "/home/stguser/devstack/python-tempestconf/.venv/lib/python3.12/site-packages/urllib3/connectionpool.py", line 787, in urlopen
    response = self._make_request(
               ^^^^^^^^^^^^^^^^^^^

      File "/home/stguser/devstack/python-tempestconf/.venv/lib/python3.12/site-packages/urllib3/connectionpool.py", line 536, in _make_request
    self._raise_timeout(err=e, url=url, timeout_value=read_timeout)

      File "/home/stguser/devstack/python-tempestconf/.venv/lib/python3.12/site-packages/urllib3/connectionpool.py", line 367, in _raise_timeout
    raise ReadTimeoutError(

    urllib3.exceptions.ReadTimeoutError: HTTPConnectionPool(host='9.180.170.14', port=80): Read timed out. (read timeout=60)


setUpClass (tempest.api.volume.test_volumes_actions.VolumesActionsTest)
-----------------------------------------------------------------------

Captured traceback:
~~~~~~~~~~~~~~~~~~~
    Traceback (most recent call last):

      File "/home/stguser/devstack/python-tempestconf/.venv/lib/python3.12/site-packages/urllib3/connectionpool.py", line 534, in _make_request
    response = conn.getresponse()
               ^^^^^^^^^^^^^^^^^^

      File "/home/stguser/devstack/python-tempestconf/.venv/lib/python3.12/site-packages/urllib3/connection.py", line 565, in getresponse
    httplib_response = super().getresponse()
                       ^^^^^^^^^^^^^^^^^^^^^

      File "/usr/lib/python3.12/http/client.py", line 1428, in getresponse
    response.begin()

      File "/usr/lib/python3.12/http/client.py", line 331, in begin
    version, status, reason = self._read_status()
                              ^^^^^^^^^^^^^^^^^^^

      File "/usr/lib/python3.12/http/client.py", line 292, in _read_status
    line = str(self.fp.readline(_MAXLINE + 1), "iso-8859-1")
               ^^^^^^^^^^^^^^^^^^^^^^^^^^^^^^

      File "/usr/lib/python3.12/socket.py", line 707, in readinto
    return self._sock.recv_into(b)
           ^^^^^^^^^^^^^^^^^^^^^^^

    TimeoutError: timed out

    
The above exception was the direct cause of the following exception:


    Traceback (most recent call last):

      File "/home/stguser/devstack/python-tempestconf/.venv/lib/python3.12/site-packages/tempest/test.py", line 185, in setUpClass
    raise value.with_traceback(trace)

      File "/home/stguser/devstack/python-tempestconf/.venv/lib/python3.12/site-packages/tempest/test.py", line 170, in setUpClass
    cls.setup_credentials()

      File "/home/stguser/devstack/python-tempestconf/.venv/lib/python3.12/site-packages/tempest/api/volume/base.py", line 62, in setup_credentials
    super(BaseVolumeTest, cls).setup_credentials()

      File "/home/stguser/devstack/python-tempestconf/.venv/lib/python3.12/site-packages/tempest/test.py", line 398, in setup_credentials
    manager = cls.get_client_manager(
              ^^^^^^^^^^^^^^^^^^^^^^^

      File "/home/stguser/devstack/python-tempestconf/.venv/lib/python3.12/site-packages/tempest/test.py", line 743, in get_client_manager
    creds = getattr(cred_provider, credentials_method)()
            ^^^^^^^^^^^^^^^^^^^^^^^^^^^^^^^^^^^^^^^^^^^^

      File "/home/stguser/devstack/python-tempestconf/.venv/lib/python3.12/site-packages/tempest/lib/common/dynamic_creds.py", line 473, in get_primary_creds
    return self.get_project_member_creds()
           ^^^^^^^^^^^^^^^^^^^^^^^^^^^^^^^

      File "/home/stguser/devstack/python-tempestconf/.venv/lib/python3.12/site-packages/tempest/lib/common/dynamic_creds.py", line 514, in get_project_member_creds
    return self.get_credentials(['member'], scope='project')
           ^^^^^^^^^^^^^^^^^^^^^^^^^^^^^^^^^^^^^^^^^^^^^^^^^

      File "/home/stguser/devstack/python-tempestconf/.venv/lib/python3.12/site-packages/tempest/lib/common/dynamic_creds.py", line 459, in get_credentials
    network, subnet, router = self._create_network_resources(
                              ^^^^^^^^^^^^^^^^^^^^^^^^^^^^^^^

      File "/home/stguser/devstack/python-tempestconf/.venv/lib/python3.12/site-packages/tempest/lib/common/dynamic_creds.py", line 310, in _create_network_resources
    network = self._create_network(network_name, tenant_id)
              ^^^^^^^^^^^^^^^^^^^^^^^^^^^^^^^^^^^^^^^^^^^^^

      File "/home/stguser/devstack/python-tempestconf/.venv/lib/python3.12/site-packages/tempest/lib/common/dynamic_creds.py", line 338, in _create_network
    resp_body = self.networks_admin_client.create_network(
                ^^^^^^^^^^^^^^^^^^^^^^^^^^^^^^^^^^^^^^^^^^

      File "/home/stguser/devstack/python-tempestconf/.venv/lib/python3.12/site-packages/tempest/lib/services/network/networks_client.py", line 27, in create_network
    return self.create_resource(uri, post_data)
           ^^^^^^^^^^^^^^^^^^^^^^^^^^^^^^^^^^^^

      File "/home/stguser/devstack/python-tempestconf/.venv/lib/python3.12/site-packages/tempest/lib/services/network/base.py", line 62, in create_resource
    resp, body = self.post(req_uri, req_post_data)
                 ^^^^^^^^^^^^^^^^^^^^^^^^^^^^^^^^^

      File "/home/stguser/devstack/python-tempestconf/.venv/lib/python3.12/site-packages/tempest/lib/common/rest_client.py", line 314, in post
    resp_header, resp_body = self.request(
                             ^^^^^^^^^^^^^

      File "/home/stguser/devstack/python-tempestconf/.venv/lib/python3.12/site-packages/tempest/lib/common/rest_client.py", line 746, in request
    resp, resp_body = self._request(method, url, headers=headers,
                      ^^^^^^^^^^^^^^^^^^^^^^^^^^^^^^^^^^^^^^^^^^^

      File "/home/stguser/devstack/python-tempestconf/.venv/lib/python3.12/site-packages/tempest/lib/common/rest_client.py", line 612, in _request
    resp, resp_body = self.raw_request(
                      ^^^^^^^^^^^^^^^^^

      File "/home/stguser/devstack/python-tempestconf/.venv/lib/python3.12/site-packages/tempest/lib/common/rest_client.py", line 661, in raw_request
    resp, resp_body = self.http_obj.request(
                      ^^^^^^^^^^^^^^^^^^^^^^

      File "/home/stguser/devstack/python-tempestconf/.venv/lib/python3.12/site-packages/tempest/lib/common/http.py", line 123, in request
    r = super(ClosingHttp, self).request(method, url, retries=retry,
        ^^^^^^^^^^^^^^^^^^^^^^^^^^^^^^^^^^^^^^^^^^^^^^^^^^^^^^^^^^^^

      File "/home/stguser/devstack/python-tempestconf/.venv/lib/python3.12/site-packages/urllib3/_request_methods.py", line 143, in request
    return self.request_encode_body(
           ^^^^^^^^^^^^^^^^^^^^^^^^^

      File "/home/stguser/devstack/python-tempestconf/.venv/lib/python3.12/site-packages/urllib3/_request_methods.py", line 278, in request_encode_body
    return self.urlopen(method, url, **extra_kw)
           ^^^^^^^^^^^^^^^^^^^^^^^^^^^^^^^^^^^^^

      File "/home/stguser/devstack/python-tempestconf/.venv/lib/python3.12/site-packages/urllib3/poolmanager.py", line 459, in urlopen
    response = conn.urlopen(method, u.request_uri, **kw)
               ^^^^^^^^^^^^^^^^^^^^^^^^^^^^^^^^^^^^^^^^^

      File "/home/stguser/devstack/python-tempestconf/.venv/lib/python3.12/site-packages/urllib3/connectionpool.py", line 841, in urlopen
    retries = retries.increment(
              ^^^^^^^^^^^^^^^^^^

      File "/home/stguser/devstack/python-tempestconf/.venv/lib/python3.12/site-packages/urllib3/util/retry.py", line 474, in increment
    raise reraise(type(error), error, _stacktrace)
          ^^^^^^^^^^^^^^^^^^^^^^^^^^^^^^^^^^^^^^^^

      File "/home/stguser/devstack/python-tempestconf/.venv/lib/python3.12/site-packages/urllib3/util/util.py", line 39, in reraise
    raise value

      File "/home/stguser/devstack/python-tempestconf/.venv/lib/python3.12/site-packages/urllib3/connectionpool.py", line 787, in urlopen
    response = self._make_request(
               ^^^^^^^^^^^^^^^^^^^

      File "/home/stguser/devstack/python-tempestconf/.venv/lib/python3.12/site-packages/urllib3/connectionpool.py", line 536, in _make_request
    self._raise_timeout(err=e, url=url, timeout_value=read_timeout)

      File "/home/stguser/devstack/python-tempestconf/.venv/lib/python3.12/site-packages/urllib3/connectionpool.py", line 367, in _raise_timeout
    raise ReadTimeoutError(

    urllib3.exceptions.ReadTimeoutError: HTTPConnectionPool(host='9.180.170.14', port=9696): Read timed out. (read timeout=60)


setUpClass (tempest.api.volume.admin.test_volumes_actions.VolumesActionsTest)
-----------------------------------------------------------------------------

Captured traceback:
~~~~~~~~~~~~~~~~~~~
    Traceback (most recent call last):

      File "/home/stguser/devstack/python-tempestconf/.venv/lib/python3.12/site-packages/tempest/test.py", line 185, in setUpClass
    raise value.with_traceback(trace)

      File "/home/stguser/devstack/python-tempestconf/.venv/lib/python3.12/site-packages/tempest/test.py", line 170, in setUpClass
    cls.setup_credentials()

      File "/home/stguser/devstack/python-tempestconf/.venv/lib/python3.12/site-packages/tempest/api/volume/base.py", line 62, in setup_credentials
    super(BaseVolumeTest, cls).setup_credentials()

      File "/home/stguser/devstack/python-tempestconf/.venv/lib/python3.12/site-packages/tempest/test.py", line 398, in setup_credentials
    manager = cls.get_client_manager(
              ^^^^^^^^^^^^^^^^^^^^^^^

      File "/home/stguser/devstack/python-tempestconf/.venv/lib/python3.12/site-packages/tempest/test.py", line 743, in get_client_manager
    creds = getattr(cred_provider, credentials_method)()
            ^^^^^^^^^^^^^^^^^^^^^^^^^^^^^^^^^^^^^^^^^^^^

      File "/home/stguser/devstack/python-tempestconf/.venv/lib/python3.12/site-packages/tempest/lib/common/dynamic_creds.py", line 473, in get_primary_creds
    return self.get_project_member_creds()
           ^^^^^^^^^^^^^^^^^^^^^^^^^^^^^^^

      File "/home/stguser/devstack/python-tempestconf/.venv/lib/python3.12/site-packages/tempest/lib/common/dynamic_creds.py", line 514, in get_project_member_creds
    return self.get_credentials(['member'], scope='project')
           ^^^^^^^^^^^^^^^^^^^^^^^^^^^^^^^^^^^^^^^^^^^^^^^^^

      File "/home/stguser/devstack/python-tempestconf/.venv/lib/python3.12/site-packages/tempest/lib/common/dynamic_creds.py", line 459, in get_credentials
    network, subnet, router = self._create_network_resources(
                              ^^^^^^^^^^^^^^^^^^^^^^^^^^^^^^^

      File "/home/stguser/devstack/python-tempestconf/.venv/lib/python3.12/site-packages/tempest/lib/common/dynamic_creds.py", line 318, in _create_network_resources
    router = self._create_router(router_name, tenant_id)
             ^^^^^^^^^^^^^^^^^^^^^^^^^^^^^^^^^^^^^^^^^^^

      File "/home/stguser/devstack/python-tempestconf/.venv/lib/python3.12/site-packages/tempest/lib/common/dynamic_creds.py", line 379, in _create_router
    resp_body = self.routers_admin_client.create_router(**kwargs)
                ^^^^^^^^^^^^^^^^^^^^^^^^^^^^^^^^^^^^^^^^^^^^^^^^^

      File "/home/stguser/devstack/python-tempestconf/.venv/lib/python3.12/site-packages/tempest/lib/services/network/routers_client.py", line 27, in create_router
    return self.create_resource(uri, post_body)
           ^^^^^^^^^^^^^^^^^^^^^^^^^^^^^^^^^^^^

      File "/home/stguser/devstack/python-tempestconf/.venv/lib/python3.12/site-packages/tempest/lib/services/network/base.py", line 62, in create_resource
    resp, body = self.post(req_uri, req_post_data)
                 ^^^^^^^^^^^^^^^^^^^^^^^^^^^^^^^^^

      File "/home/stguser/devstack/python-tempestconf/.venv/lib/python3.12/site-packages/tempest/lib/common/rest_client.py", line 314, in post
    resp_header, resp_body = self.request(
                             ^^^^^^^^^^^^^

      File "/home/stguser/devstack/python-tempestconf/.venv/lib/python3.12/site-packages/tempest/lib/common/rest_client.py", line 762, in request
    self._error_checker(resp, resp_body)

      File "/home/stguser/devstack/python-tempestconf/.venv/lib/python3.12/site-packages/tempest/lib/common/rest_client.py", line 892, in _error_checker
    raise exceptions.Conflict(resp_body, resp=resp)

    tempest.lib.exceptions.Conflict: Conflict with state of target resource
Details: {'type': 'IpAddressGenerationFailure', 'message': 'No more IP addresses available on network 0cdb1fc2-5ef2-42d1-9505-33350276d87e.', 'detail': ''}


setUpClass (tempest.api.volume.admin.test_volume_retype.VolumeRetypeWithoutMigrationTest)
-----------------------------------------------------------------------------------------

Captured traceback:
~~~~~~~~~~~~~~~~~~~
    Traceback (most recent call last):

      File "/home/stguser/devstack/python-tempestconf/.venv/lib/python3.12/site-packages/tempest/test.py", line 185, in setUpClass
    raise value.with_traceback(trace)

      File "/home/stguser/devstack/python-tempestconf/.venv/lib/python3.12/site-packages/tempest/test.py", line 178, in setUpClass
    cls.resource_setup()

      File "/home/stguser/devstack/python-tempestconf/.venv/lib/python3.12/site-packages/tempest/api/volume/admin/test_volume_retype.py", line 172, in resource_setup
    cls.src_vol_type = cls.create_volume_type('volume-type-1')
                       ^^^^^^^^^^^^^^^^^^^^^^^^^^^^^^^^^^^^^^^

      File "/home/stguser/devstack/python-tempestconf/.venv/lib/python3.12/site-packages/tempest/api/volume/base.py", line 366, in create_volume_type
    volume_type = self.admin_volume_types_client.create_volume_type(
                  ^^^^^^^^^^^^^^^^^^^^^^^^^^^^^^^^^^^^^^^^^^^^^^^^^^

      File "/home/stguser/devstack/python-tempestconf/.venv/lib/python3.12/site-packages/tempest/lib/services/volume/v3/types_client.py", line 90, in create_volume_type
    resp, body = self.post('types', post_body)
                 ^^^^^^^^^^^^^^^^^^^^^^^^^^^^^

      File "/home/stguser/devstack/python-tempestconf/.venv/lib/python3.12/site-packages/tempest/lib/common/rest_client.py", line 314, in post
    resp_header, resp_body = self.request(
                             ^^^^^^^^^^^^^

      File "/home/stguser/devstack/python-tempestconf/.venv/lib/python3.12/site-packages/tempest/lib/common/rest_client.py", line 762, in request
    self._error_checker(resp, resp_body)

      File "/home/stguser/devstack/python-tempestconf/.venv/lib/python3.12/site-packages/tempest/lib/common/rest_client.py", line 892, in _error_checker
    raise exceptions.Conflict(resp_body, resp=resp)

    tempest.lib.exceptions.Conflict: Conflict with state of target resource
Details: {'code': 409, 'message': 'Volume Type volume-type-1 already exists.'}


setUpClass (tempest.api.volume.test_volumes_snapshots.VolumesSnapshotTestJSON)
------------------------------------------------------------------------------

Captured traceback:
~~~~~~~~~~~~~~~~~~~
    Traceback (most recent call last):

      File "/home/stguser/devstack/python-tempestconf/.venv/lib/python3.12/site-packages/tempest/test.py", line 185, in setUpClass
    raise value.with_traceback(trace)

      File "/home/stguser/devstack/python-tempestconf/.venv/lib/python3.12/site-packages/tempest/test.py", line 170, in setUpClass
    cls.setup_credentials()

      File "/home/stguser/devstack/python-tempestconf/.venv/lib/python3.12/site-packages/tempest/api/volume/base.py", line 62, in setup_credentials
    super(BaseVolumeTest, cls).setup_credentials()

      File "/home/stguser/devstack/python-tempestconf/.venv/lib/python3.12/site-packages/tempest/test.py", line 398, in setup_credentials
    manager = cls.get_client_manager(
              ^^^^^^^^^^^^^^^^^^^^^^^

      File "/home/stguser/devstack/python-tempestconf/.venv/lib/python3.12/site-packages/tempest/test.py", line 743, in get_client_manager
    creds = getattr(cred_provider, credentials_method)()
            ^^^^^^^^^^^^^^^^^^^^^^^^^^^^^^^^^^^^^^^^^^^^

      File "/home/stguser/devstack/python-tempestconf/.venv/lib/python3.12/site-packages/tempest/lib/common/dynamic_creds.py", line 473, in get_primary_creds
    return self.get_project_member_creds()
           ^^^^^^^^^^^^^^^^^^^^^^^^^^^^^^^

      File "/home/stguser/devstack/python-tempestconf/.venv/lib/python3.12/site-packages/tempest/lib/common/dynamic_creds.py", line 514, in get_project_member_creds
    return self.get_credentials(['member'], scope='project')
           ^^^^^^^^^^^^^^^^^^^^^^^^^^^^^^^^^^^^^^^^^^^^^^^^^

      File "/home/stguser/devstack/python-tempestconf/.venv/lib/python3.12/site-packages/tempest/lib/common/dynamic_creds.py", line 459, in get_credentials
    network, subnet, router = self._create_network_resources(
                              ^^^^^^^^^^^^^^^^^^^^^^^^^^^^^^^

      File "/home/stguser/devstack/python-tempestconf/.venv/lib/python3.12/site-packages/tempest/lib/common/dynamic_creds.py", line 318, in _create_network_resources
    router = self._create_router(router_name, tenant_id)
             ^^^^^^^^^^^^^^^^^^^^^^^^^^^^^^^^^^^^^^^^^^^

      File "/home/stguser/devstack/python-tempestconf/.venv/lib/python3.12/site-packages/tempest/lib/common/dynamic_creds.py", line 379, in _create_router
    resp_body = self.routers_admin_client.create_router(**kwargs)
                ^^^^^^^^^^^^^^^^^^^^^^^^^^^^^^^^^^^^^^^^^^^^^^^^^

      File "/home/stguser/devstack/python-tempestconf/.venv/lib/python3.12/site-packages/tempest/lib/services/network/routers_client.py", line 27, in create_router
    return self.create_resource(uri, post_body)
           ^^^^^^^^^^^^^^^^^^^^^^^^^^^^^^^^^^^^

      File "/home/stguser/devstack/python-tempestconf/.venv/lib/python3.12/site-packages/tempest/lib/services/network/base.py", line 62, in create_resource
    resp, body = self.post(req_uri, req_post_data)
                 ^^^^^^^^^^^^^^^^^^^^^^^^^^^^^^^^^

      File "/home/stguser/devstack/python-tempestconf/.venv/lib/python3.12/site-packages/tempest/lib/common/rest_client.py", line 314, in post
    resp_header, resp_body = self.request(
                             ^^^^^^^^^^^^^

      File "/home/stguser/devstack/python-tempestconf/.venv/lib/python3.12/site-packages/tempest/lib/common/rest_client.py", line 762, in request
    self._error_checker(resp, resp_body)

      File "/home/stguser/devstack/python-tempestconf/.venv/lib/python3.12/site-packages/tempest/lib/common/rest_client.py", line 892, in _error_checker
    raise exceptions.Conflict(resp_body, resp=resp)

    tempest.lib.exceptions.Conflict: Conflict with state of target resource
Details: {'type': 'IpAddressGenerationFailure', 'message': 'No more IP addresses available on network 0cdb1fc2-5ef2-42d1-9505-33350276d87e.', 'detail': ''}



======
Totals
======
Ran: 166 tests in 267.1886 sec.
 - Passed: 155
 - Skipped: 6
 - Expected Fail: 0
 - Unexpected Success: 0
 - Failed: 5
Sum of execute time for each test: 3092.5905 sec.

==============
Worker Balance
==============
 - Worker 0 (3 tests) => 0:04:26.904654
 - Worker 1 (2 tests) => 0:03:42.592783
 - Worker 2 (8 tests) => 0:04:08.896362
 - Worker 3 (2 tests) => 0:03:45.909522
 - Worker 4 (3 tests) => 0:03:11.618374
 - Worker 5 (3 tests) => 0:03:40.474832
 - Worker 6 (2 tests) => 0:02:17.361147
 - Worker 7 (4 tests) => 0:02:50.252239
 - Worker 8 (27 tests) => 0:02:09.727629
 - Worker 9 (2 tests) => 0:02:13.801722
 - Worker 10 (1 tests) => 0:02:09.255338
 - Worker 11 (2 tests) => 0:02:11.795371
 - Worker 12 (5 tests) => 0:02:10.057158
 - Worker 13 (7 tests) => 0:01:50.764594
 - Worker 14 (2 tests) => 0:01:39.616719
 - Worker 15 (6 tests) => 0:01:40.929759
 - Worker 16 (6 tests) => 0:01:23.835940
 - Worker 17 (3 tests) => 0:01:33.032534
 - Worker 18 (12 tests) => 0:00:40.809239
 - Worker 19 (2 tests) => 0:01:15.344047
 - Worker 20 (1 tests) => 0:00:00
 - Worker 21 (2 tests) => 0:00:33.845642
 - Worker 22 (1 tests) => 0:00:00
 - Worker 23 (1 tests) => 0:00:00
 - Worker 24 (5 tests) => 0:00:25.045277
 - Worker 25 (1 tests) => 0:00:00
 - Worker 26 (2 tests) => 0:00:20.167135
 - Worker 27 (2 tests) => 0:00:39.790379
 - Worker 28 (2 tests) => 0:00:09.278998
 - Worker 29 (1 tests) => 0:00:24.077217
 - Worker 30 (2 tests) => 0:00:11.915880
 - Worker 31 (2 tests) => 0:00:15.743080
 - Worker 32 (5 tests) => 0:00:20.440060
 - Worker 33 (1 tests) => 0:00:16.718504
 - Worker 34 (1 tests) => 0:00:21.942126
 - Worker 35 (1 tests) => 0:00:18.880540
 - Worker 36 (2 tests) => 0:00:06.973156
 - Worker 37 (1 tests) => 0:00:06.585303
 - Worker 38 (18 tests) => 0:00:06.264134
 - Worker 39 (13 tests) => 0:00:01.544808
